Workbook
Name BdgtYear: [1]index!$L$8
Name Description: "P_A_C_Ex"
Name List_Smry_0: CapitalListA!#REF!
Name List_Smry_0: CapitalListC!#REF!
Name List_Smry_0: RevenueListA!#REF!
Name List_Smry_0: RevenueListC!#REF!
Name List_Smry_1: CapitalListA!#REF!
Name List_Smry_1: CapitalListC!#REF!
Name List_Smry_1: RevenueListA!#REF!
Name List_Smry_1: RevenueListC!#REF!
Name List_Smry_2: CapitalListA!#REF!
Name List_Smry_2: CapitalListC!#REF!
Name List_Smry_2: RevenueListA!#REF!
Name List_Smry_2: RevenueListC!#REF!
Name P_A_A03: RevenueIncomeA!$A$7:$N$494
Name P_A_A05: RevenueExpenditureA!$A$4:$H$1582
Name P_A_A10: [1]A10!$A$2:$N$36,[1]A10!$H$43:$N$75
Name P_A_A12: CapitalExpenditureA!$A$10:$O$426
Name P_A_A14: LandAcquisition!$A$5:$E$384
Name P_A_A15: SpecialFund!$A$10:$O$127
Name P_A_A16: 'DPDC-Machinery-Tree'!$A$7:$H$169
Name P_A_APP: #REF!
Name P_A_APP: #REF!
Name P_A_APP: #REF!
Name P_A_APP: #REF!
Name P_A_Bdgt: CapitalExpenditureC!$A$10:$O$74
Name P_A_Bdgt: 'DPDC-Machinery-Tree'!$A$7:$H$169
Name P_A_Bdgt: LandAcquisition!$A$5:$E$384
Name P_A_Bdgt: RevenueExpenditureC!$A$4:$H$342
Name P_A_Bdgt: RevenueIncomeA!$A$7:$N$494
Name P_A_Bdgt: SpecialFund!$A$10:$O$127
Name P_A_Bdgt: WO_Work16!$A$4:$R$153
Name P_A_C02: RevenueInconeC!$A$7:$N$60
Name P_A_C03: RevenueExpenditureC!$A$4:$H$342
Name P_A_C07: CapitalExpenditureC!$A$10:$O$74
Name P_A_Fnl_Rec: #REF!
Name P_A_Fnl_Rec: #REF!
Name P_A_Fnl_Rec: #REF!
Name P_A_Fnl_Rec: #REF!
Name P_A_jnnurm: JNNURM!$A$1:$H$62
Name P_A_ListA: CapitalListA!$A$1:$G$4689
Name P_A_ListA: CapitalListC!$A$1:$G$1
Name P_A_ListA: RevenueListA!$A$1:$G$852
Name P_A_ListA: RevenueListC!$A$1:$G$1
Name P_A_ListC: CapitalListA!#REF!
Name P_A_ListC: CapitalListC!$A$2:$G$1125
Name P_A_ListC: RevenueListA!#REF!
Name P_A_ListC: RevenueListC!$A$2:$G$289
Name P_A_MC_Mar: [1]doller!$B$8:$AI$60,[1]doller!$AK$62:$BB$117,[1]doller!$BM$157:$BP$211
Name P_A_Octroi: #REF!
Name P_A_Octroi: #REF!
Name P_A_Octroi: #REF!
Name P_A_Octroi: #REF!
Name P_A_SC_Mar: [1]doller!$B$8:$AI$60,[1]doller!$AK$62:$BB$117,[1]doller!$BQ$157:$BT$211
Name P_A_SMRY: #REF!
Name P_A_SMRY: #REF!
Name P_A_SMRY: #REF!
Name P_A_SMRY: #REF!
Name P_A_Smry: SpecialFund!$A$118:$O$127
Name P_A_SMRY: #REF!

Sheet RevenueIncomeA
A1: जमेचा | G1: तपशील
A2: विवरण | C2: नक्की आकडा | H2: 2015-16 वर्षाचा अंदाज | J2: 2016-17 वर्षाचा अंदाज | M2: 2015-16 वर्षाच्या मान्य अंदाजाशी तुलना केलेला 2016-17 वर्षाचा मा. स्थायी समितीने मान्यता दिलेला अंदाज
C3: 2012-13 | D3: 2013-14 | E3: 2014-15 | F3: 2014-15 शेवटची सहामाही | G3: 2015-16 पहिली सहामाही | H3: मान्य अंदाज | I3: दुरूस्त अंदाज | J3: मा. महापालिका आयुक्त यांनी सुचविलेला | K3: मा. स्थायी समितीने मान्यता दिलेला | L3: मा. महानगर- पालिकेने संमत केलेला
M5: अधिक | N5: कमी
A7: अधिनियमाप्रमाणे कमीत कमी रोख शिल्लक ठेवण्याची रक्कम जमेस धरून वर्षारंभीची शिल्लक | B7: 0 | C7: 100000 | D7: 100000 | E7: 100000 | H7: 100000 | I7: 100000 | J7: 100000 | K7: 100000 | L7: 0 | M7: 0 | N7: 0
A8: १. सर्वसाधारण कर, अप्रत्यक्ष कर व इतर जमा | C8: 0 | D8: 0 | E8: 0 | F8: 0 | G8: 0 | H8: 0 | I8: 0 | J8: 0 | K8: 0 | L8: 0 | M8: 0 | N8: 0
A9: क. सर्वसाधारण पट्टी | C9: 0 | D9: 0 | E9: 0 | F9: 0 | G9: 0 | H9: 0 | I9: 0 | J9: 0 | K9: 0 | L9: 0 | M9: 0 | N9: 0
A10: १. नागरिकांकडून (कआकसंप्र) | B10: RI11A101 | C10: 2087844636 | D10: 2360443372 | E10: 2428110703 | F10: 7.8282367e+08 | G10: 1.8942875e+09 | H10: 4023900000 | I10: 4023900000 | J10: 3762500000 | K10: 6262500000 | L10: 0 | M10: 2238600000 | N10: 0
A11: २. राज्य सरकारकडून (कआकसंप्र) | B11: RI11A102 | C11: 20349693 | D11: 41256357 | E11: 52267173 | F11: 28099903 | G11: 86413676 | H11: 40000000 | I11: 40000000 | J11: 50000000 | K11: 50000000 | L11: 0 | M11: 10000000 | N11: 0
A12: ३. मध्यवर्ती शासनाकडून करांऐवजी येणारे सहाय्य (कआकसंप्र) | B12: RI11A103 | C12: 17004572 | D12: 36225809 | E12: 32670437 | F12: 6538432 | G12: 39580798 | H12: 40000000 | I12: 40000000 | J12: 50000000 | K12: 50000000 | L12: 0 | M12: 10000000 | N12: 0
A13: ४. पुणे वाहन व्यवहार खात्याकडील मिळकतींवरील कर (कआकसंप्र) | B13: RI11A104 | C13: 3117563 | D13: 5931633 | E13: 8123432 | F13: 796153 | G13: 7030308 | H13: 10000000 | I13: 10000000 | J13: 10000000 | K13: 10000000 | L13: 0 | M13: 0 | N13: 0
C14: 0 | D14: 0 | E14: 0 | F14: 0 | G14: 0 | H14: 0 | I14: 0 | J14: 0 | K14: 0 | L14: 0 | M14: 0 | N14: 0
A15: क. सर्वसाधारण पट्टी बेरीज | C15: 2128316464 | D15: 2443857171 | E15: 2521171745 | F15: 8.1825815e+08 | G15: 2.0273122e+09 | H15: 4113900000 | I15: 4113900000 | J15: 3872500000 | K15: 6372500000 | L15: 0 | M15: 2258600000 | N15: 0
C16: 0 | D16: 0 | E16: 0 | F16: 0 | G16: 0 | H16: 0 | I16: 0 | J16: 0 | K16: 0 | L16: 0 | M16: 0 | N16: 0
A17: ख. आयातकर | C17: 0 | D17: 0 | E17: 0 | F17: 0 | G17: 0 | H17: 0 | I17: 0 | J17: 0 | K17: 0 | L17: 0 | M17: 0 | N17: 0
A18: १. पक्की जमा (आ.क.प्र.) | B18: RI11B101 | C18: 12374676100 | D18: 153877910 | E18: 87959085 | F18: 101193615 | G18: 0 | H18: 0 | I18: 0 | J18: 0 | K18: 0 | L18: 0 | M18: 0 | N18: 0
A19: २. निर्गत रिफंडमधील १० टक्के हिस्सा (आ.क.प्र.) | B19: RI11B102 | C19: 97737490 | D19: 58164061 | E19: 0 | F19: 0 | G19: 0 | H19: 0 | I19: 0 | J19: 0 | K19: 0 | L19: 0 | M19: 0 | N19: 0
A20: ३. प्रलंबित असलेल्या करवाढीपोटी येणारे उत्पन्न | B20: RI11B108 | C20: 48481 | D20: 80 | E20: 0 | F20: 0 | G20: 0 | H20: 0 | I20: 0 | J20: 0 | K20: 0 | L20: 0 | M20: 0 | N20: 0
C21: 0 | D21: 0 | E21: 0 | F21: 0 | G21: 0 | H21: 0 | I21: 0 | J21: 0 | K21: 0 | L21: 0 | M21: 0 | N21: 0
A22: बेरीज | C22: 12472462071 | D22: 212042051 | E22: 87959085 | F22: 101193615 | G22: 0 | H22: 0 | I22: 0 | J22: 0 | K22: 0 | L22: 0 | M22: 0 | N22: 0
C23: 0 | D23: 0 | E23: 0 | F23: 0 | G23: 0 | H23: 0 | I23: 0 | J23: 0 | K23: 0 | L23: 0 | M23: 0 | N23: 0
A24: वजा :- परत करावयाची रक्कम (रिफंड) पक्का (आ.क.प्र.) | B24: RI11B103 | C24: 995507283 | D24: 576144247 | E24: 0 | F24: 0 | G24: 0 | H24: 0 | I24: 0 | J24: 0 | K24: 0 | L24: 0 | M24: 0 | N24: 0
A25: बेरीज | C25: 995507283 | D25: 576144247 | E25: 0 | F25: 0 | G25: 0 | H25: 0 | I25: 0 | J25: 0 | K25: 0 | L25: 0 | M25: 0 | N25: 0
C26: 0 | D26: 0 | E26: 0 | F26: 0 | G26: 0 | H26: 0 | I26: 0 | J26: 0 | K26: 0 | L26: 0 | M26: 0 | N26: 0
A27: निव्वळ जमा | C27: 11476954788 | D27: -364102196 | E27: 87959085 | F27: 101193615 | G27: 0 | H27: 0 | I27: 0 | J27: 0 | K27: 0 | L27: 0 | M27: 0 | N27: 0
C28: 0 | D28: 0 | E28: 0 | F28: 0 | G28: 0 | H28: 0 | I28: 0 | J28: 0 | K28: 0 | L28: 0 | M28: 0 | N28: 0
A29: ट्रॅन्झिट फी (रहदारी फी) (आ.क.प्र.) | B29: RI11B105 | C29: 528053185 | D29: 393634637 | E29: 136555000 | F29: 0 | G29: 0 | H29: 0 | I29: 0 | J29: 0 | K29: 0 | L29: 0 | M29: 0 | N29: 0
C30: 0 | D30: 0 | E30: 0 | F30: 0 | G30: 0 | H30: 0 | I30: 0 | J30: 0 | K30: 0 | L30: 0 | M30: 0 | N30: 0
A31: बेरीज | C31: 12005007973 | D31: 29532441 | E31: 224514085 | F31: 101193615 | G31: 0 | H31: 0 | I31: 0 | J31: 0 | K31: 0 | L31: 0 | M31: 0 | N31: 0
C32: 0 | D32: 0 | E32: 0 | F32: 0 | G32: 0 | H32: 0 | I32: 0 | J32: 0 | K32: 0 | L32: 0 | M32: 0 | N32: 0
A33: वजा :- पुणे सेना विभाग (कॅन्टोन्मेंट) हिस्सा (मु.ले.) | B33: RI11B106 | C33: 248974314 | D33: 0 | E33: 0 | F33: 0 | G33: 0 | H33: 0 | I33: 0 | J33: 0 | K33: 0 | L33: 0 | M33: 0 | N33: 0
A34: वजा :- खडकी सेना विभाग (कॅन्टोन्मेंट) हिस्सा (मु.ले.) | B34: RI11B107 | C34: 268547450 | D34: 0 | E34: 0 | F34: 0 | G34: 0 | H34: 0 | I34: 0 | J34: 0 | K34: 0 | L34: 0 | M34: 0 | N34: 0
C35: 0 | D35: 0 | E35: 0 | F35: 0 | G35: 0 | H35: 0 | I35: 0 | J35: 0 | K35: 0 | L35: 0 | M35: 0 | N35: 0
A36: बेरीज | C36: 517521764 | D36: 0 | E36: 0 | F36: 0 | G36: 0 | H36: 0 | I36: 0 | J36: 0 | K36: 0 | L36: 0 | M36: 0 | N36: 0
C37: 0 | D37: 0 | E37: 0 | F37: 0 | G37: 0 | H37: 0 | I37: 0 | J37: 0 | K37: 0 | L37: 0 | M37: 0 | N37: 0
A38: ख. निव्वळ आयातकर एकूण बेरीज | C38: 11487486209 | D38: 29532441 | E38: 224514085 | F38: 101193615 | G38: 0 | H38: 0 | I38: 0 | J38: 0 | K38: 0 | L38: 0 | M38: 0 | N38: 0
C39: 0 | D39: 0 | E39: 0 | F39: 0 | G39: 0 | H39: 0 | I39: 0 | J39: 0 | K39: 0 | L39: 0 | M39: 0 | N39: 0
A40: ख-१. स्थानिक संस्था कर | C40: 0 | D40: 0 | E40: 0 | F40: 0 | G40: 0 | H40: 0 | I40: 0 | J40: 0 | K40: 0 | L40: 0 | M40: 0 | N40: 0
A41: स्थानिक संस्था कर नोंदणी शुल्क | B41: RI11B201 | C41: 59902 | D41: 1640462 | E41: 275729 | F41: 121204 | G41: 64193 | H41: 1000000 | I41: 1000000 | J41: 1000 | K41: 1000 | L41: 0 | M41: 0 | N41: 999000
A42: स्थानिक संस्था कर | B42: RI11B202 | C42: 0 | D42: 8816353567 | E42: 9885567929 | F42: 4.9451268e+09 | G42: 4.6629141e+09 | H42: 12400000000 | I42: 12400000000 | J42: 4500000000 | K42: 5500000000 | L42: 0 | M42: 0 | N42: 6900000000
...

Sheet RevenueExpenditureA
A1: योजनेतर खर्च तपशील
A2: विवरण | D2: नक्‍की आकडा | G2: मान्य अंदाज 2015-16 | H2: नवीन अंदाज 2016-17
D3: 2012-13 | E3: 2013-14 | F3: 2014-15
A5: १. मुख्य देखरेख, वसुली वगैरे | D5: 0 | E5: 0 | F5: 0 | G5: 0 | H5: 0
A6: क. महानगरपालिका व स्थायी समिती | D6: 0 | E6: 0 | F6: 0 | G6: 0 | H6: 0
A7: १ नगरसचिव यांचे कार्यालय | D7: 0 | E7: 0 | F7: 0 | G7: 0 | H7: 0
A8: १. नगरसचिव (म्युनिसिपल सेक्रेटरी) (मुं.प्रां. मनपा अधिनियम, कलम४५(३) प्रमाणे) वेतन | B8: RE11A101A | D8: 855726 | E8: 1031198 | F8: 1101057 | G8: 1200000 | H8: 1500000
A9: २. कायम सेवकवर्ग वेतन | B9: RE11A102A | D9: 31021031 | E9: 31853678 | F9: 33475150 | G9: 37500000 | H9: 42500000
A10: ३. संकीर्ण (न.स.) | B10: RE11A103 | D10: 9994392 | E10: 7392997 | F10: 5578556 | G10: 6400000 | H10: 7500000
A11: ३अ. मागील बिले देण्यासाठी (न.स.) | B11: RE11A103A | D11: 843860 | E11: 793104 | F11: 643043 | G11: 800000 | H11: 2500000
A12: ४. प्रवास खर्च (न.स.) | B12: RE11A104 | D12: 10016 | E12: 0 | F12: 3362 | G12: 1600000 | H12: 2000000
A13: ५. ग्रंथालय व वाचनालय | B13: RE11A105 | D13: 134157 | E13: 150457 | F13: 148487 | G13: 140000 | H13: 200000
A14: ६. समारंभ खर्च (न.स. व वि.अ.) | B14: RE11A106 | D14: 270840 | E14: 297860 | F14: 253700 | G14: 240000 | H14: 500000
A15: १०. अखिल भारतीय/महाराष्ट्र महापौर परिषद व अखिल भारतीय स्थानिक स्वराज्य संस्था प्रतिनिधी अधिवेशन | B15: RE11A110 | D15: 0 | E15: 0 | F15: 1800 | G15: 96000 | H15: 120000
A16: ११. मनपा व शासकीय निवृत्त सेवकांना द्यावयाचा चहापान खर्च | B16: RE11A111 | D16: 57580 | E16: 76493 | F16: 73480 | G16: 240000 | H16: 300000
A17: १३. महाराष्ट्र राज्य महानगरपालिका स्थायी समिती अध्यक्ष परिषद वर्गणी व तद्‌नुषंगिक खर्च | B17: RE11A113 | D17: 0 | E17: 0 | F17: 0 | G17: 800 | H17: 1000
A18: १४. मा. महापौर यांचा व्ययनियमन (सम्प्च्युअरी) भत्ता | B18: RE11A114 | D18: 0 | E18: 0 | F18: 0 | G18: 4000 | H18: 5000
A19: १५. मा. महापौर यांचा ऐच्छिक खर्च | B19: RE11A115 | D19: 111767 | E19: 150789 | F19: 260496 | G19: 160000 | H19: 200000
... A51: सत्कार, अभिनंदन, पुरस्कार, बक्षिसे यासारखे कार्यक्रम साजरे करणे (यादी आर3) | B51: RE11A276# | D51: 2768389 | E51: 4598403 | F51: 4132623 | G51: 22812000 | H51: 9440000
D52: 0 | E52: 0 | F52: 0 | G52: 0 | H52: 0
A53: क. मनपा व स्थायी समिती बेरीज | D53: 77229108 | E53: 78238158 | F53: 69785307 | G53: 119208800 | H53: 168411000
D54: 0 | E54: 0 | F54: 0 | G54: 0 | H54: 0
A55: ख. मुख्य लेखापरिक्षक यांचे कार्यालय | D55: 0 | E55: 0 | F55: 0 | G55: 0 | H55: 0
A56: १. मुख्य लेखापरिक्षक (म्युनिसिपल चीफ ऑडिटर) (मु.प्रां. मनपा अधिनियम, कलम ४५ (३) प्रमाणे) यांचे वेतन | B56: RE11B101A | D56: 1092467 | E56: 1600994 | F56: 1626729 | G56: 2200000 | H56: 2200000
A57: २. कायम सेवकवर्ग वेतन | B57: RE11B102A | D57: 22242113 | E57: 22855648 | F57: 24303637 | G57: 28500000 | H57: 31500000
A58: ३. संकीर्ण | B58: RE11B103 | D58: 107923 | E58: 153324 | F58: 56982 | G58: 240000 | H58: 300000
D59: 0 | E59: 0 | F59: 0 | G59: 0 | H59: 0
A60: ख. मुख्यलेखापरिक्षक यांचे कार्या. बेरीज | D60: 23442503 | E60: 24609966 | F60: 25987348 | G60: 30940000 | H60: 34000000
D61: 0 | E61: 0 | F61: 0 | G61: 0 | H61: 0
A62: ग१. महापालिका आयुक्त यांचे कार्यालय | D62: 0 | E62: 0 | F62: 0 | G62: 0 | H62: 0
A63: १. महापालिका आयुक्त (म्युनिसिपल कमिशनर) (मु. प्रां. मनपा अधिनियम, कलम ३७ (१) प्रमाणे) यांचे वेतन | B63: RE11C101A | D63: 1510814 | E63: 1488203 | F63: 2711973 | G63: 2500000 | H63: 2500000
A64: २. उपआयुक्त (जनरल) (मुं. प्रां. मनपा अधिनियम, कलम ४५(३) प्रमाणे) यांचे वेतन | B64: RE11C102A | D64: 1614033 | E64: 1713176 | F64: 1139336 | G64: 1200000 | H64: 1500000
A65: ३. कायम सेवकवर्ग वेतन | B65: RE11C103A | D65: 15590612 | E65: 15963608 | F65: 16474467 | G65: 20000000 | H65: 20000000
A66: ४. संकीर्ण | B66: RE11C104 | D66: 970880 | E66: 962423 | F66: 666868 | G66: 1020000 | H66: 1275000
A67: ६. मा. महापालिका आयुक्त यांचा ऐच्छिक खर्च (म.स.आ.) | B67: RE11C106 | D67: 0 | E67: 0 | F67: 0 | G67: 289000 | H67: 700000
A68: पुणे मनपाने ज्या देशांशी मैत्री करार केले आहेत त्यांचे संबंध अधिक दृढ करणे | B68: RE11C168 | D68: 0 | E68: 0 | F68: 0 | G68: 10000000 | H68: 0
A69: पुणे ब्रॅडिंग | B69: RE11C169 | D69: 0 | E69: 0 | F69: 0 | G69: 10000000 | H69: 0
D70: 0 | E70: 0 | F70: 0 | G70: 0 | H70: 0
A71: ग१. महापालिका आयुक्त कार्यालय बेरीज | D71: 19686339 | E71: 20127410 | F71: 20992644 | G71: 45009000 | H71: 25975000
D72: 0 | E72: 0 | F72: 0 | G72: 0 | H72: 0
...

Sheet RevenueListA
A3: यादी क्र. आर१
A4: थोर व्यक्तींच्या जयंती / पुण्यतिथी साजरी करणे
A5: RE11A274/R1-
A7: क्र. | B7: code | C7: ward | E7: कामाचे नाव | F7: प्रकल्पीय रक्कम | G7: तरतूद
A9: 1 | B9: RE11A274/R1-1 | E9: महात्मा फुले जयंती | G9: 100000
A10: 2 | B10: RE11A274/R1-2 | E10: डॉ. बाबासाहेब आंबेडकर जयंती | G10: 150000
A11: 3 | B11: RE11A274/R1-3 | E11: लोकशाहीर अण्णाभाऊ साठे जयंती | G11: 100000
A12: 4 | B12: RE11A274/R1-4 | E12: ईद-ए-मिलाद (पैगंबर जयंती) | G12: 150000
A13: 5 | B13: RE11A274/R1-5 | E13: शहरातील शिवजयंती साजरी करणे, रोषणाई करणे | G13: 6800000
A14: 6 | B14: RE11A274/R1-6 | E14: महात्मा फुले यांची पुण्यतिथी साजरी करणे (दि. 28 नोव्हेंबर) | G14: 500000
A15: 7 | B15: RE11A274/R1-7 | E15: मौलाना अब्दुल कलाम आझाद जयंती व पुण्यतिथी साजरी करणे | G15: 600000
A16: 8 | B16: RE11A274/R1-8 | E16: लहुजी वस्ताद साळवे जयंती महोत्सव गंज पेठ व संगमवाडी येथे साजरा करणे | G16: 400000
A17: 9 | B17: RE11A274/R1-9 | E17: नेताजी सुभाषचंद्र बोस यांची जयंती साजरी करणे | G17: 25000
A18: 10 | B18: RE11A274/R1-10 | E18: येरवडा येथे लोकशाहिर अण्णाभाऊ साठे जयंती महोत्सव साजरा करणे | G18: 100000
A19: 11 | B19: RE11A274/R1-11 | E19: श्री संत रोहिदास महाराज जयंती, पुण्यतिथी साजरी करणे | G19: 2525000
E21: यादी क्र. आर१ एकूण | F21: 0 | G21: 11450000
A24: यादी क्र. आर2
A25: शहरामध्ये विविध कार्यक्रम, उत्सव, महोत्सव, संमेलन/ सहप्रायोजक तत्वावर कार्यक्रम साजरे करणे
A26: RE11A275/R2-
A28: क्र. | B28: code | C28: ward | E28: कामाचे नाव | F28: प्रकल्पीय रक्कम | G28: तरतूद
A30: 1 | B30: RE11A275/R2-1 | E30: महानगरपालिका वर्धापन दिन / सुवर्ण महोत्सव साजरा करणे | G30: 300000
A31: 2 | B31: RE11A275/R2-2 | E31: वर्षातील महत्त्वपूर्ण दिन : | G31: 600000
A32: 3 | B32: RE11A275/R2-3 | E32: राजगड श्री शिवाजीमहाराज आग्र्‍याहून सुटून परत आले तो स्मृती दिन प्रतिवर्षी साजरा करणे | G32: 215000
A33: 4 | B33: RE11A275/R2-4 | E33: शनिवारवाडा सांस्कृतिक महोत्सव | G33: 2000000
A34: 5 | B34: RE11A275/R2-5 | E34: भारतरत्न डॉ. बाबासाहेब आंबेडकर सांस्कृतिक महोत्सव साजरा करणे/ भिम फेस्टिवल (शनिवारवाडा पटांगण) / फुले आंबेडकर फेस्टिवल (समताभूमी) | G34: 5000000
A35: 6 | B35: RE11A275/R2-6 | E35: शिवमहोत्सव साजरा करणे (१४ ते २० फेब्रुवारी) | G35: 2000000
A36: 7 | B36: RE11A275/R2-7 | E36: अण्णाभाऊ साठे महोत्सव | G36: 4500000
A37: 8 | B37: RE11A275/R2-8 | E37: भारतरत्न डॉ. बाबासाहेब आंबेडकर यांचा शतकोत्तर रजत महोत्सव वर्ष साजरे करणे | G37: 25000000
A38: 9 | B38: RE11A275/R2-9 | E38: सावित्रीबाई फुले व्याख्यानमाला सुरु करणे | G38: 1000000
A39: 10 | B39: RE11A275/R2-10 | E39: युवा महोत्सव | G39: 5000000
A40: 11 | B40: RE11A275/R2-11 | E40: महिला महोत्सव | G40: 2500000
A41: 12 | B41: RE11A275/R2-12 | E41: महात्मा फुले पुण्यतिथी निमित्त फुलेवाडा सुशोभिकरण व कार्यक्रम घेणे | G41: 500000
... A43: 14 | B43: RE11A275/R2-14 | E43: महात्मा फुले नाट्‌यगृह वानवडी येथे म. फुले यांचे तैलचित्र व जीवनावर आधारित म्युरल करणे | G43: 5000000
A44: 15 | B44: RE11A275/R2-15 | C44: 67 | E44: प्र.क्र. ६७ब, शारदाबाई पवार कलामहोत्सव साजरा करणे | G44: 2500000
E46: यादी क्र. आर2 एकूण | F46: 0 | G46: 57115000
A49: यादी क्र. आर3
A50: सत्कार, अभिनंदन, पुरस्कार, बक्षिसे यासारखे कार्यक्रम साजरे करणे
A51: RE11A276/R3-
A53: क्र. | B53: code | C53: ward | E53: कामाचे नाव | F53: प्रकल्पीय रक्कम | G53: तरतूद
A55: 1 | B55: RE11A276/R3-1 | E55: गणेशोत्सव प्रशस्तिपत्रके वितरण | G55: 1000000
...

Sheet CapitalExpenditureA
A1: सन 2016-17 चे योजनांतर्गत | I1: खर्चाबाबतचे अंदाजपत्रक
A2: अनुक्रमांक | B2: मान्यतेचा ठराव क्र. दिनांक (कोड) | C2: प्रभाग क्रमांक | D2: BPL | E2: कामाचे नाव अगर वर्णन | F2: दि. 31 मार्च 2016 अखेरपर्यंत केलेली तरतूद | I2: दि. 31 मार्च 2015 पर्यंतचा खर्चाचा नक्‍की आकडा | J2: 2015-16 मधील खर्चाची अंदाजी रक्कम | L2: 2016-17 साठी अधिक तरतूद | N2: 2016-17 साठी एकूण तरतूद | O2: प्रकल्पीय रक्कम
F3: कर्जातून | G3: महसूल निधीतून | H3: एकूण | J3: प्रत्यक्ष उपलब्ध तरतूद | K3: कर्जातून तरतूद | L3: कर्जातून | M3: महसूल निधी व इतर निधी
E11: १. मनपा भवन व मनपा इमारती | F11: 0 | G11: 0 | H11: 0 | I11: 0 | J11: 0 | M11: 0 | N11: 0
A12: 1 | B12: CE11A122 | C12: G | E12: मनपा भवन येथे विस्तारित इमारत बांधणे व पुणे मनपा मिळकतीमध्ये क्षेत्रिय कार्यालय/ प्रशासकिय इमारतीचे विस्तारीकरण करणे | F12: 0 | G12: 64997756 | H12: 64997756 | I12: 18197756 | J12: 46800000 | M12: 0 | N12: 0 | O12: 200000000
A13: 2 | B13: CE11A129# | E13: शहरात विविध ठिकाणी मनपासाठी इमारती बांधणे व विकास कामे करणे | F13: 0 | G13: 0 | H13: 0 | I13: 0 | J13: 0 | M13: 290450000 | N13: 290450000
F14: 0 | G14: 0 | H14: 0 | I14: 0 | J14: 0 | M14: 0 | N14: 0
E15: १. मनपा भवन व मनपा इमारती एकूण बेरीज | F15: 0 | G15: 64997756 | H15: 64997756 | I15: 18197756 | J15: 46800000 | M15: 290450000 | N15: 290450000
F16: 0 | G16: 0 | H16: 0 | I16: 0 | J16: 0 | M16: 0 | N16: 0
F17: 0 | G17: 0 | H17: 0 | I17: 0 | J17: 0 | M17: 0 | N17: 0
E18: २. प्राथमिक शिक्षण | F18: 0 | G18: 0 | H18: 0 | I18: 0 | J18: 0 | M18: 0 | N18: 0
A19: 1 | B19: CE12A264 | C19: G | D19: P | E19: पुणे शहरातील प्राथमिक शाळांमध्ये वर्गखोल्या, सिमाभिंत, स्वच्छतागृह, वॉचमन क्वॉर्टर, वॉटर प्रुफिंग, पाण्याची व्यवस्था व इतर तद्‌नुषंगिक कामे व देखभाल दुरूस्तीची कामे करणे | F19: 0 | G19: 99767935 | H19: 99767935 | I19: 92567935 | J19: 7200000 | M19: 0 | N19: 0 | O19: 37500000
A20: 2 | B20: CE12A381# | E20: प्राथमिक शाळेमध्ये मुलभूत सोयी सुविधांसाठी विविध विकासकामे करणे | F20: 0 | G20: 902631240 | H20: 902631240 | I20: 677931240 | J20: 224700000 | M20: 158490000 | N20: 158490000
A21: 3 | B21: CE12A400 | C21: 67 | D21: P | E21: वि.स.खांडेकर शाळा दुसर्‍या मजल्यावर नविन ६ वर्ग खोल्या बांधणे | F21: 0 | G21: 7624342 | H21: 7624342 | I21: 5464342 | J21: 2160000 | M21: 0 | N21: 0
A22: 4 | B22: CE12A411 | C22: 67 | D22: P | E22: वॉर्ड क्र.११६ फायनल प्लॉट क्र.४७८ पर्वती येथील राजीव गांधी प्रायमरी शाळेचे उर्वरित काम पुर्ण करणे | F22: 0 | G22: 49647496 | H22: 49647496 | I22: 47847496 | J22: 1800000 | M22: 0 | N22: 0
A23: 5 | B23: CE12A412 | C23: 53 | D23: P | E23: वॉर्ड क्र. १२७ मधील हिंगणे खुर्द शाळा क्र. १६८ शाळेचा हॉल व वर्गखोल्या बांधणे व नुतनीकरण करणे | F23: 0 | G23: 4837618 | H23: 4837618 | I23: 3037618 | J23: 1800000 | M23: 0 | N23: 0
A24: 6 | B24: CE12A413 | C24: 43 | E24: वॉ.क्रं.९३ साधना विद्यालय येथे शाळा बांधणे | F24: 0 | G24: 19225330 | H24: 19225330 | I24: 17425330 | J24: 1800000 | M24: 0 | N24: 0
A25: 7 | B25: CE12A414 | C25: 36 | E25: एरंडवणा येथील मनपा च्या ताब्यात आलेल्या सन-डयु अपार्टमेंट या ठिकाणी इमारतीत प्राथमिक शाळेसाठी विविध विकासाची कामे करणे | F25: 0 | G25: 17381860 | H25: 17381860 | I25: 13781860 | J25: 3600000 | M25: 0 | N25: 0
A26: 8 | B26: CE12A415 | E26: प्रभाग क्र. १२ अ, बालवीर शिरिषकुमार विालय येथील वॉटर प्रुफिंग,रंगरंगोटी व स्ट्रकरल स्टॅबिलिटी रिपोर्ट प्रमाणे दुरुस्तीची कामे करणे. | F26: 0 | G26: 5619124 | H26: 5619124 | I26: 5619124 | J26: 0 | M26: 0 | N26: 0
A27: 9 | B27: CE12A417 | E27: मनपाच्या अस्तित्वात असलेल्या शाळा इमारतींमध्ये मुलींसाठी नवीन स्वच्छतागृहे बांधणे | F27: 0 | G27: 21925776 | H27: 21925776 | I27: 16525776 | J27: 5400000 | M27: 0 | N27: 0
A28: 10 | B28: CE12A419 | E28: येरवडा, मातोश्री इग्लीश स्कुल मध्ये वर्ग खोल्या बांधणे. | F28: 0 | G28: 1570928 | H28: 1570928 | I28: 1570928 | J28: 0 | M28: 0 | N28: 0
A29: 11 | B29: CE12A420 | C29: 62 | E29: प्र.क्र.६२ कोंढवा बु. येथे शाळा इमारत बांधणे. | F29: 0 | G29: 5418187 | H29: 5418187 | I29: 1818187 | J29: 3600000 | M29: 0 | N29: 0
A30: 12 | B30: CE12A421 | E30: पुणे शहरातील मध्यवर्ती भागाच्या मनपा शाळांमध्ये विविध दुरूस्त्या व विकासकामे करणे | F30: 0 | G30: 5845861 | H30: 5845861 | I30: 2245861 | J30: 3600000 | M30: 0 | N30: 0
A31: 13 | B31: CE12A422# | E31: प्राथमिक शाळेसाठी नवीन इमारत बांधणे | F31: 0 | G31: 0 | H31: 0 | I31: 0 | J31: 0 | M31: 205240000 | N31: 205240000
A32: 14 | B32: CE12A423# | E32: प्राथमिक शाळेसाठी वर्गखोल्या बांधणे | F32: 0 | G32: 0 | H32: 0 | I32: 0 | J32: 0 | M32: 78040000 | N32: 78040000
A33: 15 | B33: CE12A424# | E33: प्राथमिक शाळांची मैदाने विकसित करणे | F33: 0 | G33: 0 | H33: 0 | I33: 0 | J33: 0 | M33: 11650000 | N33: 11650000
A34: 16 | B34: #+ | E34: सन २०१३-१४ मधील अपूर्ण कामांसाठी सन २०१४-१५ मध्ये उपलब्ध केलेली तरतूद | F34: 0 | G34: 92446665 | H34: 92446665 | I34: 92446665 | J34: 0 | M34: 0 | N34: 0
A35: 17 | B35: #+ | E35: सन २०१४-१५ मधील अपूर्ण कामांसाठी सन २०१५-१६ मध्ये उपलब्ध केलेली तरतूद | F35: 0 | G35: 83160000 | H35: 83160000 | I35: 0 | J35: 83160000 | M35: 0 | N35: 0
F36: 0 | G36: 0 | H36: 0 | I36: 0 | J36: 0 | M36: 0 | N36: 0
E37: २. प्राथमिक शिक्षण एकूण बेरीज | F37: 0 | G37: 1317102362 | H37: 1317102362 | I37: 978282362 | J37: 338820000 | M37: 453420000 | N37: 453420000
F38: 0 | G38: 0 | H38: 0 | I38: 0 | J38: 0 | M38: 0 | N38: 0
E39: ३. दुय्यम शिक्षण | F39: 0 | G39: 0 | H39: 0 | I39: 0 | J39: 0 | M39: 0 | N39: 0
A40: 1 | B40: CE13A128# | E40: माध्यमिक शाळांमध्ये मुलभूत सोयी सुविधांसाठी विविध विकासकामे करणे | F40: 0 | G40: 14087912 | H40: 14087912 | I40: 14087912 | J40: 0 | M40: 1050000 | N40: 1050000
A41: 2 | B41: CE13A215 | D41: PL | E41: मनपा शाळांमध्ये मुलींसाठी स्वच्छतागृहे बांधणे | F41: 0 | G41: 28434823 | H41: 28434823 | I41: 25554823 | J41: 2880000 | M41: 0 | N41: 0
F42: 0 | G42: 0 | H42: 0 | I42: 0 | J42: 0 | M42: 0 | N42: 0
E43: ३. दुय्यम शिक्षण एकूण बेरीज | F43: 0 | G43: 42522735 | H43: 42522735 | I43: 39642735 | J43: 2880000 | M43: 1050000 | N43: 1050000
F44: 0 | G44: 0 | H44: 0 | I44: 0 | J44: 0 | M44: 0 | N44: 0
E45: ७. आरोग्य विभाग | F45: 0 | G45: 0 | H45: 0 | I45: 0 | J45: 0 | M45: 0 | N45: 0
A46: 1 | B46: CE17A209 | E46: महाराष्ट्र शासनाच्या धर्तीवर आय.ई.सी. सेंटर उभारणे | F46: 0 | G46: 0 | H46: 0 | I46: 0 | J46: 0 | M46: 0 | N46: 0
A47: 2 | B47: CE17A192# | E47: दवाखान्यातील मुलभूत सोयी सुविधांसाठी विविध विकासकामे करणे | F47: 0 | G47: 364552201 | H47: 364552201 | I47: 290552201 | J47: 74000000 | M47: 225950000 | N47: 225950000
...

Sheet LandAcquisition
A1: सन 2016-17 चे अंदाजपत्रक - खास निधीतून करावयाची योजनांतर्गत कामे
A2: अनुक्रमांक | C2: कामाचे नाव | D2: मान्य अंदाज 2015-16 | E2: नवीन अंदाज 2016-17
A7: (अ) | C7: भूमी संपादन निधीतून करावयाचा खर्च | D7: 0 | E7: 0
D8: 0 | E8: 0
A9: 1 | B9: FE11A101 | C9: भूमी संपादन विशेष अधिकारी यांचा कार्यालयीन खर्च - | D9: 36000000 | E9: 35000000
A10: 2 | C10: कोर्टाच्या निकालानुसार वाढीव नुकसानभरपाई कोर्ट खर्च, वकील फी, जॉइन्ट जज्ज यांचा खर्च वगैरे | D10: 0 | E10: 0
A11: 3 | C11: भूमी संपादन अधिनियमात नव्याने केलेल्या दुरुस्तीमुळे यापूर्वी जाहीर झालेल्या योजनापोटी ावयाच्या वाढीव रकमेचा खर्च | D11: 0 | E11: 0
A12: 4 | C12: परचेस नोटीसांमुळे (नवीन) पाठवावयाच्या भूमी संपादन योजनांसाठी तरतूद | D12: 0 | E12: 0
A13: 5 | C13: ताब्यात घेतलेल्या मिळकती पाडणे, ड्रेनेज, वॉटर, इलेक्ट्रीक टेलिफोन वगैरे कनेक्शन्स हलविणे, जोडणे व इतर तद्‌नुषंगिक कामे करणे. | D13: 0 | E13: 0
A14: 6 | C14: कार्यालयीन कामासाठी साधने, डेडस्टॉक वस्तू खरेदी करणे, हत्यारे खरेदी करणे, कार्यालय व कोठीची दुरुस्ती करणे, आवश्यक सुधारणा करणे, प्रकटन खर्च, प्रवास खर्च वगैर | D14: 0 | E14: 0
A15: 7 | C15: मुंबई प्रांतिक मनपा अधिनियम १९४९ च्या कलम २१३ अन्वये रस्तारूंदीसाठी ताब्यात घेतलेल्या मोकळ्या जागा व त्याप्रित्यर्थ ावयाची नुकसानभरपाईची रक्कम | D15: 0 | E15: 0
A16: 8 | C16: इतर योजनांमधील मोजणी फी व इतर तद्‌नुषंगिक रक्कम | D16: 0 | E16: 0
A17: 9 | C17: भूमी संपादन अधिकारी ह्यांचेकडील खालील नमूद केलेल्या ज्या जागांचे निवाडे जाहीर करतील त्यासाठी रक्कम | D17: 0 | E17: 0
A18: 10 | C18: संगणक दुरूस्ती व आवश्यक साहित्य | D18: 0 | E18: 0
D19: 0 | E19: 0
C20: (अ) बेरीज | D20: 36000000 | E20: 35000000
D21: 0 | E21: 0
D22: 0 | E22: 0
B23: FE11A102 | C23: भूसंपादनासाठी आवश्यक जागांची यादी :- | D23: 504000000 | E23: 4.9e+08
D24: 0 | E24: 0
C25: सी.वाय.जी अंतर्गत रस्ते : | D25: 0 | E25: 0
C26: बाणेर मुख्य रस्ता २६१ ते १०५ | D26: 0 | E26: 0
C27: बाणेर स.क्र. १३३ ते बालेवाडी स.क्र. १० बालेवाडीकडे जाणारा रस्ता मुख्य रस्ता (बालेवाडी) | D27: 0 | E27: 0
C28: बालेवाडी स.क्र. ३४, ३५ जी१ गार्डनचे आरक्षण | D28: 0 | E28: 0
C29: बाणेर स.क्र. २८, २९० जी२ गार्डनचे आरक्षण व बाणेर स.क्र. ३५ जी३ गार्डनचे आरक्षण | D29: 0 | E29: 0
C30: कल्याणीनगर जंक्शन ते आळंदी रोड | D30: 0 | E30: 0
C31: बाणेर स.क्र. १०५, १०६, ११०, १११ पीएमटी१ | D31: 0 | E31: 0
C32: बाणेर स.क्र. ३३ पी.३ | D32: 0 | E32: 0
C33: बाणेर स.क्र. १०० पी.४ | D33: 0 | E33: 0
C34: बाणेर स.क्र. १७४ पी.४ | D34: 0 | E34: 0
C35: बाणेर स.क्र. ७९ पी.६ | D35: 0 | E35: 0
C36: बाणेर स.क्र. १०५, १०६ पी.७ पार्किंगचे आरक्षण | D36: 0 | E36: 0
... C42: एअरपोर्ट रोड ते डेक्कन कॉलेज व्हाया हॉटमिक्स प्लँट | D42: 0 | E42: 0
D43: 0 | E43: 0
C44: जेएनएनयुआरएम / बीआरटी अंतर्गत रस्ते : | D44: 0 | E44: 0
C45: बाणेर स.क्र. १०७, १०८ व ११० मधून जाणारा १८ मी. रस्ता. | D45: 0 | E45: 0
C46: मौजे खराडी ता. हवेली, संगमवाडी ते खराडी २४ मी. नदीकाठचा डी.पी. रस्ता | D46: 0 | E46: 0
C47: मौजे वडगांव शेरी ता. हवेली, संगमवाडी ते खराडी २४ मी. नदीकाठचा डी.पी. रस्ता | D47: 0 | E47: 0
C48: सिंहगड रस्ता महानगरपालिका हद्द दरम्यान नियोजनाते विकसीत करणे (वडगांव बुद्रुक) | D48: 0 | E48: 0
C49: सिंहगड रस्ता महानगरपालिका हद्द दरम्यान नियोजनाते विकसीत करणे (वडगांव खुर्द) | D49: 0 | E49: 0
...

Sheet SpecialFund
A1: सन 2016-17 चे उपनगरे विकास निधीचे | I1: योजनांतर्गत खर्चाबाबतचे अंदाजपत्रक
A2: अनुक्रमांक | B2: मान्यतेचा ठराव क्र. दिनांक (कोड) | C2: प्रभाग क्रमांक | D2: BPL | E2: कामाचे नाव अगर वर्णन | F2: दि. 31 मार्च 2016 अखेरपर्यंत केलेली तरतूद | I2: दि. 31 मार्च 2014 पर्यंतचा खर्चाचा नक्‍की आकडा | J2: 2014-15 मधील खर्चाचा नक्‍की आकडा | K2: 2015-16 मधील खर्चाची अंदाजी रक्‍कम | L2: 2016-17 साठी अधिक तरतूद | N2: 2016-17 साठी एकूण तरतूद | O2: शेरा
F3: कर्जातून | G3: महसूल निधीतून | H3: एकूण | L3: कर्जातून | M3: महसूल निधी व इतर निधी
E11: ४. झोपडपट्टी निर्मूलन व पुनर्वसन निधीतून करावयाची कामे | F11: 0 | G11: 0 | H11: 0 | I11: 0 | J11: 0 | K11: 0 | M11: 0 | N11: 0
A12: 1 | B12: FE14A101# | D12: B | E12: निरनिराळ्या झोपडपट्टींमध्ये विविध विकासाची कामे करणे | F12: 33377000 | G12: 1252004249 | H12: 1285381249 | I12: 886586887 | J12: 99994362 | K12: 298800000 | M12: 375000000 | N12: 375000000
A13: 2 | B13: FE14A104 | D13: B | E13: झो.नि.पु. अंतर्गत करावयाची कामे | F13: 0 | G13: 196669858 | H13: 196669858 | I13: 188695199 | J13: 1974659 | K13: 6000000 | M13: 10500000 | N13: 10500000
A14: 3 | B14: FE14A105# | D14: B | E14: सुलभ पद्धतीची शौच्छालये बांधणे | F14: 0 | G14: 1066597075 | H14: 1066597075 | I14: 776879569 | J14: 94717506 | K14: 195000000 | M14: 212000000 | N14: 212000000
A15: 4 | B15: FE14A107 | D15: B | E15: दलित वस्ती सुधारणा अंतर्गत कामे करणे | F15: 0 | G15: 164657962 | H15: 164657962 | I15: 121183811 | J15: 2474151 | K15: 41000000 | M15: 75180000 | N15: 75180000
A16: 5 | B16: FE14A129 | D16: PL | E16: सार्वजनिक ठिकाणी शौचालय बांधणे | F16: 0 | G16: 34030200 | H16: 34030200 | I16: 17926211 | J16: 4103989 | K16: 12000000 | M16: 10500000 | N16: 10500000
A17: 6 | B17: FE14A130 | D17: PL | E17: सार्वजनिक ठिकाणी मुतार्‍या बांधणे | F17: 0 | G17: 22952631 | H17: 22952631 | I17: 8833045 | J17: 2119586 | K17: 12000000 | M17: 10500000 | N17: 10500000
A18: 7 | B18: FE14A131 | C18: 71 | E18: प्रभाग क्र. ७१ गंगाधाम चौक, नविन डी.पी. रस्ता सुलभ स्वच्छतागृह बांधणे | F18: 0 | G18: 2000000 | H18: 2000000 | I18: 0 | J18: 0 | K18: 2000000 | M18: 0 | N18: 0
A19: 8 | B19: FE14A132 | C19: 18 | E19: प्रभाग क्र. १८ व वडगाव शेरी परिसरामध्ये विविध ठिकाणी स्वच्छतागृह बांधणे | F19: 0 | G19: 1600000 | H19: 1600000 | I19: 0 | J19: 0 | K19: 1600000 | M19: 0 | N19: 0
A20: 9 | B20: FE14A133 | C20: 60 | E20: प्र. क्र. ६० मधील पी.एम.सी. कॉलनीजवळील अस्तित्वातील शौचालयाचे नूतनीकरण करणे व नवीन शौचालय बांधणे. | F20: 0 | G20: 1200000 | H20: 1200000 | I20: 0 | J20: 0 | K20: 1200000 | M20: 0 | N20: 0
F21: 0 | G21: 0 | H21: 0 | I21: 0 | J21: 0 | K21: 0 | M21: 0 | N21: 0
E22: ४. झोपडपट्टी निर्मूलन व पुनर्वसन निधीतून करावयाची कामे बेरीज | F22: 33377000 | G22: 2742905025 | H22: 2776282025 | I22: 2000104722 | J22: 206577303 | K22: 569600000 | M22: 693680000 | N22: 693680000
F23: 0 | G23: 0 | H23: 0 | I23: 0 | J23: 0 | K23: 0 | M23: 0 | N23: 0
E24: क्षेत्रिय कार्यालयाने करावयाची कामे :- | F24: 0 | G24: 0 | H24: 0 | I24: 0 | J24: 0 | K24: 0 | M24: 0 | N24: 0
F25: 0 | G25: 0 | H25: 0 | I25: 0 | J25: 0 | K25: 0 | M25: 0 | N25: 0
A26: • | B26: FE14A118# | C26: W5 | D26: B | E26: क्षेत्रिय कार्यालय : झो.नि.पु. विभागाने करावयाची कामे | F26: 0 | G26: 213253229 | H26: 213253229 | I26: 188875207 | J26: 9792022 | K26: 14586000 | M26: 3500000 | N26: 3500000
A27: • | B27: FE14A121# | C27: C5 | D27: B | E27: क्षेत्रिय कार्यालय : नागरिकांच्या सहभाग योजनेतून झो.नि.पु. विभागाने करावयाची कामे | F27: 0 | G27: 128632254 | H27: 128632254 | I27: 128653723 | J27: 2164531 | K27: -2186000 | M27: 7140000 | N27: 7140000
F28: 0 | G28: 0 | H28: 0 | I28: 0 | J28: 0 | K28: 0 | M28: 0 | N28: 0
E29: क्षेत्रिय कार्यालयाने करावयाची कामे एकूण बेरीज | F29: 0 | G29: 341885483 | H29: 341885483 | I29: 317528930 | J29: 11956553 | K29: 12400000 | M29: 10640000 | N29: 10640000
F30: 0 | G30: 0 | H30: 0 | I30: 0 | J30: 0 | K30: 0 | M30: 0 | N30: 0
E31: ४. झोपडपट्टी निर्मूलन व पुनर्वसन निधीतून करावयाची कामे + क्षेत्रिय कार्यालयाने करावयाची कामे एकूण बेरीज | F31: 33377000 | G31: 3084790508 | H31: 3118167508 | I31: 2317633652 | J31: 218533856 | K31: 582000000 | M31: 704320000 | N31: 704320000
F32: 0 | G32: 0 | H32: 0 | I32: 0 | J32: 0 | K32: 0 | M32: 0 | N32: 0
E33: ४अ. मागासवर्गीय कल्याणकारी योजना निधी | F33: 0 | G33: 0 | H33: 0 | I33: 0 | J33: 0 | K33: 0 | M33: 0 | N33: 0
A34: 1 | B34: FE14B101 | D34: B | E34: यू.सी.डी. अंतर्गत मागासवर्गीय योजना | F34: 0 | G34: 364459481 | H34: 364459481 | I34: 303039214 | J34: 29420267 | K34: 32000000 | M34: 35000000 | N34: 35000000
A35: 2 | B35: FE14B112 | D35: B | E35: लोकशाहीर अण्णाभाऊ साठे शैक्षणिक मदत योजना | F35: 0 | G35: 166342082 | H35: 166342082 | I35: 61753600 | J35: 18588482 | K35: 86000000 | M35: 0 | N35: 0
A36: 3 | B36: FE14B113 | D36: B | E36: मौ. अबुल कलाम आझाद शैक्षणिक मदत योजना | F36: 0 | G36: 251748546 | H36: 251748546 | I36: 118000064 | J36: 47748482 | K36: 86000000 | M36: 0 | N36: 0
A37: 4 | B37: FE14B121 | D37: B | E37: मागासवर्गीय विद्यार्थ्यांना स्पर्धा परिक्षा मार्गदर्शन केंद्र चालविणे | F37: 0 | G37: 4923784 | H37: 4923784 | I37: 1612396 | J37: 1711388 | K37: 1600000 | M37: 2000000 | N37: 2000000
A38: 5 | B38: FE14B122 | D38: B | E38: बालविकास केंद्र व वस्ती रिसोर्स सेंटर सुरू करणे | F38: 0 | G38: 6660140 | H38: 6660140 | I38: 2397374 | J38: 1462766 | K38: 2800000 | M38: 2800000 | N38: 2800000
A39: 6 | B39: FE14B123 | D39: B | E39: मागासवर्गीय कल्याणकारी योजनेअंतर्गत विविध योजना राबविणेसाठी मानधन तत्वावरील सेवकांचा मानधन खर्च | F39: 0 | G39: 16076688 | H39: 16076688 | I39: 10070854 | J39: 2805834 | K39: 3200000 | M39: 3500000 | N39: 3500000
A40: 7 | B40: FE14B126 | E40: बार्टीचे ४ केंद्र सुरू करणे (कोथरूड, सहकारनगर, शिवाजीनगर, भवानीपेठ) | F40: 0 | G40: 4000000 | H40: 4000000 | I40: 0 | J40: 0 | K40: 4000000 | M40: 2000000 | N40: 2000000
A41: 8 | B41: FE14B127 | E41: डॉ.बाबासाहेब आंबेडकर यांच्या 125 व्या जयंती निमित्त माता रमार्इ भिमराव आंबेडकर योजनेअंतर्गत गवनि घोषीत व शहरी गरीब योजनेतील पात्र ठरणाऱ्या विधवा, निराधार महिलांसाठी दरमहा रू.1000/- अर्थसहाय्य करणे (मागासवर्गीय कल्याणकारी योजना) | M41: 40000000 | N41: 40000000
F42: 0 | G42: 0 | H42: 0 | I42: 0 | J42: 0 | K42: 0 | M42: 0 | N42: 0
E43: ४अ. मागासवर्गीय कल्याणकारी योजना निधी बेरीज | F43: 0 | G43: 814210721 | H43: 814210721 | I43: 496873502 | J43: 101737219 | K43: 215600000 | M43: 85300000 | N43: 85300000
F44: 0 | G44: 0 | H44: 0 | I44: 0 | J44: 0 | K44: 0 | M44: 0 | N44: 0
E45: ४ब. महिलाबालकल्याण योजना निधी | F45: 0 | G45: 0 | H45: 0 | I45: 0 | J45: 0 | K45: 0 | M45: 0 | N45: 0
A46: 1 | B46: FE14C101 | D46: PL | E46: महिलाबालकल्याण योजना | F46: 0 | G46: 319232829 | H46: 319232829 | I46: 263262945 | J46: 23969884 | K46: 32000000 | M46: 34000000 | N46: 34000000
A47: 2 | B47: FE14C108 | D47: PL | E47: महिला सक्षमिकरणासाठी अनुदानाची योजना | F47: 0 | G47: 134663020 | H47: 134663020 | I47: 110968139 | J47: 7694881 | K47: 16000000 | M47: 15000000 | N47: 15000000
...

Sheet DPDC-Machinery-Tree
A1: सन 2016-17चे अंदाजपत्रक – खास निधीतून करावयाची योजनांतर्गत कामे
A2: अनुक्रमांक | B2: विवरण | D2: नक्की आकडा | G2: मान्य अंदाज 2015-16 | H2: नवीन अंदाज 2016-17
D3: 2012-13 | E3: 2013-14 | F3: 2014-15
C7: ५. पुणे जिल्हा नियोजन व विकास मंडळ निधीतून करावयाची कामे | D7: 0 | E7: 0 | F7: 0 | G7: 0 | H7: 0
C8: ५अ. मा. आमदारांनी सुचविल्याप्रमाणे करावयाची विकासाची कामे | D8: 0 | E8: 0 | F8: 0 | G8: 0 | H8: 0
A9: 1 | B9: FE15A101 | C9: बोपोडी मतदार संघ क्र. २४६ | D9: 0 | E9: 0 | F9: 0 | G9: 4000000 | H9: 3500000
A10: 2 | B10: FE15A102 | C10: शिवाजीनगर मतदार संघ क्र. २४७ | D10: 9863574 | E10: 7532054 | F10: 13029718 | G10: 4000000 | H10: 3500000
A11: 3 | B11: FE15A103 | C11: पर्वती मतदार संघ क्र. २४८ | D11: 6067684 | E11: 9635820 | F11: 2017582 | G11: 4000000 | H11: 3500000
A12: 4 | B12: FE15A104 | C12: कसबा पेठ मतदार संघ क्र. २४९ | D12: 13159782 | E12: 14151588 | F12: 12514432 | G12: 4000000 | H12: 3500000
A13: 5 | B13: FE15A105 | C13: भवानी पेठ मतदार संघ क्र. २५० | D13: 0 | E13: 0 | F13: 0 | G13: 4000000 | H13: 3500000
A14: 6 | B14: FE15A106 | C14: पुणे (कॅन्टोन्मेंट) मतदार संघ क्र. २५१ | D14: 8829803 | E14: 6538428 | F14: 8828578 | G14: 4000000 | H14: 3500000
A15: 7 | B15: FE15A107 | C15: विधान परिषद सदस्य | D15: 3487881 | E15: 6077326 | F15: 669792 | G15: 800000 | H15: 700000
D16: 0 | E16: 0 | F16: 0 | G16: 0 | H16: 0
A17: 8 | B17: FE15A108 | C17: ५ब. मा. खासदारांनी सुचविल्याप्रमाणे करावयाची विकासाची कामे | D17: 4002623 | E17: 4501132 | F17: 3109500 | G17: 20000000 | H17: 21000000
D18: 0 | E18: 0 | F18: 0 | G18: 0 | H18: 0
A19: 9 | B19: FE15A110 | C19: महानगरपालिका क्षेत्रात मुलभूत सोईसुविधांसाठी विशेष अनुदान | D19: 3330624 | E19: 19144878 | F19: 21871594 | G19: 0 | H19: 0
A20: 10 | B20: FE15A111 | C20: मुळशी मतदार संघ | D20: 0 | E20: 0 | F20: 0 | G20: 800000 | H20: 700000
A21: 11 | B21: FE15A112 | C21: कोथरूड विधानसभा मतदार संघ | D21: 9347706 | E21: 9852858 | F21: 4018776 | G21: 4000000 | H21: 3500000
A22: 12 | B22: FE15A113 | C22: हडपसर विधानसभा मतदार संघ | D22: 60271 | E22: 701627 | F22: 2705850 | G22: 3200000 | H22: 3500000
A23: 13 | B23: FE15A114 | C23: वडगांवशेरी विधानसभा मतदार संघ | D23: 1762314 | E23: 202985 | F23: 249992 | G23: 3200000 | H23: 3500000
A24: 14 | B24: FE15A115 | C24: खडकवासला विधानसभा मतदार संघ | D24: 0 | E24: 1381004 | F24: 254896 | G24: 0 | H24: 2100000
A25: 15 | B25: FE15A116 | C25: सर्वसाधारण जिल्हा वार्षिक योजना १२-१३ अंतर्गत घनकचरा व्यवस्थापनास निधी | D25: 0 | E25: 1499720 | F25: 0 | G25: 0 | H25: 0
D26: 0 | E26: 0 | F26: 0 | G26: 0 | H26: 0
C27: ५. पुणे जिल्हा नियोजन व विकास मंडळ निधीतून करावयाची कामे बेरीज | D27: 59912262 | E27: 81219420 | F27: 69270710 | G27: 56000000 | H27: 56000000
D28: 0 | E28: 0 | F28: 0 | G28: 0 | H28: 0
C29: ७. यंत्रसामुग्री घसारा निधीतून विकत घ्याववयाची नवीन सामुग्री | D29: 0 | E29: 0 | F29: 0 | G29: 0 | H29: 0
C30: अग्निशामक दलासाठी यंत्रसामुग्री :- | D30: 0 | E30: 0 | F30: 0 | G30: 0 | H30: 0
B31: FE17A103-1 | C31: वॉटर टँकर पंपासह (बाउझर) | D31: 4435930 | E31: 6087913 | F31: 0 | G31: 4500000 | H31: 7000000
B32: FE17A103-2 | C32: फायर इंजिन गाडी | D32: 5200000 | E32: 2786000 | F32: 24000000 | G32: 21600000 | H32: 21000000
B33: FE17A103-4 | C33: हायड्रोलिक प्लॅटफॉर्म | D33: 68000000 | E33: 0 | F33: 0 | G33: 0 | H33: 0
B34: FE17A103-9 | C34: शववाहिनी गाडी २ नग | D34: 0 | E34: 0 | F34: 0 | G34: 1080000 | H34: 0
B35: FE17A103-12 | C35: रेस्क्यू इक्वीपमेंट व लाईट मास्ट | D35: 0 | E35: 0 | F35: 11319330 | G35: 0 | H35: 0
B36: FE17A103-17 | C36: रेस्क्यू व्हॅन | D36: 1714067 | E36: 0 | F36: 0 | G36: 0 | H36: 0
B37: FE17A103-25 | C37: अग्निशमन फवारके व स्थायी अग्निशमन यंत्रणा | D37: 4000000 | E37: 916854 | F37: 0 | G37: 0 | H37: 0
B38: FE17A103-27 | C38: हायट्रन्स फायर सिस्टीम मोबाईल वॉटर सप्लाय सिस्टीम | D38: 65791078 | E38: 0 | F38: 0 | G38: 0 | H38: 0
B39: FE17A103-30 | C39: अल्ट्रा हायप्रेशर पिआर्सी मशीन | D39: 0 | E39: 0 | F39: 5991000 | G39: 0 | H39: 0
B40: FE17A103-31 | C40: मुख्य अग्निशमन अधिकारी यांचे कार्यालय वापरासाठी महेंद्र कंपनीचे स्कॉर्पीओ जीप खरेदी | D40: 0 | E40: 0 | F40: 0 | G40: 0 | H40: 700000
B41: FE17A107-18 | C41: कमला नेहरू रुग्णालयासाठी आवत अ‍ॅम्ब्युलन्स खरेदी करणे (२ नग) | D41: 544182 | E41: 0 | F41: 0 | G41: 0 | H41: 0
B42: FE17A107-20 | C42: ४ झोनसाठी डुक्कर स्कॉड करिता युटिलीटी वाहन खरेदी करणे | D42: 1402005 | E42: 0 | F42: 0 | G42: 0 | H42: 0
... B114: FE17A277# | C114: यंत्रसामुग्री घसारा निधीतून विकत घ्याववयाची सामुग्री | D114: 0 | E114: 0 | F114: 0 | G114: 0 | H114: 125500000
...

Sheet CapitalListA
A2: पथ विभागाकडील कामाच्या याद्या
A4: यादी क्र. ए२
A5: शहरातील रस्ते डांबरीकरणाने विकसित करणे
A6: CE20A102/A2-
A8: क्र. | B8: code | C8: ward | E8: कामाचे नाव | F8: प्रकल्पीय रक्कम | G8: तरतूद
E10: सन 2015-16 मधील अपूर्ण कामांसाठी सन 2016-17 मध्ये उपलब्ध केलेली तरतूद
A11: 1 | B11: CE20A819/S2-703+ | C11: 29 | E11: प्रभाग क्र.२९ वेदभवन ते डुंकरखिंड पर्यंतचा रस्ता ग्राउटींग व डांबरीकरण करणे. | G11: 2450000
A12: 2 | B12: CE20A102/A2-1577+ | E12: पुणे महानगरपालिकेच्या हॉट मिक्‍स प्लान्ट करीता नवीन बॅच मिक्‍स प्लॅन्ट खरेदी करणे. | G12: 21000000
A13: 3 | B13: CE20A102/A2-1109+ | E13: सन 2015-16 मधील कामे पुर्ण करण्यासाठी व जुने देयकांसाठी ( पेंडींग बिलांसाठी ) | G13: 53830000
A14: 4 | B14: CE20A1252+ | E14: एच.सी.एम.टी.आर.जागा ताब्यात घेउन रोड पुर्ण करणे, सल्लागार नेमणे, मार्कींग करणे. | G14: 3150000
A15: 5 | B15: CE20A102/A2-1402+ | E15: पुणे मुंबई रस्ता विकसित करणे | G15: 14000000
A16: 6 | B16: CE20A1250/A7-1+ | E16: पुणे शहरात सी.एम.पी. आराखड्यानुसार (मनपा तरतूद / PPP / Development TDR / Deffered payment / Premium Charges / SUTP world bank loan) अन्वये प्रशासकीय मुल्यमापनानुसार प्रत्यक्ष अंमलबजावणी करून कामे करणे तज्ज्ञ सल्लागार फी आदा करणे | G16: 3500000
A17: 7 | B17: CE20A102/A2-1574+ | E17: पुणे महानगरपालिकेने जागा मालक व विकसकाकडून डी.पी.रस्ता रुंदीच्या बदल्यात ज्या जागा विकसननिधी भरुन ताब्यात आलेल्या जागांचे विकसन कामे करणे व डीपी रस्त्याचे मार्किंग करणे | G17: 3500000
E19: यादी क्र. ए२ एकूण | F19: 0 | G19: 101430000
A22: यादी क्र. एसए२
A23: शहरातील रस्ते डांबरीकरणाने विकसित करणे
A24: CE20A102/SA2-
A26: क्र. | B26: code | C26: ward | E26: कामाचे नाव | F26: प्रकल्पीय रक्कम | G26: तरतूद
A28: 1 | B28: CE20A102/SA2-1 | C28: 1 | E28: प्रभाग क्र. १ अ मध्ये दादाची वस्ती येथील रस्ते डांबरीकरण करणे | G28: 1000000
A29: 2 | B29: CE20A102/SA2-2 | C29: 1 | E29: प्रभाग क्र. १ अ मध्ये खेसे पार्क येथील अंतर्गत रस्ते डांबरीकरण करणे | G29: 4000000
A30: 3 | B30: CE20A102/SA2-3 | C30: 1 | E30: प्रभाग क्र. १ अ मध्ये कलवड येथील अंतर्गत रस्ते डांबरीकरण करणे | G30: 4000000
A31: 4 | B31: CE20A102/SA2-4 | C31: 1 | E31: प्रभाग क्र. १ अ मध्ये गुरूद्वारा , संतनगर दादाची वस्ती येथील अंतर्गत रस्ते डांबरीकरण करणे | G31: 4000000
A32: 5 | B32: CE20A102/SA2-5 | C32: 1 | E32: प्रभाग क्र. १ अ मध्ये आनंद पार्क, भैरवनगर, मुंजाबा वस्ती, माधवनगर, कमल पार्क येथील अंतर्गत रस्ते डांबरीकरण करणे | G32: 5000000
A33: 6 | B33: CE20A102/SA2-6 | C33: 1 | E33: प्रभाग क्र. १ अ मध्ये कलवड येथील रोड नं.१ डांबरीकरण करणे | G33: 2000000
A34: 7 | B34: CE20A102/SA2-7 | C34: 1 | E34: प्रभाग क्र. १ अ मध्ये कमल पार्क रोड नं.७ परिसरातील अंतर्गत रस्ते डांबरीकरण करणे | G34: 1000000
A35: 8 | B35: CE20A102/SA2-8 | C35: 1 | E35: प्रभाग क्र. १ अ मध्ये धानोरी परिसरात रस्ते डांबरीकरण करणे | G35: 4000000
A36: 9 | B36: CE20A102/SA2-9 | C36: 1 | E36: प्रभाग क्र. १ अ मधील स.नं.51 मधील रोड नं.1 ते 4 परिसरातील अंतर्गत रस्ते डांबरीकरण करणे | G36: 2000000
A37: 10 | B37: CE20A102/SA2-10 | C37: 1 | E37: प्रभाग क्र. १ ब (धानोरी) मधील विविध रस्ते ग्राऊट करून डांबरीकरण करणे | G37: 4000000
A38: 11 | B38: CE20A102/SA2-11 | C38: 2 | E38: प्रभाग क्र. २ अ मध्ये ठुबे पठारेनगर व पाराशर सोसा.येथील रस्ते डांबरीकरण करणे | G38: 2000000
A39: 12 | B39: CE20A102/SA2-12 | C39: 2 | E39: प्रभाग क्र. २ अ मध्ये आत्माराम पठारे वस्ती येथील रस्ते डांबरीकरण करणे | G39: 1000000
... A313: 286 | B313: CE20A102/SA2-286 | C313: 9 | E313: प्र.क्र.९ब बाणेर मधील कपिल मल्हार ते अर्जुन शिंदे यांच्या घराकडे जाणारा रस्ता पेव्हरने डांबरीकरण करणे | G313: 2500000
A314: 287 | B314: CE20A102/SA2-287 | E314: पुणे शहरातील मुख्य रस्ते इंटिग्रेटेड रोड डेव्हलपमेंट अंतर्गत विकसीत करणे | G314: 20000000
A315: 288 | B315: CE20A102/SA2-288 | E315: धायरी बारांगणी मळा स.न.१३३ मधील रस्ता डांबरीकरण करणे. | G315: 2500000
A316: 289 | B316: CE20A102/SA2-289 | E316: धायरी मेन रोड ते आंबेडकरनगर स.न.१४६/१/१/२ ब्रम्हगिरी आर्केड शेजारी रस्ता पुर्नडांबरीकरण करणे | G316: 5000000
A317: 290 | B317: CE20A102/SA2-290 | E317: कात्रज कोंढवा रस्ता खडी मशीन पर्यंत डिफर्ड पेमेंट पद्धतीने विकसीत करणे | G317: 150000000
A318: 291 | B318: CE20A102/SA2-291 | C318: 62 | E318: प्रभाग क्र.६२ ब अशरफनगर, काकडेनगर, हगवणेनगर लक्ष्मीनगर येथील रस्ते खडीकरण व डांबरीकरण करणे | G318: 10000000
A319: 292 | B319: CE20A102/SA2-292 | C319: 62 | E319: प्रभाग क्र.६२ ब गोकुळनगर, विघ्नहर्ता कॉलनी, साईनगर कोंढवा बु. परिसर येथील रस्ते खडीकरण व डांबरीकरण करणे | G319: 10000000
A320: 293 | B320: CE20A102/SA2-293 | C320: 62 | E320: प्रभाग क्र.६२ ब कोंढवा बु. परिसरातील विविध ठिकाणी रस्ते डांबरीकरण करणे | G320: 5000000
A321: 294 | B321: CE20A102/SA2-294 | C321: 74 | E321: प्रभाग क्र. ७४ ब मध्ये विविध ठिकाणी खडीकरण , डांबरीकरण करणे व तदनुषंगीक कामे करणे | G321: 2000000
A322: 295 | B322: CE20A102/SA2-295 | C322: 12 | E322: प्रभाग क्र.12 ब कॅनॉल रोडवरील रस्ते डांबरीकरण करणे | G322: 2500000
...

Sheet RevenueInconeC
A1: पाणीपुरवठा व जलोत्सारण प्रकल्पांतर्गत | G1: खास निधी 'क' चा जमेचा गोषवारा व तपशील
A2: विवरण | C2: नक्की आकडा | H2: 2015-16 वर्षाचा अंदाज | J2: 2016-17 वर्षाचा अंदाज | M2: 2015-16 वर्षाच्या मान्य अंदाजाशी तुलना केलेला 2016-17 वर्षाचा मा. स्थायी समितीने मान्यता दिलेला अंदाज
C3: 2012-13 | D3: 2013-14 | E3: 2014-15 | F3: 2014-15 शेवटची सहामाही | G3: 2015-16 पहिली सहामाही | H3: मान्य अंदाज | I3: दुरूस्त अंदाज | J3: मा. महापालिका आयुक्त यांनी सुचविलेला | K3: मा. स्थायी समितीने मान्यता दिलेला | L3: मा. महानगर- पालिकेने संमत केलेला
M5: अधिक | N5: कमी
A7: अधिनियमाप्रमाणे कमीत कमी रोख शिल्लक ठेवण्याची रक्कम जमेस धरून वर्षारंभीची शिल्लक | C7: 100000 | D7: 100000 | E7: 100000 | G7: 0 | H7: 100000 | I7: 100000 | J7: 100000 | K7: 100000 | L7: 0 | M7: 0 | N7: 0
C8: 0 | D8: 0 | E8: 0 | G8: 0 | H8: 0 | I8: 0 | J8: 0 | K8: 0 | L8: 0 | M8: 0 | N8: 0
A9: १. पाणीपुरवठा (अति. न.अ.) | C9: 0 | D9: 0 | E9: 0 | F9: 0 | G9: 0 | H9: 0 | I9: 0 | J9: 0 | K9: 0 | L9: 0 | M9: 0 | N9: 0
A10: क. पाणीपट्टी साधारण पाणीपट्टी (कआकसंप्र) | B10: XI12A101 | C10: 957468962 | D10: 811521615 | E10: 1341089335 | F10: 634004501 | G10: 1090659990 | H10: 2090000000 | I10: 2090000000 | J10: 2359500000 | K10: 2359500000 | L10: 0 | M10: 269500000 | N10: 0
A11: ख. शासनाकडून (कआकसंप्र) | B11: XI12B101 | C11: 0 | D11: 0 | E11: 0 | F11: 0 | G11: 0 | H11: 100000 | I11: 100000 | J11: 100000 | K11: 100000 | L11: 0 | M11: 0 | N11: 0
A12: च. पुणे महानगर परिवहन महामंडळ लि. कडील मिळकतीवरील पाणीपट्टी (कआकसंप्र) | B12: XI12F101 | C12: 0 | D12: 0 | E12: 0 | F12: 0 | G12: 0 | H12: 100000 | I12: 100000 | J12: 100000 | K12: 100000 | L12: 0 | M12: 0 | N12: 0
A13: छ. वॉटर बेनिफीट टॅक्स (जललाभकर) (कआकसंप्र) (करपात्र रकमेच्या ३ टक्के) | B13: XI12G101 | C13: 197205040 | D13: 274834595 | E13: 302692528 | F13: 98802938 | G13: 246939193 | H13: 731400000 | I13: 731400000 | J13: 520200000 | K13: 520200000 | L13: 0 | M13: 0 | N13: 211200000
A14: ग. पाणीपट्टी पाणीमापकानुसार (अति.न.अ.) | B14: XI12C101 | C14: 334485239 | D14: 335645669 | E14: 359356133 | F14: 201608877 | G14: 1.6836123e+08 | H14: 800000000 | I14: 800000000 | J14: 615000000 | K14: 615000000 | L14: 0 | M14: 0 | N14: 185000000
A15: ग१. मीटर पाणीपट्टी थकबाकीपोटी जमा | B15: XI12C101A | C15: 0 | D15: 0 | E15: 0 | F15: 0 | G15: 0 | H15: 0 | I15: 0 | J15: 155000000 | K15: 718700000 | L15: 0 | M15: 718700000 | N15: 0
A16: ग२. गवनि खात्याअंतर्गत होणारी पाणीपट्टी जमा | B16: XI12C101B | C16: 5990669 | D16: 23592647 | E16: 41474022 | F16: 40425099 | G16: 26881510 | H16: 30000000 | I16: 30000000 | J16: 30000000 | K16: 30000000 | L16: 0 | M16: 0 | N16: 0
A17: अनधिकृत कनेक्शन नियमित करण्यापोटी जमा | B17: XI12S101 | C17: 0 | D17: 19160 | E17: 74895 | F17: 72395 | G17: 7305 | H17: 0 | I17: 0 | J17: 250000000 | K17: 250000000 | L17: 0 | M17: 250000000 | N17: 0
A18: घ. पाणीमापक भाडे | B18: XI12D101 | C18: 0 | D18: 15600 | E18: 1972 | F18: 1972 | G18: 1745 | H18: 0 | I18: 0 | J18: 10000000 | K18: 10000000 | L18: 0 | M18: 10000000 | N18: 0
A19: ड. नवीन नळ आकार नळदुरुस्ती व साफसफी (परतजमा) | B19: XI12E101 | C19: 3872364 | D19: 4597263 | E19: 6509624 | F19: 4419154 | G19: 3699952.7 | H19: 4000000 | I19: 4000000 | J19: 5000000 | K19: 5000000 | L19: 0 | M19: 1000000 | N19: 0
A20: ठ. कॉलनी रस्त्यावर पाईप टाकणे कामापोटी सुपरव्हिजन स्क्रुटीनी फी व अन्य जमा होणार | B20: XI12K101 | C20: 115563 | D20: 973708 | E20: 1180267 | F20: 888081 | G20: 530823 | H20: 800000 | I20: 800000 | J20: 10000000 | K20: 10000000 | L20: 0 | M20: 9200000 | N20: 0
A21: थ. पाणी वजावट ठेकेदार | B21: XI12R101 | C21: 5090222 | D21: 5474244 | E21: 5645606 | F21: 4942177 | G21: 1321072 | H21: 6000000 | I21: 6000000 | J21: 6000000 | K21: 6000000 | L21: 0 | M21: 0 | N21: 0
... A29: ण. अंदाजपत्रक 'अ' कडून वर्ग | B29: XI12M101 | C29: 2364078117 | D29: 3305964246 | E29: 3087694698 | F29: 3087694698 | G29: 0 | H29: 42029393 | I29: 42029393 | J29: 2138384749 | K29: 1630361499 | L29: 0 | M29: 1588332106 | N29: 0
C30: 0 | D30: 0 | E30: 0 | F30: 0 | G30: 0 | H30: 0 | I30: 0 | J30: 0 | K30: 0 | L30: 0 | M30: 0 | N30: 0
A31: १. बेरीज | C31: 3973705123 | D31: 4782638747 | E31: 5165719080 | F31: 4092859892 | G31: 1.5384028e+09 | H31: 3724429393 | I31: 3724429393 | J31: 6159284749 | K31: 6214961499 | L31: 0 | M31: 2886732106 | N31: 396200000
C32: 0 | D32: 0 | E32: 0 | F32: 0 | G32: 0 | H32: 0 | I32: 0 | J32: 0 | K32: 0 | L32: 0 | M32: 0 | N32: 0
A33: १अ. पुणे कॅन्टोन्मेंट पाणीपुरवठा जमा (अति.न.अ.) | C33: 0 | D33: 0 | E33: 0 | F33: 0 | G33: 0 | H33: 0 | I33: 0 | J33: 0 | K33: 0 | L33: 0 | M33: 0 | N33: 0
A34: (१) पाणीमापकानुसार पाणीपट्टी | B34: XI12Q101 | C34: 179515568 | D34: 193347221 | E34: 181297563 | F34: 112634662 | G34: 32942575 | H34: 250000000 | I34: 250000000 | J34: 170000000 | K34: 170000000 | L34: 0 | M34: 0 | N34: 80000000
A35: (२) एच.ई. फॅक्टरीकडून येणारी जमा | B35: XI12Q102 | C35: 53874219 | D35: 34000327 | E35: 20768047 | F35: 20768047 | G35: 0 | H35: 55000000 | I35: 55000000 | J35: 55000000 | K35: 55000000 | L35: 0 | M35: 0 | N35: 0
C36: 0 | D36: 0 | E36: 0 | F36: 0 | G36: 0 | H36: 0 | I36: 0 | J36: 0 | K36: 0 | L36: 0 | M36: 0 | N36: 0
A37: १अ. बेरीज | C37: 233389787 | D37: 227347548 | E37: 202065610 | F37: 133402709 | G37: 32942575 | H37: 305000000 | I37: 305000000 | J37: 225000000 | K37: 225000000 | L37: 0 | M37: 0 | N37: 80000000
C38: 0 | D38: 0 | E38: 0 | F38: 0 | G38: 0 | H38: 0 | I38: 0 | J38: 0 | K38: 0 | L38: 0 | M38: 0 | N38: 0
A39: जागतिक बँक, एशियन डेव्हलपमेंट बँक, जपान बँकेकडून अथवा अन्य बँका व वित्त संस्था यांचेकडून दिर्घ व लघु मुदतीसाठी कर्ज | B39: ZI12A101 | C39: 0 | D39: 0 | E39: 0 | F39: 0 | G39: 0 | H39: 0 | I39: 0 | J39: 1280000000 | K39: 896000000 | L39: 0 | M39: 896000000 | N39: 0
A40: राष्ट्रीय नदीसुधारणा प्रकल्पातंर्गत (जायका) केंद्र सरकारकडून अनुदान | B40: ZI12A102 | C40: 0 | D40: 0 | E40: 0 | F40: 0 | G40: 0 | H40: 0 | I40: 0 | J40: 800000000 | K40: 560000000 | L40: 0 | M40: 560000000 | N40: 0
A41: ज.ने.रा.श.पु.अ., अमृत व स्मार्ट सिटी आभियान अंतर्गत केंद्र व राज्य शासनाकडील अनुदानाचा हिस्सा | B41: ZI12A103 | C41: 0 | D41: 0 | E41: 0 | F41: 0 | G41: 0 | H41: 0 | I41: 0 | J41: 270000000 | K41: 189000000 | L41: 0 | M41: 189000000 | N41: 0
C42: 0 | D42: 0 | E42: 0 | F42: 0 | G42: 0 | H42: 0 | I42: 0 | J42: 0 | K42: 0 | L42: 0 | M42: 0 | N42: 0
A43: १. एकूण बेरीज | C43: 4207094910 | D43: 5009986295 | E43: 5367784690 | F43: 4226262601 | G43: 1.5713454e+09 | H43: 4029429393 | I43: 4029429393 | J43: 8734284749 | K43: 8084961499 | L43: 0 | M43: 4531732106 | N43: 476200000
C44: 0 | D44: 0 | E44: 0 | F44: 0 | G44: 0 | H44: 0 | I44: 0 | J44: 0 | K44: 0 | L44: 0 | M44: 0 | N44: 0
C45: 0 | D45: 0 | E45: 0 | F45: 0 | G45: 0 | H45: 0 | I45: 0 | J45: 0 | K45: 0 | L45: 0 | M45: 0 | N45: 0
A46: २. गटारे व नाले सुधारणा (अति.न.अ.) | C46: 0 | D46: 0 | E46: 0 | F46: 0 | G46: 0 | H46: 0 | I46: 0 | J46: 0 | K46: 0 | L46: 0 | M46: 0 | N46: 0
A47: क. सफाईपट्टी (करपात्र रकमेच्या १४%) (कआकसंप्र) | B47: XI23A101 | C47: 863141289 | D47: 1266493037 | E47: 1496037193 | F47: 522053042 | G47: 1217010196 | H47: 1797900000 | I47: 1797900000 | J47: 1768800000 | K47: 1768800000 | L47: 0 | M47: 0 | N47: 29100000
A48: घ. सुअरेज बेनिफीट टॅक्स (जलनिस्सारण लाभकर करपात्र रकमेच्या ६%) (कआकसंप्र) | B48: XI23D101 | C48: 394371659 | D48: 514638663 | E48: 619016536 | F48: 209705757 | G48: 503111143 | H48: 906200000 | I48: 906200000 | J48: 850000000 | K48: 850000000 | L48: 0 | M48: 0 | N48: 56200000
A49: ग. ड्रेनेज / सलेज कनेक्शन व सेवावाढ आकार नियोजित बांधकाम क्षेत्रफळावर रु. ११ चौ. मि | B49: XI23C101 | C49: 7603122 | D49: 8013571 | E49: 7333434 | F49: 3750151 | G49: 3583360.5 | H49: 10000000 | I49: 10000000 | J49: 10000000 | K49: 10000000 | L49: 0 | M49: 0 | N49: 0
...

Sheet RevenueExpenditureC
A1: योजनेतर खर्च तपशील
A2: विवरण | D2: नक्‍की आकडा | G2: मान्य अंदाज 2015-16 | H2: नवीन अंदाज 2016-17
D3: 2012-13 | E3: 2013-14 | F3: 2014-15
A5: १. पाणीपुरवठा | D5: 0 | E5: 0 | F5: 0 | G5: 0 | H5: 0
A6: क. पाणीपुरवठा | D6: 0 | E6: 0 | F6: 0 | G6: 0 | H6: 0
A7: १. मध्यवर्ती कार्यालय, कायम सेवकवर्ग वेतन | B7: XE12A101A | D7: 15239552 | E7: 13724143 | F7: 17277661 | G7: 18588000 | H7: 25000000
A8: २अ. कायम सेवकवर्ग वेतन | B8: XE12A101B | D8: 79810144 | E8: 85088436 | F8: 94860971 | G8: 90000000 | H8: 130000000
A9: २ब. कायम सेवकवर्ग वेतन (वि.का.) | B9: XE12A###A | D9: 9039415 | E9: 9246112 | F9: 9542874 | G9: 10526000 | H9: 12500000
A10: ३. संकीर्ण | B10: XE12A103 | D10: 1181463 | E10: 1267246 | F10: 785104 | G10: 800000 | H10: 1100000
A11: ४. पाण्याची किंमत (पर्वती पंपिंग स्टेशन) | B11: XE12A104 | D11: 147968426 | E11: 159000000 | F11: 161500000 | G11: 129200000 | H11: 145000000
A12: ५. पाणी शुद्ध करणे व तद्‌नुषंगिक कामे करणे | B12: XE12A105 | D12: 39388533 | E12: 54155100 | F12: 52999452 | G12: 43200000 | H12: 45000000
A13: ६. प्रयोगशाळा देखभाल खर्च | B13: XE12A106 | D13: 1499153 | E13: 1373228 | F13: 1193434 | G13: 1200000 | H13: 1200000
A14: ७-अ. पंपिंग वीज खर्च | B14: XE12A107 | D14: 489432391 | E14: 462455350 | F14: 494546000 | G14: 400000000 | H14: 530000000
A15: ९. कोठी इतर साहित्य खर्च | B15: XE12A109 | D15: 4132721 | E15: 3221160 | F15: 3239120 | G15: 2800000 | H15: 3500000
A16: १२. पर्वती जलकेंद्रातील यंत्रसामुग्रीवरील घसारा (मु.ले.) | B16: XE12A112 | D16: 179878 | E16: 193922 | F16: 163912 | G16: 163906 | H16: 164000
A17: १४. जलप्रदूषण प्रतिबंधक खर्च | B17: XE12A115 | D17: 5997000 | E17: 2436058 | F17: 8850000 | G17: 5200000 | H17: 6000000
A18: १८. जलकेंद्र पाण्याच्या टाक्या येथे प्रकाश व्यवस्था व दूरध्वनी व्यवस्था | B18: XE12A120 | D18: 0 | E18: 0 | F18: 0 | G18: 400000 | H18: 440000
... A39: पर्वती जलकेंद्र प्रयोगशाळा येथे पाणी तपासणीसाठी लागणारी विविध उपकरणे व तद्‌नुषंगिक साहित्य खरेदी करणे | B39: XE12A146 | D39: 0 | E39: 0 | F39: 0 | G39: 0 | H39: 0
A40: क. बेरीज | D40: 868241521 | E40: 871090881 | F40: 908151990 | G40: 760561906 | H40: 980604000
D41: 0 | E41: 0 | F41: 0 | G41: 0 | H41: 0
A42: ख१. नळ खाते (स्वारगेट विभाग) | D42: 0 | E42: 0 | F42: 0 | G42: 0 | H42: 0
A43: १. कायम सेवक वर्ग वेतन | B43: XE12B101A | D43: 137334257 | E43: 153660558 | F43: 166857797 | G43: 170000000 | H43: 205000000
A44: २. संकीर्ण | B44: XE12B102 | D44: 913686 | E44: 885210 | F44: 344423 | G44: 680000 | H44: 800000
A45: ४. शहरांतील / नव्याने समाविष्ट गावांतील सर्व व्हॉल्व्हज्‌ चालू व बंद करणे | B45: XE12B107 | D45: 22917553 | E45: 23900210 | F45: 26432807 | G45: 18400000 | H45: 35830000
A46: ८. टँकरने पाणीपुरवठा करणे | B46: XE12B111 | D46: 9072422 | E46: 6483276 | F46: 10314298 | G46: 6400000 | H46: 19000000
A47: ९. कोठी व इतर साहित्य खरेदी | B47: XE12B112 | D47: 26602856 | E47: 14733918 | F47: 15266437 | G47: 12000000 | H47: 25500000
A48: १०. देखभाल दुरुस्ती : नळदुरुस्ती व स्वच्छता तातडीच्या दुरुस्त्या चेंबर करणे, आर.सी.सी, कव्हर बसविणे व तदनुषंगिक कामे करणे | B48: XE12B113 | D48: 26273076 | E48: 29914211 | F48: 27459984 | G48: 20000000 | H48: 50000000
A49: ११. टाक्‍यांची दुरुस्ती | B49: XE12B114 | D49: 0 | E49: 0 | F49: 99862 | G49: 800000 | H49: 1000000
A50: पाणीपुरवठा विभागाकडील देखभाल दुरूस्तीची कामे | B50: XE12B115# | D50: 0 | E50: 0 | F50: 0 | G50: 0 | H50: 43500000
D51: 0 | E51: 0 | F51: 0 | G51: 0 | H51: 0
A52: ख१. बेरीज | D52: 223113850 | E52: 229577383 | F52: 246775608 | G52: 228280000 | H52: 380630000
D53: 0 | E53: 0 | F53: 0 | G53: 0 | H53: 0
A54: ख२. नळ खाते (विभागीय कार्यालय) | D54: 0 | E54: 0 | F54: 0 | G54: 0 | H54: 0
A55: १. कायम सेवकवर्ग वेतन | B55: XE12B###A | D55: 30500446 | E55: 35324245 | F55: 35079153 | G55: 35588000 | H55: 45000000
A56: क्षेत्रीय कार्यालयाने करावयाची योजनेतर कामे | B56: XE12B301/W6-# | D56: 0 | E56: 0 | F56: 0 | G56: 600000 | H56: 2000000
A57: क्षेत्रीय कार्यालयाने नागरिकांच्या सहभागातून करावयाची योजनेतर कामे | B57: XE12B302/C6-# | D57: 2639210 | E57: 3054966 | F57: 5632324 | G57: 7040000 | H57: 12800000
D58: 0 | E58: 0 | F58: 0 | G58: 0 | H58: 0
A59: ख२. बेरीज | D59: 33139656 | E59: 38379211 | F59: 40711477 | G59: 43228000 | H59: 59800000
D60: 0 | E60: 0 | F60: 0 | G60: 0 | H60: 0
A61: ख. एकूण बेरीज | D61: 256253506 | E61: 267956594 | F61: 287487085 | G61: 271508000 | H61: 440430000
...

Sheet RevenueListC
A2: पाणीपुरवठा विभागाकडील कामाच्या याद्या
A5: यादी क्र. एसएक्स१
A6: पाणीपुरवठा विभागाकडील देखभाल दुरूस्तीची कामे
A7: XE12B115/SX1-
A9: क्र. | B9: code | C9: ward | E9: कामाचे नाव | F9: प्रकल्पीय रक्कम | G9: तरतूद
A11: 1 | B11: XE12B115/SX1-1 | C11: 3 | E11: प्रभाग क्र. ३ अ मध्ये विविध कनेक्शनची दुरूस्ती करणे | G11: 1000000
A12: 2 | B12: XE12B115/SX1-2 | C12: 3 | E12: प्रभाग क्र. ३ ब मधील विविध ठिकाणी बोअरवेल दुरुस्ती करणे व नविन घेणे | G12: 1000000
A13: 3 | B13: XE12B115/SX1-3 | C13: 6 | E13: प्रभाग क्र.६ अ मध्ये बोअरवेल बसविणे व दुरूस्त करणे | G13: 500000
A14: 4 | B14: XE12B115/SX1-4 | C14: 7 | E14: प्रभाग क्र. ७ ब मध्ये विविध ठिकाणी पाण्याची लाईन दुरूस्त करणे | G14: 1000000
A15: 5 | B15: XE12B115/SX1-5 | C15: 9 | E15: प्रभाग क्र.९ब, बाणेर - बालेवाडी परिसरामध्ये टँकरने पाणी पुरवठा करणे | G15: 2500000
A16: 6 | B16: XE12B115/SX1-6 | C16: 10 | E16: प्रभाग क्र.१० अ टँकरने पाणी पुरवठा करणे | G16: 1000000
A17: 7 | B17: XE12B115/SX1-7 | C17: 11 | E17: प्रभाग क्र.११ ब मध्ये विविध सोसायटयांमध्ये पाण्याचे टँकर पुरविणे. | G17: 500000
A18: 8 | B18: XE12B115/SX1-8 | C18: 13 | E18: प्रभाग क्र.१३ अ मध्ये विविध ठिकाणी जुन्या पाईपलाईन दुरूस्ती व बदलणे. | G18: 1000000
A19: 9 | B19: XE12B115/SX1-9 | C19: 23 | E19: प्रभाग क्र. २३ अ मध्ये भिमनगर, इंदिरानगर, पारगे चौक परिसरात विविध ठिकाणी नळकोंडाळे दुरूस्त करणे व तदनुषंगीक कामे करणे | G19: 1000000
A20: 10 | B20: XE12B115/SX1-10 | C20: 23 | E20: प्रभाग क्र.२३ ब मध्ये विविध ठिकाणी पाण्याच्या लाईन टाकणे व दुरूस्तीविषयक कामे करणे. | G20: 1000000
A21: 11 | B21: XE12B115/SX1-11 | C21: 23 | E21: प्रभाग क्र.२३ ब मध्ये विविध ठिकाणी नळकोंडाळे दुरूस्त करणे | G21: 1000000
A22: 12 | B22: XE12B115/SX1-12 | C22: 27 | E22: प्रभाग क्र. २७ ब प्रभागामध्ये विविध ठिकाणी टँकरने पाणीपुरवठा करणे | G22: 500000
... A40: 30 | B40: XE12B115/SX1-30 | C40: 74 | E40: प्रभाग क्र. ७४ ब मध्ये रस्ते खोदाईतील लाईन्स जिरविणे, जुने नादुररूस्त व्हॉल्व्ह बदलणे, टँकरने पाणी पुरवठा करणे, नव्याने जलवाहीन्या टाकणे व तदनुषंगीक कामे करणे | G40: 2500000
A41: 31 | B41: XE12B115/SX1-31 | E41: १५ क्षेत्रिय कार्यालयाअंतर्गत पाणी वापरासाठी जनजागृती करणे | G41: 7500000
E43: यादी क्र. एसएक्स१ एकूण | F43: 0 | G43: 43500000
A46: यादी क्र. एक्स2
A47: मलनिःस्सारण विभागाकडील देखभाल दुरूस्तीची कामे
A48: XE23A117/X2-
A50: क्र. | B50: code | C50: ward | E50: कामाचे नाव | F50: प्रकल्पीय रक्कम | G50: तरतूद
A52: 1 | B52: XE23A117/X2-1 | E52: भैरोबा नाल्यातील एस.टी.पी कडे जाणा-या जुन्या ड्रेनेज लाईन काढुन त्या ठिकाणी मोठया व्यासाच्या ड्रेनेज लाईन टाकणे व तद्‌नुषंगिक कामे करणे | G52: 1750000
A53: 2 | B53: XE23A117/X2-2 | E53: कल्याणीनगर पंपिगकडे जाणा-या जुन्या ड्रेनेज लाईन काढुन त्या ठिकाणी मोठया व्यासाच्या ड्रेनेज लाईन टाकणे व तद्‌नुषंगिक कामे करणे | G53: 1750000
A54: 3 | B54: XE23A117/X2-3 | E54: ढोलेपाटील क्षेत्रिय कार्यालया अंतर्गत पंपिग स्टेशनला जाणा-या जुन्या ड्रेनेज लाईन काढुन त्या ठिकाणी मोठया व्यासाच्या ड्रेनेज लाईन टाकणे व तद्‌नुषंगिक कामे करणे | G54: 1750000
A55: 4 | B55: XE23A117/X2-4 | E55: एरंडवणा मैलापाणी शुध्दीकरण केंद्राकडे येणा-या कर्वेनगरकडून येणा-या मलवाहिनीची देखभाल दुरूस्ती करणे. | G55: 1750000
A56: 5 | B56: XE23A117/X2-5 | E56: वारजे शुध्दीकरण केंद्राजवळील नाल्या मधील मलवाहिनीची दुरूस्ती करणे. | G56: 1750000
A57: 6 | B57: XE23A117/X2-6 | E57: औंध क्षेत्रिय कार्यालयांतर्गत देखभाल दुरूस्तीची कामे करणे. | G57: 2800000
A58: 7 | B58: XE23A117/X2-7 | E58: घोले रोड क्षेत्रिय कार्यालयांतर्गत देखभाल दुरूस्तीची कामे करणे. | G58: 2800000
A59: 8 | B59: XE23A117/X2-8 | E59: कोथरूड क्षेत्रिय कार्यालय अंतर्गत येणा-या मुख्य मलःवाहिन्यांची देखभाल दुरूस्ती करणे. | G59: 2800000
A60: 9 | B60: XE23A117/X2-9 | E60: वारजे कर्वेनगर क्षेत्रिय कार्यालय अंतर्गत येणा-या मुख्य मलःवाहिनीची देखभाल दुरूस्ती करणे. | G60: 2800000
A61: 10 | B61: XE23A117/X2-10 | E61: नगर रोड (वडगावशेरी) क्षे.कार्यालयचे कार्यक्षेत्रातील नाल्यातील मुळा मुठा नदीच्या तिरावरील व रस्त्यावरील मुख्य मलवाहिन्यांची देखभाल दुरूस्ती करणे व तदृनुषंगिक कामे करणे. | G61: 2800000
A62: 11 | B62: XE23A117/X2-11 | E62: येरवडा (जुने संगमवाडी) क्षे.कार्यालयाचे अखत्यारातील नाल्याच्या कडेच्या मुख्य मलवाहिन्यांची देखभाल दुरूस्ती करणे व तद्‌नुषंगिक कामे करणे. | G62: 2800000
A63: 12 | B63: XE23A117/X2-12 | E63: ढोले पाटिल क्षे.कार्यालयाचे आखत्यारातील नाल्याच्या कडेच्या मुख्य मलवाहिन्यांची देखभाल दुरूस्ती करणे व तदृनुषंगिक कामे करणे. | G63: 2800000
... A75: 24 | B75: XE23A117/X2-24 | E75: कोंढवा वानवडी व हडपसर कार्यालया अंतर्गत येणा-या नाल्यातील जुन्या ड्रेनेज लाईन काढुन त्या ठिकाणी मोठया व्यासाच्या ड्रेनेज लाईन टाकणे व तद्‌नुषंगिक कामे करणे | G75: 1400000
E77: यादी क्र. एक्स2 एकूण | F77: 0 | G77: 56000000
A80: यादी क्र. एसएक्स2
A81: मलनिःस्सारण विभागाकडील देखभाल दुरूस्तीची कामे
...

Sheet CapitalExpenditureC
A1: सन 2016-17 चे योजनांतर्गत | I1: खर्चाबाबतचे अंदाजपत्रक
A2: अनुक्रमांक | B2: मान्यतेचा ठराव क्र. दिनांक (कोड) | C2: प्रभाग क्रमांक | D2: BPL | E2: कामाचे नाव अगर वर्णन | F2: दि. 31 मार्च 2016 अखेरपर्यंत केलेली तरतूद | I2: दि. 31 मार्च 2015 पर्यंतचा खर्चाचा नक्‍की आकडा | J2: 2015-16 मधील खर्चाची अंदाजी रक्कम | L2: 2016-17 साठी अधिक तरतूद | N2: 2016-17 साठी एकूण तरतूद | O2: प्रकल्पीय रक्कम
F3: कर्जातून | G3: महसूल निधीतून | H3: एकूण | J3: प्रत्यक्ष उपलब्ध तरतूद | K3: कर्जातून तरतूद | L3: कर्जातून | M3: महसूल निधी व इतर निधी
E11: 1. पाणीपुरवठा | F11: 0 | G11: 0 | H11: 0 | I11: 0 | J11: 0 | K11: 0 | M11: 0 | N11: 0
F12: 0 | G12: 0 | H12: 0 | I12: 0 | J12: 0 | K12: 0 | M12: 0 | N12: 0
A13: 1 | B13: ZE16A104# | E13: शहरामध्ये पाण्याच्या नवीन लाईन विकसित करणे | F13: 0 | G13: 5087759184 | H13: 5087759184 | I13: 4166555184 | J13: 921204000 | K13: 0 | M13: 826745000 | N13: 826745000
A14: 2 | B14: ZE16A106# | E14: शहरामध्ये पाण्याच्या टाक्या बांधणे / बोअरवेल घेणे | F14: 0 | G14: 78145020 | H14: 78145020 | I14: 78145020 | J14: 0 | K14: 0 | M14: 229360000 | N14: 229360000
A15: 3 | B15: ZE16A107# | E15: शहरामधील विविध जलशुध्दीकरण केंद्रामध्ये विद्युत / यांत्रिकीविषयक कामे करणे | F15: 0 | G15: 314067558 | H15: 314067558 | I15: 314067558 | J15: 0 | K15: 0 | M15: 103720000 | N15: 103720000
A16: 4 | B16: #+ | E16: सन २०१३-१४ मधील अपूर्ण कामांसाठी सन २०१४-१५ मध्ये उपलब्ध केलेली तरतूद | F16: 0 | G16: 962850882 | H16: 962850882 | I16: 962850882 | J16: 0 | M16: 0 | N16: 0
A17: 5 | B17: #+ | E17: सन २०१४-१५ मधील अपूर्ण कामांसाठी सन २०१५-१६ मध्ये उपलब्ध केलेली तरतूद | F17: 0 | G17: 1326896000 | H17: 1326896000 | I17: 0 | J17: 1326896000 | K17: 0 | M17: 0 | N17: 0
F18: 0 | G18: 0 | H18: 0 | I18: 0 | J18: 0 | K18: 0 | M18: 0 | N18: 0
E19: पाणीपुरवठा एकूण | F19: 0 | G19: 7769718644 | H19: 7769718644 | I19: 5521618644 | J19: 2248100000 | K19: 0 | M19: 1159825000 | N19: 1159825000
