Workbook
Name BdgtNo: #REF!
Name BdgtNo: #REF!
Name BdgtNo: [1]index!$L$9
Name BdgtNo: #REF!
Name BdgtNo: #REF!
Name BdgtYear: #REF!
Name BdgtYear: #REF!
Name BdgtYear: [1]index!$L$8
Name BdgtYear: #REF!
Name BdgtYear: #REF!
Name BdgtYrFrom: #REF!
Name BdgtYrFrom: #REF!
Name BdgtYrFrom: [1]index!$L$13
Name BdgtYrFrom: #REF!
Name BdgtYrFrom: #REF!
Name BdgtYrTo: #REF!
Name BdgtYrTo: #REF!
Name BdgtYrTo: [1]index!$L$14
Name BdgtYrTo: #REF!
Name BdgtYrTo: #REF!
Name Description: "P_A_C_Ex"
Name FinYrFrom: #REF!
Name FinYrFrom: #REF!
Name FinYrFrom: [1]index!$L$11
Name FinYrFrom: #REF!
Name FinYrFrom: #REF!
Name FinYrTo: #REF!
Name FinYrTo: #REF!
Name FinYrTo: [1]index!$L$12
Name FinYrTo: #REF!
Name FinYrTo: #REF!
Name Head: #REF!
Name Head: #REF!
Name Head: '[1]a|ex|smry'!$B$1:$L$1
Name Head: #REF!
Name Head: #REF!
Name Last2Yr: #REF!
Name Last2Yr: #REF!
Name Last2Yr: [1]index!$L$7
Name Last2Yr: #REF!
Name Last2Yr: #REF!
Name Last3Yr: #REF!
Name Last3Yr: #REF!
Name Last3Yr: [1]index!$L$6
Name Last3Yr: #REF!
Name Last3Yr: #REF!
Name Last4Yr: #REF!
Name Last4Yr: #REF!
Name Last4Yr: [1]index!$L$5
Name Last4Yr: #REF!
Name Last4Yr: #REF!
Name Last5Yr: #REF!
Name Last5Yr: #REF!
Name Last5Yr: [1]index!$L$4
Name Last5Yr: #REF!
Name Last5Yr: #REF!
Name List_Smry_0: A_Capital_List!#REF!
Name List_Smry_0: A_Revenue_List!#REF!
Name List_Smry_0: C_Capital_List!#REF!
Name List_Smry_0: C_Revenue_List!#REF!

Sheet A_Revenue_Income
A1: जमेचा | G1: तपशील
A2: विवरण | C2: नक्की आकडा | H2: 2017-18 वर्षाचा अंदाज | J2: 2018-19 वर्षाचा अंदाज | M2: 2017-18 वर्षाच्या मान्य अंदाजाशी तुलना केलेला 2018-19 वर्षाचा मा. महा. आयुक्त यांनी सुचविलेला अंदाज
C3: 2014-15 | D3: 2015-16 | E3: 2016-17 | F3: 2016-17 शेवटची सहामाही | G3: 2017-18 पहिली सहामाही | H3: मान्य अंदाज | I3: दुरूस्त अंदाज | J3: मा. महापालिका आयुक्त यांनी सुचविलेला | K3: मा. स्थायी समितीने मान्यता दिलेला | L3: मा. महानगर- पालिकेने संमत केलेला
M5: अधिक | N5: कमी
A7: अधिनियमाप्रमाणे कमीत कमी रोख शिल्लक ठेवण्याची रक्कम जमेस धरून वर्षारंभीची शिल्लक | B7: 0 | C7: 100000 | D7: 100000 | E7: 100000 | F7: 100000 | G7: 0 | H7: 100000 | I7: 100000 | J7: 100000 | K7: 0 | L7: 0 | M7: 0 | N7: 0
C8: 0 | D8: 0 | E8: 0 | F8: 0 | G8: 0 | H8: 0 | I8: 0 | J8: 0 | K8: 0 | L8: 0 | M8: 0 | N8: 0
A9: १. सर्वसाधारण कर, अप्रत्यक्ष कर व इतर जमा | C9: 0 | D9: 0 | F9: 0 | G9: 0 | H9: 0 | I9: 0 | J9: 0 | K9: 0 | L9: 0 | M9: 0 | N9: 0
A10: क. सर्वसाधारण पट्टी | C10: 0 | D10: 0 | E10: 0 | F10: 0 | G10: 0 | H10: 0 | I10: 0 | J10: 0 | K10: 0 | L10: 0 | M10: 0 | N10: 0
A11: १. नागरिकांकडून (कआकसंप्र) | B11: RI11A101 | C11: 2428110703 | D11: 3224088721 | E11: 3579419675 | F11: 1562913282 | G11: 2149789191 | H11: 6690000000 | I11: 6690000000 | J11: 6000000000 | K11: 0 | L11: 0 | M11: 0 | N11: 690000000
A12: लोहगाव (उर्वरित) | B12: RI11AA101 | C12: 0 | D12: 0 | E12: 0 | F12: 0 | G12: 0 | H12: 0 | I12: 0 | J12: 66600000 | K12: 0 | L12: 0 | M12: 66600000 | N12: 0
A13: मुंढवा (उर्वरित केशवनगर) | B13: RI11AB101 | C13: 0 | D13: 0 | E13: 0 | F13: 0 | G13: 0 | H13: 0 | I13: 0 | J13: 31000000 | K13: 0 | L13: 0 | M13: 31000000 | N13: 0
A14: हडपसर (संपूर्ण साडेसतरानळी) | B14: RI11AC101 | C14: 0 | D14: 0 | E14: 0 | F14: 0 | G14: 0 | H14: 0 | I14: 0 | J14: 120800000 | K14: 0 | L14: 0 | M14: 120800000 | N14: 0
A15: शिवणे (संपूर्ण उत्तमनगर) | B15: RI11AD101 | C15: 0 | D15: 0 | E15: 0 | F15: 0 | G15: 0 | H15: 0 | I15: 0 | J15: 5600000 | K15: 0 | L15: 0 | M15: 5600000 | N15: 0
A16: शिवणे | B16: RI11AE101 | C16: 0 | D16: 0 | E16: 0 | F16: 0 | G16: 0 | H16: 0 | I16: 0 | J16: 40000000 | K16: 0 | L16: 0 | M16: 40000000 | N16: 0
A17: आंबेगाव खुर्द | B17: RI11AF101 | C17: 0 | D17: 0 | E17: 0 | F17: 0 | G17: 0 | H17: 0 | I17: 0 | J17: 28500000 | K17: 0 | L17: 0 | M17: 28500000 | N17: 0
A18: उंड्री | B18: RI11AG101 | C18: 0 | D18: 0 | E18: 0 | F18: 0 | G18: 0 | H18: 0 | I18: 0 | J18: 33100000 | K18: 0 | L18: 0 | M18: 33100000 | N18: 0
A19: धायरी | B19: RI11AH101 | C19: 0 | D19: 0 | E19: 0 | F19: 0 | G19: 0 | H19: 0 | I19: 0 | J19: 47600000 | K19: 0 | L19: 0 | M19: 47600000 | N19: 0
A20: आंबेगाव बुद्रुक | B20: RI11AJ101 | C20: 0 | D20: 0 | E20: 0 | F20: 0 | G20: 0 | H20: 0 | I20: 0 | J20: 73000000 | K20: 0 | L20: 0 | M20: 73000000 | N20: 0
A21: फुरसुंगी | B21: RI11AK101 | C21: 0 | D21: 0 | E21: 0 | F21: 0 | G21: 0 | H21: 0 | I21: 0 | J21: 85000000 | K21: 0 | L21: 0 | M21: 85000000 | N21: 0
A22: उरुळी देवाची | B22: RI11AL101 | C22: 0 | D22: 0 | E22: 0 | F22: 0 | G22: 0 | H22: 0 | I22: 0 | J22: 30200000 | K22: 0 | L22: 0 | M22: 30200000 | N22: 0
... A25: ४. पुणे वाहन व्यवहार खात्याकडील मिळकतींवरील कर (कआकसंप्र) | B25: RI11A104 | C25: 8123432 | D25: 26466145 | E25: 14042374 | F25: 4782935 | G25: 9081253 | H25: 20000000 | I25: 20000000 | J25: 10000000 | K25: 0 | L25: 0 | M25: 0 | N25: 10000000
C26: 0 | D26: 0 | E26: 0 | F26: 0 | G26: 0 | H26: 0 | I26: 0 | J26: 0 | K26: 0 | L26: 0 | M26: 0 | N26: 0
A27: क. सर्वसाधारण कर बेरीज | C27: 2521171745 | D27: 3485431565 | E27: 3814921689 | F27: 1680350959 | G27: 2253244415 | H27: 6910000000 | I27: 6910000000 | J27: 6711400000 | K27: 0 | L27: 0 | M27: 0 | N27: 198600000
C28: 0 | D28: 0 | E28: 0 | F28: 0 | G28: 0 | H28: 0 | I28: 0 | J28: 0 | K28: 0 | L28: 0 | M28: 0 | N28: 0
A29: ख. आयातकर | C29: 0 | D29: 0 | E29: 0 | F29: 0 | G29: 0 | H29: 0 | I29: 0 | J29: 0 | K29: 0 | L29: 0 | M29: 0 | N29: 0
A30: १. पक्की जमा (आ.क.प्र.) | B30: RI11B101 | C30: 87959085 | D30: 134378501 | E30: -10809081 | F30: -10809081 | G30: 235776 | H30: 0 | I30: 0 | J30: 0 | K30: 0 | L30: 0 | M30: 0 | N30: 0
C31: 0 | D31: 0 | E31: 0 | F31: 0 | G31: 0 | H31: 0 | I31: 0 | J31: 0 | K31: 0 | L31: 0 | M31: 0 | N31: 0
A32: निव्वळ जमा | C32: 87959085 | D32: 134378501 | E32: -10809081 | F32: -10809081 | G32: 235776 | H32: 0 | I32: 0 | J32: 0 | K32: 0 | L32: 0 | M32: 0 | N32: 0
C33: 0 | D33: 0 | E33: 0 | F33: 0 | G33: 0 | H33: 0 | I33: 0 | J33: 0 | K33: 0 | L33: 0 | M33: 0 | N33: 0
A34: ट्रॅन्झिट फी (रहदारी फी) (आ.क.प्र.) | B34: RI11B105 | C34: 136555000 | D34: 0 | E34: 0 | F34: 0 | G34: 0 | H34: 0 | I34: 0 | J34: 0 | K34: 0 | L34: 0 | M34: 0 | N34: 0
C35: 0 | D35: 0 | E35: 0 | F35: 0 | G35: 0 | H35: 0 | I35: 0 | J35: 0 | K35: 0 | L35: 0 | M35: 0 | N35: 0
A36: बेरीज | C36: 224514085 | D36: 134378501 | E36: -10809081 | F36: -10809081 | G36: 235776 | H36: 0 | I36: 0 | J36: 0 | K36: 0 | L36: 0 | M36: 0 | N36: 0
C37: 0 | D37: 0 | E37: 0 | F37: 0 | G37: 0 | H37: 0 | I37: 0 | J37: 0 | K37: 0 | L37: 0 | M37: 0 | N37: 0
A38: ख. निव्वळ आयातकर एकूण बेरीज | C38: 224514085 | D38: 134378501 | E38: -10809081 | F38: -10809081 | G38: 235776 | H38: 0 | I38: 0 | J38: 0 | K38: 0 | L38: 0 | M38: 0 | N38: 0
C39: 0 | D39: 0 | E39: 0 | F39: 0 | G39: 0 | H39: 0 | I39: 0 | J39: 0 | K39: 0 | L39: 0 | M39: 0 | N39: 0
A40: ख-१. स्थानिक संस्था कर | C40: 0 | D40: 0 | E40: 0 | F40: 0 | G40: 0 | H40: 0 | I40: 0 | J40: 0 | K40: 0 | L40: 0 | M40: 0 | N40: 0
A41: स्थानिक संस्था कर नोंदणी शुल्क | B41: RI11B201 | C41: 275729 | D41: 65050 | E41: -3033323 | F41: -3034348 | G41: 375 | H41: 0 | I41: 0 | J41: 0 | K41: 0 | L41: 0 | M41: 0 | N41: 0
A42: स्थानिक संस्था कर | B42: RI11B202 | C42: 9885567929 | D42: 6697263834 | E42: 3919870123 | F42: 2193581335 | G42: 1486050555 | H42: 5000000000 | I42: 5000000000 | J42: 10000000 | K42: 0 | L42: 0 | M42: 0 | N42: 4990000000
A43: चौरस मीटर बांधकामाप्रमाणे भरावयाची ठोक रक्कम | B43: RI11B202B | C43: 326733396 | D43: 218475764 | E43: 152493815 | F43: 101269415 | G43: 73722887 | H43: 170000000 | I43: 170000000 | J43: 0 | K43: 0 | L43: 0 | M43: 0 | N43: 170000000
A44: कंत्राटदाराने एकूण उलाढाल / करारानुसार ०.२५ % भरावयाची रक्कम | B44: RI11B202C | C44: 3925 | D44: 1153 | E44: 0 | F44: 0 | G44: 0 | H44: 0 | I44: 0 | J44: 0 | K44: 0 | L44: 0 | M44: 0 | N44: 0
...

Sheet A_Revenue_Expenditure
A1: योजनेतर खर्च तपशील
A2: विवरण | D2: नक्‍की आकडा | G2: मान्य अंदाज 2017-18 | H2: नवीन अंदाज 2018-19
D3: 2014-15 | E3: 2015-16 | F3: 2016-17
A5: १. मुख्य देखरेख, वसुली वगैरे | D5: 0 | E5: 0 | F5: 0 | G5: 0 | H5: 0
A6: क. महानगरपालिका व स्थायी समिती | D6: 0 | E6: 0 | F6: 0 | G6: 0 | H6: 0
A7: १ नगरसचिव यांचे कार्यालय | D7: 0 | E7: 0 | F7: 0 | G7: 0 | H7: 0
A8: १. नगरसचिव (म्युनिसिपल सेक्रेटरी) (मुं.प्रां. मनपा अधिनियम, कलम४५(३) प्रमाणे) वेतन | B8: RE11A101A | D8: 1101057 | E8: 1191964 | F8: 1345488 | G8: 2000000 | H8: 1500000
A9: २. कायम सेवकवर्ग वेतन | B9: RE11A102A | D9: 33475150 | E9: 35806543 | F9: 38012640 | G9: 45000000 | H9: 45000000
A10: ३. संकीर्ण (न.स.) | B10: RE11A103 | D10: 5578556 | E10: 5089168 | F10: 5914622 | G10: 10000000 | H10: 10000000
A11: ३अ. मागील बिले देण्यासाठी (न.स.) | B11: RE11A103A | D11: 643043 | E11: 713127 | F11: 2128349 | G11: 4000000 | H11: 4000000
A12: ४. प्रवास खर्च (न.स.) | B12: RE11A104 | D12: 3362 | E12: 35220 | F12: 12586 | G12: 1600000 | H12: 1800000
A13: ५. ग्रंथालय व वाचनालय | B13: RE11A105 | D13: 148487 | E13: 189830 | F13: 179955 | G13: 200000 | H13: 200000
A14: ६. समारंभ खर्च (न.स. व वि.अ.) | B14: RE11A106 | D14: 253700 | E14: 158700 | F14: 0 | G14: 500000 | H14: 500000
A15: १०. अखिल भारतीय/महाराष्ट्र महापौर परिषद व अखिल भारतीय स्थानिक स्वराज्य संस्था प्रतिनिधी अधिवेशन | B15: RE11A110 | D15: 1800 | E15: 0 | F15: 0 | G15: 160000 | H15: 200000
A16: ११. मनपा व शासकीय निवृत्त सेवकांना द्यावयाचा चहापान खर्च | B16: RE11A111 | D16: 73480 | E16: 46400 | F16: 780 | G16: 300000 | H16: 300000
A17: १३. महाराष्ट्र राज्य महानगरपालिका स्थायी समिती अध्यक्ष परिषद वर्गणी व तद्‌नुषंगिक खर्च | B17: RE11A113 | D17: 0 | E17: 0 | F17: 0 | G17: 800 | H17: 1000
A18: १४. मा. महापौर यांचा व्ययनियमन (सम्प्च्युअरी) भत्ता | B18: RE11A114 | D18: 0 | E18: 0 | F18: 0 | G18: 4000 | H18: 5000
A19: १५. मा. महापौर यांचा ऐच्छिक खर्च | B19: RE11A115 | D19: 260496 | E19: 290981 | F19: 159775 | G19: 200000 | H19: 200000
... A51: देशी खेळांना प्रोत्साहन देण्याकरिता शिबिरे व स्पर्धा आयोजित करणे. | B51: RE11A279 | D51: 0 | E51: 0 | F51: 0 | G51: 1000000 | H51: 0
D52: 0 | E52: 0 | F52: 0 | G52: 0 | H52: 0
A53: क. मनपा व स्थायी समिती बेरीज | D53: 69785307 | E53: 88248698 | F53: 111232206 | G53: 163519600 | H53: 150104000
D54: 0 | E54: 0 | F54: 0 | G54: 0 | H54: 0
A55: ख. मुख्य लेखापरिक्षक यांचे कार्यालय | D55: 0 | E55: 0 | F55: 0 | G55: 0 | H55: 0
A56: १. मुख्य लेखापरिक्षक (म्युनिसिपल चीफ ऑडिटर) (मु.प्रां. मनपा अधिनियम, कलम ४५ (३) प्रमाणे) यांचे वेतन | B56: RE11B101A | D56: 1626729 | E56: 1755460 | F56: 1610523 | G56: 2500000 | H56: 2500000
A57: २. कायम सेवकवर्ग वेतन | B57: RE11B102A | D57: 24303637 | E57: 28145211 | F57: 27837708 | G57: 32500000 | H57: 32500000
A58: ३. संकीर्ण | B58: RE11B103 | D58: 56982 | E58: 96249 | F58: 53529 | G58: 270000 | H58: 300000
D59: 0 | E59: 0 | F59: 0 | G59: 0 | H59: 0
A60: ख. मुख्यलेखापरिक्षक यांचे कार्या. बेरीज | D60: 25987348 | E60: 29996920 | F60: 29501760 | G60: 35270000 | H60: 35300000
D61: 0 | E61: 0 | F61: 0 | G61: 0 | H61: 0
A62: ग१. महापालिका आयुक्त यांचे कार्यालय | D62: 0 | E62: 0 | F62: 0 | G62: 0 | H62: 0
A63: १. महापालिका आयुक्त (म्युनिसिपल कमिशनर) (मु. प्रां. मनपा अधिनियम, कलम ३७ (१) प्रमाणे) यांचे वेतन | B63: RE11C101A | D63: 2711973 | E63: 1744095 | F63: 2174568 | G63: 3000000 | H63: 3000000
A64: २. उपआयुक्त (जनरल) (मुं. प्रां. मनपा अधिनियम, कलम ४५(३) प्रमाणे) यांचे वेतन | B64: RE11C102A | D64: 1139336 | E64: 1051185 | F64: 558905 | G64: 2000000 | H64: 2200000
A65: ३. कायम सेवकवर्ग वेतन | B65: RE11C103A | D65: 16474467 | E65: 15941845 | F65: 25487531 | G65: 25000000 | H65: 30000000
A66: ४. संकीर्ण | B66: RE11C104 | D66: 666868 | E66: 1929754 | F66: 1172964 | G66: 1350000 | H66: 1500000
A67: ६. मा. महापालिका आयुक्त यांचा ऐच्छिक खर्च (म.स.आ.) | B67: RE11C106 | D67: 0 | E67: 0 | F67: 0 | G67: 504000 | H67: 800000
D68: 0 | E68: 0 | F68: 0 | G68: 0 | H68: 0
A69: ग१. महापालिका आयुक्त कार्यालय बेरीज | D69: 20992644 | E69: 20666879 | F69: 29393968 | G69: 31854000 | H69: 37500000
D70: 0 | E70: 0 | F70: 0 | G70: 0 | H70: 0
A71: ग२. अतिरिक्त महापालिका आयुक्त (विशेष) यांचे कार्यालय | D71: 0 | E71: 0 | F71: 0 | G71: 0 | H71: 0
A72: १. अतिरिक्त महापालिका आयुक्त (विशेष) यांचे वेतन | B72: RE11C126A | D72: 756064 | E72: 945856 | F72: 1172527 | G72: 3000000 | H72: 3000000
...

Sheet A_Revenue_List
F1: प्रकल्पीय रक्कम | G1: 1819 आयुक्त
A3: यादी क्र. R1
A4: थोर व्यक्तींच्या जयंती / पुण्यतिथी साजरी करणे
A5: RE11A274/R1-
A7: क्र. | B7: code | C7: ward | E7: कामाचे नाव | F7: प्रकल्पीय रक्कम | G7: तरतूद
A9: 1 | B9: RE11A274/R1-1 | E9: महात्मा फुले जयंती | G9: 100000
A10: 2 | B10: RE11A274/R1-2 | E10: डॉ. बाबासाहेब आंबेडकर जयंती | G10: 150000
A11: 3 | B11: RE11A274/R1-3 | E11: लोकशाहीर अण्णाभाऊ साठे जयंती | G11: 200000
A12: 4 | B12: RE11A274/R1-4 | E12: ईद-ए-मिलाद (पैगंबर जयंती) | G12: 150000
A13: 5 | B13: RE11A274/R1-5 | E13: शहरातील शिवजयंती साजरी करणे, रोषणाई करणे | G13: 200000
A14: 6 | B14: RE11A274/R1-6 | E14: महात्मा फुले यांची पुण्यतिथी साजरी करणे (दि. 28 नोव्हेंबर) | G14: 500000
A15: 7 | B15: RE11A274/R1-7 | E15: मौलाना अब्दुल कलाम आझाद जयंती व पुण्यतिथी साजरी करणे | G15: 600000
A16: 8 | B16: RE11A274/R1-8 | E16: लहुजी वस्ताद साळवे जयंती महोत्सव गंज पेठ व संगमवाडी येथे साजरा करणे | G16: 500000
A17: 9 | B17: RE11A274/R1-9 | E17: नेताजी सुभाषचंद्र बोस यांची जयंती साजरी करणे | G17: 10000
A18: 10 | B18: RE11A274/R1-10 | E18: येरवडा येथे लोकशाहिर अण्णाभाऊ साठे जयंती महोत्सव साजरा करणे | G18: 100000
A19: 11 | B19: RE11A274/R1-11 | E19: श्री संत रोहिदास महाराज जयंती, पुण्यतिथी साजरी करणे | G19: 50000
A20: 13 | B20: RE11A274/R1-13 | E20: मौलाना अबुल कलाम आझाद जयंती महोत्सव | G20: 500000
A21: 14 | B21: RE11A274/R1-14 | E21: महावीर जयंती | G21: 100000
E23: यादी क्र. R1 एकूण | F23: 0 | G23: 3160000
A26: यादी क्र. R2
A27: शहरामध्ये विविध कार्यक्रम, उत्सव, महोत्सव, संमेलन/ सहप्रायोजक तत्वावर कार्यक्रम साजरे करणे
A28: RE11A275/R2-
A30: क्र. | B30: code | C30: ward | E30: कामाचे नाव | F30: प्रकल्पीय रक्कम | G30: तरतूद
A32: 1 | B32: RE11A275/R2-1 | E32: महानगरपालिका वर्धापन दिन / सुवर्ण महोत्सव साजरा करणे | G32: 700000
A33: 2 | B33: RE11A275/R2-2 | E33: वर्षातील महत्त्वपूर्ण दिन | G33: 600000
A34: 3 | B34: RE11A275/R2-3 | E34: शिवाजीमहाराज आग्र्‍याहून सुटून परत आले तो स्मृती दिन साजरा करणे | G34: 515000
A35: 4 | B35: RE11A275/R2-4 | E35: शनिवारवाडा सांस्कृतिक महोत्सव | G35: 2000000
A36: 5 | B36: RE11A275/R2-5 | E36: भारतरत्न डॉ. बाबासाहेब आंबेडकर सांस्कृतिक महोत्सव साजरा करणे/ भिम फेस्टिवल (शनिवारवाडा पटांगण) / फुले आंबेडकर फेस्टिवल (समताभूमी) | G36: 2000000
A37: 6 | B37: RE11A275/R2-6 | E37: शिवमहोत्सव साजरा करणे (१४ ते २० फेब्रुवारी) | G37: 2000000
A38: 7 | B38: RE11A275/R2-7 | E38: अण्णाभाऊ साठे महोत्सव | G38: 2000000
A39: 8 | B39: RE11A275/R2-8 | E39: जागतिक आदिवासी दिन | G39: 500000
E41: यादी क्र. R2 एकूण | F41: 0 | G41: 10315000
A44: यादी क्र. R3
A45: सत्कार, अभिनंदन, पुरस्कार, बक्षिसे यासारखे कार्यक्रम साजरे करणे
A46: RE11A276/R3-
A48: क्र. | B48: code | C48: ward | E48: कामाचे नाव | F48: प्रकल्पीय रक्कम | G48: तरतूद
A50: 1 | B50: RE11A276/R3-1 | E50: गणेशोत्सव प्रशस्तिपत्रके वितरण | G50: 1000000
A51: 2 | B51: RE11A276/R3-2 | E51: श्री. संत ज्ञानेश्वर व तुकाराम महाराज पालखी स्वागत व दिंडी प्रमुखांचा स्मृतीचिन्ह देऊन सत्कार | G51: 1000000
A52: 3 | B52: RE11A276/R3-3 | E52: प्रतिवर्षी पुणे शहरातील इयत्ता १० वी, १२ वी परिक्षेत गुणवत्ता यादीत येणार्‍या विद्यार्थ्यांचे अभिनंदन | G52: 60000
A53: 4 | B53: RE11A276/R3-4 | E53: बालगंधर्व पुरस्कार प्रदानकरिता | G53: 500000
...

Sheet A_Capital_Expenditure
A1: सन 2018-19 चे योजनांतर्गत | I1: खर्चाबाबतचे अंदाजपत्रक
A2: अनुक्रमांक | B2: मान्यतेचा ठराव क्र. दिनांक (कोड) | C2: प्रभाग क्रमांक | D2: BPL | E2: कामाचे नाव अगर वर्णन | F2: दि. 31 मार्च 2018 अखेरपर्यंत केलेली तरतूद | I2: दि. 31 मार्च 2017 पर्यंतचा खर्चाचा नक्‍की आकडा | J2: 2017-18 मधील खर्चाची अंदाजी रक्कम | L2: 2018-19 साठी अधिक तरतूद | N2: 2018-19 साठी एकूण तरतूद | O2: प्रकल्पीय रक्कम
F3: कर्जातून | G3: महसूल निधीतून | H3: एकूण | J3: प्रत्यक्ष उपलब्ध तरतूद | K3: कर्जातून तरतूद | L3: कर्जातून | M3: महसूल निधी व इतर निधी
E8: १. मनपा भवन व मनपा इमारती | F8: 0 | G8: 0 | H8: 0 | I8: 0 | J8: 0 | M8: 0 | N8: 0
A9: 1 | B9: CE11A122 | C9: G | E9: मनपा भवन येथे विस्तारित इमारत बांधणे व पुणे मनपा मिळकतीमध्ये क्षेत्रिय कार्यालय/ प्रशासकिय इमारतीचे विस्तारीकरण करणे | F9: 0 | G9: 110042095 | H9: 110042095 | I9: 110042095 | J9: 0 | M9: 0 | N9: 0 | O9: 200000000
A10: 2 | B10: CE11A129# | C10: J1- | D10: _ | E10: शहरात विविध ठिकाणी मनपासाठी इमारती बांधणे व विकास कामे करणे | F10: 0 | G10: 619391500 | H10: 619391500 | I10: 213494607 | J10: 405896893 | M10: 67500000 | N10: 67500000
F11: 0 | G11: 0 | H11: 0 | I11: 0 | J11: 0 | M11: 0 | N11: 0
E12: १. मनपा भवन व मनपा इमारती एकूण बेरीज | F12: 0 | G12: 729433595 | H12: 729433595 | I12: 323536702 | J12: 405896893 | M12: 67500000 | N12: 67500000
F13: 0 | G13: 0 | H13: 0 | I13: 0 | J13: 0 | M13: 0 | N13: 0
E14: २. प्राथमिक शिक्षण | F14: 0 | G14: 0 | H14: 0 | I14: 0 | J14: 0 | M14: 0 | N14: 0
A15: 1 | B15: CE12A264 | C15: G | D15: P | E15: पुणे शहरातील प्राथमिक शाळांमध्ये वर्गखोल्या, सिमाभिंत, स्वच्छतागृह, वॉचमन क्वॉर्टर, वॉटर प्रुफिंग, पाण्याची व्यवस्था व इतर तद्‌नुषंगिक कामे व देखभाल दुरूस्तीची कामे करणे | F15: 0 | G15: 99322156 | H15: 99322156 | I15: 99322156 | J15: 0 | M15: 0 | N15: 0 | O15: 37500000
A16: 2 | B16: CE12A381# | C16: J11- | D16: _ | E16: प्राथमिक शाळेमध्ये मुलभूत सोयी सुविधांसाठी विविध विकासकामे करणे | F16: 0 | G16: 1086115286 | H16: 1086115286 | I16: 962003220 | J16: 124112066 | M16: 292800000 | N16: 292800000
A17: 3 | B17: CE12A400 | C17: 67 | D17: P | E17: वि.स.खांडेकर शाळा दुसर्‍या मजल्यावर नविन ६ वर्ग खोल्या बांधणे | F17: 0 | G17: 5464342 | H17: 5464342 | I17: 5464342 | J17: 0 | M17: 0 | N17: 0
A18: 4 | B18: CE12A411 | C18: 67 | D18: P | E18: वॉर्ड क्र.११६ फायनल प्लॉट क्र.४७८ पर्वती येथील राजीव गांधी प्रायमरी शाळेचे उर्वरित काम पुर्ण करणे | F18: 0 | G18: 49557496 | H18: 49557496 | I18: 49557496 | J18: 0 | M18: 0 | N18: 0
A19: 5 | B19: CE12A412 | C19: 53 | D19: P | E19: वॉर्ड क्र. १२७ मधील हिंगणे खुर्द शाळा क्र. १६८ शाळेचा हॉल व वर्गखोल्या बांधणे व नुतनीकरण करणे | F19: 0 | G19: 4248634 | H19: 4248634 | I19: 4248634 | J19: 0 | M19: 0 | N19: 0
A20: 6 | B20: CE12A413 | C20: 43 | E20: वॉ.क्रं.९३ साधना विद्यालय येथे शाळा बांधणे | F20: 0 | G20: 19135330 | H20: 19135330 | I20: 19135330 | J20: 0 | M20: 0 | N20: 0
A21: 7 | B21: CE12A414 | C21: 36 | E21: एरंडवणा येथील मनपा च्या ताब्यात आलेल्या सन-डयु अपार्टमेंट या ठिकाणी इमारतीत प्राथमिक शाळेसाठी विविध विकासाची कामे करणे | F21: 0 | G21: 16701860 | H21: 16701860 | I21: 16701860 | J21: 0 | M21: 0 | N21: 0
A22: 9 | B22: CE12A417 | E22: मनपाच्या अस्तित्वात असलेल्या शाळा इमारतींमध्ये मुलींसाठी नवीन स्वच्छतागृहे बांधणे | F22: 0 | G22: 21655528 | H22: 21655528 | I22: 21655528 | J22: 0 | M22: 0 | N22: 0
A23: 12 | B23: CE12A420 | C23: 62 | E23: प्र.क्र.६२ कोंढवा बु. येथे शाळा इमारत बांधणे. | F23: 0 | G23: 5118234 | H23: 5118234 | I23: 5118234 | J23: 0 | M23: 0 | N23: 0
A24: 13 | B24: CE12A421 | E24: पुणे शहरातील मध्यवर्ती भागाच्या मनपा शाळांमध्ये विविध दुरूस्त्या व विकासकामे करणे | F24: 0 | G24: 5658310 | H24: 5658310 | I24: 5658310 | J24: 0 | M24: 0 | N24: 0
A25: 14 | B25: CE12A422# | C25: J2- | D25: _ | E25: प्राथमिक शाळेसाठी नवीन इमारत बांधणे | F25: 0 | G25: 432045500 | H25: 432045500 | I25: 61570297 | J25: 370475203 | M25: 21000000 | N25: 21000000
A26: 15 | B26: CE12A423# | C26: _ | D26: _ | E26: प्राथमिक शाळेसाठी वर्गखोल्या बांधणे | F26: 0 | G26: 61484000 | H26: 61484000 | I26: 48906901 | J26: 12577099 | M26: 0 | N26: 0
A27: 16 | B27: CE12A424# | C27: _ | D27: _ | E27: प्राथमिक शाळांची मैदाने विकसित करणे | F27: 0 | G27: 30727500 | H27: 30727500 | I27: 10533916 | J27: 20193584 | M27: 0 | N27: 0
A28: 18 | B28: #+ | E28: सन २०१४-१५ मधील अपूर्ण कामांसाठी सन २०१५-१६ मध्ये उपलब्ध केलेली तरतूद | F28: 0 | G28: 65921767 | H28: 65921767 | I28: 65921767 | J28: 0 | M28: 0 | N28: 0
F29: 0 | G29: 0 | H29: 0 | I29: 0 | J29: 0 | M29: 0 | N29: 0
E30: २. प्राथमिक शिक्षण एकूण बेरीज | F30: 0 | G30: 2002792660 | H30: 2002792660 | I30: 1475434708 | J30: 527357952 | M30: 313800000 | N30: 313800000
F31: 0 | G31: 0 | H31: 0 | I31: 0 | J31: 0 | M31: 0 | N31: 0
E32: ३. दुय्यम शिक्षण | F32: 0 | G32: 0 | H32: 0 | I32: 0 | J32: 0 | M32: 0 | N32: 0
A33: 1 | B33: CE13A128# | C33: J5- | E33: माध्यमिक शाळांमध्ये मुलभूत सोयी सुविधांसाठी विविध विकासकामे करणे | F33: 0 | G33: 17145412 | H33: 17145412 | I33: 14931759 | J33: 2213653 | M33: 2500000 | N33: 2500000
A34: 2 | B34: CE13A215 | D34: PL | E34: मनपा शाळांमध्ये मुलींसाठी स्वच्छतागृहे बांधणे | F34: 0 | G34: 27758288 | H34: 27758288 | I34: 27758288 | J34: 0 | M34: 0 | N34: 0
F35: 0 | G35: 0 | H35: 0 | I35: 0 | J35: 0 | M35: 0 | N35: 0
E36: ३. दुय्यम शिक्षण एकूण बेरीज | F36: 0 | G36: 44903700 | H36: 44903700 | I36: 42690047 | J36: 2213653 | M36: 2500000 | N36: 2500000
F37: 0 | G37: 0 | H37: 0 | I37: 0 | J37: 0 | M37: 0 | N37: 0
E38: ७. आरोग्य विभाग | F38: 0 | G38: 0 | H38: 0 | I38: 0 | J38: 0 | M38: 0 | N38: 0
A39: 2 | B39: CE17A192# | C39: J13- | D39: _ | E39: दवाखान्यातील मुलभूत सोयी सुविधांसाठी विविध विकासकामे करणे | F39: 0 | G39: 570695045 | H39: 570695045 | I39: 530104452 | J39: 40590593 | M39: 29500000 | N39: 29500000
A40: 3 | B40: CE17A205 | C40: 28 | D40: L | E40: सुतार रुग्णालय (कोथरूड) येथे विस्तारीकरण व इतर सुविधा पुरविणे | F40: 0 | G40: 30242691 | H40: 30242691 | I40: 30242691 | J40: 0 | M40: 0 | N40: 0
A41: 4 | B41: CE17A206 | C41: 23 | D41: L | E41: कमला नेहरू रुग्णालय प्रोजेक्ट अंतर्गत विविध उपकरणे खरेदी व तद्‌नुषंगिक कामे करणे | F41: 0 | G41: 258881822 | H41: 258881822 | I41: 258881822 | J41: 0 | M41: 0 | N41: 0
A42: 5 | B42: CE17A217 | D42: PL | E42: शहरातील इतर सर्व दवाखाने, प्रसुतिगृहे व रुग्णालये यांचेकरिता विविध शस्त्रे व उपकरणे खरेदी करणे | F42: 0 | G42: 201470861 | H42: 201470861 | I42: 201470861 | J42: 0 | M42: 0 | N42: 0
A43: 6 | B43: CE17A218 | D43: PL | E43: डॉ. नायडू हॉस्पिटल प्रोजेक्ट | F43: 0 | G43: 4409032 | H43: 4409032 | I43: 4409032 | J43: 0 | M43: 0 | N43: 0
A44: 7 | B44: CE17A227# | C44: J12- | D44: _ | E44: शहरातील विविध स्मशानभूमी / दफनभूमी साठी विविध विकासकामे करणे | F44: 0 | G44: 403698045 | H44: 403698045 | I44: 269818495 | J44: 133879550 | M44: 50000000 | N44: 50000000
...

Sheet A_Land_Acquisition
A1: सन 2018-19 चे अंदाजपत्रक - खास निधीतून करावयाची योजनांतर्गत कामे
A2: अनुक्रमांक | C2: कामाचे नाव | D2: मान्य अंदाज 2017-18 | E2: नवीन अंदाज 2018-19
A7: (अ) | C7: भूमी संपादन निधीतून करावयाचा खर्च | D7: 0 | E7: 0
D8: 0 | E8: 0
A9: 1 | B9: FE11A101 | C9: भूमी संपादन विशेष अधिकारी यांचा कार्यालयीन खर्च - | D9: 30000000 | E9: 30000000
A10: 2 | C10: कोर्टाच्या निकालानुसार वाढीव नुकसानभरपाई कोर्ट खर्च, वकील फी, जॉइन्ट जज्ज यांचा खर्च वगैरे | D10: 0 | E10: 0
A11: 3 | C11: भूमी संपादन अधिनियमात नव्याने केलेल्या दुरुस्तीमुळे यापूर्वी जाहीर झालेल्या योजनापोटी ावयाच्या वाढीव रकमेचा खर्च | D11: 0 | E11: 0
A12: 4 | C12: परचेस नोटीसांमुळे (नवीन) पाठवावयाच्या भूमी संपादन योजनांसाठी तरतूद | D12: 0 | E12: 0
A13: 5 | C13: ताब्यात घेतलेल्या मिळकती पाडणे, ड्रेनेज, वॉटर, इलेक्ट्रीक टेलिफोन वगैरे कनेक्शन्स हलविणे, जोडणे व इतर तद्‌नुषंगिक कामे करणे. | D13: 0 | E13: 0
A14: 6 | C14: कार्यालयीन कामासाठी साधने, डेडस्टॉक वस्तू खरेदी करणे, हत्यारे खरेदी करणे, कार्यालय व कोठीची दुरुस्ती करणे, आवश्यक सुधारणा करणे, प्रकटन खर्च, प्रवास खर्च वगैर | D14: 0 | E14: 0
A15: 7 | C15: मुंबई प्रांतिक मनपा अधिनियम १९४९ च्या कलम २१३ अन्वये रस्तारूंदीसाठी ताब्यात घेतलेल्या मोकळ्या जागा व त्याप्रित्यर्थ ावयाची नुकसानभरपाईची रक्कम | D15: 0 | E15: 0
A16: 8 | C16: इतर योजनांमधील मोजणी फी व इतर तद्‌नुषंगिक रक्कम | D16: 0 | E16: 0
A17: 9 | C17: भूमी संपादन अधिकारी ह्यांचेकडील खालील नमूद केलेल्या ज्या जागांचे निवाडे जाहीर करतील त्यासाठी रक्कम | D17: 0 | E17: 0
A18: 10 | C18: संगणक दुरूस्ती व आवश्यक साहित्य | D18: 0 | E18: 0
D19: 0 | E19: 0
C20: (अ) बेरीज | D20: 30000000 | E20: 30000000
D21: 0 | E21: 0
D22: 0 | E22: 0
B23: FE11A102 | C23: भूसंपादनासाठी आवश्यक जागांची यादी :- | D23: 470000000 | E23: 470000000
D24: 0 | E24: 0
C25: सी.वाय.जी अंतर्गत रस्ते : | D25: 0 | E25: 0
C26: बाणेर मुख्य रस्ता २६१ ते १०५ | D26: 0 | E26: 0
C27: बाणेर स.क्र. १३३ ते बालेवाडी स.क्र. १० बालेवाडीकडे जाणारा रस्ता मुख्य रस्ता (बालेवाडी) | D27: 0 | E27: 0
C28: बालेवाडी स.क्र. ३४, ३५ जी१ गार्डनचे आरक्षण | D28: 0 | E28: 0
C29: बाणेर स.क्र. २८, २९० जी२ गार्डनचे आरक्षण व बाणेर स.क्र. ३५ जी३ गार्डनचे आरक्षण | D29: 0 | E29: 0
C30: कल्याणीनगर जंक्शन ते आळंदी रोड | D30: 0 | E30: 0
C31: बाणेर स.क्र. १०५, १०६, ११०, १११ पीएमटी१ | D31: 0 | E31: 0
C32: बाणेर स.क्र. ३३ पी.३ | D32: 0 | E32: 0
C33: बाणेर स.क्र. १०० पी.४ | D33: 0 | E33: 0
C34: बाणेर स.क्र. १७४ पी.४ | D34: 0 | E34: 0
C35: बाणेर स.क्र. ७९ पी.६ | D35: 0 | E35: 0
C36: बाणेर स.क्र. १०५, १०६ पी.७ पार्किंगचे आरक्षण | D36: 0 | E36: 0
... C42: एअरपोर्ट रोड ते डेक्कन कॉलेज व्हाया हॉटमिक्स प्लँट | D42: 0 | E42: 0
D43: 0 | E43: 0
C44: जेएनएनयुआरएम / बीआरटी अंतर्गत रस्ते : | D44: 0 | E44: 0
C45: बाणेर स.क्र. १०७, १०८ व ११० मधून जाणारा १८ मी. रस्ता. | D45: 0 | E45: 0
C46: मौजे खराडी ता. हवेली, संगमवाडी ते खराडी २४ मी. नदीकाठचा डी.पी. रस्ता | D46: 0 | E46: 0
C47: मौजे वडगांव शेरी ता. हवेली, संगमवाडी ते खराडी २४ मी. नदीकाठचा डी.पी. रस्ता | D47: 0 | E47: 0
C48: सिंहगड रस्ता महानगरपालिका हद्द दरम्यान नियोजनाते विकसीत करणे (वडगांव बुद्रुक) | D48: 0 | E48: 0
C49: सिंहगड रस्ता महानगरपालिका हद्द दरम्यान नियोजनाते विकसीत करणे (वडगांव खुर्द) | D49: 0 | E49: 0
...

Sheet A_Special_Fund
A1: सन 2018-19 चे उपनगरे विकास निधीचे | I1: योजनांतर्गत खर्चाबाबतचे अंदाजपत्रक
A2: अनुक्रमांक | B2: मान्यतेचा ठराव क्र. दिनांक (कोड) | C2: प्रभाग क्रमांक | D2: BPL | E2: कामाचे नाव अगर वर्णन | F2: दि. 31 मार्च 2018 अखेरपर्यंत केलेली तरतूद | I2: दि. 31 मार्च 2016 पर्यंतचा खर्चाचा नक्‍की आकडा | J2: 2016-17 मधील खर्चाचा नक्‍की आकडा | K2: 2017-18 मधील खर्चाची अंदाजी रक्‍कम | L2: 2018-19 साठी अधिक तरतूद | N2: 2018-19 साठी एकूण तरतूद | O2: शेरा
F3: कर्जातून | G3: महसूल निधीतून | H3: एकूण | L3: कर्जातून | M3: महसूल निधी व इतर निधी
E8: ४. झोपडपट्टी निर्मूलन व पुनर्वसन निधीतून करावयाची कामे | F8: 0 | G8: 0 | H8: 0 | I8: 0 | J8: 0 | K8: 0 | M8: 0 | N8: 0
A9: 1 | B9: FE14A101# | C9: _ | D9: _ | E9: निरनिराळ्या झोपडपट्टींमध्ये विविध विकासाची कामे करणे | F9: 33377000 | G9: 1530296070 | H9: 1563673070 | I9: 1186303250 | J9: 251305849 | K9: 126063971 | M9: 0 | N9: 0
A10: 2 | B10: FE14A104 | D10: B | E10: झो.नि.पु. अंतर्गत करावयाची कामे | F10: 0 | G10: 217214647 | H10: 217214647 | I10: 194201996 | J10: 2087651 | K10: 20925000 | M10: 1200000 | N10: 1200000
A11: 3 | B11: FE14A105# | C11: _ | D11: _ | E11: सुलभ पद्धतीची शौच्छालये बांधणे | F11: 0 | G11: 1371944850 | H11: 1371944850 | I11: 959891297 | J11: 61343612 | K11: 350709941 | M11: 0 | N11: 0
A12: 4 | B12: FE14A107 | D12: B | E12: दलित वस्ती सुधारणा अंतर्गत कामे करणे | F12: 0 | G12: 257194516 | H12: 257194516 | I12: 143291516 | J12: 21525306 | K12: 92377694 | M12: 50000000 | N12: 50000000
A13: 5 | B13: FE14A129 | D13: PL | E13: सार्वजनिक ठिकाणी शौचालय बांधणे | F13: 0 | G13: 49398926 | H13: 49398926 | I13: 28473926 | J13: 5535285 | K13: 15389715 | M13: 12000000 | N13: 12000000
A14: 6 | B14: FE14A130 | D14: PL | E14: सार्वजनिक ठिकाणी मुतार्‍या बांधणे | F14: 0 | G14: 42622473 | H14: 42622473 | I14: 17350588 | J14: 4346885 | K14: 20925000 | M14: 1200000 | N14: 1200000
A15: 7 | B15: FE14A131 | C15: 71 | E15: प्रभाग क्र. ७१ गंगाधाम चौक, नविन डी.पी. रस्ता सुलभ स्वच्छतागृह बांधणे | F15: 0 | G15: 1900000 | H15: 1900000 | I15: 1702765 | J15: 197235 | K15: 0 | M15: 0 | N15: 0
A16: 8 | B16: FE14A132 | C16: 18 | E16: प्रभाग क्र. १८ व वडगाव शेरी परिसरामध्ये विविध ठिकाणी स्वच्छतागृह बांधणे | F16: 0 | G16: 814635 | H16: 814635 | I16: 339297 | J16: 475338 | K16: 0 | M16: 0 | N16: 0
A17: 10 | B17: FE14A134 | E17: सन २०१४-१५ या आर्थिक वर्षातील अपूर्ण कामाच्या बिलासाठी सन १५-१६ च्या अंदाजपत्रकीय तरतुदीमधून ५% वजावट करून प्राप्त झालेली रक्कम | F17: 0 | G17: 2567092 | H17: 2567092 | I17: 2567092 | J17: 0 | K17: 0 | M17: 0 | N17: 0
F18: 0 | G18: 0 | H18: 0 | I18: 0 | J18: 0 | K18: 0 | M18: 0 | N18: 0
E19: ४. झोपडपट्टी निर्मूलन व पुनर्वसन निधीतून करावयाची कामे बेरीज | F19: 33377000 | G19: 3475146259 | H19: 3508523259 | I19: 2535314777 | J19: 346817161 | K19: 626391321 | M19: 64400000 | N19: 64400000
F20: 0 | G20: 0 | H20: 0 | I20: 0 | J20: 0 | K20: 0 | M20: 0 | N20: 0
E21: क्षेत्रिय कार्यालयाने करावयाची कामे :- | F21: 0 | G21: 0 | H21: 0 | I21: 0 | J21: 0 | K21: 0 | M21: 0 | N21: 0
F22: 0 | G22: 0 | H22: 0 | I22: 0 | J22: 0 | K22: 0 | M22: 0 | N22: 0
A23: • | B23: FE14A118# | C23: W5 | D23: B | E23: क्षेत्रिय कार्यालय : झो.नि.पु. विभागाने करावयाची कामे | F23: 0 | G23: 240351629 | H23: 240351629 | I23: 230908835 | J23: 3141990 | K23: 6300804 | M23: 6200000 | N23: 6200000
A24: • | B24: FE14A121# | C24: C5 | D24: B | E24: क्षेत्रिय कार्यालय : नागरिकांच्या सहभाग योजनेतून झो.नि.पु. विभागाने करावयाची कामे | F24: 0 | G24: 136079154 | H24: 136079154 | I24: 132596154 | J24: 3107582 | K24: 375418 | M24: 1700000 | N24: 1700000
F25: 0 | G25: 0 | H25: 0 | I25: 0 | J25: 0 | K25: 0 | M25: 0 | N25: 0
E26: क्षेत्रिय कार्यालयाने करावयाची कामे एकूण बेरीज | F26: 0 | G26: 376430783 | H26: 376430783 | I26: 363504989 | J26: 6249572 | K26: 6676222 | M26: 7900000 | N26: 7900000
F27: 0 | G27: 0 | H27: 0 | I27: 0 | J27: 0 | K27: 0 | M27: 0 | N27: 0
E28: ४. झोपडपट्टी निर्मूलन व पुनर्वसन निधीतून करावयाची कामे + क्षेत्रिय कार्यालयाने करावयाची कामे एकूण बेरीज | F28: 33377000 | G28: 3851577042 | H28: 3884954042 | I28: 2898819766 | J28: 353066733 | K28: 633067543 | M28: 72300000 | N28: 72300000
F29: 0 | G29: 0 | H29: 0 | I29: 0 | J29: 0 | K29: 0 | M29: 0 | N29: 0
E30: ४अ. मागासवर्गीय कल्याणकारी योजना निधी | F30: 0 | G30: 0 | H30: 0 | I30: 0 | J30: 0 | K30: 0 | M30: 0 | N30: 0
A31: 1 | B31: FE14B101 | D31: B-FA | E31: समाज विकास विभाग अंतर्गत मागासवर्गीय योजना | F31: 0 | G31: 434454191 | H31: 434454191 | I31: 364454191 | J31: 31975263 | K31: 38024737 | M31: 37500000 | N31: 37500000
A32: 2 | B32: FE14B112 | D32: B-FA | E32: लोकशाहीर अण्णाभाऊ साठे शैक्षणिक मदत योजना | F32: 0 | G32: 159992082 | H32: 159992082 | I32: 101992082 | J32: 0 | K32: 58000000 | M32: 31000000 | N32: 31000000
A33: 3 | B33: FE14B113 | D33: B-FA | E33: मौ. अबुल कलाम आझाद शैक्षणिक मदत योजना | F33: 0 | G33: 318978546 | H33: 318978546 | I33: 214978546 | J33: 43880000 | K33: 60120000 | M33: 51000000 | N33: 51000000
A34: 6 | B34: FE14B121 | D34: B-T | E34: मागासवर्गीय विद्यार्थ्यांना स्पर्धा परिक्षा मार्गदर्शन केंद्र चालविणे | F34: 0 | G34: 8806896 | H34: 8806896 | I34: 4806896 | J34: 595000 | K34: 3405000 | M34: 2000000 | N34: 2000000
A35: 7 | B35: FE14B122 | D35: B-T | E35: बालविकास केंद्र व वस्ती रिसोर्स सेंटर सुरू करणे | F35: 0 | G35: 11286196 | H35: 11286196 | I35: 5986196 | J35: 1418717 | K35: 3881283 | M35: 2500000 | N35: 2500000
A36: 8 | B36: FE14B123 | D36: B | E36: मागासवर्गीय कल्याणकारी योजनेअंतर्गत विविध योजना राबविणेसाठी मानधन तत्वावरील सेवकांचा मानधन खर्च | F36: 0 | G36: 23029628 | H36: 23029628 | I36: 16029628 | J36: 3487933 | K36: 3512067 | M36: 8500000 | N36: 8500000
A37: 9 | B37: FE14B126 | D37: B | E37: बार्टीचे ४ केंद्र सुरू करणे (कोथरूड, सहकारनगर, शिवाजीनगर, भवानीपेठ) | F37: 0 | G37: 3000000 | H37: 3000000 | I37: 0 | J37: 0 | K37: 3000000 | M37: 0 | N37: 0
A38: 10 | B38: FE14B127 | D38: B | E38: डॉ.बाबासाहेब आंबेडकर यांच्या 125 व्या जयंती निमित्त माता रमार्इ भिमराव आंबेडकर योजनेअंतर्गत गवनि घोषीत व शहरी गरीब योजनेतील पात्र ठरणाऱ्या विधवा, निराधार महिलांसाठी दरमहा रू.1000/- अर्थसहाय्य करणे (मागासवर्गीय कल्याणकारी योजना) | F38: 0 | G38: 50878788 | H38: 50878788 | I38: 878788 | J38: 124000 | K38: 49876000 | M38: 0 | N38: 0
A39: 11 | B39: FE14B128 | D39: B-FA | E39: डॉ. बाबासाहेब आंबेडकर विद्यार्थी वसतिगृह, घोले रोड येथील खाणावळीचा खर्च | F39: 0 | G39: 10000000 | H39: 10000000 | I39: 0 | J39: 0 | K39: 10000000 | M39: 4000000 | N39: 4000000
A40: 12 | B40: FE14B129 | D40: B-I | E40: शहरात आदिवासी विद्यार्थ्यांसाठी वसतिगृहे उभारणे | F40: 0 | G40: 10000000 | H40: 10000000 | I40: 0 | J40: 0 | K40: 10000000 | M40: 10000000 | N40: 10000000
A41: 13 | B41: FE14B130 | E41: बार्टी संस्थेच्या मदतीने विविध व्यावसायिक प्रशिक्षण देणे | F41: 0 | G41: 0 | H41: 0 | I41: 0 | J41: 0 | K41: 0 | M41: 5000000 | N41: 5000000
A42: 14 | B42: FE14B131 | D42: B-T | E42: विविध व्यावसायिक प्रशिक्षण देणे | F42: 0 | G42: 0 | H42: 0 | I42: 0 | J42: 0 | K42: 0 | M42: 5000000 | N42: 5000000
A43: 15 | B43: FE14B132 | D43: B-S | E43: मागासवर्गीय कल्याणकारी योजनेचा अभ्यास, ऑडिट व सर्वेक्षण करणे | F43: 0 | G43: 0 | H43: 0 | I43: 0 | J43: 0 | K43: 0 | M43: 1000000 | N43: 1000000
F44: 0 | G44: 0 | H44: 0 | I44: 0 | J44: 0 | K44: 0 | M44: 0 | N44: 0
...

Sheet A_DPDC_Machinery_Tree
A1: सन 2018-19 चे अंदाजपत्रक – खास निधीतून करावयाची योजनांतर्गत कामे
A2: अनुक्रमांक | B2: विवरण | D2: नक्की आकडा | G2: मान्य अंदाज 2017-18 | H2: नवीन अंदाज 2018-19
D3: 2014-15 | E3: 2015-16 | F3: 2016-17
C7: ५. पुणे जिल्हा नियोजन व विकास मंडळ निधीतून करावयाची कामे
C8: ५अ. मा. आमदारांनी सुचविल्याप्रमाणे करावयाची विकासाची कामे
A9: 1 | B9: FE15A101 | C9: बोपोडी मतदार संघ क्र. २४६ | D9: 0 | E9: 0 | F9: 0 | G9: 5000000 | H9: 5000000
A10: 2 | B10: FE15A102 | C10: शिवाजीनगर मतदार संघ क्र. २४७ | D10: 13029718 | E10: 10537543 | F10: 6974020 | G10: 5000000 | H10: 5000000
A11: 3 | B11: FE15A103 | C11: पर्वती मतदार संघ क्र. २४८ | D11: 2017582 | E11: 3329762 | F11: 6077423 | G11: 5000000 | H11: 5000000
A12: 4 | B12: FE15A104 | C12: कसबा पेठ मतदार संघ क्र. २४९ | D12: 12514432 | E12: 16963092 | F12: 9342997 | G12: 5000000 | H12: 5000000
A13: 5 | B13: FE15A105 | C13: भवानी पेठ मतदार संघ क्र. २५० | D13: 0 | E13: 0 | F13: 0 | G13: 5000000 | H13: 5000000
A14: 6 | B14: FE15A106 | C14: पुणे (कॅन्टोन्मेंट) मतदार संघ क्र. २५१ | D14: 8828578 | E14: 2055269 | F14: 3669469 | G14: 5000000 | H14: 5000000
A15: 7 | B15: FE15A107 | C15: विधान परिषद सदस्य | D15: 669792 | E15: 4063280 | F15: 3175750 | G15: 2500000 | H15: 2500000
D16: 0 | E16: 0 | F16: 0 | G16: 0 | H16: 0
A17: 8 | B17: FE15A108 | C17: ५ब. मा. खासदारांनी सुचविल्याप्रमाणे करावयाची विकासाची कामे | D17: 3109500 | E17: 1785256 | F17: 3969772 | G17: 20000000 | H17: 20000000
D18: 0 | E18: 0 | F18: 0 | G18: 0 | H18: 0
A19: 9 | B19: FE15A110 | C19: महानगरपालिका क्षेत्रात मुलभूत सोईसुविधांसाठी विशेष अनुदान | D19: 21871594 | E19: 56938302 | F19: 37747679 | G19: 0 | H19: 0
A20: 10 | B20: FE15A111 | C20: मुळशी मतदार संघ | D20: 0 | E20: 0 | F20: 0 | G20: 2500000 | H20: 2500000
A21: 11 | B21: FE15A112 | C21: कोथरूड विधानसभा मतदार संघ | D21: 4018776 | E21: 1965863 | F21: 4981436 | G21: 5000000 | H21: 5000000
A22: 12 | B22: FE15A113 | C22: हडपसर विधानसभा मतदार संघ | D22: 2705850 | E22: 231750 | F22: 1365800 | G22: 5000000 | H22: 5000000
A23: 13 | B23: FE15A114 | C23: वडगांवशेरी विधानसभा मतदार संघ | D23: 249992 | E23: 1258089 | F23: 429548 | G23: 5000000 | H23: 5000000
A24: 14 | B24: FE15A115 | C24: खडकवासला विधानसभा मतदार संघ | D24: 254896 | E24: 698976 | F24: 0 | G24: 5000000 | H24: 5000000
A25: 15 | B25: FE15A117 | C25: सर्वसाधारण जिल्हा वार्षिक योजना अंतर्गत नाविन्यपूर्ण योजनांचा निधी | D25: 0 | E25: 0 | F25: 4417087 | G25: 0 | H25: 0
A26: RE53A101 | C26: ५. पुणे जिल्हा नियोजन व विकास मंडळ निधीतून करावयाची कामे बेरीज | D26: 69270710 | E26: 99827182 | F26: 82150981 | G26: 75000000 | H26: 75000000
D27: 0 | E27: 0 | F27: 0 | G27: 0 | H27: 0
D28: 0 | E28: 0 | F28: 0 | G28: 0 | H28: 0
C29: ७. यंत्रसामुग्री घसारा निधीतून विकत घ्याववयाची नवीन सामुग्री | D29: 0 | E29: 0 | F29: 0 | G29: 0 | H29: 0
C30: अग्निशामक दलासाठी यंत्रसामुग्री :- | D30: 0 | E30: 0 | F30: 0 | G30: 0 | H30: 0
B31: FE17A103-1 | C31: वॉटर टँकर पंपासह (2 नग) | D31: 0 | E31: 3921953 | F31: 5629684 | G31: 10000000 | H31: 16000000
B32: FE17A103-2 | C32: फायर इंजिन गाडी (7 नग) | D32: 24000000 | E32: 20520000 | F32: 17850000 | G32: 10000000 | H32: 40000000
B33: FE17A103-4 | C33: हायड्रोलिक प्लॅटफॉर्म | D33: 0 | E33: 0 | F33: 0 | G33: 15000000 | H33: 0
B34: FE17A103-12 | C34: रेस्क्यू इक्वीपमेंट व लाईट मास्ट | D34: 11319330 | E34: 0 | F34: 0 | G34: 10000000 | H34: 0
B35: FE17A103-30 | C35: अल्ट्रा हायप्रेशर पिआर्सी मशीन | D35: 5991000 | E35: 0 | F35: 0 | G35: 0 | H35: 0
B36: FE17A103-31 | C36: मुख्य अग्निशमन अधिकारी यांचे कार्यालय वापरासाठी महेंद्र कंपनीचे स्कॉर्पीओ जीप खरेदी | D36: 0 | E36: 0 | F36: 595000 | G36: 0 | H36: 0
B37: FE17A103-32 | C37: अत्याधुनिक बिनतारी संदेशवहन यंत्रणा उभारणे | D37: 0 | E37: 0 | F37: 0 | G37: 10000000 | H37: 0
B38: FE17A107-23 | C38: आरोग्य विभागाकडील सरासरी आयुर्मान संपलेल्या आर्टीक्युलेटेड क्रेन निरस्त करून नवीन वाहने खरेदी करणे | D38: 0 | E38: 2054871 | F38: 0 | G38: 0 | H38: 0
B39: FE17A113-6 | C39: विद्युत विभाग :- हायड्रॉलिक प्लॅटफॉर्म (2 नग) | D39: 0 | E39: 0 | F39: 0 | G39: 0 | H39: 5000000
B40: FE17A114-6 | C40: बॅकहो लोडर खरेदी करणे | D40: 0 | E40: 0 | F40: 0 | G40: 6000000 | H40: 6000000
B41: FE17A114-9 | C41: पथ विभागासाठी ५ टिपर खरेदी करणे | D41: 0 | E41: 0 | F41: 0 | G41: 51000000 | H41: 20000000
B42: FE17A114-10 | C42: पथ विभागाकडील कोठ्यांसाठी रोलर्स, मिक्‍सर्स, पेव्हर अन्य यंत्रसामुग्री खरेदी करणे | D42: 0 | E42: 0 | F42: 0 | G42: 25000000 | H42: 0
... B102: FE17A298 | C102: प्र.क.५० ब मध्ये घनकचरा व्यवस्थापनासाठी छोटे वाहन खरेदी करणे. | D102: 0 | E102: 466088 | F102: 0 | G102: 0 | H102: 0
...

Sheet A_Capital_List
F1: प्रकल्पीय रक्कम | G1: 1819 आयुक्त | H1: H
A3: पथ विभागाकडील कामाच्या याद्या
A6: यादी क्र. A2
A7: शहरातील रस्ते डांबरीकरणाने विकसित करणे
A8: CE20A102/A2-
A10: क्र. | B10: code | C10: ward | E10: कामाचे नाव | F10: प्रकल्पीय रक्कम | G10: तरतूद
A12: 1 | B12: CE20A102/A2-101 | E12: शिवणे खराडी नदीकाठचा रस्ता विकसित करणेसाठी भूसंपादनासाठी | G12: 20000000
A13: 2 | B13: CE20A102/A2-102 | E13: बावधन स.क्र.24, 49,58 पी.व्ही.आय.पी.आय.टी.येथील 24/18/12 मी. रस्त्याचे विकसन करणे, भूसंपादनासाठी | G13: 10000000
A14: 3 | B14: CE20A102/A2-103 | E14: खडकवासला विधानसभा मतदारसंघ अंतर्गत नवले पुल ते सिंहगड 12 मी डी पी रस्ता दोन्ही बाजुचा सर्व्हिस रस्ता व लगतचे रस्ते करणे, भूसंपादनासाठी | G14: 5000000
A15: 4 | B15: CE20A102/A2-104 | E15: सुस ते पाषाण यांना जोडणार्‍या स.न.१३४ ,१३५,१३६,१३७,१३८ व १४० पाषाण या मिळकतीमधून जाणार्‍या ३६ मी. डी.पी.रस्त्याचे डांबरीकरण / काँक्रिटीकरण करणे, भूसंपादनासाठी | G15: 10000000
A16: 5 | B16: CE20A102/A2-105 | E16: सॅलिसबरी पार्क येथील गिडणी पार्क परिसरामध्ये विविध ठिकाणी मिलींग करुन डांबरीकरण करणे | G16: 10000000
A17: 6 | B17: CE20A102/A2-106 | E17: हडपसर औदयोगिक वसाहतीमधील टाटा हनीवेल कंपनी जवळीलहडपसर औद्योगिक वसाहत ते मगरपट्टच्या मागील 24.00 मी. एच.सी.एम.टी.आर. रस्ता जोडणारया डी.पी. रस्तच्या दोनही कॅनॉलवरील पुल बांधणे. | F17: 50000000 | G17: 20000000
E19: सन 2017-18 मधील अपूर्ण कामांसाठी सन 2018-19 मध्ये उपलब्ध केलेली तरतूद
A20: 7 | B20: CE20A102/A2-1109+ | E20: सन 2016 - 2017 मधील कामे पुर्ण करणेसाठी व जुने देयकासाठी (पेडींग बिलासाठी) | F20: 0 | G20: 200000000
A21: 8 | B21: CE20A102/A2-1427+ | C21: 30.,34 | E21: सिंहगड रस्ता वडगाव बु. स.न. ३० पासून पु.ल. देशपांडे उदयान पर्यंत ७.५ मी. रुंदीचा रस्ता कॅनालच्या कडेने विकसित करणे | F21: 160000000 | G21: 20000000
A22: 9 | B22: CE20A102/A2-1539+ | C22: 41 | E22: हडपसर औोध्योगीक वसाहत येथे कॅनालवर पुल बांधणे. | F22: 60000000 | G22: 15000000
A23: 10 | B23: CE20A102/A2-1546+ | C23: 4 | E23: खराडी येथील ब्लु बेरी व डेक्‍कन गोल्ड येथील अर्धवट असलेला १२मी. डी.पी.रस्ता ६०मी.डी रस्त्यला जोडणे. | F23: 10000000 | G23: 5000000
A24: 11 | B24: CE20A102/A2-1590+ | C24: G | E24: शिवणे खराडी नदीकाठचा रस्ता विकसित करणे (डीफर्ड पेमेंट पदधतीने) | F24: 3650000000 | G24: 300000000
A25: 12 | B25: CE20A102/SA2-296+ | E25: सुस ते पाषाण यांना जोडणार्‍या स.न.१३४ ,१३५,१३६,१३७,१३८ व १४० पाषाण या मिळकतीमधून जाणार्‍या ३६ मी. डी.पी.रस्त्याचे डांबरीकरण / काँक्रिटीकरण करणे. | F25: 100000000 | G25: 10000000
A26: 13 | B26: CE20A102/SA2-524 | E26: बालेवाडी मुख्य रस्त्याची उर्वरित विकास कामे करणे | F26: 10000000 | G26: 10000000
A27: 14 | B27: CE20A102/SA2-724 | C27: 26 | E27: महमंद वाडी प्र.क्र. 26 न्याती क्‍लब समोरील टी रस्ते स.नं. 40, 42 येथील डी.पी. रस्ते तयार करणे. | F27: 28000000 | G27: 10000000
A28: 15 | B28: CE20A102/SA2-772 | C28: 30 | E28: आशा हॉटेल ते म्हसोबा चौक पर्यंतचा 12 मी डी पी रस्ता विकसित करणे | F28: 5000000 | G28: 5000000
A29: 16 | B29: CE20A102/SA2-784 | C29: 31 | E29: तिरुपतीनगर रस्ता विकसित करणे. | F29: 5000000 | G29: 5000000
A30: 17 | B30: CE20A102/SA2-829 | C30: 33 | E30: बावधन खु. फॉर्च्युना बिल्डिंग ते स.नं. १५१ , 24 मी डी.पी. रोड तयार करणे | F30: 30000000 | G30: 5000000
A31: 18 | B31: CE20A102/SA2-911 | C31: 36 | E31: प्रभाग क्र.३६ मधील बिबवेवाडी मुख्य रस्ता विकसित करणे | F31: 286500000 | G31: 110000000
A32: 19 | B32: CE20A102/SA2-914 | C32: 10 | E32: बावधन स.क्र.24, 49,58 पी.व्ही.आय.पी.आय.टी.येथील 24/18/12 मी. रस्त्याचे विकसन करणे. | F32: 40000000 | G32: 5000000
A33: 20 | B33: CE20A102/SA2-920 | C33: 33 | E33: खडकवासला विधानसभा मतदारसंघ अंतर्गत नवले पुल ते सिंहगड 12 मी डी पी रस्ता दोन्ही बाजुचा सर्व्हिस रस्ता व लगतचे रस्ते करणे (डांबरीकरण करणे) | F33: 250000000 | G33: 5000000
E35: यादी क्र. A2 एकूण | F35: 4684500000 | G35: 780000000
A38: यादी क्र. A6
A39: शहरामधील रस्ते विकसित करणे
A40: CE20A1249/A6-
A42: क्र. | B42: code | C42: ward | E42: कामाचे नाव | F42: प्रकल्पीय रक्कम | G42: तरतूद
A44: 1 | B44: CE20A1249/A6-101 | C44: 38 | E44: धनकवडी स. नं. 30,31,32 कात्रज 12 डी. पी. रस्ता विकसीत करणे. | F44: 14000000 | G44: 3000000
A45: 2 | B45: CE20A1249/A6-102 | C45: 38 | E45: धनकवडी स. नं. २३ कात्रज 12 डी. पी. रस्ता विकसीत करणे. | F45: 8000000 | G45: 3000000
A46: 3 | B46: CE20A1249/A6-103 | C46: 39 | E46: धनकवडी मधील आंबेगाव पठार फॉरेस्ट कडेला 18 मी. डी. पी.रस्ता विकसीत करणे. | F46: 15000000 | G46: 3000000
A47: 4 | B47: CE20A1249/A6-104 | C47: 35 | E47: पदमावती सोसायटी ते तीन हत्ती चौकापर्यंतचा कलम २०५ रस्ता विकसीत करणे. | F47: 9000000 | G47: 3000000
A48: 5 | B48: CE20A1249/A6-105 | C48: 35 | E48: धनकवडी मानवेंद्र सोसायटी ते स. नं. 5,6,10 मधुन जाणारा 12 मी. डी. पी. विकसीत करणे. | F48: 10000000 | G48: 3000000
A49: 6 | B49: CE20A1249/A6-106 | C49: 40 | E49: मैत्री चौकालत कात्रज डेअरी उत्तेरेकडील स. नं. १३३ मधुन जाणारा 24 मी. डी. पी. रस्ता विकसीत करणे. | F49: 12000000 | G49: 3000000
A50: 7 | B50: CE20A1249/A6-107 | C50: 40 | E50: कात्रज बायपास रस्ता ते आंबेगाव बु स. नं. २८ कडे जाणारा १८ मी. रूंदीचा रस्ता व सर्व्हिस रस्ता विकसीत करणे. | F50: 15000000 | G50: 5500000
A51: 8 | B51: CE20A1249/A6-108 | C51: 40 | E51: आंबेगाव बु. स. नं.36 व 39 मधील 12 मी. डी. पी. रस्त्यावरील नाल्यावर कर्ल्व्हट करणे व रस्ता करणे. | F51: 15000000 | G51: 3000000
...

Sheet C_Revenue_Income
A1: पाणीपुरवठा व जलोत्सारण प्रकल्पांतर्गत | G1: खास निधी 'क' चा जमेचा गोषवारा व तपशील
A2: विवरण | C2: नक्की आकडा | H2: 2017-18 वर्षाचा अंदाज | J2: 2018-19 वर्षाचा अंदाज | M2: 2017-18 वर्षाच्या मान्य अंदाजाशी तुलना केलेला 2018-19 वर्षाचा मा. महा. आयुक्त यांनी सुचविलेला अंदाज
C3: 2014-15 | D3: 2015-16 | E3: 2016-17 | F3: 2016-17 शेवटची सहामाही | G3: 2017-18 पहिली सहामाही | H3: मान्य अंदाज | I3: दुरूस्त अंदाज | J3: मा. महापालिका आयुक्त यांनी सुचविलेला | K3: मा. स्थायी समितीने मान्यता दिलेला | L3: मा. महानगर- पालिकेने संमत केलेला
M5: अधिक | N5: कमी
A7: अधिनियमाप्रमाणे कमीत कमी रोख शिल्लक ठेवण्याची रक्कम जमेस धरून वर्षारंभीची शिल्लक | C7: 100000 | D7: 100000 | E7: 100000 | F7: 100000 | G7: 0 | H7: 100000 | I7: 100000 | J7: 100000 | K7: 0 | L7: 0 | M7: 0 | N7: 0
C8: 0 | D8: 0 | E8: 0 | F8: 0 | G8: 0 | H8: 0 | I8: 0 | J8: 0 | K8: 0 | L8: 0 | M8: 0 | N8: 0
A9: १. पाणीपुरवठा (अति. न.अ.) | C9: 0 | D9: 0 | E9: 0 | F9: 0 | G9: 0 | H9: 0 | I9: 0 | J9: 0 | K9: 0 | L9: 0 | M9: 0 | N9: 0
A10: क. पाणीपट्टी साधारण पाणीपट्टी (कआकसंप्र) | B10: XI12A101 | C10: 1341089335 | D10: 1852452983 | E10: 1114584244 | F10: 316808513 | G10: 932668414 | H10: 2290000000 | I10: 2290000000 | J10: 1800000000 | K10: 0 | L10: 0 | M10: 0 | N10: 490000000
A11: ख. शासनाकडून (कआकसंप्र) | B11: XI12B101 | C11: 0 | D11: 0 | E11: 0 | F11: 0 | G11: 0 | H11: 100000 | I11: 100000 | J11: 100000 | K11: 0 | L11: 0 | M11: 0 | N11: 0
A12: च. PMPML कडील मिळकतीवरील पाणीपट्टी (कआकसंप्र) | B12: XI12F101 | C12: 0 | D12: 0 | E12: 0 | F12: 0 | G12: 0 | H12: 100000 | I12: 100000 | J12: 100000 | K12: 0 | L12: 0 | M12: 0 | N12: 0
A13: छ. जललाभ कर (Water Benefit Tax) (कआकसंप्र) | B13: XI12G101 | C13: 302692528 | D13: 418910163 | E13: 543166436 | F13: 210147743 | G13: 375121840 | H13: 800000000 | I13: 800000000 | J13: 920000000 | K13: 0 | L13: 0 | M13: 120000000 | N13: 0
A14: ग. पाणीपट्टी पाणीमापकानुसार (अति.न.अ.) | B14: XI12C101 | C14: 359356133 | D14: 388645935 | E14: 401229463 | F14: 187649622 | G14: 241451816 | H14: 1161700000 | I14: 1161700000 | J14: 1164000000 | K14: 0 | L14: 0 | M14: 2300000 | N14: 0
A15: ग१. मीटर पाणीपट्टी थकबाकीपोटी जमा | B15: XI12C101A | C15: 0 | D15: 0 | E15: 0 | F15: 0 | G15: 0 | H15: 140000000 | I15: 140000000 | J15: 140000000 | K15: 0 | L15: 0 | M15: 0 | N15: 0
A16: ग२. गवनि खात्याअंतर्गत होणारी पाणीपट्टी जमा | B16: XI12C101B | C16: 41474022 | D16: 33175546 | E16: 10942484 | F16: 4397287 | G16: 5287392 | H16: 25000000 | I16: 25000000 | J16: 25000000 | K16: 0 | L16: 0 | M16: 0 | N16: 0
A17: अनधिकृत कनेक्शन नियमित करण्यापोटी जमा | B17: XI12S101 | C17: 74895 | D17: 30515 | E17: 739 | F17: 739 | G17: 0 | H17: 180000000 | I17: 180000000 | J17: 40500000 | K17: 0 | L17: 0 | M17: 0 | N17: 139500000
A18: घ. पाणीमापक भाडे | B18: XI12D101 | C18: 1972 | D18: 5797 | E18: 5473 | F18: 5473 | G18: 3074 | H18: 75000000 | I18: 75000000 | J18: 75000000 | K18: 0 | L18: 0 | M18: 0 | N18: 0
A19: ड. नवीन नळ आकार नळदुरुस्ती व साफसफी (परतजमा) | B19: XI12E101 | C19: 6509624 | D19: 8676617 | E19: 7255295 | F19: 1871539 | G19: 14329307 | H19: 500000 | I19: 500000 | J19: 15000000 | K19: 0 | L19: 0 | M19: 14500000 | N19: 0
A20: ऊर्जा बचत कक्षामार्फत पाणीपुरवठा योजनेसंदर्भात ऊर्जा संवर्धन पथदर्शी प्रकल्पासाठी मेढाकडून अनुदान | B20: XI12E102 | C20: 0 | D20: 500000 | E20: 0 | F20: 0 | G20: 0 | H20: 0 | I20: 0 | J20: 0 | K20: 0 | L20: 0 | M20: 0 | N20: 0
A21: ठ. कॉलनी रस्त्यावर पाईप टाकणे कामापोटी सुपरव्हिजन स्क्रुटीनी फी व अन्य जमा होणार | B21: XI12K101 | C21: 1180267 | D21: 1352460 | E21: 12393427 | F21: 7225349 | G21: 5125128 | H21: 8000000 | I21: 8000000 | J21: 20000000 | K21: 0 | L21: 0 | M21: 12000000 | N21: 0
... A29: ण. अंदाजपत्रक 'अ' कडून वर्ग | B29: XI12M101 | C29: 3087694698 | D29: 400282726 | E29: 2363450642 | F29: 2363450642 | G29: 0 | H29: -253367047 | I29: -253367047 | J29: 685744409 | K29: 0 | L29: 0 | M29: 939111456 | N29: 0
C30: 0 | D30: 0 | E30: 0 | F30: 0 | G30: 0 | H30: 0 | I30: 0 | J30: 0 | K30: 0 | L30: 0 | M30: 0 | N30: 0
A31: १. बेरीज | C31: 5165719080 | D31: 3145131258 | E31: 4517524035 | F31: 3129490693 | G31: 1599094226 | H31: 4486832953 | I31: 4486832953 | J31: 4999700000 | K31: 0 | L31: 0 | M31: 1142911456 | N31: 630044409
C32: 0 | D32: 0 | E32: 0 | F32: 0 | G32: 0 | H32: 0 | I32: 0 | J32: 0 | K32: 0 | L32: 0 | M32: 0 | N32: 0
A33: १अ. पुणे कॅन्टोन्मेंट पाणीपुरवठा जमा (अति.न.अ.) | C33: 0 | D33: 0 | E33: 0 | F33: 0 | G33: 0 | H33: 0 | I33: 0 | J33: 0 | K33: 0 | L33: 0 | M33: 0 | N33: 0
A34: (१) पाणीमापकानुसार पाणीपट्टी | B34: XI12Q101 | C34: 181297563 | D34: 237495666 | E34: 172872513 | F34: 66129497 | G34: 1370736 | H34: 130000000 | I34: 130000000 | J34: 200000000 | K34: 0 | L34: 0 | M34: 70000000 | N34: 0
A35: (२) H.E. Factory कडून येणारी जमा | B35: XI12Q102 | C35: 20768047 | D35: 12409034 | E35: 131099065 | F35: 99855514 | G35: 120948445 | H35: 50000000 | I35: 50000000 | J35: 70000000 | K35: 0 | L35: 0 | M35: 20000000 | N35: 0
C36: 0 | D36: 0 | E36: 0 | F36: 0 | G36: 0 | H36: 0 | I36: 0 | J36: 0 | K36: 0 | L36: 0 | M36: 0 | N36: 0
A37: १अ. बेरीज | C37: 202065610 | D37: 249904700 | E37: 303971578 | F37: 165985011 | G37: 122319181 | H37: 180000000 | I37: 180000000 | J37: 270000000 | K37: 0 | L37: 0 | M37: 90000000 | N37: 0
C38: 0 | D38: 0 | E38: 0 | F38: 0 | G38: 0 | H38: 0 | I38: 0 | J38: 0 | K38: 0 | L38: 0 | M38: 0 | N38: 0
A39: पुणे शहरात तंत्रशुध्द पध्दतीने पाणीपुरवठा करण्याची योजना (24x7) अनुदान (AMRUT) | B39: ZI12A111 | C39: 0 | D39: 0 | E39: 0 | F39: 0 | G39: 0 | H39: 350000000 | I39: 350000000 | J39: 750000000 | K39: 0 | L39: 0 | M39: 400000000 | N39: 0
A40: पुणे शहरात तंत्रशुध्द पध्दतीने पाणीपुरवठा करण्याची योजना (24x7) कर्जरोखे विक्री | B40: ZI12A112 | C40: 0 | D40: 0 | E40: 0 | F40: 0 | G40: 0 | H40: 2000000000 | I40: 2000000000 | J40: 0 | K40: 0 | L40: 0 | M40: 0 | N40: 2000000000
C41: 0 | D41: 0 | E41: 0 | F41: 0 | G41: 0 | H41: 0 | I41: 0 | J41: 0 | K41: 0 | L41: 0 | M41: 0 | N41: 0
A42: राष्ट्रीय नदीसुधारणा प्रकल्पातंर्गत (JICA) केंद्र सरकारकडून अनुदान | B42: ZI12A102 | C42: 0 | D42: 0 | E42: 259899999 | F42: 259899999 | G42: 0 | H42: 1275000000 | I42: 1275000000 | J42: 0 | K42: 0 | L42: 0 | M42: 0 | N42: 1275000000
C43: 0 | D43: 0 | E43: 0 | F43: 0 | G43: 0 | H43: 0 | I43: 0 | J43: 0 | K43: 0 | L43: 0 | M43: 0 | N43: 0
A44: १. एकूण बेरीज | C44: 5367784690 | D44: 3395035958 | E44: 5081395612 | F44: 3555375703 | G44: 1721413407 | H44: 8291832953 | I44: 8291832953 | J44: 6019700000 | K44: 0 | L44: 0 | M44: 1632911456 | N44: 3905044409
C45: 0 | D45: 0 | E45: 0 | F45: 0 | G45: 0 | H45: 0 | I45: 0 | J45: 0 | K45: 0 | L45: 0 | M45: 0 | N45: 0
A46: २. गटारे व नाले सुधारणा (अति.न.अ.) | C46: 0 | D46: 0 | E46: 0 | F46: 0 | G46: 0 | H46: 0 | I46: 0 | J46: 0 | K46: 0 | L46: 0 | M46: 0 | N46: 0
A47: क. सफाईपट्टी (कआकसंप्र) | B47: XI23A101 | C47: 1496037193 | D47: 2066573109 | E47: 2148672982 | F47: 859816399 | G47: 1393154490 | H47: 2750000000 | I47: 2750000000 | J47: 3096000000 | K47: 0 | L47: 0 | M47: 346000000 | N47: 0
A48: घ. सुअरेज बेनिफीट टॅक्स (कआकसंप्र) | B48: XI23D101 | C48: 619016536 | D48: 883719673 | E48: 967066203 | F48: 383016898 | G48: 645474320 | H48: 1600000000 | I48: 1600000000 | J48: 1680000000 | K48: 0 | L48: 0 | M48: 80000000 | N48: 0
A49: ग. ड्रेनेज / सलेज कनेक्शन व सेवावाढ आकार नियोजित बांधकाम क्षेत्रफळावर रु. ११ चौ. मि. | B49: XI23C101 | C49: 7333434 | D49: 8579633 | E49: 9116859 | F49: 4345583 | G49: 3652209 | H49: 10000000 | I49: 10000000 | J49: 10000000 | K49: 0 | L49: 0 | M49: 0 | N49: 0
...

Sheet C_Revenue_Expenditure
A1: योजनेतर खर्च तपशील
A2: विवरण | D2: नक्‍की आकडा | G2: मान्य अंदाज 2017-18 | H2: नवीन अंदाज 2018-19
D3: 2014-15 | E3: 2015-16 | F3: 2016-17
A5: १. पाणीपुरवठा | D5: 0 | E5: 0 | F5: 0 | G5: 0 | H5: 0
A6: क. पाणीपुरवठा | D6: 0 | E6: 0 | F6: 0 | G6: 0 | H6: 0
A7: १. मध्यवर्ती कार्यालय, कायम सेवकवर्ग वेतन | B7: XE12A101A | D7: 17277661 | E7: 20163697 | F7: 24270905 | G7: 28000000 | H7: 30000000
A8: २अ. कायम सेवकवर्ग वेतन | B8: XE12A101B | D8: 94860971 | E8: 112681352 | F8: 129159922 | G8: 145000000 | H8: 143000000
A9: २ब. कायम सेवकवर्ग वेतन (वि.का.) | B9: XE12A###A | D9: 9542874 | E9: 10813818 | F9: 10793008 | G9: 15000000 | H9: 15000000
A10: ३. संकीर्ण | B10: XE12A103 | D10: 785104 | E10: 799999 | F10: 496203 | G10: 1080000 | H10: 1200000
A11: ४. पाण्याची किंमत (पर्वती पंपिंग स्टेशन) | B11: XE12A104 | D11: 161500000 | E11: 149074723 | F11: 130832460 | G11: 145000000 | H11: 160000000
A12: ५. पाणी शुद्ध करणे व तद्‌नुषंगिक कामे करणे | B12: XE12A105 | D12: 52999452 | E12: 54099331 | F12: 68067821 | G12: 58880000 | H12: 60000000
A13: ६. प्रयोगशाळा देखभाल खर्च | B13: XE12A106 | D13: 1193434 | E13: 1131134 | F13: 956631 | G13: 1080000 | H13: 1200000
A14: ७-अ. पंपिंग वीज खर्च | B14: XE12A107 | D14: 494546000 | E14: 493452559 | F14: 479999999 | G14: 570000000 | H14: 667000000
A15: ९. कोठी इतर साहित्य खर्च | B15: XE12A109 | D15: 3239120 | E15: 1275116 | F15: 2975682 | G15: 2520000 | H15: 2800000
A16: १२. पर्वती जलकेंद्रातील यंत्रसामुग्रीवरील घसारा (मु.ले.) | B16: XE12A112 | D16: 163912 | E16: 163906 | F16: 164000 | G16: 190000 | H16: 215000
A17: १४. जलप्रदूषण प्रतिबंधक खर्च | B17: XE12A115 | D17: 8850000 | E17: 3224833 | F17: 4823834 | G17: 4320000 | H17: 4700000
A18: १८. जलकेंद्र पाण्याच्या टाक्या येथे प्रकाश व्यवस्था व दूरध्वनी व्यवस्था | B18: XE12A120 | D18: 0 | E18: 0 | F18: 0 | G18: 360000 | H18: 800000
... A37: पर्वती जलकेंद्र प्रयोगशाळा येथे पाणी तपासणीसाठी लागणारी विविध उपकरणे व तद्‌नुषंगिक साहित्य खरेदी करणे | B37: XE12A146 | D37: 0 | E37: 0 | F37: 0 | G37: 360000 | H37: 500000
A38: क. बेरीज | D38: 908151990 | E38: 903255059 | F38: 957068541 | G38: 1080510000 | H38: 1221070000
D39: 0 | E39: 0 | F39: 0 | G39: 0 | H39: 0
A40: ख१. नळ खाते (स्वारगेट विभाग) | D40: 0 | E40: 0 | F40: 0 | G40: 0 | H40: 0
A41: १. कायम सेवक वर्ग वेतन | B41: XE12B101A | D41: 166857797 | E41: 180097170 | F41: 198416480 | G41: 215000000 | H41: 233500000
A42: २. संकीर्ण | B42: XE12B102 | D42: 344423 | E42: 665438 | F42: 799999 | G42: 900000 | H42: 1000000
A43: ४. शहरांतील / नव्याने समाविष्ट गावांतील सर्व व्हॉल्व्हज्‌ चालू व बंद करणे | B43: XE12B107 | D43: 26432807 | E43: 41880675 | F43: 31092583 | G43: 39600000 | H43: 39600000
A44: ८. टँकरने पाणीपुरवठा करणे | B44: XE12B111 | D44: 10314298 | E44: 12384914 | F44: 16107816 | G44: 7200000 | H44: 14000000
A45: ९. कोठी व इतर साहित्य खरेदी | B45: XE12B112 | D45: 15266437 | E45: 11946296 | F45: 23841464 | G45: 21600000 | H45: 40000000
A46: १०. देखभाल दुरुस्ती : नळदुरुस्ती व स्वच्छता तातडीच्या दुरुस्त्या चेंबर करणे, आर.सी.सी, कव्हर बसविणे व तदनुषंगिक कामे करणे | B46: XE12B113 | D46: 27459984 | E46: 27690999 | F46: 44788541 | G46: 43200000 | H46: 54000000
A47: ११. टाक्‍यांची दुरुस्ती | B47: XE12B114 | D47: 99862 | E47: 0 | F47: 0 | G47: 720000 | H47: 800000
A48: पाणीपुरवठा विभागाकडील देखभाल दुरूस्तीची कामे | B48: XE12B115# | D48: 0 | E48: 0 | F48: 20005303 | G48: 16650000 | H48: 0
D49: 0 | E49: 0 | F49: 0 | G49: 0 | H49: 0
A50: ख१. बेरीज | D50: 246775608 | E50: 274665492 | F50: 335052186 | G50: 344870000 | H50: 382900000
D51: 0 | E51: 0 | F51: 0 | G51: 0 | H51: 0
A52: ख२. नळ खाते (विभागीय कार्यालय) | D52: 0 | E52: 0 | F52: 0 | G52: 0 | H52: 0
A53: १. कायम सेवकवर्ग वेतन | B53: XE12B###A | D53: 35079153 | E53: 38369636 | F53: 36831303 | G53: 55000000 | H53: 50000000
A54: क्षेत्रीय कार्यालयाने करावयाची योजनेतर कामे | B54: XE12B301/W6-# | D54: 0 | E54: 0 | F54: 1380528 | G54: 0 | H54: 1300000
A55: क्षेत्रीय कार्यालयाने नागरिकांच्या सहभागातून करावयाची योजनेतर कामे | B55: XE12B302/C6-# | D55: 5632324 | E55: 4386080 | F55: 8138352 | G55: 10200000 | H55: 10200000
D56: 0 | E56: 0 | F56: 0 | G56: 0 | H56: 0
A57: ख२. बेरीज | D57: 40711477 | E57: 42755716 | F57: 46350183 | G57: 65200000 | H57: 61500000
D58: 0 | E58: 0 | F58: 0 | G58: 0 | H58: 0
A59: ख. एकूण बेरीज | D59: 287487085 | E59: 317421208 | F59: 381402369 | G59: 410070000 | H59: 444400000
...

Sheet C_Revenue_List
F1: प्रकल्पीय रक्कम | G1: 1819 आयुक्त
A3: पाणीपुरवठा विभागाकडील कामाच्या याद्या
A6: यादी क्र. X2
A7: मलनिःस्सारण विभागाकडील देखभाल दुरूस्तीची कामे
A8: XE23A117/X2-
A10: क्र. | B10: code | C10: ward | E10: कामाचे नाव | F10: प्रकल्पीय रक्कम | G10: तरतूद
A12: 1 | B12: XE23A117/X2-101 | E12: धनकवडी सहकारनगर क्षेत्रिय कार्यालयाच्या अंतर्गत येणा-या ६०० मि. मी. व त्यापुढील व्यासाच्या नाल्यातील व मुख्य रस्त्यावरील मलवाहिन्यांची देखभाल व दुरुस्तीची कामे करणे. | G12: 4500000
A13: 2 | B13: XE23A117/X2-102 | E13: धनकवडी सहकारनगर क्षेत्रिय कार्यालया लगत नव्याने समाविष्ठ ग्रामपंचायत काळातील गावांमधील अस्तित्वातील मैलापाणी वहन व्यवस्था सुधारणे कामी अत्यावश्यक देखभाल व दुरुस्ती तसेच तद्‌नुषंगिक कामे करणे. (आंबेगाव खुर्द / आंबेगाव बु।।.) | G13: 10000000
A14: 3 | B14: XE23A117/X2-103 | E14: वारजे कर्वेनगर क्षेत्रिय कार्यालया लगत नव्याने समाविष्ठ ग्रामपंचायत काळातील गावांमधील अस्तित्वातील मैलापाणी वहन व्यवस्था सुधारणे कामी अत्यावश्यक देखभाल व दुरुस्ती तसेच तद्‌नुषंगिक कामे करणे. (शिवणे / उत्तमनगर) | G14: 5000000
A15: 4 | B15: XE23A117/X2-104 | E15: प्रभाग क्र. ३९ मध्ये धनकवडी गावठाण मधील ग्रामपंचायत काळातील जुन्या व जीर्ण झालेल्या मलवाहिन्या काढून मोठ्या व्यासाच्या मलवाहिन्या विकसीत करणे व देखभाल व दुरुस्तीची कामे करणे व तद्‌नुषंगिक कामे करणे. | G15: 8000000
A16: 5 | B16: XE23A117/X2-105 | E16: प्रभाग क्र. ३८ मध्ये के. के. मार्केट ते लेकटाऊन दरम्यान मुख्य मलवाहिनी टाकणे व दुरुस्ती करणे. | G16: 7000000
A17: 6 | B17: XE23A117/X2-106 | E17: प्रभाग क्र. ४१ मधील भैरोबा नाल्यामधील मुख्य ड्रेनेज लाईन व चेंबर दुरुस्ती विषयक कामे करणे. | G17: 4000000
A18: 7 | B18: XE23A117/X2-107 | E18: कोंढवा येवलेवाडी क्षेत्रिय कार्यालयाच्या अखत्यारीत येणाऱ्या परिसरामधील अस्तित्वातील मलवाहिन्यांची दैनदिन देखभाल दुरुस्ती करणे. | G18: 4000000
A19: 8 | B19: XE23A117/X2-108 | E19: नव्याने मनपा हद्दीमध्ये समाविष्ट झालेल्या कोंढवा येवलेवाडी क्षेत्रिय कार्यालयाच्या अखत्यारीतील ग्रामपंचायत काळामधील अस्तित्वातील मैलापाणी वहन व्यवस्था अबाधित राहणेकरीता मलवाहिन्यांची दैनदिन देखभाल दुरुस्ती करणे. | G19: 6000000
A20: 9 | B20: XE23A117/X2-109 | E20: हडपसर क्षेत्रिय कार्यालयाअंतर्गत येणाऱ्या मुख्य रस्त्यावरील व नाल्यातील ६०० मि. मी. व्यासाच्या मलवाहिन्यांची देखभाल दुरुस्ती करणे. | G20: 5000000
A21: 10 | B21: XE23A117/X2-110 | E21: हडपसर क्षेत्रिय कार्यालयाअंतर्गत येणाऱ्या पुणे मनपाचे हद्दीमध्ये नव्याने समाविष्ट झालेल्या गावांच्या परिसरात अस्तित्वातील मुख्य मलवाहिन्यांची देखभाल दुरुस्ती करणे. | G21: 5000000
A22: 11 | B22: XE23A117/X2-111 | E22: बिबवेवाडी क्षेत्रिय कार्यालयाअंतर्गत येणाऱ्या ६०० मि. मी. व त्यापुढील व्यासाच्या मुख्य रस्त्यावरील व नाल्यातील मुख्य मलवाहिन्यांची देखभाल दुरुस्ती करणे. | G22: 4500000
A23: 12 | B23: XE23A117/X2-112 | E23: कसबा - विश्रामवाडा क्षेत्रिय कार्यालय अंतर्गत येणारे ६०० मि. मी. व त्यापुढील व्यासाच्या मुख्य मलवाहिन्यांची देखभाल व दुरुस्ती करणे. | G23: 4500000
... A48: 37 | B48: XE23A117/X2-137 | E48: मलनि:सारण विभागाकडील प्रशासकीय कार्यालयाकरीता झेरॉक्स मशिन आणि प्रिंटर्सचे ड्रम, टोनर पुरविणे तसेच वार्षिक देखभाल दुरुस्ती व तद्‌नुषंगिक कामे करणे. | G48: 500000
E50: यादी क्र. X2 एकूण | F50: 0 | G50: 168000000

Sheet C_Capital_Expenditure
A1: सन 2018-19 चे योजनांतर्गत | I1: खर्चाबाबतचे अंदाजपत्रक
A2: अनुक्रमांक | B2: मान्यतेचा ठराव क्र. दिनांक (कोड) | C2: प्रभाग क्रमांक | D2: BPL | E2: कामाचे नाव अगर वर्णन | F2: दि. 31 मार्च 2018 अखेरपर्यंत केलेली तरतूद | I2: दि. 31 मार्च 2017 पर्यंतचा खर्चाचा नक्‍की आकडा | J2: 2017-18 मधील खर्चाची अंदाजी रक्कम | L2: 2018-19 साठी अधिक तरतूद | N2: 2018-19 साठी एकूण तरतूद | O2: प्रकल्पीय रक्कम
F3: कर्जातून | G3: महसूल निधीतून | H3: एकूण | J3: प्रत्यक्ष उपलब्ध तरतूद | K3: कर्जातून तरतूद | L3: कर्जातून | M3: महसूल निधी व इतर निधी
E8: 1. पाणीपुरवठा | F8: 0 | G8: 0 | H8: 0 | I8: 0 | J8: 0 | M8: 0 | N8: 0
F9: 0 | G9: 0 | H9: 0 | I9: 0 | J9: 0 | M9: 0 | N9: 0
A10: 2 | B10: ZE16A103# | C10: P1- | D10: _ | E10: शहरामध्ये जलशुध्दीकरण केंद्रे बांधणे | F10: 0 | G10: 0 | H10: 0 | I10: 0 | J10: 0 | M10: 32500000 | N10: 32500000
A11: 1 | B11: ZE16A104# | C11: P2- | D11: _ | E11: शहरामध्ये पाण्याच्या नवीन लाईन विकसित करणे | F11: 0 | G11: 6484371460 | H11: 6484371460 | I11: 5119012214 | J11: 1365359246 | M11: 211000000 | N11: 211000000
A12: 2 | B12: ZE16A106# | C12: P3- | D12: _ | E12: शहरामध्ये पाण्याच्या टाक्या बांधणे / बोअरवेल घेणे | F12: 0 | G12: 578881020 | H12: 578881020 | I12: 204561005 | J12: 374320015 | M12: 84200000 | N12: 84200000
A13: 3 | B13: ZE16A107# | C13: P8- | D13: _ | E13: शहरामधील विविध जलशुध्दीकरण केंद्रामध्ये विद्युत / यांत्रिकीविषयक कामे करणे | F13: 0 | G13: 523169558 | H13: 523169558 | I13: 365174123 | J13: 157995435 | M13: 445400000 | N13: 445400000
A14: 5 | B14: #+ | E14: सन २०१४-१५ मधील अपूर्ण कामांसाठी सन २०१५-१६ मध्ये उपलब्ध केलेली तरतूद | F14: 0 | G14: 1365768924 | H14: 1365768924 | I14: 1365768924 | J14: 0 | M14: 0 | N14: 0
F15: 0 | G15: 0 | H15: 0 | I15: 0 | J15: 0 | M15: 0 | N15: 0
E16: पाणीपुरवठा एकूण | F16: 0 | G16: 8952190962 | H16: 8952190962 | I16: 7054516266 | J16: 1897674696 | M16: 773100000 | N16: 773100000
F17: 0 | G17: 0 | H17: 0 | I17: 0 | J17: 0 | M17: 0 | N17: 0
F18: 0 | G18: 0 | H18: 0 | I18: 0 | J18: 0 | M18: 0 | N18: 0
E19: 2. मलनिःसारण | F19: 0 | G19: 0 | H19: 0 | I19: 0 | J19: 0 | M19: 0 | N19: 0
F20: 0 | G20: 0 | H20: 0 | I20: 0 | J20: 0 | M20: 0 | N20: 0
A21: 1 | B21: ZE16B102# | C21: D2- | D21: _ | E21: शहरामध्ये मलवाहिन्या विकसित करणे | F21: 0 | G21: 5229133792 | H21: 5229133792 | I21: 3894301064 | J21: 1334832728 | M21: 173000000 | N21: 173000000
A22: 2 | B22: ZE16B103# | C22: D3- | D22: _ | E22: शहरामध्ये नाला चॅनलायझेशन करणे / नाल्याला सिमाभिंत बांधणे व तद्नुषंगिक कामे करणे | F22: 0 | G22: 262385423 | H22: 262385423 | I22: 48694838 | J22: 213690585 | M22: 65200000 | N22: 65200000
A23: 3 | B23: ZE16B104# | E23: शहरामध्ये मैलापाणी शुध्दीकरण केंद्रामध्ये स्थापत्यविषयक कामे करणे | F23: 0 | G23: 41102691 | H23: 41102691 | I23: 38592666 | J23: 2510025 | M23: 0 | N23: 0
A24: 4 | B24: ZE16B105# | C24: D5- | D24: _ | E24: शहरामध्ये मैलापाणी शुध्दीकरण केंद्रामध्ये विद्युत / यांत्रिकीविषयक कामे करणे | F24: 0 | G24: 78080800 | H24: 78080800 | I24: 31415131 | J24: 46665669 | M24: 25000000 | N24: 25000000
A25: 6 | B25: #+ | E25: सन २०१४-१५ मधील अपूर्ण कामांसाठी सन २०१५-१६ मध्ये उपलब्ध केलेली तरतूद | F25: 0 | G25: 12417042 | H25: 12417042 | I25: 12417042 | J25: 0 | M25: 0 | N25: 0
F26: 0 | G26: 0 | H26: 0 | I26: 0 | J26: 0 | M26: 0 | N26: 0
E27: मलनिःसारण एकूण | F27: 0 | G27: 5623119748 | H27: 5623119748 | I27: 4025420741 | J27: 1597699007 | M27: 263200000 | N27: 263200000
F28: 0 | G28: 0 | H28: 0 | I28: 0 | J28: 0 | M28: 0 | N28: 0
