Workbook
Name BdgtNo: #REF!
Name BdgtYear: #REF!
Name BdgtYrFrom: #REF!
Name BdgtYrTo: #REF!
Name Description: "P_A_C_Ex"
Name FinYrFrom: #REF!
Name FinYrTo: #REF!
Name Head: #REF!
Name Last2Yr: #REF!
Name Last3Yr: #REF!
Name Last4Yr: #REF!
Name Last5Yr: #REF!
Name List_Smry_0: A_Capital_List!#REF!
Name List_Smry_0: A_Revenue_List!#REF!
Name List_Smry_0: C_Capital_List!$A$1784:$G$1786
Name List_Smry_0: C_Revenue_List!#REF!
Name List_Smry_1: A_Capital_List!#REF!
Name List_Smry_1: A_Revenue_List!#REF!
Name List_Smry_1: C_Capital_List!#REF!
Name List_Smry_1: C_Revenue_List!#REF!
Name List_Smry_2: A_Capital_List!#REF!
Name List_Smry_2: A_Revenue_List!#REF!
Name List_Smry_2: C_Capital_List!$A$1784:$G$1785
Name List_Smry_2: C_Revenue_List!#REF!
Name P_A_A_Ex: #REF!
Name P_A_A01: #REF!
Name P_A_A02: #REF!
Name P_A_A03: A_Revenue_Income!$A$7:$N$490
Name P_A_A04: #REF!
Name P_A_A05: A_Revenue_Expenditure!$A$4:$H$1628
Name P_A_A08: #REF!
Name P_A_A09: #REF!
Name P_A_A10: #REF!,#REF!
Name P_A_A11: #REF!
Name P_A_A12: A_Capital_Expenditure!$A$7:$O$220
Name P_A_A13: #REF!
Name P_A_A14: A_Land_Acquisition!$A$5:$E$387
Name P_A_A15: A_Fund_Expenditure!$A$6:$O$159
Name P_A_A16: A_DPDC_Machinery_Tree!$A$7:$G$121
Name P_A_AC_In1: #REF!
Name P_A_APP: #REF!
Name P_A_Bdgt: A_DPDC_Machinery_Tree!$A$7:$G$121
Name P_A_Bdgt: A_Fund_Expenditure!$A$6:$O$159
Name P_A_Bdgt: A_Land_Acquisition!$A$5:$E$387
Name P_A_Bdgt: A_Revenue_Income!$A$7:$N$490
Name P_A_Bdgt: C_Capital_Expenditure!$A$6:$O$63
Name P_A_Bdgt: C_Revenue_Expenditure!$A$4:$H$359
Name P_A_Bdgt: WO_Work20_SC!$A$3:$Q$144
Name P_A_C_Ex: #REF!
Name P_A_C01: #REF!
Name P_A_C02: C_Revenue_Income!$A$7:$N$62
Name P_A_C02A: #REF!
Name P_A_C03: C_Revenue_Expenditure!$A$4:$H$359
Name P_A_C05: #REF!
Name P_A_C07: C_Capital_Expenditure!$A$6:$O$63
Name P_A_Doller_MC: #REF!,#REF!,#REF!
Name P_A_Doller_SC: #REF!,#REF!,#REF!
Name P_A_dvdr: #REF!
Name P_A_Fnl_Rec: #REF!
Name P_A_Info: #REF!

Sheet A_Revenue_Income
A1: जमेचा | G1: तपशील
A2: विवरण | C2: नक्की आकडा | H2: 2019-20 वर्षाचा अंदाज | J2: 2020-21 वर्षाचा अंदाज | M2: 2019-20 वर्षाच्या मान्य अंदाजाशी तुलना केलेला 2020-21 वर्षाचा मा. स्थायी समितीने मान्यता दिलेला अंदाज
C3: 2016-17 | D3: 2017-18 | E3: 2018-19 | F3: 2018-19 शेवटची सहामाही | G3: 2019-20 पहिली सहामाही | H3: मान्य अंदाज | I3: दुरूस्त अंदाज | J3: मा. महापालिका आयुक्त यांनी सुचविलेला | K3: मा. स्थायी समितीने मान्यता दिलेला | L3: मा. महानगर- पालिकेने संमत केलेला
M5: अधिक | N5: कमी
A7: अधिनियमाप्रमाणे कमीत कमी रोख शिल्लक ठेवण्याची रक्कम जमेस धरून वर्षारंभीची शिल्लक | C7: 100000 | D7: 100000 | E7: 100000 | F7: 100000 | G7: 0 | H7: 100000 | I7: 100000 | J7: 100000 | K7: 100000 | L7: 0 | M7: 0 | N7: 0
C8: 0 | D8: 0 | E8: 0 | F8: 0 | G8: 0 | H8: 0 | I8: 0 | J8: 0 | K8: 0 | L8: 0 | M8: 0 | N8: 0
A9: १. सर्वसाधारण कर, अप्रत्यक्ष कर व इतर जमा | C9: 0 | D9: 0 | E9: 0 | F9: 0 | G9: 0 | H9: 0 | I9: 0 | J9: 0 | K9: 0 | L9: 0 | M9: 0 | N9: 0
A10: क. सर्वसाधारण पट्टी | C10: 0 | D10: 0 | E10: 0 | F10: 0 | G10: 0 | H10: 0 | I10: 0 | J10: 0 | K10: 0 | L10: 0 | M10: 0 | N10: 0
A11: १. नागरिकांकडून (कआकसंप्र) | B11: RI11A101 | C11: 3579419675 | D11: 3311564173 | E11: 3361147014 | F11: 942374982 | G11: 2536000928 | H11: 5790000000 | I11: 5790000000 | J11: 8050000000 | K11: 8050000000 | L11: 0 | M11: 2260000000 | N11: 0
A12: लोहगाव (उर्वरित) | B12: RI11AA101 | C12: 0 | D12: 6685 | E12: 37675 | F12: 11400 | G12: 214260 | H12: 80000000 | I12: 80000000 | J12: 0 | K12: 0 | L12: 0 | M12: 0 | N12: 80000000
A13: मुंढवा (उर्वरित केशवनगर) | B13: RI11AB101 | C13: 0 | D13: 2930 | E13: 8185 | F13: 1450 | G13: 389885 | H13: 40000000 | I13: 40000000 | J13: 0 | K13: 0 | L13: 0 | M13: 0 | N13: 40000000
A14: हडपसर (संपूर्ण साडेसतरानळी) | B14: RI11AC101 | C14: 0 | D14: 865 | E14: 3735 | F14: 1250 | G14: 150 | H14: 150000000 | I14: 150000000 | J14: 0 | K14: 0 | L14: 0 | M14: 0 | N14: 150000000
A15: शिवणे (संपूर्ण उत्तमनगर) | B15: RI11AD101 | C15: 0 | D15: 295 | E15: 13465 | F15: 2765 | G15: 141865 | H15: 10000000 | I15: 10000000 | J15: 0 | K15: 0 | L15: 0 | M15: 0 | N15: 10000000
A16: शिवणे | B16: RI11AE101 | C16: 0 | D16: 0 | E16: 9565 | F16: 4425 | G16: 1127870 | H16: 50000000 | I16: 50000000 | J16: 0 | K16: 0 | L16: 0 | M16: 0 | N16: 50000000
A17: आंबेगाव खुर्द | B17: RI11AF101 | C17: 0 | D17: 4070 | E17: 6810 | F17: 1890 | G17: 872045 | H17: 40000000 | I17: 40000000 | J17: 0 | K17: 0 | L17: 0 | M17: 0 | N17: 40000000
A18: उंड्री | B18: RI11AG101 | C18: 0 | D18: 3145 | E18: 3755 | F18: 2370 | G18: 220900 | H18: 40000000 | I18: 40000000 | J18: 0 | K18: 0 | L18: 0 | M18: 0 | N18: 40000000
A19: धायरी | B19: RI11AH101 | C19: 0 | D19: 1460 | E19: 32565 | F19: 4570 | G19: 21470 | H19: 60000000 | I19: 60000000 | J19: 0 | K19: 0 | L19: 0 | M19: 0 | N19: 60000000
A20: आंबेगाव बुद्रुक | B20: RI11AJ101 | C20: 0 | D20: 19000 | E20: 19645 | F20: 5320 | G20: 1014975 | H20: 80000000 | I20: 80000000 | J20: 0 | K20: 0 | L20: 0 | M20: 0 | N20: 80000000
A21: फुरसुंगी | B21: RI11AK101 | C21: 0 | D21: 31460 | E21: 110450 | F21: 32485 | G21: 512980 | H21: 100000000 | I21: 100000000 | J21: 0 | K21: 0 | L21: 0 | M21: 0 | N21: 100000000
A22: उरुळी देवाची | B22: RI11AL101 | C22: 0 | D22: 15030 | E22: 33235 | F22: 14385 | G22: 38190 | H22: 40000000 | I22: 40000000 | J22: 0 | K22: 0 | L22: 0 | M22: 0 | N22: 40000000
... A26: ५. मिळकतकर थकबाकी वसुली (कआकसंप्र) | B26: RI11A106 | C26: 0 | D26: 0 | E26: 0 | F26: 0 | G26: 0 | H26: 2000000000 | I26: 2000000000 | J26: 0 | K26: 3500000000 | L26: 0 | M26: 1500000000 | N26: 0
C27: 0 | D27: 0 | E27: 0 | F27: 0 | G27: 0 | H27: 0 | I27: 0 | J27: 0 | K27: 0 | L27: 0 | M27: 0 | N27: 0
A28: क. सर्वसाधारण कर बेरीज | C28: 3814921689 | D28: 3431242459 | E28: 3525303066 | F28: 994425018 | G28: 2681682415 | H28: 8630000000 | I28: 8630000000 | J28: 8207800000 | K28: 11707800000 | L28: 0 | M28: 3077800000 | N28: 0
C29: 0 | D29: 0 | E29: 0 | F29: 0 | G29: 0 | H29: 0 | I29: 0 | J29: 0 | K29: 0 | L29: 0 | M29: 0 | N29: 0
A30: ख. आयातकर | C30: 0 | D30: 0 | E30: 0 | F30: 0 | G30: 0 | H30: 0 | I30: 0 | J30: 0 | K30: 0 | L30: 0 | M30: 0 | N30: 0
A31: १. पक्की जमा (आ.क.प्र.) | B31: RI11B101 | C31: -10809081 | D31: 0 | E31: -5618500 | F31: 0 | G31: 0 | H31: 0 | I31: 0 | J31: 0 | K31: 0 | L31: 0 | M31: 0 | N31: 0
C32: 0 | D32: 0 | E32: 0 | F32: 0 | G32: 0 | H32: 0 | I32: 0 | J32: 0 | K32: 0 | L32: 0 | M32: 0 | N32: 0
A33: ख. निव्वळ आयातकर एकूण बेरीज | C33: -10809081 | D33: 0 | E33: -5618500 | F33: 0 | G33: 0 | H33: 0 | I33: 0 | J33: 0 | K33: 0 | L33: 0 | M33: 0 | N33: 0
C34: 0 | D34: 0 | E34: 0 | F34: 0 | G34: 0 | H34: 0 | I34: 0 | J34: 0 | K34: 0 | L34: 0 | M34: 0 | N34: 0
A35: ख-१. स्थानिक संस्था कर | C35: 0 | D35: 0 | E35: 0 | F35: 0 | G35: 0 | H35: 0 | I35: 0 | J35: 0 | K35: 0 | L35: 0 | M35: 0 | N35: 0
A36: स्थानिक संस्था कर नोंदणी शुल्क | B36: RI11B201 | C36: -3033323 | D36: 489206 | E36: 300 | F36: 0 | G36: 0 | H36: 0 | I36: 0 | J36: 0 | K36: 0 | L36: 0 | M36: 0 | N36: 0
A37: स्थानिक संस्था कर | B37: RI11B202 | C37: 3919870123 | D37: 1514559653 | E37: 14074585 | F37: 3253814 | G37: 659630 | H37: 10000000 | I37: 10000000 | J37: 10000000 | K37: 10000000 | L37: 0 | M37: 0 | N37: 0
A38: चौरस मीटर बांधकामाप्रमाणे भरावयाची ठोक रक्कम | B38: RI11B202B | C38: 152493815 | D38: 87144478 | E38: 3832035 | F38: 2115948 | G38: 3179873 | H38: 1000000 | I38: 1000000 | J38: 100000 | K38: 100000 | L38: 0 | M38: 0 | N38: 900000
A39: निर्गत मालापोटी १० % हिस्सा | B39: RI11B202D | C39: 6045544 | D39: 1498056 | E39: 0 | F39: 0 | G39: 0 | H39: 0 | I39: 0 | J39: 0 | K39: 0 | L39: 0 | M39: 0 | N39: 0
A40: इतर जमा - स्थानिक संस्था कर | B40: RI11B202E | C40: 76000 | D40: 0 | E40: 25232 | F40: 0 | G40: 0 | H40: 1000 | I40: 1000 | J40: 0 | K40: 0 | L40: 0 | M40: 0 | N40: 1000
A41: स्थानिक संस्था करापोटी व्याज | B41: RI11B203 | C41: 17179218 | D41: 24745902 | E41: 6911393 | F41: -216938 | G41: 452870 | H41: 500000 | I41: 500000 | J41: 1400000 | K41: 1400000 | L41: 0 | M41: 900000 | N41: 0
A42: स्थानिक संस्था कर शास्ती (दंड) | B42: RI11B204 | C42: 2020670 | D42: 295000 | E42: 80000 | F42: 40000 | G42: 0 | H42: 0 | I42: 0 | J42: 0 | K42: 0 | L42: 0 | M42: 0 | N42: 0
A43: राज्य शासनाकडून मुद्रांक शुल्क अधिभारापोटी मिळालेली रक्कम (१%) | B43: RI11B206 | C43: 2194142347 | D43: 1769515876 | E43: 2758200420 | F43: 2051760336 | G43: 512940084 | H43: 2000000000 | I43: 2000000000 | J43: 2500000000 | K43: 2500000000 | L43: 0 | M43: 500000000 | N43: 0
A44: मनपा ठेकेदारांच्या बिलांमधून एल.बी.टी. वसुली | B44: RI11B207 | C44: 11186427 | D44: 3161206 | E44: 92301 | F44: 51487 | G44: 87 | H44: 0 | I44: 0 | J44: 0 | K44: 0 | L44: 0 | M44: 0 | N44: 0
A45: राज्यशासनाकडून एल.बी.टी.साठी सहाय्यक अनुदान | B45: RI11B208 | C45: 7646900000 | D45: 4285500000 | E45: 0 | F45: 0 | G45: 0 | H45: 0 | I45: 0 | J45: 0 | K45: 0 | L45: 0 | M45: 0 | N45: 0
...

Sheet A_Revenue_Expenditure
A1: योजनेतर खर्च तपशील
A2: विवरण | D2: नक्‍की आकडा | G2: मान्य अंदाज 2019-20 | H2: नवीन अंदाज 2020-21
D3: 2016-17 | E3: 2017-18 | F3: 2018-19
A5: १. मुख्य देखरेख, वसुली वगैरे | D5: 0 | E5: 0 | F5: 0 | G5: 0 | H5: 0
A6: क. महानगरपालिका व स्थायी समिती | D6: 0 | E6: 0 | F6: 0 | G6: 0 | H6: 0
A7: १ नगरसचिव यांचे कार्यालय | D7: 0 | E7: 0 | F7: 0 | G7: 0 | H7: 0
A8: १. नगरसचिव (म्युनिसिपल सेक्रेटरी) (मुं.प्रां. मनपा अधिनियम, कलम४५(३) प्रमाणे) वेतन | B8: RE11A101A | D8: 1345488 | E8: 1142457 | F8: 1357957 | G8: 1500000 | H8: 1600000
A9: २. कायम सेवकवर्ग वेतन | B9: RE11A102A | D9: 38012640 | E9: 39568566 | F9: 38537287 | G9: 40000000 | H9: 42500000
A10: ३. संकीर्ण (न.स.) | B10: RE11A103 | D10: 5914622 | E10: 4393519 | F10: 4967904 | G10: 8000000 | H10: 7200000
A11: ३अ. मागील बिले देण्यासाठी (न.स.) | B11: RE11A103A | D11: 2128349 | E11: 3965718 | F11: 2886671 | G11: 3200000 | H11: 3600000
A12: ४. प्रवास खर्च (न.स.) | B12: RE11A104 | D12: 12586 | E12: 22316 | F12: 35207 | G12: 1600000 | H12: 1800000
A13: ५. ग्रंथालय व वाचनालय | B13: RE11A105 | D13: 179955 | E13: 196204 | F13: 172716 | G13: 200000 | H13: 225000
A14: ६. समारंभ खर्च (न.स. व वि.अ.) | B14: RE11A106 | D14: 0 | E14: 45760 | F14: 68200 | G14: 400000 | H14: 450000
A15: १०. अखिल भारतीय/महाराष्ट्र महापौर परिषद व अखिल भारतीय स्थानिक स्वराज्य संस्था प्रतिनिधी अधिवेशन | B15: RE11A110 | D15: 0 | E15: 0 | F15: 0 | G15: 160000 | H15: 270000
A16: ११. मनपा व शासकीय निवृत्त सेवकांना द्यावयाचा चहापान खर्च | B16: RE11A111 | D16: 780 | E16: 114450 | F16: 3000 | G16: 240000 | H16: 270000
A17: १३. महाराष्ट्र राज्य महानगरपालिका स्थायी समिती अध्यक्ष परिषद वर्गणी व तद्‌नुषंगिक खर्च | B17: RE11A113 | D17: 0 | E17: 0 | F17: 0 | G17: 800 | H17: 900
A18: १४. मा. महापौर यांचा व्ययनियमन (सम्प्च्युअरी) भत्ता | B18: RE11A114 | D18: 0 | E18: 0 | F18: 0 | G18: 4000 | H18: 4500
A19: १५. मा. महापौर यांचा ऐच्छिक खर्च | B19: RE11A115 | D19: 159775 | E19: 199238 | F19: 95427 | G19: 160000 | H19: 180000
... A50: नगरसचिव विभागामार्फत आवश्यक सेवक भरती करणे (कंत्राटी) | B50: RE11A280 | D50: 0 | E50: 0 | F50: 0 | G50: 0 | H50: 10000000
D51: 0 | E51: 0 | F51: 0 | G51: 0 | H51: 0
A52: क. मनपा व स्थायी समिती बेरीज | D52: 111232206 | E52: 109200819 | F52: 87211238 | G52: 143029200 | H52: 172230100
D53: 0 | E53: 0 | F53: 0 | G53: 0 | H53: 0
A54: ख. मुख्य लेखापरिक्षक यांचे कार्यालय | D54: 0 | E54: 0 | F54: 0 | G54: 0 | H54: 0
A55: १. मुख्य लेखापरिक्षक (म्युनिसिपल चीफ ऑडिटर) (मु.प्रां. मनपा अधिनियम, कलम ४५ (३) प्रमाणे) यांचे वेतन | B55: RE11B101A | D55: 1610523 | E55: 4018155 | F55: 2623589 | G55: 2500000 | H55: 2700000
A56: २. कायम सेवकवर्ग वेतन | B56: RE11B102A | D56: 27837708 | E56: 23877085 | F56: 29232284 | G56: 30000000 | H56: 30000000
A57: ३. संकीर्ण | B57: RE11B103 | D57: 53529 | E57: 109686 | F57: 115189 | G57: 240000 | H57: 225000
D58: 0 | E58: 0 | F58: 0 | G58: 0 | H58: 0
A59: ख. मुख्यलेखापरिक्षक यांचे कार्या. बेरीज | D59: 29501760 | E59: 28004926 | F59: 31971062 | G59: 32740000 | H59: 32925000
D60: 0 | E60: 0 | F60: 0 | G60: 0 | H60: 0
A61: ग१. महापालिका आयुक्त यांचे कार्यालय | D61: 0 | E61: 0 | F61: 0 | G61: 0 | H61: 0
A62: १. महापालिका आयुक्त (म्युनिसिपल कमिशनर) (मु. प्रां. मनपा अधिनियम, कलम ३७ (१) प्रमाणे) यांचे वेतन | B62: RE11C101A | D62: 2174568 | E62: 2633227 | F62: 2531394 | G62: 3000000 | H62: 3200000
A63: २. उपआयुक्त (जनरल) (मुं. प्रां. मनपा अधिनियम, कलम ४५(३) प्रमाणे) यांचे वेतन | B63: RE11C102A | D63: 558905 | E63: 610426 | F63: 1175614 | G63: 2200000 | H63: 2500000
A64: ३. कायम सेवकवर्ग वेतन | B64: RE11C103A | D64: 25487531 | E64: 28024193 | F64: 29549463 | G64: 30000000 | H64: 31000000
A65: ४. संकीर्ण | B65: RE11C104 | D65: 1172964 | E65: 1342954 | F65: 1356556 | G65: 1600000 | H65: 1800000
A66: ६. मा. महापालिका आयुक्त यांचा ऐच्छिक खर्च (म.स.आ.) | B66: RE11C106 | D66: 0 | E66: 14147 | F66: 50003 | G66: 800000 | H66: 720000
D67: 0 | E67: 0 | F67: 0 | G67: 0 | H67: 0
A68: ग१. महापालिका आयुक्त कार्यालय बेरीज | D68: 29393968 | E68: 32624947 | F68: 34663030 | G68: 37600000 | H68: 39220000
A69: ग२. अतिरिक्त महापालिका आयुक्त (विशेष) यांचे कार्यालय | D69: 0 | E69: 0 | F69: 0 | G69: 0 | H69: 0
A70: १. अतिरिक्त महापालिका आयुक्त (विशेष) यांचे वेतन | B70: RE11C126A | D70: 1172527 | E70: 1012344 | F70: 2041368 | G70: 3000000 | H70: 3200000
A71: २. कायम सेवकवर्ग वेतन | B71: RE11C127A | D71: 12260312 | E71: 12079222 | F71: 13598908 | G71: 15000000 | H71: 15000000
...

Sheet A_Revenue_List
A2: यादी क्र. R1
A3: थोर व्यक्तींच्या जयंती / पुण्यतिथी साजरी करणे (यादी R1)
A4: RE11A274/R1-
A6: क्र. | B6: code | C6: ward | D6: कामाचे नाव | E6: प्रकल्पीय रक्कम | F6: तरतूद
A8: 1 | B8: RE11A274/R1-1 | D8: महात्मा फुले जयंती | F8: 100000
A9: 2 | B9: RE11A274/R1-2 | D9: डॉ. बाबासाहेब आंबेडकर जयंती | F9: 150000
A10: 3 | B10: RE11A274/R1-3 | D10: लोकशाहीर अण्णाभाऊ साठे जयंती | F10: 200000
A11: 4 | B11: RE11A274/R1-4 | D11: ईद-ए-मिलाद (पैगंबर जयंती) | F11: 150000
A12: 5 | B12: RE11A274/R1-5 | D12: शहरातील शिवजयंती साजरी करणे, रोषणाई करणे | F12: 200000
A13: 6 | B13: RE11A274/R1-6 | D13: महात्मा फुले यांची पुण्यतिथी साजरी करणे (दि. 28 नोव्हेंबर) | F13: 500000
A14: 7 | B14: RE11A274/R1-7 | D14: मौलाना अब्दुल कलाम आझाद जयंती व पुण्यतिथी साजरी करणे | F14: 600000
A15: 8 | B15: RE11A274/R1-8 | D15: लहुजी वस्ताद साळवे जयंती महोत्सव गंज पेठ व संगमवाडी येथे साजरा करणे | F15: 500000
A16: 9 | B16: RE11A274/R1-9 | D16: नेताजी सुभाषचंद्र बोस यांची जयंती साजरी करणे | F16: 10000
A17: 10 | B17: RE11A274/R1-10 | D17: येरवडा येथे लोकशाहिर अण्णाभाऊ साठे जयंती महोत्सव साजरा करणे | F17: 100000
A18: 11 | B18: RE11A274/R1-11 | D18: श्री संत रोहिदास महाराज जयंती, पुण्यतिथी साजरी करणे | F18: 50000
A19: 12 | B19: RE11A274/R1-13 | D19: मौलाना अबुल कलाम आझाद जयंती महोत्सव | F19: 500000
A20: 13 | B20: RE11A274/R1-14 | D20: महावीर जयंती | F20: 100000
D22: यादी क्र. R1 एकूण | E22: 0 | F22: 3160000
A24: यादी क्र. R2
A25: शहरामध्ये विविध कार्यक्रम, उत्सव, महोत्सव, संमेलन/ सहप्रायोजक तत्वावर कार्यक्रम साजरे करणे (यादी R2)
A26: RE11A275/R2-
A28: क्र. | B28: code | C28: ward | D28: कामाचे नाव | E28: प्रकल्पीय रक्कम | F28: तरतूद
A30: 1 | B30: RE11A275/R2-1 | D30: महानगरपालिका वर्धापन दिन / सुवर्ण महोत्सव साजरा करणे | F30: 700000
A31: 2 | B31: RE11A275/R2-2 | D31: वर्षातील महत्त्वपूर्ण दिन | F31: 600000
A32: 3 | B32: RE11A275/R2-3 | D32: शिवाजीमहाराज आग्र्‍याहून सुटून परत आले तो स्मृती दिन साजरा करणे | F32: 515000
A33: 4 | B33: RE11A275/R2-4 | D33: शनिवारवाडा सांस्कृतिक महोत्सव | F33: 2000000
A34: 5 | B34: RE11A275/R2-5 | D34: भारतरत्न डॉ. बाबासाहेब आंबेडकर सांस्कृतिक महोत्सव साजरा करणे/ भिम फेस्टिवल (शनिवारवाडा पटांगण) / फुले आंबेडकर फेस्टिवल (समताभूमी) | F34: 2000000
A35: 6 | B35: RE11A275/R2-6 | D35: शिवमहोत्सव साजरा करणे (१४ ते २० फेब्रुवारी) | F35: 2000000
A36: 7 | B36: RE11A275/R2-7 | D36: अण्णाभाऊ साठे महोत्सव | F36: 2000000
A37: 8 | B37: RE11A275/R2-8 | D37: जागतिक आदिवासी दिन | F37: 500000
A38: 9 | B38: RE11A275/R2-9 | D38: पत्रकार डी.आर.कुलकर्णी गृहनिर्माण संस्था व्यासपीठ, जनजागृती व प्रशिक्षण कार्यक्रमांचे आयोजन करणे. | F38: 5000000
D40: यादी क्र. R2 एकूण | E40: 0 | F40: 15315000
A42: यादी क्र. R3
A43: सत्कार, अभिनंदन, पुरस्कार, बक्षिसे यासारखे कार्यक्रम साजरे करणे (यादी R3)
A44: RE11A276/R3-
A46: क्र. | B46: code | C46: ward | D46: कामाचे नाव | E46: प्रकल्पीय रक्कम | F46: तरतूद
A48: 1 | B48: RE11A276/R3-1 | D48: गणेशोत्सव प्रशस्तिपत्रके वितरण | F48: 1000000
A49: 2 | B49: RE11A276/R3-2 | D49: श्री. संत ज्ञानेश्वर व तुकाराम महाराज पालखी स्वागत व दिंडी प्रमुखांचा स्मृतीचिन्ह देऊन सत्कार | F49: 1000000
A50: 3 | B50: RE11A276/R3-3 | D50: प्रतिवर्षी पुणे शहरातील इयत्ता १० वी, १२ वी परिक्षेत गुणवत्ता यादीत येणार्‍या विद्यार्थ्यांचे अभिनंदन | F50: 60000
A51: 4 | B51: RE11A276/R3-4 | D51: बालगंधर्व पुरस्कार प्रदानकरिता | F51: 500000
...

Sheet A_Capital_Expenditure
A1: सन 2020-21 चे योजनांतर्गत | I1: खर्चाबाबतचे अंदाजपत्रक
A2: अनुक्रमांक | B2: मान्यतेचा ठराव क्र. दिनांक (कोड) | C2: प्रभाग क्रमांक | D2: BPL | E2: कामाचे नाव अगर वर्णन | F2: दि. 31 मार्च 2020 अखेरपर्यंत केलेली तरतूद | I2: दि. 31 मार्च 2019 पर्यंतचा खर्चाचा नक्‍की आकडा | J2: 2019-20 मधील खर्चाची अंदाजी रक्कम | L2: 2020-21 साठी अधिक तरतूद | N2: 2020-21 साठी एकूण तरतूद | O2: प्रकल्पीय रक्कम
F3: कर्जातून | G3: महसूल निधीतून | H3: एकूण | J3: प्रत्यक्ष उपलब्ध तरतूद | K3: कर्जातून तरतूद | L3: कर्जातून | M3: महसूल निधी व इतर निधी
E7: १. मनपा भवन व मनपा इमारती | F7: 0 | G7: 0 | H7: 0 | I7: 0 | J7: 0 | M7: 0 | N7: 0
A8: 1 | B8: CE11A129# | C8: J1- | D8: SJ1- | E8: शहरात विविध ठिकाणी मनपासाठी इमारती बांधणे व विकास कामे करणे | F8: 0 | G8: 662260838 | H8: 662260838 | I8: 603672243 | J8: 58588595 | M8: 167300000 | N8: 167300000
F9: 0 | G9: 0 | H9: 0 | I9: 0 | J9: 0 | M9: 0 | N9: 0
E10: १. मनपा भवन व मनपा इमारती एकूण बेरीज | F10: 0 | G10: 662260838 | H10: 662260838 | I10: 603672243 | J10: 58588595 | M10: 167300000 | N10: 167300000
F11: 0 | G11: 0 | H11: 0 | I11: 0 | J11: 0 | M11: 0 | N11: 0
E12: २. प्राथमिक शिक्षण | F12: 0 | G12: 0 | H12: 0 | I12: 0 | J12: 0 | M12: 0 | N12: 0
A13: 1 | B13: CE12A381# | C13: _ | D13: _ | E13: प्राथमिक शाळेमध्ये मुलभूत सोयी सुविधांसाठी विविध विकासकामे करणे | F13: 0 | G13: 1413642992 | H13: 1413642992 | I13: 1216649043 | J13: 196993949 | M13: 0 | N13: 0
A14: 2 | B14: CE12A422# | C14: J2- | D14: SJ2- | E14: प्राथमिक शाळेसाठी नवीन इमारत बांधणे / वर्गखोल्या बांधणे / मैदाने विकसित करणे व मुलभूत सोयी सुविधांसाठी विविध विकासकामे करणे | F14: 0 | G14: 1090664562 | H14: 1090664562 | I14: 480383579 | J14: 610280983 | M14: 493800000 | N14: 493800000
A15: 3 | B15: CE12A423# | C15: _ | D15: _ | E15: प्राथमिक शाळेसाठी वर्गखोल्या बांधणे | F15: 0 | G15: 48906901 | H15: 48906901 | I15: 48906901 | J15: 0 | M15: 0 | N15: 0
A16: 4 | B16: CE12A424# | C16: _ | D16: _ | E16: प्राथमिक शाळांची मैदाने विकसित करणे | F16: 0 | G16: 10533916 | H16: 10533916 | I16: 10533916 | J16: 0 | M16: 0 | N16: 0
F17: 0 | G17: 0 | H17: 0 | I17: 0 | J17: 0 | M17: 0 | N17: 0
E18: २. प्राथमिक शिक्षण एकूण बेरीज | F18: 0 | G18: 2563748371 | H18: 2563748371 | I18: 1756473439 | J18: 807274932 | M18: 493800000 | N18: 493800000
F19: 0 | G19: 0 | H19: 0 | I19: 0 | J19: 0 | M19: 0 | N19: 0
E20: ३. दुय्यम शिक्षण | F20: 0 | G20: 0 | H20: 0 | I20: 0 | J20: 0 | M20: 0 | N20: 0
A21: 1 | B21: CE13A128# | C21: J5- | E21: माध्यमिक शाळांमध्ये मुलभूत सोयी सुविधांसाठी विविध विकासकामे करणे | F21: 0 | G21: 59867417 | H21: 59867417 | I21: 52485069 | J21: 7382348 | M21: 16800000 | N21: 16800000
F22: 0 | G22: 0 | H22: 0 | I22: 0 | J22: 0 | M22: 0 | N22: 0
E23: ३. दुय्यम शिक्षण एकूण बेरीज | F23: 0 | G23: 59867417 | H23: 59867417 | I23: 52485069 | J23: 7382348 | M23: 16800000 | N23: 16800000
F24: 0 | G24: 0 | H24: 0 | I24: 0 | J24: 0 | M24: 0 | N24: 0
E25: ७. आरोग्य विभाग | F25: 0 | G25: 0 | H25: 0 | I25: 0 | J25: 0 | M25: 0 | N25: 0
A26: 1 | B26: CE17A192# | C26: _ | D26: _ | E26: दवाखान्यातील मुलभूत सोयी सुविधांसाठी विविध विकासकामे करणे | F26: 0 | G26: 610691818 | H26: 610691818 | I26: 570366405 | J26: 40325413 | M26: 0 | N26: 0
A27: 2 | B27: CE17A227# | C27: J12- | D27: SJ12 | E27: शहरामध्ये विविध ठिकाणी स्मशानभूमी / दफनभूमी विकसित करणे / दशक्रीया विधीसाठी घाट बांधणे व विविध विकासकामे करणे | F27: 0 | G27: 686631360 | H27: 686631360 | I27: 465820672 | J27: 220810688 | M27: 209600000 | N27: 209600000
A28: 3 | B28: CE17A242# | C28: J6- | D28: SJ6- | E28: शहरामध्ये दवाखाने / प्रसुतिगृह बांधणे / दवाखान्यांसाठी विविध उपकरणे खरेदी करणे / दवाखान्यातील मुलभूत सोयी सुविधांसाठी विविध विकासकामे करणे | F28: 0 | G28: 840987568 | H28: 840987568 | I28: 264252728 | J28: 576734840 | M28: 828200000 | N28: 828200000
A29: 4 | B29: CE17A243# | C29: _ | D29: _ | E29: प्राथमिक आरोग्य केंद्र उभारणे | F29: 0 | G29: 21662492 | H29: 21662492 | I29: 21662492 | J29: 0 | M29: 0 | N29: 0
A30: 5 | B30: CE17A244# | C30: _ | D30: _ | E30: शहरातील दवाखान्यांसाठी विविध उपकरणे खरेदी करणे | F30: 0 | G30: 163080010 | H30: 163080010 | I30: 153267558 | J30: 9812452 | M30: 0 | N30: 0
A31: 6 | B31: CE17A246# | C31: _ | D31: _ | E31: शहरातील दशक्रीया विधीसाठी घाट बांधणे, विविध विकास कामे करणे | F31: 0 | G31: 6384646 | H31: 6384646 | I31: 6384646 | J31: 0 | M31: 0 | N31: 0
F32: 0 | G32: 0 | H32: 0 | I32: 0 | J32: 0 | M32: 0 | N32: 0
E33: ७. आरोग्य विभाग एकूण बेरीज | F33: 0 | G33: 2329437894 | H33: 2329437894 | I33: 1481754501 | J33: 847683393 | M33: 1037800000 | N33: 1037800000
F34: 0 | G34: 0 | H34: 0 | I34: 0 | J34: 0 | M34: 0 | N34: 0
E35: ९. पथांची झाडलोट / घनकचरा व्यवस्थापन विभाग | F35: 0 | G35: 0 | H35: 0 | I35: 0 | J35: 0 | M35: 0 | N35: 0
A36: 1 | B36: CE19A116 | E36: उरूळी देवाची/फुरसंगी डेपो परिसर कचरा डेपोवरील उर्वरित कचर्‍याचे नॉर्म्सप्रमाणे कॅपिंग करणे व तद्‌नुषंगिक कामे करणे | F36: 0 | G36: 813320173 | H36: 813320173 | I36: 790856400 | J36: 22463773 | M36: 16000000 | N36: 16000000
A37: 2 | B37: CE19A117 | E37: उरुळी देवाची/फुरसुंगी येथील कचरा डेपोच्या भोवती सिमाभिंत बांधणे. | F37: 0 | G37: 51114640 | H37: 51114640 | I37: 43929374 | J37: 7185266 | M37: 5600000 | N37: 5600000
A38: 3 | B38: CE19A120 | E38: व्हर्मीकंपोस्ट पध्दतीचे प्रक्रिया प्रकल्प उभारणे. | F38: 0 | G38: 158603349 | H38: 158603349 | I38: 153449062 | J38: 5154287 | M38: 0 | N38: 0
A39: 4 | B39: CE19A122 | E39: कचरा प्रक्रिया प्रकल्पासाठी जागा ताब्यात घेणे, कंपाउंड करणे, रस्ते करणे व तदनुषंगिक कामे करणे. | F39: 0 | G39: 70227366 | H39: 70227366 | I39: 61347347 | J39: 8880019 | M39: 8000000 | N39: 8000000
A40: 5 | B40: CE19A123 | E40: ताब्यात येणार्‍या जागांवर प्रक्रिया प्रकल्प उभारणे, प्रकल्पांसाठी आवश्यक सुविधा विषयक कामे करणे इत्यादी. | F40: 0 | G40: 201235156 | H40: 201235156 | I40: 170507493 | J40: 30727663 | M40: 64000000 | N40: 64000000
A41: 6 | B41: CE19A139 | E41: उरुळी देवाची/फुरसंगी येथील गावांमध्ये विविध विकास कामे करणे | F41: 0 | G41: 522978961 | H41: 522978961 | I41: 503977745 | J41: 19001216 | M41: 4000000 | N41: 4000000
A42: 7 | B42: CE19A141 | E42: घनकचरा व्यवस्थापनकडील कचरागाडया, बंदिस्त करणे विविध रॅम्प बंदिस्त करणे व कॉक्रीट करणे. | F42: 0 | G42: 121265592 | H42: 121265592 | I42: 111136555 | J42: 10129037 | M42: 8000000 | N42: 8000000
A43: 8 | B43: CE19A143 | E43: गार्डन वेस्टसाठी विविध ठिकाणी पुणे मनपा हद्दीत श्रेडर मशिन बसविणे | F43: 0 | G43: 7120378 | H43: 7120378 | I43: 4692213 | J43: 2428165 | M43: 1600000 | N43: 1600000
...

Sheet A_Land_Acquisition
A1: सन 2020-21 चे अंदाजपत्रक - खास निधीतून करावयाची योजनांतर्गत कामे
A2: अनुक्रमांक | C2: कामाचे नाव | D2: मान्य अंदाज 2019-20 | E2: नवीन अंदाज 2020-21
A6: s
A7: (अ) | C7: भूमी संपादन निधीतून करावयाचा खर्च | D7: 0 | E7: 0
D8: 0 | E8: 0
A9: 1 | B9: FE11A101 | C9: भूमी संपादन विशेष अधिकारी यांचा कार्यालयीन खर्च - | D9: 14000000 | E9: 16000000
A10: 2 | C10: कोर्टाच्या निकालानुसार वाढीव नुकसानभरपाई कोर्ट खर्च, वकील फी, जॉइन्ट जज्ज यांचा खर्च वगैरे | D10: 0 | E10: 0
A11: 3 | C11: भूमी संपादन अधिनियमात नव्याने केलेल्या दुरुस्तीमुळे यापूर्वी जाहीर झालेल्या योजनापोटी ावयाच्या वाढीव रकमेचा खर्च | D11: 0 | E11: 0
A12: 4 | C12: परचेस नोटीसांमुळे (नवीन) पाठवावयाच्या भूमी संपादन योजनांसाठी तरतूद | D12: 0 | E12: 0
A13: 5 | C13: ताब्यात घेतलेल्या मिळकती पाडणे, ड्रेनेज, वॉटर, इलेक्ट्रीक टेलिफोन वगैरे कनेक्शन्स हलविणे, जोडणे व इतर तद्‌नुषंगिक कामे करणे. | D13: 0 | E13: 0
A14: 6 | C14: कार्यालयीन कामासाठी साधने, डेडस्टॉक वस्तू खरेदी करणे, हत्यारे खरेदी करणे, कार्यालय व कोठीची दुरुस्ती करणे, आवश्यक सुधारणा करणे, प्रकटन खर्च, प्रवास खर्च वगैर | D14: 0 | E14: 0
A15: 7 | C15: मुंबई प्रांतिक मनपा अधिनियम १९४९ च्या कलम २१३ अन्वये रस्तारूंदीसाठी ताब्यात घेतलेल्या मोकळ्या जागा व त्याप्रित्यर्थ ावयाची नुकसानभरपाईची रक्कम | D15: 0 | E15: 0
A16: 8 | C16: इतर योजनांमधील मोजणी फी व इतर तद्‌नुषंगिक रक्कम | D16: 0 | E16: 0
A17: 9 | C17: भूमी संपादन अधिकारी ह्यांचेकडील खालील नमूद केलेल्या ज्या जागांचे निवाडे जाहीर करतील त्यासाठी रक्कम | D17: 0 | E17: 0
A18: 10 | C18: संगणक दुरूस्ती व आवश्यक साहित्य | D18: 0 | E18: 0
D19: 0 | E19: 0
C20: (अ) बेरीज | D20: 14000000 | E20: 16000000
D21: 0 | E21: 0
D22: 0 | E22: 0
B23: FE11A102 | C23: भूसंपादनासाठी आवश्यक जागांची यादी :- | D23: 196000000 | E23: 224000000
D24: 0 | E24: 0
C25: सी.वाय.जी अंतर्गत रस्ते : | D25: 0 | E25: 0
C26: बाणेर मुख्य रस्ता २६१ ते १०५ | D26: 0 | E26: 0
C27: बाणेर स.क्र. १३३ ते बालेवाडी स.क्र. १० बालेवाडीकडे जाणारा रस्ता मुख्य रस्ता (बालेवाडी) | D27: 0 | E27: 0
C28: बालेवाडी स.क्र. ३४, ३५ जी१ गार्डनचे आरक्षण | D28: 0 | E28: 0
C29: बाणेर स.क्र. २८, २९० जी२ गार्डनचे आरक्षण व बाणेर स.क्र. ३५ जी३ गार्डनचे आरक्षण | D29: 0 | E29: 0
C30: कल्याणीनगर जंक्शन ते आळंदी रोड | D30: 0 | E30: 0
C31: बाणेर स.क्र. १०५, १०६, ११०, १११ पीएमटी१ | D31: 0 | E31: 0
C32: बाणेर स.क्र. ३३ पी.३ | D32: 0 | E32: 0
C33: बाणेर स.क्र. १०० पी.४ | D33: 0 | E33: 0
C34: बाणेर स.क्र. १७४ पी.४ | D34: 0 | E34: 0
C35: बाणेर स.क्र. ७९ पी.६ | D35: 0 | E35: 0
C36: बाणेर स.क्र. १०५, १०६ पी.७ पार्किंगचे आरक्षण | D36: 0 | E36: 0
... C42: एअरपोर्ट रोड ते डेक्कन कॉलेज व्हाया हॉटमिक्स प्लँट | D42: 0 | E42: 0
D43: 0 | E43: 0
C44: जेएनएनयुआरएम / बीआरटी अंतर्गत रस्ते : | D44: 0 | E44: 0
C45: बाणेर स.क्र. १०७, १०८ व ११० मधून जाणारा १८ मी. रस्ता. | D45: 0 | E45: 0
C46: मौजे खराडी ता. हवेली, संगमवाडी ते खराडी २४ मी. नदीकाठचा डी.पी. रस्ता | D46: 0 | E46: 0
C47: मौजे वडगांव शेरी ता. हवेली, संगमवाडी ते खराडी २४ मी. नदीकाठचा डी.पी. रस्ता | D47: 0 | E47: 0
C48: सिंहगड रस्ता महानगरपालिका हद्द दरम्यान नियोजनाते विकसीत करणे (वडगांव बुद्रुक) | D48: 0 | E48: 0
...

Sheet A_Fund_Expenditure
A1: सन 2020-21 चे उपनगरे विकास निधीचे | I1: योजनांतर्गत खर्चाबाबतचे अंदाजपत्रक
A2: अनुक्रमांक | B2: मान्यतेचा ठराव क्र. दिनांक (कोड) | C2: प्रभाग क्रमांक | D2: BPL | E2: कामाचे नाव अगर वर्णन | F2: दि. 31 मार्च 2020 अखेरपर्यंत केलेली तरतूद | I2: दि. 31 मार्च 2018 पर्यंतचा खर्चाचा नक्‍की आकडा | J2: 2018-19 मधील खर्चाचा नक्‍की आकडा | K2: 2019-20 मधील खर्चाची अंदाजी रक्‍कम | L2: 2020-21 साठी अधिक तरतूद | N2: 2020-21 साठी एकूण तरतूद | O2: शेरा
F3: कर्जातून | G3: महसूल निधीतून | H3: एकूण | L3: कर्जातून | M3: महसूल निधी व इतर निधी
E7: ४. झोपडपट्टी निर्मूलन व पुनर्वसन निधी | F7: 0 | G7: 0 | H7: 0 | I7: 0 | J7: 0 | K7: 0 | M7: 0 | N7: 0
A8: 1 | B8: FE14A101# | C8: _ | D8: SG1- | E8: निरनिराळ्या झोपडपट्टींमध्ये विविध विकासाची कामे करणे | F8: 33377000 | G8: 1481216179 | H8: 1514593179 | I8: 1451524833 | J8: 22589988 | K8: 40478358 | M8: 48000000 | N8: 48000000
A9: 2 | B9: FE14A104 | D9: B | E9: झो.नि.पु. अंतर्गत करावयाची कामे | F9: 0 | G9: 218678409 | H9: 218678409 | I9: 200515533 | J9: 2344077 | K9: 15818799 | M9: 15750000 | N9: 15750000
A10: 3 | B10: FE14A105# | C10: _ | D10: SG2- | E10: शहरामध्ये शौच्छालये / मुताऱ्या बांधणे | F10: 0 | G10: 1592998612 | H10: 1592998612 | I10: 1110668506 | J10: 197318651 | K10: 285011455 | M10: 83500000 | N10: 83500000
A11: 4 | B11: FE14A107 | D11: B | E11: दलित वस्ती सुधारणा अंतर्गत कामे करणे | F11: 0 | G11: 217095507 | H11: 217095507 | I11: 180595507 | J11: 20909876 | K11: 15590124 | M11: 0 | N11: 0
A12: 5 | B12: FE14A129 | D12: PL | E12: सार्वजनिक ठिकाणी शौचालय बांधणे | F12: 0 | G12: 61972215 | H12: 61972215 | I12: 36833637 | J12: 8957746 | K12: 16180832 | M12: 15750000 | N12: 15750000
A13: 6 | B13: FE14A130 | D13: PL | E13: सार्वजनिक ठिकाणी मुतार्‍या बांधणे | F13: 0 | G13: 40276532 | H13: 40276532 | I13: 23650532 | J13: 875626 | K13: 15750374 | M13: 15750000 | N13: 15750000
A14: 7 | B14: FE14A135 | E14: प्रभाग क्र.14ब, मधील बाबासाहेब आंबेडकर हॉस्टेल विकसित करणेकरिता अहवाल तयार करणे | F14: 0 | G14: 2000000 | H14: 2000000 | I14: 0 | J14: 0 | K14: 2000000 | M14: 0 | N14: 0
F15: 0 | G15: 0 | H15: 0 | I15: 0 | J15: 0 | K15: 0 | M15: 0 | N15: 0
E16: ४. झोपडपट्टी निर्मूलन व पुनर्वसन निधी एकूण बेरीज | F16: 33377000 | G16: 3614237454 | H16: 3647614454 | I16: 3003788548 | J16: 252995964 | K16: 390829942 | M16: 178750000 | N16: 178750000
F17: 0 | G17: 0 | H17: 0 | I17: 0 | J17: 0 | K17: 0 | M17: 0 | N17: 0
E18: क्षेत्रिय कार्यालयाने करावयाची कामे | F18: 0 | G18: 0 | H18: 0 | I18: 0 | J18: 0 | K18: 0 | M18: 0 | N18: 0
F19: 0 | G19: 0 | H19: 0 | I19: 0 | J19: 0 | K19: 0 | M19: 0 | N19: 0
A20: • | B20: FE14A118# | C20: W5 | D20: B | E20: क्षेत्रिय कार्यालय : झो.नि.पु. विभागाने करावयाची कामे | F20: 0 | G20: 250536825 | H20: 250536825 | I20: 234050825 | J20: 4402967 | K20: 12083033 | M20: 7950000 | N20: 7950000
A21: • | B21: FE14A121# | C21: C5 | D21: B | E21: क्षेत्रिय कार्यालय : नागरिकांच्या सहभाग योजनेतून झो.नि.पु. विभागाने करावयाची कामे | F21: 0 | G21: 136782423 | H21: 136782423 | I21: 136868423 | J21: 1265713 | K21: -1351713 | M21: 5950000 | N21: 5950000
F22: 0 | G22: 0 | H22: 0 | I22: 0 | J22: 0 | K22: 0 | M22: 0 | N22: 0
E23: क्षेत्रिय कार्यालयाने करावयाची कामे एकूण बेरीज | F23: 0 | G23: 387319248 | H23: 387319248 | I23: 370919248 | J23: 5668680 | K23: 10731320 | M23: 13900000 | N23: 13900000
F24: 0 | G24: 0 | H24: 0 | I24: 0 | J24: 0 | K24: 0 | M24: 0 | N24: 0
E25: ४. झोपडपट्टी निर्मूलन व पुनर्वसन निधीतून करावयाची कामे + क्षेत्रिय कार्यालयाने करावयाची कामे एकूण बेरीज | F25: 33377000 | G25: 4001556702 | H25: 4034933702 | I25: 3374707796 | J25: 258664644 | K25: 401561262 | M25: 192650000 | N25: 192650000
F26: 0 | G26: 0 | H26: 0 | I26: 0 | J26: 0 | K26: 0 | M26: 0 | N26: 0
E27: ४अ. मागासवर्गीय कल्याणकारी योजना निधी | F27: 0 | G27: 0 | H27: 0 | I27: 0 | J27: 0 | K27: 0 | M27: 0 | N27: 0
A28: 1 | B28: FE14B101 | D28: B-FA | E28: समाज विकास विभाग अंतर्गत मागासवर्गीय योजना | F28: 0 | G28: 496023151 | H28: 496023151 | I28: 418523151 | J28: 27131465 | K28: 50368535 | M28: 35000000 | N28: 35000000
A29: 2 | B29: FE14B112 | D29: B-FA | E29: लोकशाहीर अण्णाभाऊ साठे शैक्षणिक मदत योजना | F29: 0 | G29: 185242082 | H29: 185242082 | I29: 123242082 | J29: 24625000 | K29: 37375000 | M29: 41000000 | N29: 41000000
A30: 3 | B30: FE14B113 | D30: B-FA | E30: मौ. अबुल कलाम आझाद शैक्षणिक मदत योजना | F30: 0 | G30: 393988546 | H30: 393988546 | I30: 291988546 | J30: 40770000 | K30: 61230000 | M30: 71000000 | N30: 71000000
A31: 4 | B31: FE14B121 | D31: B-T | E31: मागासवर्गीय विद्यार्थ्यांना स्पर्धा परिक्षा मार्गदर्शन केंद्र चालविणे | F31: 0 | G31: 10401896 | H31: 10401896 | I31: 5401896 | J31: 442000 | K31: 4558000 | M31: 3000000 | N31: 3000000
A32: 5 | B32: FE14B122 | D32: B-T | E32: बालविकास केंद्र व वस्ती रिसोर्स सेंटर सुरू करणे | F32: 0 | G32: 13983487 | H32: 13983487 | I32: 9483487 | J32: 1446452 | K32: 3053548 | M32: 2000000 | N32: 2000000
A33: 6 | B33: FE14B123 | D33: B | E33: मागासवर्गीय कल्याणकारी योजनेअंतर्गत विविध योजना राबविणेसाठी मानधन तत्वावरील सेवकांचा मानधन खर्च | F33: 0 | G33: 31457860 | H33: 31457860 | I33: 22957860 | J33: 8044799 | K33: 455201 | M33: 5000000 | N33: 5000000
A34: 7 | B34: FE14B126 | D34: B | E34: बार्टीचे ४ केंद्र सुरू करणे (कोथरूड, सहकारनगर, शिवाजीनगर, भवानीपेठ) | F34: 0 | G34: 0 | H34: 0 | I34: 0 | J34: 0 | K34: 0 | M34: 0 | N34: 0
A35: 8 | B35: FE14B127 | D35: B | E35: माता रमार्इ भिमराव आंबेडकर योजनेअंतर्गत गवनि घोषीत व शहरी गरीब योजनेतील पात्र ठरणाऱ्या विधवा, निराधार महिलांसाठी दरमहा रू.1,000/- अर्थसहाय्य करणे (मागासवर्गीय कल्याणकारी योजना) | F35: 0 | G35: 16002788 | H35: 16002788 | I35: 1002788 | J35: 0 | K35: 15000000 | M35: 17000000 | N35: 17000000
A36: 9 | B36: FE14B128 | D36: B-FA | E36: डॉ. बाबासाहेब आंबेडकर विद्यार्थी वसतिगृह, घोले रोड येथील खाणावळीचा खर्च | F36: 0 | G36: 13920540 | H36: 13920540 | I36: 4920540 | J36: 2215717 | K36: 6784283 | M36: 5000000 | N36: 5000000
A37: 10 | B37: FE14B129 | D37: B-I | E37: शहरात आदिवासी विद्यार्थ्यांसाठी वसतिगृहे उभारणे | F37: 0 | G37: 40000000 | H37: 40000000 | I37: 0 | J37: 3885336 | K37: 36114664 | M37: 30000000 | N37: 30000000
A38: 11 | B38: FE14B130 | E38: बार्टी संस्थेच्या मदतीने विविध व्यावसायिक प्रशिक्षण देणे | F38: 0 | G38: 5000000 | H38: 5000000 | I38: 0 | J38: 0 | K38: 5000000 | M38: 0 | N38: 0
A39: 12 | B39: FE14B131 | D39: B-T | E39: विविध व्यावसायिक प्रशिक्षण देणे | F39: 0 | G39: 7000000 | H39: 7000000 | I39: 0 | J39: 795454 | K39: 6204546 | M39: 0 | N39: 0
A40: 13 | B40: FE14B132 | D40: B-S | E40: मागासवर्गीय कल्याणकारी योजनेचा अभ्यास, ऑडिट व सर्वेक्षण करणे | F40: 0 | G40: 1000000 | H40: 1000000 | I40: 0 | J40: 0 | K40: 1000000 | M40: 0 | N40: 0
A41: 14 | B41: FE14B133 | D41: B | E41: लोकशाहिर अण्णा भाऊ साठे यांच्या जन्मशताब्दी वर्षानिमित्त विविध कार्यक्रमाचे आयोजन करणे | F41: 0 | G41: 0 | H41: 0 | I41: 0 | J41: 0 | K41: 0 | M41: 10000000 | N41: 10000000
F42: 0 | G42: 0 | H42: 0 | I42: 0 | J42: 0 | K42: 0 | M42: 0 | N42: 0
E43: ४अ. मागासवर्गीय कल्याणकारी योजना निधी एकूण बेरीज | F43: 0 | G43: 1214020350 | H43: 1214020350 | I43: 877520350 | J43: 109356223 | K43: 227143777 | M43: 219000000 | N43: 219000000
...

Sheet A_DPDC_Machinery_Tree
A1: सन 2020-21 चे अंदाजपत्रक – खास निधीतून करावयाची योजनांतर्गत कामे
A2: अनुक्रमांक | B2: विवरण | F2: मान्य अंदाज 2019-20 | G2: नवीन अंदाज 2020-21
D3: 2017-18 | E3: 2018-19
C7: ५. पुणे जिल्हा नियोजन व विकास मंडळ निधीतून करावयाची कामे
C8: ५अ. मा. आमदारांनी सुचविल्याप्रमाणे करावयाची विकासाची कामे
A9: 1 | B9: FE15A101 | C9: बोपोडी मतदार संघ क्र. २४६ | D9: 0 | E9: 0 | F9: 5000000 | G9: 5000000
A10: 2 | B10: FE15A102 | C10: शिवाजीनगर मतदार संघ क्र. २४७ | D10: 8245720 | E10: 7569383 | F10: 5000000 | G10: 5000000
A11: 3 | B11: FE15A103 | C11: पर्वती मतदार संघ क्र. २४८ | D11: 7741474 | E11: 4049517 | F11: 5000000 | G11: 5000000
A12: 4 | B12: FE15A104 | C12: कसबा पेठ मतदार संघ क्र. २४९ | D12: 19590563 | E12: 17250785 | F12: 5000000 | G12: 5000000
A13: 5 | B13: FE15A105 | C13: भवानी पेठ मतदार संघ क्र. २५० | D13: 2233120 | E13: 0 | F13: 5000000 | G13: 5000000
A14: 6 | B14: FE15A106 | C14: पुणे (कॅन्टोन्मेंट) मतदार संघ क्र. २५१ | D14: 6010802 | E14: 6022891 | F14: 5000000 | G14: 5000000
A15: 7 | B15: FE15A107 | C15: विधान परिषद सदस्य | D15: 2598815 | E15: 1627378 | F15: 2500000 | G15: 2500000
D16: 0 | E16: 0 | F16: 0 | G16: 0
A17: 8 | B17: FE15A108 | C17: ५ब. मा. खासदारांनी सुचविल्याप्रमाणे करावयाची विकासाची कामे | D17: 12299310 | E17: 48067028 | F17: 20000000 | G17: 20000000
D18: 0 | E18: 0 | F18: 0 | G18: 0
A19: 9 | B19: FE15A110 | C19: महानगरपालिका क्षेत्रात मुलभूत सोईसुविधांसाठी विशेष अनुदान | D19: 43052096 | E19: 8971934 | F19: 0 | G19: 0
A20: 10 | B20: FE15A111 | C20: मुळशी मतदार संघ | D20: 0 | E20: 0 | F20: 2500000 | G20: 2500000
A21: 11 | B21: FE15A112 | C21: कोथरूड विधानसभा मतदार संघ | D21: 4660732 | E21: 2487968 | F21: 5000000 | G21: 5000000
A22: 12 | B22: FE15A113 | C22: हडपसर विधानसभा मतदार संघ | D22: 950400 | E22: 1486525 | F22: 5000000 | G22: 5000000
A23: 13 | B23: FE15A114 | C23: वडगांवशेरी विधानसभा मतदार संघ | D23: 0 | E23: 0 | F23: 5000000 | G23: 5000000
A24: 14 | B24: FE15A115 | C24: खडकवासला विधानसभा मतदार संघ | D24: 2531383 | E24: 0 | F24: 5000000 | G24: 5000000
A25: 15 | B25: FE15A117 | C25: सर्वसाधारण जिल्हा वार्षिक योजना अंतर्गत नाविन्यपूर्ण योजनांचा निधी | D25: 2499811 | E25: 0 | F25: 0 | G25: 0
A26: RE53A101 | C26: ५. पुणे जिल्हा नियोजन व विकास मंडळ निधीतून करावयाची कामे बेरीज | D26: 112414226 | E26: 97533409 | F26: 75000000 | G26: 75000000
D27: 0 | E27: 0 | F27: 0 | G27: 0
D28: 0 | E28: 0 | F28: 0 | G28: 0
C29: ७. यंत्रसामुग्री घसारा निधीतून विकत घ्याववयाची नवीन सामुग्री | D29: 0 | E29: 0 | F29: 0 | G29: 0
C30: अग्निशामक दलासाठी यंत्रसामुग्री :- | D30: 0 | E30: 0 | F30: 0 | G30: 0
B31: FE17A103-1 | C31: वॉटर टँकर पंपासह (2 नग) | D31: 9299998 | E31: 11680000 | F31: 39480000 | G31: 0
B32: FE17A103-2 | C32: फायर इंजिन गाडी (7 नग) | D32: 9300000 | E32: 29199998 | F32: 55440000 | G32: 56000000
B33: FE17A103-4 | C33: हायड्रोलिक प्लॅटफॉर्म | D33: 12798069 | E33: 0 | F33: 0 | G33: 0
B34: FE17A103-12 | C34: रेस्क्यू इक्वीपमेंट व लाईट मास्ट | D34: 7388960 | E34: 0 | F34: 28000000 | G34: 44000000
B35: FE17A103-31 | C35: मुख्य अग्निशमन अधिकारी यांचे कार्यालय वापरासाठी महेंद्र कंपनीचे स्कॉर्पीओ जीप खरेदी | D35: 0 | E35: 0 | F35: 0 | G35: 0
B36: FE17A107-23 | C36: आरोग्य विभागाकडील सरासरी आयुर्मान संपलेल्या आर्टीक्युलेटेड क्रेन निरस्त करून नवीन वाहने खरेदी करणे | D36: 0 | E36: 0 | F36: 0 | G36: 5600000
B37: FE17A114-6 | C37: बॅकहो लोडर खरेदी करणे | D37: 0 | E37: 4000200 | F37: 10500000 | G37: 0
B38: FE17A114-9 | C38: पथ विभागासाठी टिपर खरेदी करणे | D38: 0 | E38: 13749120 | F38: 10500000 | G38: 8000000
B39: FE17A114-10 | C39: पथ विभागाकडील कोठ्यांसाठी रोलर्स, मिक्‍सर्स, पेव्हर अन्य यंत्रसामुग्री खरेदी करणे | D39: 18701411 | E39: 0 | F39: 0 | G39: 0
B40: FE17A124 | C40: मोटार वाहन विभाग मशिनरी | D40: 124045 | E40: 81895 | F40: 1050000 | G40: 1600000
B41: FE17A146 | C41: मनपा पदाधिकारी व अधिकार्‍यांसाठी मोटारकार खरेदी करणे | D41: 9660473 | E41: 3145700 | F41: 7000000 | G41: 8000000
B42: FE17A149-3 | C42: कंटेनर दुरुस्ती व रंगवणे | D42: 1844372 | E42: 1973896 | F42: 1750000 | G42: 2000000
... B55: FE17A277# | C55: यंत्रसामुग्री घसारा निधीतून विकत घ्याववयाची सामुग्री (यादी Y1) | D55: 40925716 | E55: 40881598 | F55: 209200000 | G55: 106000000
...

Sheet A_Capital_List
A1: पथ विभागाकडील कामाच्या याद्या
A3: यादी क्र. A2
A4: शहरामधील रस्ते विकसित करणे आणि डांबरीकरण करणे
A5: CE20A102/A2-
A7: क्र. | B7: code | C7: ward | D7: कामाचे नाव | E7: प्रकल्पीय रक्कम | F7: तरतूद
A9: 1 | B9: CE20A102/A2-202 | C9: 8 | D9: पुणे पेठ औंध, स.नं. 126 / 2 क, सि.स.नं. 1185 येथील रस्ता विकसनसाठी भूसंपादन करणे. | F9: 4000000
A10: 2 | B10: CE20A102/A2-203 | C10: 9 | D10: स.नं. 116, 118 व स.नं. 113 मधून जाणारा 24 मी.डी.पी. रस्त्याचे भूसंपादन करणे. | F10: 4000000
A11: 3 | B11: CE20A102/A2-204 | C11: 9 | D11: शिवशक्ती चौक पाषाण स.नं. 112 व 123 मधून जाणारा 24 मी. डी.पी. रस्त्याचे भूसंपादन करणे. | F11: 4000000
A12: 4 | B12: CE20A102/A2-205 | C12: 9 | D12: सुस ते पाषाण यांना जोडणारा स.नं. 134, 135, 136, 137, 138 व 140 मधून जाणारा 36 मी.डी.पी. रस्त्याचे भूसंपादन करणे. | F12: 6000000
A13: 5 | B13: CE20A102/A2-206 | C13: 9 | D13: बाणेर स.नं. 102 व 103 मधून जाणा-या 36 मी.डी.पी. रस्त्याचे भूसंपादन करणे. | F13: 6000000
A14: 6 | B14: CE20A102/A2-207 | C14: 9 | D14: पाषाण स.नं. 1, 2, 3, 4, 5, 6, 7, 10, 11, 12 व 13 मधून जाणा-या 30 मी. रस्त्याचे भूसंपादन करणे. | F14: 4000000
A15: 7 | B15: CE20A102/A2-208 | C15: 27 | D15: प्रभाग क्रमांक 27 मधील शिवनेरीनगर येथील 18 मी. डी.पी. रस्ता कुमार पृथ्वी पर्यंत भूसंपादन करणे. | F15: 8000000
A16: 8 | B16: CE20A102/A2-209 | C16: 40 | D16: प्रभाग क्रमांक 40, दत्तनगर चौक ते लेक विस्टा, जांभूळवाडी रस्ता रुंदीकरणासह विकसित करणे व भूसंपादन करणे. | F16: 4000000
A17: 9 | B17: CE20A102/A2-210 | C17: 3 | D17: विमाननगर येथील साकोरेनगर ते निको गार्डन रस्ता डांबरीकरण करणे. | F17: 3200000
A18: 10 | B18: CE20A102/A2-211 | C18: 3 | D18: प्रभाग क्रमांक 3 मधील हर्मेस ड्रोम सोसायटी ते गणपती चौक रस्ता डांबरीकरण करणे. | F18: 3200000
A19: 11 | B19: CE20A102/A2-212 | C19: 4 | D19: खराडी श्री.छत्रपती शिवाजी महाराज पुतळा ते यशवंतनगर रस्ता डांबरीकरण करणे. | F19: 3200000
A20: 12 | B20: CE20A102/A2-213 | C20: 9 | D20: पाषाण स.नं. 137 व 138 मधून जाणा-या 12 मी.डी.पी.रस्त्याचे डांबरीकरण करणे व पदपथ करणे. | F20: 3200000
... A56: 48 | B56: CE20A102/A2-249 | C56: 40 | D56: प्रभाग क्रमांक 40, मैत्री चौक ते वंडरसिटी पर्यंतचा रस्ता भूसंपादन करून डांबरीकरण करणे. | F56: 3200000
A57: 49 | B57: CE20A102/A2-250 | C57: G | D57: पुणे नगर सर्व्हिस रस्ता डांबरीकरण करणे व तद्नुषंगिक कामे करणे. | F57: 3200000
A58: 50 | B58: CE20A102/A2-251 | C58: 11 | D58: प्रभाग क्रमांक 11, शिवराय शाळा समोरील 24 मी.डी. रस्ता पुर्न:डांबरीकरण करणे. | F58: 2000000
A59: 51 | B59: CE20A102/A2-252 | C59: 20 | D59: पॉवर हाऊस चौक ते ए.डी.कॅम्प रस्ता पुर्न:डांबरीकरण करणे. | F59: 2400000
A60: 52 | B60: CE20A102/A2-253 | C60: 24 | D60: हेलन केलर रस्ता पुर्न:डांबरीकरण करणे. | F60: 3200000
A61: 53 | B61: CE20A102/A2-254 | C61: 24 | D61: प्रभाग क्रमांक 24 मध्ये सय्यद नगर रस्ता पुर्न:डांबरीकरण करणे. | F61: 4000000
A62: 54 | B62: CE20A102/A2-255 | C62: 27 | D62: प्रभाग क्रमांक 27 मधील युनिटी पार्क रस्ता पुर्न:डांबरीकरण करणे. | F62: 6400000
A63: 55 | B63: CE20A102/A2-256 | C63: 40 | D63: प्रभाग क्रमांक 40, कात्रज चौक ते मांगडेवाडी पर्यंतचा रस्ता पुर्न:डांबरीकरण करणे. | F63: 3200000
A64: 56 | B64: CE20A102/A2-257 | C64: 41 | D64: प्रभाग क्रमांक 41, कोंढवा बुद्रुक खडी मशीन चौक ते येवलेवाडी रस्ता पुर्न:डांबरीकरण करणे. | F64: 4800000
A65: 57 | B65: CE20A102/A2-258 | C65: 41 | D65: प्रभाग क्रमांक 41, येवलेवाडी कमान ते मनपा शाळेपर्यंत रस्ता पुर्न:डांबरीकरण करणे. | F65: 3200000
A66: 58 | B66: CE20A102/A2-259 | C66: 41 | D66: प्रभाग क्रमांक 41, कोंढवा बुद्रुक अग्नीशमन केंद्र ते मनपा व्हेईकल पार्कींगपर्यंत 18मी. डी.पी. रस्ता पुर्न:डांबरीकरण करणे. | F66: 3200000
F67: 0
D68: सन 2019-20 मधील अपूर्ण कामांसाठी सन 2020-21 मध्ये उपलब्ध केलेली तरतूद | F68: 0
A69: 59 | B69: CE20A102/SA2-1725 | D69: तळजाई ते सिंहगड रस्ता नव्याने रस्ता करणेसाठी बोगदा तयार करणेसाठी सल्लागार नेमणे व डी.पी.आर.करणे. | F69: 10400000
A70: 60 | B70: CE20A102/A2-106 | D70: हडपसर औदयोगिक वसाहतीमधील टाटा हनीवेल कंपनी जवळील हडपसर औद्योगिक वसाहत ते मगरपट्टच्या मागील 24.00 मी. HCMTR रस्ता जोडणारया डी.पी. रस्तच्या दोनही कॅनॉलवरील पुल बांधणे | F70: 20000000
A71: 61 | B71: CE20A102/A2-1109+ | D71: सन 2019-20 मधील कामे पुर्ण करणेसाठी व जुने देयकासाठी (पेडींग बिलासाठी) | F71: 112000000
A72: 62 | B72: CE20A102/A2-1590+ | D72: शिवणे खराडी नदीकाठचा रस्ता विकसित करणे डीर्फड | E72: 3180000000 | F72: 280000000
A73: 63 | B73: CE20A102/A2-1619 | C73: 35D | D73: प्र. क्र. ३५ ड मधील मौलाना आझाद रस्ता विकसित करणे. | E73: 12900000 | F73: 1600000
A74: 64 | B74: CE20A102/A2-911 | C74: 36 | D74: बिबवेवाडी मुख्य रस्ता विकसित करणे | E74: 192600000 | F74: 40000000
A75: 65 | B75: CE20A102/SA2-1681 | C75: 23D | D75: प.क्र.23 ड हडपसर गाव ससाणेनगर रोडवरील छोटा कॅनॉलवरील पुल बांधुन रस्त्याची रूंदी वाढवुन रस्ता विकसित करणे | F75: 2400000
A76: 66 | B76: CE20A102/SA2-1715 | C76: 32 | D76: वारजे येथील कॅनॉल रोड ते मुठानदी पात्रापर्यंत हायवेलगत 12 मीटर सर्व्हिंस रस्ता डांबरीकरण करणे, आर.सी.सी.कल्व्हर्ट बांधणे,आर.सी.सी. रिटेनिंग वॉल करणे. | F76: 4000000
A77: 67 | B77: CE20A102/SA2-914 | D77: औंध, जंगली महाराज रोड च्या धर्तीवर USDG प्रमाणे बावधन परिसर विकसित करणे | F77: 13200000
A78: 68 | B78: CE20A884/SA10-309 | C78: 35D | D78: प्र. क्र. ३५ ड मधील शिवदर्शन येथे विविध विकास कामे करणे. | F78: 1600000
...

Sheet C_Revenue_Income
A1: पाणीपुरवठा व जलोत्सारण प्रकल्पांतर्गत | G1: खास निधी 'क' चा जमेचा गोषवारा व तपशील
A2: विवरण | C2: नक्की आकडा | H2: 2019-20 वर्षाचा अंदाज | J2: 2020-21 वर्षाचा अंदाज | M2: 2019-20 वर्षाच्या मान्य अंदाजाशी तुलना केलेला 2020-21 वर्षाचा मा. स्थायी समितीने मान्यता दिलेला अंदाज
C3: 2016-17 | D3: 2017-18 | E3: 2018-19 | F3: 2018-19 शेवटची सहामाही | G3: 2019-20 पहिली सहामाही | H3: मान्य अंदाज | I3: दुरूस्त अंदाज | J3: मा. महापालिका आयुक्त यांनी सुचविलेला | K3: मा. स्थायी समितीने मान्यता दिलेला | L3: मा. महानगर- पालिकेने संमत केलेला
M5: अधिक | N5: कमी
A7: अधिनियमाप्रमाणे कमीत कमी रोख शिल्लक ठेवण्याची रक्कम जमेस धरून वर्षारंभीची शिल्लक | C7: 100000 | D7: 100000 | E7: 100000 | F7: 100000 | G7: 0 | H7: 100000 | I7: 100000 | J7: 100000 | K7: 100000 | L7: 0 | M7: 0 | N7: 0
C8: 0 | D8: 0 | E8: 0 | F8: 0 | G8: 0 | H8: 0 | I8: 0 | J8: 0 | K8: 0 | L8: 0 | M8: 0 | N8: 0
A9: १. पाणीपुरवठा (अति. न.अ.) | C9: 0 | D9: 0 | E9: 0 | F9: 0 | G9: 0 | H9: 0 | I9: 0 | J9: 0 | K9: 0 | L9: 0 | M9: 0 | N9: 0
A10: क. पाणीपट्टी साधारण पाणीपट्टी (कआकसंप्र) | B10: XI12A101 | C10: 1114584244 | D10: 1147803539 | E10: 1337732647 | F10: 225587270 | G10: 1325821932 | H10: 1773500000 | I10: 1773500000 | J10: 2610000000 | K10: 2610000000 | L10: 0 | M10: 836500000 | N10: 0
A11: ख. शासनाकडून (कआकसंप्र) | B11: XI12B101 | C11: 0 | D11: 0 | E11: 0 | F11: 0 | G11: 0 | H11: 100000 | I11: 100000 | J11: 100000 | K11: 100000 | L11: 0 | M11: 0 | N11: 0
A12: च. PMPML कडील मिळकतीवरील पाणीपट्टी (कआकसंप्र) | B12: XI12F101 | C12: 0 | D12: 0 | E12: 0 | F12: 0 | G12: 0 | H12: 100000 | I12: 100000 | J12: 100000 | K12: 100000 | L12: 0 | M12: 0 | N12: 0
A13: छ. जललाभ कर (Water Benefit Tax) (कआकसंप्र) | B13: XI12G101 | C13: 543166436 | D13: 519828924 | E13: 558386876 | F13: 148046386 | G13: 433807213 | H13: 928600000 | I13: 928600000 | J13: 1180000000 | K13: 1180000000 | L13: 0 | M13: 251400000 | N13: 0
A14: ग. पाणीपट्टी पाणीमापकानुसार (अति.न.अ.) | B14: XI12C101 | C14: 401229463 | D14: 545850894 | E14: 884181735 | F14: 287116123 | G14: 240063023 | H14: 2350000000 | I14: 2350000000 | J14: 1650000000 | K14: 1650000000 | L14: 0 | M14: 0 | N14: 700000000
A15: ग१. मीटर पाणीपट्टी थकबाकीपोटी जमा | B15: XI12C101A | C15: 0 | D15: 0 | E15: 0 | F15: 0 | G15: 0 | H15: 550000000 | I15: 550000000 | J15: 50000000 | K15: 50000000 | L15: 0 | M15: 0 | N15: 500000000
A16: ग२. गवनि खात्याअंतर्गत होणारी पाणीपट्टी जमा | B16: XI12C101B | C16: 10942484 | D16: 8191908 | E16: 14631177 | F16: 4633185 | G16: 8615370 | H16: 25000000 | I16: 25000000 | J16: 25000000 | K16: 25000000 | L16: 0 | M16: 0 | N16: 0
A17: अनधिकृत कनेक्शन नियमित करण्यापोटी जमा | B17: XI12S101 | C17: 739 | D17: 3067 | E17: 0 | F17: 0 | G17: 3070 | H17: 40000000 | I17: 40000000 | J17: 5000000 | K17: 5000000 | L17: 0 | M17: 0 | N17: 35000000
A18: घ. पाणीमापक भाडे | B18: XI12D101 | C18: 5473 | D18: 13202 | E18: 2741759 | F18: 2741759 | G18: 17 | H18: 75000000 | I18: 75000000 | J18: 2500000 | K18: 2500000 | L18: 0 | M18: 0 | N18: 72500000
A19: ड. नवीन नळ आकार नळदुरुस्ती व साफसफी (परतजमा) | B19: XI12E101 | C19: 7255295 | D19: 15447884 | E19: 6506111 | F19: 1853833 | G19: 3018500 | H19: 15000000 | I19: 15000000 | J19: 2500000 | K19: 2500000 | L19: 0 | M19: 0 | N19: 12500000
A20: ठ. कॉलनी रस्त्यावर पाईप टाकणे कामापोटी सुपरव्हिजन स्क्रुटीनी फी व अन्य जमा होणार | B20: XI12K101 | C20: 12393427 | D20: 10956334 | E20: 17461303 | F20: 5209272 | G20: 350817 | H20: 22500000 | I20: 22500000 | J20: 32500000 | K20: 32500000 | L20: 0 | M20: 10000000 | N20: 0
A21: ढ. जलकेंद्राच्या आवारांतील निवास स्थानापोटी जमा होणारे भाडे | B21: XI12L101 | C21: 1089901 | D21: 1412457 | E21: 0 | F21: 0 | G21: 0 | H21: 2000000 | I21: 2000000 | J21: 2000000 | K21: 2000000 | L21: 0 | M21: 0 | N21: 0
... A28: ण. अंदाजपत्रक 'अ' कडून वर्ग | B28: XI12M101 | C28: 2363450642 | D28: -696342303 | E28: 1955095785 | F28: 1955095785 | G28: 0 | H28: -820000000 | I28: -820000000 | J28: 831267000 | K28: 1243100000 | L28: 0 | M28: 2063100000 | N28: 0
C29: 0 | D29: 0 | E29: 0 | F29: 0 | G29: 0 | H29: 0 | I29: 0 | J29: 0 | K29: 0 | L29: 0 | M29: 0 | N29: 0
A30: १. बेरीज | C30: 4517524035 | D30: 1619170660 | E30: 4860707869 | F30: 2677408797 | G30: 2042767757 | H30: 5084100000 | I30: 5084100000 | J30: 6563267000 | K30: 6975000000 | L30: 0 | M30: 1890900000 | N30: 0
C31: 0 | D31: 0 | E31: 0 | F31: 0 | G31: 0 | H31: 0 | I31: 0 | J31: 0 | K31: 0 | L31: 0 | M31: 0 | N31: 0
A32: १अ. पुणे कॅन्टोन्मेंट पाणीपुरवठा जमा (अति.न.अ.) | C32: 0 | D32: 0 | E32: 0 | F32: 0 | G32: 0 | H32: 0 | I32: 0 | J32: 0 | K32: 0 | L32: 0 | M32: 0 | N32: 0
A33: (१) पाणीमापकानुसार पाणीपट्टी | B33: XI12Q101 | C33: 172872513 | D33: 74930244 | E33: 164167267 | F33: -35832733 | G33: 113521737 | H33: 200000000 | I33: 200000000 | J33: 210000000 | K33: 210000000 | L33: 0 | M33: 10000000 | N33: 0
A34: (२) H.E. Factory कडून येणारी जमा | B34: XI12Q102 | C34: 131099065 | D34: 156399237 | E34: 50889083 | F34: -19110917 | G34: 15765267 | H34: 75000000 | I34: 75000000 | J34: 85000000 | K34: 85000000 | L34: 0 | M34: 10000000 | N34: 0
C35: 0 | D35: 0 | E35: 0 | F35: 0 | G35: 0 | H35: 0 | I35: 0 | J35: 0 | K35: 0 | L35: 0 | M35: 0 | N35: 0
A36: १अ. बेरीज | C36: 303971578 | D36: 231329481 | E36: 215056350 | F36: -54943650 | G36: 129287004 | H36: 275000000 | I36: 275000000 | J36: 295000000 | K36: 295000000 | L36: 0 | M36: 20000000 | N36: 0
C37: 0 | D37: 0 | E37: 0 | F37: 0 | G37: 0 | H37: 0 | I37: 0 | J37: 0 | K37: 0 | L37: 0 | M37: 0 | N37: 0
A38: पुणे शहरात तंत्रशुध्द पध्दतीने पाणीपुरवठा करण्याची योजना (24x7) अनुदान (AMRUT) | B38: ZI12A111 | C38: 0 | D38: 0 | E38: 0 | F38: -750000000 | G38: 0 | H38: 0 | I38: 0 | J38: 0 | K38: 0 | L38: 0 | M38: 0 | N38: 0
A39: पुणे शहरात तंत्रशुध्द पध्दतीने पाणीपुरवठा (24x7) योजनेंतर्गत टाक्या बांधणेसाठी अनुदान (AMRUT) | B39: ZI12A111A | C39: 0 | D39: 399000000 | E39: 308700000 | F39: 308700000 | G39: 0 | H39: 500000000 | I39: 500000000 | J39: 310000000 | K39: 310000000 | L39: 0 | M39: 0 | N39: 190000000
A40: पुणे शहरात तंत्रशुध्द पध्दतीने पाणीपुरवठा करण्याची योजना (24x7) कर्जरोखे विक्री | B40: ZI12A112 | C40: 0 | D40: 2000000000 | E40: 0 | F40: 0 | G40: 0 | H40: 2000000000 | I40: 2000000000 | J40: 2000000000 | K40: 2000000000 | L40: 0 | M40: 0 | N40: 0
C41: 0 | D41: 0 | E41: 0 | F41: 0 | G41: 0 | H41: 0 | I41: 0 | J41: 0 | K41: 0 | L41: 0 | M41: 0 | N41: 0
A42: राष्ट्रीय नदीसुधारणा प्रकल्पातंर्गत (JICA) केंद्र सरकारकडून अनुदान | B42: ZI12A102 | C42: 259899999 | D42: 0 | E42: 317500000 | F42: 317500000 | G42: 0 | H42: 680000000 | I42: 680000000 | J42: 250000000 | K42: 250000000 | L42: 0 | M42: 0 | N42: 430000000
C43: 0 | D43: 0 | E43: 0 | F43: 0 | G43: 0 | H43: 0 | I43: 0 | J43: 0 | K43: 0 | L43: 0 | M43: 0 | N43: 0
A44: १. एकूण बेरीज | C44: 5081395612 | D44: 4249500141 | E44: 5701964219 | F44: 2498665147 | G44: 2172054761 | H44: 8539100000 | I44: 8539100000 | J44: 9418267000 | K44: 9830000000 | L44: 0 | M44: 1290900000 | N44: 0
C45: 0 | D45: 0 | E45: 0 | F45: 0 | G45: 0 | H45: 0 | I45: 0 | J45: 0 | K45: 0 | L45: 0 | M45: 0 | N45: 0
A46: २. गटारे व नाले सुधारणा (अति.न.अ.) | C46: 0 | D46: 0 | E46: 0 | F46: 0 | G46: 0 | H46: 0 | I46: 0 | J46: 0 | K46: 0 | L46: 0 | M46: 0 | N46: 0
A47: क. सफाईपट्टी (कआकसंप्र) | B47: XI23A101 | C47: 2148672982 | D47: 1941205852 | E47: 2085529792 | F47: -1010470208 | G47: 1598114042 | H47: 3961000000 | I47: 3961000000 | J47: 3400000000 | K47: 3400000000 | L47: 0 | M47: 0 | N47: 561000000
A48: घ. सुअरेज बेनिफीट टॅक्स (कआकसंप्र) | B48: XI23D101 | C48: 967066203 | D48: 896401311 | E48: 961744905 | F48: -718255095 | G48: 745079105 | H48: 1820000000 | I48: 1820000000 | J48: 2280000000 | K48: 2280000000 | L48: 0 | M48: 460000000 | N48: 0
...

Sheet C_Revenue_Expenditure
A1: योजनेतर खर्च तपशील
A2: विवरण | D2: नक्‍की आकडा | G2: मान्य अंदाज 2019-20 | H2: नवीन अंदाज 2020-21
D3: 2016-17 | E3: 2017-18 | F3: 2018-19
A5: १. पाणीपुरवठा | D5: 0 | E5: 0 | F5: 0 | G5: 0 | H5: 0
A6: क. पाणीपुरवठा | D6: 0 | E6: 0 | F6: 0 | G6: 0 | H6: 0
A7: १. मध्यवर्ती कार्यालय, कायम सेवकवर्ग वेतन | B7: XE12A101A | D7: 24270905 | E7: 23580337 | F7: 21639240 | G7: 30000000 | H7: 23300000
A8: २अ. कायम सेवकवर्ग वेतन | B8: XE12A101B | D8: 129159922 | E8: 144923511 | F8: 133028605 | G8: 150000000 | H8: 140000000
A9: २ब. कायम सेवकवर्ग वेतन (वि.का.) | B9: XE12A###A | D9: 10793008 | E9: 9860217 | F9: 8092170 | G9: 15000000 | H9: 15000000
A10: ३. संकीर्ण | B10: XE12A103 | D10: 496203 | E10: 650931 | F10: 446243 | G10: 880000 | H10: 900000
A11: ४. पाण्याची किंमत (पर्वती पंपिंग स्टेशन) | B11: XE12A104 | D11: 130832460 | E11: 319936464 | F11: 793046040 | G11: 1360000000 | H11: 729000000
A12: ५. पाणी शुद्ध करणे व तद्‌नुषंगिक कामे करणे | B12: XE12A105 | D12: 68067821 | E12: 58867962 | F12: 50205650 | G12: 48000000 | H12: 64800000
A13: ६. प्रयोगशाळा देखभाल खर्च | B13: XE12A106 | D13: 956631 | E13: 227793 | F13: 0 | G13: 985000 | H13: 1080000
A14: ७-अ. पंपिंग वीज खर्च | B14: XE12A107 | D14: 479999999 | E14: 601043722 | F14: 693640000 | G14: 763800000 | H14: 792000000
A15: ९. कोठी इतर साहित्य खर्च | B15: XE12A109 | D15: 2975682 | E15: 1189931 | F15: 340813 | G15: 2080000 | H15: 2250000
A16: १२. पर्वती जलकेंद्रातील यंत्रसामुग्रीवरील घसारा (मु.ले.) | B16: XE12A112 | D16: 164000 | E16: 190000 | F16: 215000 | G16: 0 | H16: 0
A17: १४. जलप्रदूषण प्रतिबंधक खर्च | B17: XE12A115 | D17: 4823834 | E17: 2007642 | F17: 0 | G17: 3360000 | H17: 2700000
A18: १८. जलकेंद्र पाण्याच्या टाक्या येथे प्रकाश व्यवस्था व दूरध्वनी व्यवस्था | B18: XE12A120 | D18: 0 | E18: 0 | F18: 0 | G18: 640000 | H18: 900000
... A38: पर्वती जलकेंद्र प्रयोगशाळा येथे पाणी तपासणीसाठी लागणारी विविध उपकरणे व तद्‌नुषंगिक साहित्य खरेदी करणे | B38: XE12A146 | D38: 0 | E38: 359999 | F38: 0 | G38: 400000 | H38: 0
A39: क. बेरीज | D39: 957068541 | E39: 1278265818 | F39: 1799104371 | G39: 2477705000 | H39: 1981945000
D40: 0 | E40: 0 | F40: 0 | G40: 0 | H40: 0
A41: ख१. नळ खाते (स्वारगेट विभाग) | D41: 0 | E41: 0 | F41: 0 | G41: 0 | H41: 0
A42: १. कायम सेवक वर्ग वेतन | B42: XE12B101A | D42: 198416480 | E42: 215760319 | F42: 221769160 | G42: 220000000 | H42: 244000000
A43: २. संकीर्ण | B43: XE12B102 | D43: 799999 | E43: 652480 | F43: 463550 | G43: 720000 | H43: 648000
A44: ४. शहरांतील / नव्याने समाविष्ट गावांतील सर्व व्हॉल्व्हज्‌ चालू व बंद करणे | B44: XE12B107 | D44: 31092583 | E44: 36455792 | F44: 39585979 | G44: 30800000 | H44: 47250000
A45: ८. टँकरने पाणीपुरवठा करणे | B45: XE12B111 | D45: 16107816 | E45: 9305117 | F45: 14825987 | G45: 12000000 | H45: 19800000
A46: ९. कोठी व इतर साहित्य खरेदी | B46: XE12B112 | D46: 23841464 | E46: 20282433 | F46: 17886533 | G46: 25200000 | H46: 27000000
A47: १०. देखभाल दुरुस्ती : नळदुरुस्ती व स्वच्छता तातडीच्या दुरुस्त्या चेंबर करणे, आर.सी.सी, कव्हर बसविणे व तदनुषंगिक कामे करणे | B47: XE12B113 | D47: 44788541 | E47: 45376228 | F47: 47904841 | G47: 35200000 | H47: 50400000
A48: ११. टाक्‍यांची दुरुस्ती | B48: XE12B114 | D48: 0 | E48: 719282 | F48: 0 | G48: 640000 | H48: 926100
A49: पाणीपुरवठा विभागाकडील देखभाल दुरूस्तीची कामे (यादी X1) | B49: XE12B115# | D49: 20005303 | E49: 9880350 | F49: 2634964 | G49: 0 | H49: 30700000
D50: 0 | E50: 0 | F50: 0 | G50: 0 | H50: 0
A51: ख१. बेरीज | D51: 335052186 | E51: 338432001 | F51: 345071014 | G51: 324560000 | H51: 420724100
D52: 0 | E52: 0 | F52: 0 | G52: 0 | H52: 0
A53: ख२. नळ खाते (विभागीय कार्यालय) | D53: 0 | E53: 0 | F53: 0 | G53: 0 | H53: 0
A54: १. कायम सेवकवर्ग वेतन | B54: XE12B###A | D54: 36831303 | E54: 31495599 | F54: 23964490 | G54: 50000000 | H54: 40000000
A55: क्षेत्रीय कार्यालयाने करावयाची योजनेतर कामे | B55: XE12B301/W6-# | D55: 1380528 | E55: 0 | F55: 943661 | G55: 5450000 | H55: 0
A56: क्षेत्रीय कार्यालयाने नागरिकांच्या सहभागातून करावयाची योजनेतर कामे | B56: XE12B302/C6-# | D56: 8138352 | E56: 2161144 | F56: 2817441 | G56: 6800000 | H56: 10300000
D57: 0 | E57: 0 | F57: 0 | G57: 0 | H57: 0
A58: ख२. बेरीज | D58: 46350183 | E58: 33656743 | F58: 27725592 | G58: 62250000 | H58: 50300000
D59: 0 | E59: 0 | F59: 0 | G59: 0 | H59: 0
A60: ख. एकूण बेरीज | D60: 381402369 | E60: 372088744 | F60: 372796606 | G60: 386810000 | H60: 471024100
...

Sheet C_Revenue_List
A1: पाणीपुरवठा विभागाकडील कामाच्या याद्या
A3: यादी क्र. SX1
A4: पाणीपुरवठा विभागाकडील देखभाल दुरूस्तीची कामे
A5: XE12B115/SX1-
A7: क्र. | B7: code | C7: ward | D7: कामाचे नाव | E7: प्रकल्पीय रक्कम | F7: तरतूद
A9: 1 | B9: XE12B115/SX1-1 | C9: 2C | D9: प्रभाग क्र.2क,विविध ठिकाणी पाण्याची लाईन दुरूस्त करणे | F9: 1000000
A10: 2 | B10: XE12B115/SX1-2 | C10: 3A | D10: प्रभाग क्र.3अ,मध्ये पाणीपुरवठा विषयक दुरूस्ती कामे करणे | F10: 1000000
A11: 3 | B11: XE12B115/SX1-3 | C11: 3C | D11: प्रभाग क्र.3क, परिसरात पाणीपुरवठा व्हॉल्व्ह दुरूस्ती विषयक कामे करणे | F11: 1000000
A12: 4 | B12: XE12B115/SX1-4 | C12: 5D | D12: प्रभाग क्र.5ड मध्ये पाणीपुरवठा विषयक मेंटन्स विषयक कामे करणे | F12: 1000000
A13: 5 | B13: XE12B115/SX1-5 | C13: 6B | D13: प्रभाग क्र.6ब, मध्ये विविध ठिकाणी पिण्याच्या पाण्याच्या लाईनचे दुरूस्ती विषयक कामे करणे | F13: 500000
A14: 6 | B14: XE12B115/SX1-6 | C14: 9B | D14: प्रभाग क्र.9ब, मध्ये विविध ठिकाणी बोरवेल घेणे व बोरवेल दुरूस्ती विषयक कामे करणे | F14: 1000000
A15: 7 | B15: XE12B115/SX1-7 | C15: 14A | D15: प्रभाग क्र. 14 अ, मध्ये विविध ठिकाणी नळ कोंडाळे दुरुस्ती करणे. | F15: 500000
A16: 8 | B16: XE12B115/SX1-8 | C16: 17B | D16: प्रभाग क्र. 17 ब, मध्ये विविध नळ कोंडाळे दुरुस्ती करणे. | F16: 1000000
A17: 9 | B17: XE12B115/SX1-9 | C17: 17D | D17: प्रभाग क्र. 17 ड, मध्ये नळकोंडाळे दुरुस्ती विषयक कामे करणे. | F17: 1000000
A18: 10 | B18: XE12B115/SX1-10 | C18: 18A | D18: प्रभाग क्र.18 अ,मध्ये विविध नळकोंडाळे दुरूस्ती करणे | F18: 1000000
A19: 11 | B19: XE12B115/SX1-11 | C19: 18A | D19: प्रभाग क्र.18 अ, मध्ये पी.एम.सी.कॉलनी क्र.8 व 9 येथे पाण्याची टाकी दुरूस्त करणे | F19: 1000000
A20: 12 | B20: XE12B115/SX1-12 | C20: 18D | D20: प्रभाग क्र. 18 ड, मध्ये पुणे मनपा विविध ठिकाणी पिण्याच्या पाण्याच्या टाक्या साफसफाई करणे. | F20: 300000
... A24: 16 | B24: XE12B115/SX1-16 | C24: 36B | D24: प्रभाग क्र. 36 ब मध्ये पाणीपुरवठा देखभाल व दुरुस्तीविषयक कामे करणे. | F24: 1000000
A25: 17 | B25: XE12B115/SX1-17 | D25: लष्कर पाणीपुरवठयासाठी DPR तयार करणे | F25: 5000000
A26: 18 | B26: XE12B115/SX1-18 | D26: पुणे शहर व लगतच्या टेकडयांवर शहरी जलयुक्त शिवार योजना राबविणे | F26: 1000000
A27: 19 | B27: XE12B115/SX1-19 | D27: पुणे महानगरपालिका हद्दीमध्ये जलयुक्त शहर अभियान व जलशक्ती अभियान राबविणे | F27: 10000000
D29: यादी क्र. SX1 एकूण | E29: 0 | F29: 30700000
A32: यादी क्र. X2
A33: मलनिःस्सारण विभागाकडील देखभाल दुरूस्तीची कामे
A34: XE23A117/X2-
A36: क्र. | B36: code | C36: ward | D36: कामाचे नाव | E36: प्रकल्पीय रक्कम | F36: तरतूद
A38: 1 | B38: XE23A117/X2-190 | D38: निरी अगर अन्य शासकीय संस्था यांचेकडून पुणे महानगरपालिकेच्या विविध मैलापाणी शुध्दीकरण केंद्राची वार्षिक तपासणी तसेच मान्यताप्राप्त प्रयोगशाळेमधून पाण्याची तपासणी करुन घेणे. | F38: 1800000
A39: 2 | B39: XE23A117/X2-191 | D39: विठ्ठलवाडी मैलापाणी शुध्दीकरण केंद्र / उपसा केंद्र येथे सेकंडरी झोनमधील सेटलींक टँकमधील चॅनलमध्ये फरशी बसविणे आवारातील रस्ते डांबरीकरण करणे व तद्‌नुषंगिक दुरुस्ती कामे करणे. | F39: 1800000
A40: 3 | B40: XE23A117/X2-192 | D40: बहिरोबा मैलापाणी शुध्दीकरण केंद्र येथे डायजेस्टर / थिकनर विषयक दुरुस्ती कामे करणे व खराब झालेल्या लाईन्स बदलणे व तद्‌नुषंगिक कामे करणे. | F40: 1800000
A41: 4 | B41: XE23A117/X2-193 | D41: कोथरुड बावधन क्षेत्रिय कार्यालयाच्या अंतर्गत येणाऱ्या मुख्य मलवाहिन्यांची देखभाल व दुरुस्ती करणे तसेच तद्‌नुषंगिक कामे करणे. | F41: 3150000
A42: 5 | B42: XE23A117/X2-194 | D42: औध बाणेर क्षेत्रिय कार्यालयाच्या प्रभाग क्र. ८ अंतर्गत येणाऱ्या मुख्य मलवाहिन्यांची देखभाल व दुरुस्ती करणे तसेच तद्‌नुषंगिक कामे करणे. | F42: 2700000
A43: 6 | B43: XE23A117/X2-195 | D43: औध बाणेर क्षेत्रिय कार्यालयाच्या प्रभाग क्र. ९ अंतर्गत येणाऱ्या मुख्य मलवाहिन्यांची देखभाल व दुरुस्ती करणे तसेच तद्‌नुषंगिक कामे करणे. | F43: 2700000
A44: 7 | B44: XE23A117/X2-196 | D44: भैरवी नाल्यातील जागोजागी खचलेली मुख्य मलवाहिनी बदलणे तसेच देखभाल व दुरुस्ती करणे. | F44: 2700000
A45: 8 | B45: XE23A117/X2-197 | D45: बावधन परिसरातील नाल्यामधील मुख्य मलवाहिन्यांची देखभाल, दुरुस्ती तसेच तद्‌नुषंगिक कामे करणे. | F45: 2700000
A46: 9 | B46: XE23A117/X2-198 | D46: वारजे क्षेत्रिय कार्यालयाअंतर्गत येणाऱ्या मुख्य मलवाहिन्यांची देखभाल व दुरुस्ती करणे. | F46: 1800000
A47: 10 | B47: XE23A117/X2-199 | D47: शिवणे उत्तमनगर येथील अस्तित्वात असलेल्या जुन्या व जीर्ण झालेल्या मलवाहिन्यांची देखभाल व दुरुस्ती करणे. | F47: 2250000
A48: 11 | B48: XE23A117/X2-200 | D48: आंबेगाव खुर्द आणि आंबेगाव बुद्रुक येथील अस्तित्वात असलेल्या जुन्या व जीर्ण झालेल्या मलवाहिन्यांची देखभाल व दुरुस्ती करणे. | F48: 2250000
A49: 12 | B49: XE23A117/X2-201 | D49: पुणे मनपा हद्दीमध्ये नव्याने समाविष्ठ झालेल्या गावांमधील अस्तित्वातील मलवाहिन्यांची देखभाल, दुरुस्ती व तद्‌नुषंगिक तसेच इत्यादी कामे करणे. | F49: 2250000
... A93: 57 | B93: XE23A117/X2-247 | D93: हडपसर क्षेत्रिय कार्यालयाच्या परिसरातील भैरोबा नाला व त्याचे उपनाल्यात अतिवृष्टीमुळे नादुरुस्त झालेल्या मुख्य मलवाहिन्या व चेंबर्स दुरुस्ती करणे. | F93: 2700000
D95: यादी क्र. X2 एकूण | E95: 0 | F95: 131400000
...

Sheet C_Capital_Expenditure
A1: सन 2020-21 चे योजनांतर्गत | I1: खर्चाबाबतचे अंदाजपत्रक
A2: अनुक्रमांक | B2: मान्यतेचा ठराव क्र. दिनांक (कोड) | C2: प्रभाग क्रमांक | D2: BPL | E2: कामाचे नाव अगर वर्णन | F2: दि. 31 मार्च 2020 अखेरपर्यंत केलेली तरतूद | I2: दि. 31 मार्च 2019 पर्यंतचा खर्चाचा नक्‍की आकडा | J2: 2019-20 मधील खर्चाची अंदाजी रक्कम | L2: 2020-21 साठी अधिक तरतूद | N2: 2020-21 साठी एकूण तरतूद | O2: प्रकल्पीय रक्कम
F3: कर्जातून | G3: महसूल निधीतून | H3: एकूण | J3: प्रत्यक्ष उपलब्ध तरतूद | K3: कर्जातून तरतूद | L3: कर्जातून | M3: महसूल निधी व इतर निधी
E7: 1. पाणीपुरवठा विभाग | G7: 0 | H7: 0 | I7: 0 | J7: 0 | M7: 0 | N7: 0
G8: 0 | H8: 0 | I8: 0 | J8: 0 | M8: 0 | N8: 0
A9: 1 | B9: ZE16A103# | C9: P1- | D9: SP1- | E9: शहरामध्ये पाण्याच्या टाक्या बांधणे / बोअरवेल घेणे / जलशुध्दीकरण केंद्रे बांधणे आणि विद्युत / स्थापत्य / यांत्रिकीविषयक कामे करणे | G9: 71225000 | H9: 71225000 | I9: 48702034 | J9: 22522966 | M9: 241900000 | N9: 241900000
