Workbook
Name BdgtNo: [1]index!$L$9
Name BdgtYear: [1]index!$L$8
Name BdgtYrFrom: [1]index!$L$15
Name BdgtYrTo: [1]index!$L$16
Name Description: "P_A_C_Ex"
Name FinYrFrom: [1]index!$L$13
Name FinYrTo: [1]index!$L$14
Name Head: '[1]a|ex|smry'!$B$1:$AE$1
Name Last2Yr: [1]index!$L$7
Name Last3Yr: [1]index!$L$6
Name Last4thYear: [1]index!$L$12
Name Last4Yr: [1]index!$L$5
Name Last5thYear: [1]index!$L$11
Name Last5Yr: [1]index!$L$4
Name List_Smry_0: list21!#REF!
Name List_Smry_1: list21!#REF!
Name List_Smry_2: list21!#REF!
Name P_A_A03: A_Revenue_Income!$A$7:$N$503
Name P_A_A05: A_Revenue_Expenditure!$A$4:$H$1654
Name P_A_A10: [1]A10!$A$2:$P$38,[1]A10!$I$45:$P$75
Name P_A_A12: A_Capital_Expenditure!$A$7:$N$212
Name P_A_A14: A_Land_Acquisition!$A$5:$E$387
Name P_A_A15: A_Fund_Expenditure!$A$7:$N$148
Name P_A_A16: A_DPDC_Machinery_Tree!$A$6:$G$118
Name P_A_Bdgt: A_DPDC_Machinery_Tree!$A$6:$G$118
Name P_A_Bdgt: A_Fund_Expenditure!$A$7:$N$148
Name P_A_Bdgt: A_Land_Acquisition!$A$5:$E$387
Name P_A_Bdgt: A_Revenue_Income!$A$7:$N$503
Name P_A_Bdgt: C_Revenue_Expenditure!$A$4:$H$368
Name P_A_Bdgt: WO_Work21_MC!$A$4:$Q$145
Name P_A_C02: C_Revenue_Income!$A$7:$N$61
Name P_A_C03: C_Revenue_Expenditure!$A$4:$H$368
Name P_A_Doller_MC: [1]dollar!$B$12:$AK$62,[1]dollar!$AM$76:$BH$134,[1]dollar!$BS$176:$BX$231
Name P_A_Doller_SC: [1]dollar!$B$12:$AK$62,[1]dollar!$AM$76:$BH$134,[1]dollar!$BY$176:$CD$231
Name P_A_jnnurm: JNNURM!$A$1:$H$27
Name P_A_ListA: list21!$A$2:$E$7216
Name P_A_ListC: list21!$A$7219:$E$9324
Name P_A_Smry: A_Fund_Expenditure!$A$139:$N$148
Name P_A_SPV: PMAY!$A$1:$G$7
Name P_A_SPV: SPV!$A$1:$G$25
Name P_A_W_RE: WO_Work21_MC!$A$4:$Q$162
Name Print_Area_Bdgt: [1]A10!$A$2:$P$38,[1]A10!$I$45:$P$75
Name txt_cd_1: A_DPDC_Machinery_Tree!$E:$E
Name Yantra_Series: A_DPDC_Machinery_Tree!#REF!

Sheet A_Revenue_Income
A1: जमेचा | G1: तपशील
A2: विवरण | C2: नक्की आकडा | H2: 2020-21 वर्षाचा अंदाज | J2: 2021-22 वर्षाचा अंदाज | M2: 2020-21 वर्षाच्या मान्य अंदाजाशी तुलना केलेला 2021-22 वर्षाचा मा. स्थायी समितीने मान्यता दिलेला अंदाज
C3: 2017-18 | D3: 2018-19 | E3: 2019-20 | F3: 2019-20 शेवटची सहामाही | G3: 2020-21 पहिली सहामाही | H3: मान्य अंदाज | I3: दुरूस्त अंदाज | J3: मा. महापालिका आयुक्त यांनी सुचविलेला | K3: मा. स्थायी समितीने मान्यता दिलेला | L3: मा. महानगर- पालिकेने संमत केलेला
M5: अधिक | N5: कमी
A7: अधिनियमाप्रमाणे कमीत कमी रोख शिल्लक ठेवण्याची रक्कम जमेस धरून वर्षारंभीची शिल्लक | B7: 0 | C7: 100000 | D7: 100000 | E7: 100000 | F7: 100000 | G7: 0 | H7: 100000 | I7: 100000 | J7: 100000 | K7: 100000 | L7: 0 | M7: 0 | N7: 0
C8: 0 | D8: 0 | E8: 0 | F8: 0 | G8: 0 | H8: 0 | I8: 0 | J8: 0 | K8: 0 | L8: 0 | M8: 0 | N8: 0
A9: १. सर्वसाधारण कर, अप्रत्यक्ष कर व इतर जमा | C9: 0 | D9: 0 | E9: 0 | F9: 0 | G9: 0 | H9: 0 | I9: 0 | J9: 0 | K9: 0 | L9: 0 | M9: 0 | N9: 0
A10: क. सर्वसाधारण पट्टी | C10: 0 | D10: 0 | E10: 0 | F10: 0 | G10: 0 | H10: 0 | I10: 0 | J10: 0 | K10: 0 | L10: 0 | M10: 0 | N10: 0
A11: १. नागरिकांकडून (कआकसंप्र) | B11: RI11A101 | C11: 3311564173 | D11: 3361147014 | E11: 3613696720 | F11: 1077695792 | G11: 2531474118 | H11: 8050000000 | I11: 8050000000 | J11: 9050000000 | K11: 11050000000 | L11: 0 | M11: 3000000000 | N11: 0
A12: लोहगाव (उर्वरित) | B12: RI11AA101 | C12: 6685 | D12: 37675 | E12: 646073 | F12: 431813 | G12: 191050 | H12: 0 | I12: 0 | J12: 0 | K12: 0 | L12: 0 | M12: 0 | N12: 0
A13: मुंढवा (उर्वरित केशवनगर) | B13: RI11AB101 | C13: 2930 | D13: 8185 | E13: 1067975 | F13: 678090 | G13: 70995 | H13: 0 | I13: 0 | J13: 0 | K13: 0 | L13: 0 | M13: 0 | N13: 0
A14: हडपसर (संपूर्ण साडेसतरानळी) | B14: RI11AC101 | C14: 865 | D14: 3735 | E14: 85825 | F14: 85675 | G14: 8800 | H14: 0 | I14: 0 | J14: 0 | K14: 0 | L14: 0 | M14: 0 | N14: 0
A15: शिवणे (संपूर्ण उत्तमनगर) | B15: RI11AD101 | C15: 295 | D15: 13465 | E15: 387130 | F15: 245265 | G15: 85205 | H15: 0 | I15: 0 | J15: 0 | K15: 0 | L15: 0 | M15: 0 | N15: 0
A16: शिवणे | B16: RI11AE101 | C16: 0 | D16: 9565 | E16: 2103535 | F16: 975665 | G16: 138550 | H16: 0 | I16: 0 | J16: 0 | K16: 0 | L16: 0 | M16: 0 | N16: 0
A17: आंबेगाव खुर्द | B17: RI11AF101 | C17: 4070 | D17: 6810 | E17: 1974340 | F17: 1102295 | G17: 86270 | H17: 0 | I17: 0 | J17: 0 | K17: 0 | L17: 0 | M17: 0 | N17: 0
A18: उंड्री | B18: RI11AG101 | C18: 3145 | D18: 3755 | E18: 1132345 | F18: 911445 | G18: 826845 | H18: 0 | I18: 0 | J18: 0 | K18: 0 | L18: 0 | M18: 0 | N18: 0
A19: धायरी | B19: RI11AH101 | C19: 1460 | D19: 32565 | E19: 24150 | F19: 2680 | G19: 124535 | H19: 0 | I19: 0 | J19: 0 | K19: 0 | L19: 0 | M19: 0 | N19: 0
A20: आंबेगाव बुद्रुक | B20: RI11AJ101 | C20: 19000 | D20: 19645 | E20: 2560515 | F20: 1545540 | G20: 215745 | H20: 0 | I20: 0 | J20: 0 | K20: 0 | L20: 0 | M20: 0 | N20: 0
A21: फुरसुंगी | B21: RI11AK101 | C21: 31460 | D21: 110450 | E21: 2070710 | F21: 1557730 | G21: 293510 | H21: 0 | I21: 0 | J21: 0 | K21: 0 | L21: 0 | M21: 0 | N21: 0
A22: उरुळी देवाची | B22: RI11AL101 | C22: 15030 | D22: 33235 | E22: 101150 | F22: 62960 | G22: 40770 | H22: 0 | I22: 0 | J22: 0 | K22: 0 | L22: 0 | M22: 0 | N22: 0
... A27: पुणे मनपा हद्दीमध्ये नव्याने समाविष्ट होणारी 23 गावे (कआकसंप्र) | B27: RI11A107 | C27: 0 | D27: 0 | E27: 0 | F27: 0 | G27: 0 | H27: 0 | I27: 0 | J27: 1300000000 | K27: 2300000000 | L27: 0 | M27: 2300000000 | N27: 0
C28: 0 | D28: 0 | E28: 0 | F28: 0 | G28: 0 | H28: 0 | I28: 0 | J28: 0 | K28: 0 | L28: 0 | M28: 0 | N28: 0
A29: क. सर्वसाधारण कर बेरीज | C29: 3431242459 | D29: 3525303066 | E29: 3803991790 | F29: 1122309375 | G29: 2596010987 | H29: 11707800000 | I29: 11707800000 | J29: 10516500000 | K29: 13516500000 | L29: 0 | M29: 1808700000 | N29: 0
C30: 0 | D30: 0 | E30: 0 | F30: 0 | G30: 0 | H30: 0 | I30: 0 | J30: 0 | K30: 0 | L30: 0 | M30: 0 | N30: 0
A31: ख. आयातकर | C31: 0 | D31: 0 | E31: 0 | F31: 0 | G31: 0 | H31: 0 | I31: 0 | J31: 0 | K31: 0 | L31: 0 | M31: 0 | N31: 0
A32: १. पक्की जमा (आ.क.प्र.) | B32: RI11B101 | C32: 0 | D32: -5618500 | E32: -4881548 | F32: -4881548 | G32: 0 | H32: 0 | I32: 0 | J32: 0 | K32: 0 | L32: 0 | M32: 0 | N32: 0
C33: 0 | D33: 0 | E33: 0 | F33: 0 | G33: 0 | H33: 0 | I33: 0 | J33: 0 | K33: 0 | L33: 0 | M33: 0 | N33: 0
A34: ख. निव्वळ आयातकर एकूण बेरीज | C34: 0 | D34: -5618500 | E34: -4881548 | F34: -4881548 | G34: 0 | H34: 0 | I34: 0 | J34: 0 | K34: 0 | L34: 0 | M34: 0 | N34: 0
C35: 0 | D35: 0 | E35: 0 | F35: 0 | G35: 0 | H35: 0 | I35: 0 | J35: 0 | K35: 0 | L35: 0 | M35: 0 | N35: 0
A36: ख-१. स्थानिक संस्था कर | C36: 0 | D36: 0 | E36: 0 | F36: 0 | G36: 0 | H36: 0 | I36: 0 | J36: 0 | K36: 0 | L36: 0 | M36: 0 | N36: 0
A37: स्थानिक संस्था कर नोंदणी शुल्क | B37: RI11B201 | C37: 489206 | D37: 300 | E37: 0 | F37: 0 | G37: 0 | H37: 0 | I37: 0 | J37: 0 | K37: 0 | L37: 0 | M37: 0 | N37: 0
A38: स्थानिक संस्था कर | B38: RI11B202 | C38: 1514559653 | D38: 14074585 | E38: 1120093 | F38: 460463 | G38: 0 | H38: 10000000 | I38: 10000000 | J38: 5000000 | K38: 5000000 | L38: 0 | M38: 0 | N38: 5000000
A39: चौरस मीटर बांधकामाप्रमाणे भरावयाची ठोक रक्कम | B39: RI11B202B | C39: 87144478 | D39: 3832035 | E39: 5510120 | F39: 2330247 | G39: 0 | H39: 100000 | I39: 100000 | J39: 200000 | K39: 200000 | L39: 0 | M39: 100000 | N39: 0
A40: निर्गत मालापोटी १० % हिस्सा | B40: RI11B202D | C40: 1498056 | D40: 0 | E40: 0 | F40: 0 | G40: 0 | H40: 0 | I40: 0 | J40: 0 | K40: 0 | L40: 0 | M40: 0 | N40: 0
A41: इतर जमा - स्थानिक संस्था कर | B41: RI11B202E | C41: 0 | D41: 25232 | E41: 1780 | F41: 1780 | G41: 0 | H41: 0 | I41: 0 | J41: 0 | K41: 0 | L41: 0 | M41: 0 | N41: 0
A42: स्थानिक संस्था करापोटी व्याज | B42: RI11B203 | C42: 24745902 | D42: 6911393 | E42: 821243 | F42: 368373 | G42: 0 | H42: 1400000 | I42: 1400000 | J42: 500000 | K42: 500000 | L42: 0 | M42: 0 | N42: 900000
A43: स्थानिक संस्था कर शास्ती (दंड) | B43: RI11B204 | C43: 295000 | D43: 80000 | E43: 25000 | F43: 25000 | G43: 5000 | H43: 0 | I43: 0 | J43: 0 | K43: 0 | L43: 0 | M43: 0 | N43: 0
A44: राज्य शासनाकडून मुद्रांक शुल्क अधिभारापोटी मिळालेली रक्कम (१%) | B44: RI11B206 | C44: 1769515876 | D44: 2758200420 | E44: 1749317051 | F44: 1236376967 | G44: 247275393 | H44: 2500000000 | I44: 2500000000 | J44: 1700000000 | K44: 1700000000 | L44: 0 | M44: 0 | N44: 800000000
A45: मनपा ठेकेदारांच्या बिलांमधून LBT वसुली | B45: RI11B207 | C45: 3161206 | D45: 92301 | E45: 889 | F45: 802 | G45: 6082 | H45: 0 | I45: 0 | J45: 0 | K45: 0 | L45: 0 | M45: 0 | N45: 0
A46: राज्यशासनाकडून LBT साठी सहाय्यक अनुदान | B46: RI11B208 | C46: 4285500000 | D46: 0 | E46: 0 | F46: 0 | G46: 0 | H46: 0 | I46: 0 | J46: 0 | K46: 0 | L46: 0 | M46: 0 | N46: 0
...

Sheet A_Revenue_Expenditure
A1: योजनेतर खर्च तपशील
A2: विवरण | D2: नक्‍की आकडा | G2: मान्य अंदाज 2020-21 | H2: नवीन अंदाज
D3: 2017-18 | E3: 2018-19 | F3: 2019-20 | H3: 2021-22
A5: १. मुख्य देखरेख, वसुली वगैरे | D5: 0 | E5: 0 | F5: 0 | G5: 0 | H5: 0
A6: क. महानगरपालिका व स्थायी समिती | D6: 0 | E6: 0 | F6: 0 | G6: 0 | H6: 0
A7: १ नगरसचिव यांचे कार्यालय | D7: 0 | E7: 0 | F7: 0 | G7: 0 | H7: 0
A8: १. नगरसचिव (म्युनिसिपल सेक्रेटरी) (मुं.प्रां. मनपा अधिनियम, कलम४५(३) प्रमाणे) वेतन | B8: RE11A101A | D8: 1142457 | E8: 1357957 | F8: 1343918 | G8: 1600000 | H8: 1500000
A9: २. कायम सेवकवर्ग वेतन | B9: RE11A102A | D9: 39568566 | E9: 38537287 | F9: 37739899 | G9: 42500000 | H9: 45000000
A10: ३. संकीर्ण (न.स.) | B10: RE11A103 | D10: 4393519 | E10: 4967904 | F10: 727424 | G10: 7200000 | H10: 10000000
A11: ३अ. मागील बिले देण्यासाठी (न.स.) | B11: RE11A103A | D11: 3965718 | E11: 2886671 | F11: 1251212 | G11: 3600000 | H11: 4000000
A12: ४. प्रवास खर्च (न.स.) | B12: RE11A104 | D12: 22316 | E12: 35207 | F12: 133002 | G12: 1800000 | H12: 2000000
A13: ५. ग्रंथालय व वाचनालय | B13: RE11A105 | D13: 196204 | E13: 172716 | F13: 189625 | G13: 225000 | H13: 250000
A14: ६. समारंभ खर्च (न.स. व वि.अ.) | B14: RE11A106 | D14: 45760 | E14: 68200 | F14: 0 | G14: 450000 | H14: 500000
A15: १०. अखिल भारतीय/महाराष्ट्र महापौर परिषद व अखिल भारतीय स्थानिक स्वराज्य संस्था प्रतिनिधी अधिवेशन | B15: RE11A110 | D15: 0 | E15: 0 | F15: 0 | G15: 270000 | H15: 300000
A16: ११. मनपा व शासकीय निवृत्त सेवकांना द्यावयाचा चहापान खर्च | B16: RE11A111 | D16: 114450 | E16: 3000 | F16: 0 | G16: 270000 | H16: 300000
A17: १३. महाराष्ट्र राज्य महानगरपालिका स्थायी समिती अध्यक्ष परिषद वर्गणी व तद्‌नुषंगिक खर्च | B17: RE11A113 | D17: 0 | E17: 0 | F17: 0 | G17: 900 | H17: 1000
A18: १४. मा. महापौर यांचा व्ययनियमन (सम्प्च्युअरी) भत्ता | B18: RE11A114 | D18: 0 | E18: 0 | F18: 0 | G18: 4500 | H18: 5000
A19: १५. मा. महापौर यांचा ऐच्छिक खर्च | B19: RE11A115 | D19: 199238 | E19: 95427 | F19: 57402 | G19: 180000 | H19: 200000
... A53: नगरसचिव विभागामार्फत आवश्यक सेवक भरती करणे (कंत्राटी) | B53: RE11A280 | D53: 0 | E53: 0 | F53: 0 | G53: 10000000 | H53: 10000000
D54: 0 | E54: 0 | F54: 0 | G54: 0 | H54: 0
A55: क. मनपा व स्थायी समिती बेरीज | D55: 109200819 | E55: 87211238 | F55: 94077423 | G55: 172230100 | H55: 173656000
D56: 0 | E56: 0 | F56: 0 | G56: 0 | H56: 0
A57: ख. मुख्य लेखापरिक्षक यांचे कार्यालय | D57: 0 | E57: 0 | F57: 0 | G57: 0 | H57: 0
A58: १. मुख्य लेखापरिक्षक (म्युनिसिपल चीफ ऑडिटर) (मु.प्रां. मनपा अधिनियम, कलम ४५ (३) प्रमाणे) यांचे वेतन | B58: RE11B101A | D58: 4018155 | E58: 2623589 | F58: 2390291 | G58: 2700000 | H58: 2500000
A59: २. कायम सेवकवर्ग वेतन | B59: RE11B102A | D59: 23877085 | E59: 29232284 | F59: 26552946 | G59: 30000000 | H59: 29000000
A60: ३. संकीर्ण | B60: RE11B103 | D60: 109686 | E60: 115189 | F60: 66256 | G60: 225000 | H60: 225000
D61: 0 | E61: 0 | F61: 0 | G61: 0 | H61: 0
A62: ख. मुख्यलेखापरिक्षक यांचे कार्या. बेरीज | D62: 28004926 | E62: 31971062 | F62: 29009493 | G62: 32925000 | H62: 31725000
D63: 0 | E63: 0 | F63: 0 | G63: 0 | H63: 0
A64: ग१. महापालिका आयुक्त यांचे कार्यालय | D64: 0 | E64: 0 | F64: 0 | G64: 0 | H64: 0
A65: १. महापालिका आयुक्त (म्युनिसिपल कमिशनर) (मु. प्रां. मनपा अधिनियम, कलम ३७ (१) प्रमाणे) यांचे वेतन | B65: RE11C101A | D65: 2633227 | E65: 2531394 | F65: 2816569 | G65: 3200000 | H65: 3000000
A66: २. उपआयुक्त (जनरल) (मुं. प्रां. मनपा अधिनियम, कलम ४५(३) प्रमाणे) यांचे वेतन | B66: RE11C102A | D66: 610426 | E66: 1175614 | F66: 1635153 | G66: 2500000 | H66: 2500000
A67: ३. कायम सेवकवर्ग वेतन | B67: RE11C103A | D67: 28024193 | E67: 29549463 | F67: 28289154 | G67: 31000000 | H67: 29500000
A68: ४. संकीर्ण | B68: RE11C104 | D68: 1342954 | E68: 1356556 | F68: 1450875 | G68: 1800000 | H68: 2000000
A69: ६. मा. महापालिका आयुक्त यांचा ऐच्छिक खर्च (म.स.आ.) | B69: RE11C106 | D69: 14147 | E69: 50003 | F69: 139240 | G69: 720000 | H69: 850000
D70: 0 | E70: 0 | F70: 0 | G70: 0 | H70: 0
A71: ग१. महापालिका आयुक्त कार्यालय बेरीज | D71: 32624947 | E71: 34663030 | F71: 34330991 | G71: 39220000 | H71: 37850000
D72: 0 | E72: 0 | F72: 0 | G72: 0 | H72: 0
A73: ग२. अतिरिक्त महापालिका आयुक्त (विशेष) यांचे कार्यालय | D73: 0 | E73: 0 | F73: 0 | G73: 0 | H73: 0
A74: १. अतिरिक्त महापालिका आयुक्त (विशेष) यांचे वेतन | B74: RE11C126A | D74: 1012344 | E74: 2041368 | F74: 1390901 | G74: 3200000 | H74: 3000000
...

Sheet A_Capital_Expenditure
H1: खर्चाबाबतचे अंदाजपत्रक
A2: मान्यतेचा ठराव क्र. दिनांक (Code) | B2: प्रभाग क्रमांक | C2: BPL | D2: कामाचे नाव अगर वर्णन | E2: दि. 31 मार्च 2021 अखेरपर्यंत केलेली तरतूद | H2: दि. 31 मार्च 2020 पर्यंतचा खर्चाचा नक्‍की आकडा | I2: 2020-21 मधील खर्चाची अंदाजी रक्कम | K2: 2021-22 साठी अधिक तरतूद | M2: 2021-22 साठी एकूण तरतूद | N2: प्रकल्पीय रक्कम
E3: कर्जातून | F3: महसूल निधीतून | G3: एकूण | I3: प्रत्यक्ष उपलब्ध तरतूद | J3: कर्जातून तरतूद | K3: कर्जातून | L3: महसूल निधी व इतर निधी
D8: १. मनपा भवन व मनपा इमारती | E8: 0 | F8: 0 | G8: 0 | H8: 0 | I8: 0 | L8: 0 | M8: 0
A9: CE11A129# | B9: J1- | C9: SJ1- | D9: शहरात विविध ठिकाणी मनपासाठी इमारती बांधणे व विकास कामे करणे | E9: 0 | F9: 823472243 | G9: 823472243 | H9: 631004899 | I9: 192467344 | L9: 198670000 | M9: 198670000
E10: 0 | F10: 0 | G10: 0 | H10: 0 | I10: 0 | L10: 0 | M10: 0
D11: १. मनपा भवन व मनपा इमारती एकूण बेरीज | E11: 0 | F11: 823472243 | G11: 823472243 | H11: 631004899 | I11: 192467344 | L11: 198670000 | M11: 198670000
E12: 0 | F12: 0 | G12: 0 | H12: 0 | I12: 0 | L12: 0 | M12: 0
D13: २. प्राथमिक शिक्षण | E13: 0 | F13: 0 | G13: 0 | H13: 0 | I13: 0 | L13: 0 | M13: 0
A14: CE12A381# | B14: _ | C14: _ | D14: प्राथमिक शाळेमध्ये मुलभूत सोयी सुविधांसाठी विविध विकासकामे करणे | E14: 0 | F14: 1370733043 | G14: 1370733043 | H14: 1301502862 | I14: 69230181 | L14: 0 | M14: 0
A15: CE12A422# | B15: J2- | C15: SJ2- | D15: प्राथमिक शाळेसाठी नवीन इमारत बांधणे / वर्गखोल्या बांधणे / मैदाने विकसित करणे व मुलभूत सोयी सुविधांसाठी विविध विकासकामे करणे | E15: 0 | F15: 1522133579 | G15: 1522133579 | H15: 749217804 | I15: 772915775 | L15: 237150000 | M15: 237150000
E16: 0 | F16: 0 | G16: 0 | H16: 0 | I16: 0 | L16: 0 | M16: 0
C17: B | D17: २. प्राथमिक शिक्षण एकूण बेरीज | E17: 0 | F17: 2952307439 | G17: 2952307439 | H17: 2110161483 | I17: 842145956 | L17: 237150000 | M17: 237150000
E18: 0 | F18: 0 | G18: 0 | H18: 0 | I18: 0 | L18: 0 | M18: 0
D19: ३. दुय्यम शिक्षण | E19: 0 | F19: 0 | G19: 0 | H19: 0 | I19: 0 | L19: 0 | M19: 0
A20: CE13A128# | B20: J5- | D20: माध्यमिक शाळांमध्ये मुलभूत सोयी सुविधांसाठी विविध विकासकामे करणे | E20: 0 | F20: 72785069 | G20: 72785069 | H20: 52979572 | I20: 19805497 | L20: 235600000 | M20: 235600000
E21: 0 | F21: 0 | G21: 0 | H21: 0 | I21: 0 | L21: 0 | M21: 0
C22: B | D22: ३. दुय्यम शिक्षण एकूण बेरीज | E22: 0 | F22: 72785069 | G22: 72785069 | H22: 52979572 | I22: 19805497 | L22: 235600000 | M22: 235600000
E23: 0 | F23: 0 | G23: 0 | H23: 0 | I23: 0 | L23: 0 | M23: 0
D24: ७. आरोग्य विभाग | E24: 0 | F24: 0 | G24: 0 | H24: 0 | I24: 0 | L24: 0 | M24: 0
A25: CE17A192# | B25: _ | C25: _ | D25: दवाखान्यातील मुलभूत सोयी सुविधांसाठी विविध विकासकामे करणे | E25: 0 | F25: 601866405 | G25: 601866405 | H25: 583746804 | I25: 18119601 | L25: 0 | M25: 0
A26: CE17A227# | B26: J12- | C26: SJ12 | D26: शहरामध्ये विविध ठिकाणी स्मशानभूमी / दफनभूमी विकसित करणे / दशक्रीया विधीसाठी घाट बांधणे व विविध विकासकामे करणे | E26: 0 | F26: 856012672 | G26: 856012672 | H26: 554940123 | I26: 301072549 | L26: 211850000 | M26: 211850000
A27: CE17A242# | B27: J6- | C27: SJ6- | D27: शहरामध्ये दवाखाने / प्रसुतिगृह बांधणे / दवाखान्यांसाठी विविध उपकरणे खरेदी करणे / दवाखान्यातील मुलभूत सोयी सुविधांसाठी विविध विकासकामे करणे | E27: 0 | F27: 1498602728 | G27: 1498602728 | H27: 392314381 | I27: 1106288347 | L27: 2195800000 | M27: 2195800000
A28: CE17A244# | B28: _ | C28: _ | D28: शहरातील दवाखान्यांसाठी विविध उपकरणे खरेदी करणे | E28: 0 | F28: 153267558 | G28: 153267558 | H28: 153267558 | I28: 0 | L28: 0 | M28: 0
E29: 0 | F29: 0 | G29: 0 | H29: 0 | I29: 0 | L29: 0 | M29: 0
C30: B | D30: ७. आरोग्य विभाग एकूण बेरीज | E30: 0 | F30: 3137796501 | G30: 3137796501 | H30: 1712316004 | I30: 1425480497 | L30: 2407650000 | M30: 2407650000
E31: 0 | F31: 0 | G31: 0 | H31: 0 | I31: 0 | L31: 0 | M31: 0
D32: ९. पथांची झाडलोट / घनकचरा व्यवस्थापन विभाग | E32: 0 | F32: 0 | G32: 0 | H32: 0 | I32: 0 | L32: 0 | M32: 0
A33: CE19A116 | D33: उरूळी देवाची/फुरसंगी डेपो परिसर कचरा डेपोवरील उर्वरित कचर्‍याचे नॉर्म्सप्रमाणे कॅपिंग करणे व तद्‌नुषंगिक कामे करणे | E33: 0 | F33: 824356400 | G33: 824356400 | H33: 805338528 | I33: 19017872 | L33: 14000000 | M33: 14000000
A34: CE19A117 | D34: उरुळी देवाची/फुरसुंगी येथील कचरा डेपोच्या भोवती सिमाभिंत बांधणे. | E34: 0 | F34: 55129374 | G34: 55129374 | H34: 48089046 | I34: 7040328 | L34: 4900000 | M34: 4900000
A35: CE19A120 | D35: व्हर्मीकंपोस्ट पध्दतीचे प्रक्रिया प्रकल्प उभारणे. | E35: 0 | F35: 153449062 | G35: 153449062 | H35: 153449062 | I35: 0 | L35: 0 | M35: 0
A36: CE19A122 | D36: कचरा प्रक्रिया प्रकल्पासाठी जागा ताब्यात घेणे, कंपाउंड करणे, रस्ते करणे व तदनुषंगिक कामे करणे. | E36: 0 | F36: 74597347 | G36: 74597347 | H36: 61347347 | I36: 13250000 | L36: 7000000 | M36: 7000000
A37: CE19A123 | D37: ताब्यात येणार्‍या जागांवर प्रक्रिया प्रकल्प उभारणे, प्रकल्पांसाठी आवश्यक सुविधा विषयक कामे करणे इत्यादी. | E37: 0 | F37: 255507493 | G37: 255507493 | H37: 187680442 | I37: 67827051 | L37: 70000000 | M37: 70000000
A38: CE19A139 | D38: उरुळी देवाची/फुरसंगी येथील गावांमध्ये विविध विकास कामे करणे | E38: 0 | F38: 518477745 | G38: 518477745 | H38: 505228418 | I38: 13249327 | L38: 7000000 | M38: 7000000
A39: CE19A141 | D39: घनकचरा व्यवस्थापनकडील कचरागाडया, बंदिस्त करणे विविध रॅम्प बंदिस्त करणे व कॉक्रीट करणे. | E39: 0 | F39: 126136555 | G39: 126136555 | H39: 115427594 | I39: 10708961 | L39: 7000000 | M39: 7000000
A40: CE19A143 | D40: गार्डन वेस्टसाठी विविध ठिकाणी पुणे मनपा हद्दीत श्रेडर मशिन बसविणे | E40: 0 | F40: 7622213 | G40: 7622213 | H40: 4943903 | I40: 2678310 | L40: 1050000 | M40: 1050000
A41: CE19A153 | D41: प्लास्टिक व इलेक्ट्रॉनिक वस्तू विभाजीत करणेकरीता शेड बांधणे | E41: 0 | F41: 20028393 | G41: 20028393 | H41: 16028393 | I41: 4000000 | L41: 3500000 | M41: 3500000
A42: CE19A154# | C42: SH1- | D42: शहरात घनकचरा संदर्भात विविध विकास कामे करणे | E42: 0 | F42: 331176807 | G42: 331176807 | H42: 250178553 | I42: 80998254 | L42: 359000000 | M42: 359000000
A43: CE19A155 | D43: e-waste जमा करणे व प्रक्रिया करणे | E43: 0 | F43: 4850000 | G43: 4850000 | H43: 850000 | I43: 4000000 | L43: 3500000 | M43: 3500000
A44: CE19A156 | D44: कचरा वाहतुकीसाठी नव्याने उपनगरांमध्ये रॅम्पचे आधुनिकीकरण, विकासकामे करणे, यंत्रसामग्री | E44: 0 | F44: 87192150 | G44: 87192150 | H44: 52004216 | I44: 35187934 | L44: 28000000 | M44: 28000000
...

Sheet A_Land_Acquisition
A1: सन 2021-22 चे अंदाजपत्रक - खास निधीतून करावयाची योजनांतर्गत कामे
A2: अनुक्रमांक | C2: कामाचे नाव | D2: मान्य अंदाज 2020-21 | E2: नवीन अंदाज 2021-22
A7: (अ) | C7: भूमी संपादन निधीतून करावयाचा खर्च | D7: 0 | E7: 0
D8: 0 | E8: 0
A9: 1 | B9: FE11A101 | C9: भूमी संपादन विशेष अधिकारी यांचा कार्यालयीन खर्च - | D9: 16000000 | E9: 14000000
A10: 2 | C10: कोर्टाच्या निकालानुसार वाढीव नुकसानभरपाई कोर्ट खर्च, वकील फी, जॉइन्ट जज्ज यांचा खर्च वगैरे | D10: 0 | E10: 0
A11: 3 | C11: भूमी संपादन अधिनियमात नव्याने केलेल्या दुरुस्तीमुळे यापूर्वी जाहीर झालेल्या योजनापोटी ावयाच्या वाढीव रकमेचा खर्च | D11: 0 | E11: 0
A12: 4 | C12: परचेस नोटीसांमुळे (नवीन) पाठवावयाच्या भूमी संपादन योजनांसाठी तरतूद | D12: 0 | E12: 0
A13: 5 | C13: ताब्यात घेतलेल्या मिळकती पाडणे, ड्रेनेज, वॉटर, इलेक्ट्रीक टेलिफोन वगैरे कनेक्शन्स हलविणे, जोडणे व इतर तद्‌नुषंगिक कामे करणे. | D13: 0 | E13: 0
A14: 6 | C14: कार्यालयीन कामासाठी साधने, डेडस्टॉक वस्तू खरेदी करणे, हत्यारे खरेदी करणे, कार्यालय व कोठीची दुरुस्ती करणे, आवश्यक सुधारणा करणे, प्रकटन खर्च, प्रवास खर्च वगैर | D14: 0 | E14: 0
A15: 7 | C15: मुंबई प्रांतिक मनपा अधिनियम १९४९ च्या कलम २१३ अन्वये रस्तारूंदीसाठी ताब्यात घेतलेल्या मोकळ्या जागा व त्याप्रित्यर्थ ावयाची नुकसानभरपाईची रक्कम | D15: 0 | E15: 0
A16: 8 | C16: इतर योजनांमधील मोजणी फी व इतर तद्‌नुषंगिक रक्कम | D16: 0 | E16: 0
A17: 9 | C17: भूमी संपादन अधिकारी ह्यांचेकडील खालील नमूद केलेल्या ज्या जागांचे निवाडे जाहीर करतील त्यासाठी रक्कम | D17: 0 | E17: 0
A18: 10 | C18: संगणक दुरूस्ती व आवश्यक साहित्य | D18: 0 | E18: 0
D19: 0 | E19: 0
C20: (अ) बेरीज | D20: 16000000 | E20: 14000000
D21: 0 | E21: 0
D22: 0 | E22: 0
B23: FE11A102 | C23: भूसंपादनासाठी आवश्यक जागांची यादी :- | D23: 224000000 | E23: 161000000
D24: 0 | E24: 0
C25: सी.वाय.जी अंतर्गत रस्ते : | D25: 0 | E25: 0
C26: बाणेर मुख्य रस्ता २६१ ते १०५ | D26: 0 | E26: 0
C27: बाणेर स.क्र. १३३ ते बालेवाडी स.क्र. १० बालेवाडीकडे जाणारा रस्ता मुख्य रस्ता (बालेवाडी) | D27: 0 | E27: 0
C28: बालेवाडी स.क्र. ३४, ३५ जी१ गार्डनचे आरक्षण | D28: 0 | E28: 0
C29: बाणेर स.क्र. २८, २९० जी२ गार्डनचे आरक्षण व बाणेर स.क्र. ३५ जी३ गार्डनचे आरक्षण | D29: 0 | E29: 0
C30: कल्याणीनगर जंक्शन ते आळंदी रोड | D30: 0 | E30: 0
C31: बाणेर स.क्र. १०५, १०६, ११०, १११ पीएमटी१ | D31: 0 | E31: 0
C32: बाणेर स.क्र. ३३ पी.३ | D32: 0 | E32: 0
C33: बाणेर स.क्र. १०० पी.४ | D33: 0 | E33: 0
C34: बाणेर स.क्र. १७४ पी.४ | D34: 0 | E34: 0
C35: बाणेर स.क्र. ७९ पी.६ | D35: 0 | E35: 0
C36: बाणेर स.क्र. १०५, १०६ पी.७ पार्किंगचे आरक्षण | D36: 0 | E36: 0
... C42: एअरपोर्ट रोड ते डेक्कन कॉलेज व्हाया हॉटमिक्स प्लँट | D42: 0 | E42: 0
D43: 0 | E43: 0
C44: जेएनएनयुआरएम / बीआरटी अंतर्गत रस्ते : | D44: 0 | E44: 0
C45: बाणेर स.क्र. १०७, १०८ व ११० मधून जाणारा १८ मी. रस्ता. | D45: 0 | E45: 0
C46: मौजे खराडी ता. हवेली, संगमवाडी ते खराडी २४ मी. नदीकाठचा डी.पी. रस्ता | D46: 0 | E46: 0
C47: मौजे वडगांव शेरी ता. हवेली, संगमवाडी ते खराडी २४ मी. नदीकाठचा डी.पी. रस्ता | D47: 0 | E47: 0
C48: सिंहगड रस्ता महानगरपालिका हद्द दरम्यान नियोजनाते विकसीत करणे (वडगांव बुद्रुक) | D48: 0 | E48: 0
C49: सिंहगड रस्ता महानगरपालिका हद्द दरम्यान नियोजनाते विकसीत करणे (वडगांव खुर्द) | D49: 0 | E49: 0
...

Sheet A_Fund_Expenditure
H1: योजनांतर्गत खर्चाबाबतचे अंदाजपत्रक
A2: मान्यतेचा ठराव क्र. दिनांक (कोड) | B2: प्रभाग क्रमांक | C2: BPL | D2: कामाचे नाव अगर वर्णन | E2: दि. 31 मार्च 2021 अखेरपर्यंत केलेली तरतूद | H2: दि. 31 मार्च 2019 पर्यंतचा खर्चाचा नक्‍की आकडा | I2: 2019-20 मधील खर्चाचा नक्‍की आकडा | J2: 2020-21 मधील खर्चाची अंदाजी रक्‍कम | K2: 2021-22 साठी अधिक तरतूद | M2: 2021-22 साठी एकूण तरतूद | N2: शेरा
E3: कर्जातून | F3: महसूल निधीतून | G3: एकूण | K3: कर्जातून | L3: महसूल निधी व इतर निधी
D8: ४. झोपडपट्टी निर्मूलन व पुनर्वसन निधी | E8: 0 | F8: 0 | G8: 0 | H8: 0 | I8: 0 | J8: 0 | L8: 0 | M8: 0
A9: FE14A101# | B9: _ | C9: SG1- | D9: निरनिराळ्या झोपडपट्टींमध्ये विविध विकासाची कामे करणे | E9: 33377000 | F9: 1532737821 | G9: 1566114821 | H9: 1474114821 | I9: 30158533 | J9: 61841467 | L9: 155800000 | M9: 155800000
A10: FE14A104 | C10: B | D10: झो.नि.पु. अंतर्गत करावयाची कामे | E10: 0 | F10: 234359610 | G10: 234359610 | H10: 202859610 | I10: 6281375 | J10: 25218625 | L10: 15800000 | M10: 15800000
A11: FE14A105# | B11: _ | C11: SG2- | D11: शहरामध्ये शौच्छालये / मुताऱ्या बांधणे | E11: 0 | F11: 1769487157 | G11: 1769487157 | H11: 1307987157 | I11: 223856472 | J11: 237643528 | L11: 266600000 | M11: 266600000
A12: FE14A107 | C12: B | D12: दलित वस्ती सुधारणा अंतर्गत कामे करणे | E12: 0 | F12: 201505383 | G12: 201505383 | H12: 201505383 | I12: 23191253 | J12: -23191253 | L12: 0 | M12: 0
A13: FE14A129 | C13: PL | D13: सार्वजनिक ठिकाणी शौचालय बांधणे | E13: 0 | F13: 77291383 | G13: 77291383 | H13: 45791383 | I13: 9368615 | J13: 22131385 | L13: 15750000 | M13: 15750000
A14: FE14A130 | C14: PL | D14: सार्वजनिक ठिकाणी मुतार्‍या बांधणे | E14: 0 | F14: 56026158 | G14: 56026158 | H14: 24526158 | I14: 6090590 | J14: 25409410 | L14: 15750000 | M14: 15750000
A15: FE14A135 | D15: प्रभाग क्र.14ब, मधील बाबासाहेब आंबेडकर हॉस्टेल विकसित करणेकरिता अहवाल तयार करणे | E15: 0 | F15: 2000000 | G15: 2000000 | H15: 0 | I15: 0 | J15: 2000000 | L15: 0 | M15: 0
E16: 0 | F16: 0 | G16: 0 | H16: 0 | I16: 0 | J16: 0 | L16: 0 | M16: 0
D17: ४. झोपडपट्टी निर्मूलन व पुनर्वसन निधी एकूण बेरीज | E17: 33377000 | F17: 3873407512 | G17: 3906784512 | H17: 3256784512 | I17: 298946838 | J17: 351053162 | L17: 469700000 | M17: 469700000
E18: 0 | F18: 0 | G18: 0 | H18: 0 | I18: 0 | J18: 0 | L18: 0 | M18: 0
D19: क्षेत्रिय कार्यालयाने करावयाची कामे | E19: 0 | F19: 0 | G19: 0 | H19: 0 | I19: 0 | J19: 0 | L19: 0 | M19: 0
E20: 0 | F20: 0 | G20: 0 | H20: 0 | I20: 0 | J20: 0 | L20: 0 | M20: 0
A21: FE14A118# | B21: W5 | C21: B | D21: क्षेत्रिय कार्यालय : झो.नि.पु. विभागाने करावयाची कामे | E21: 0 | F21: 256689792 | G21: 256689792 | H21: 238453792 | I21: 2847704 | J21: 15388296 | L21: 8250000 | M21: 8250000
A22: FE14A121# | B22: C5 | C22: B | D22: क्षेत्रिय कार्यालय : नागरिकांच्या सहभाग योजनेतून झो.नि.पु. विभागाने करावयाची कामे | E22: 0 | F22: 142298136 | G22: 142298136 | H22: 138134136 | I22: 1773068 | J22: 2390932 | L22: 5500000 | M22: 5500000
E23: 0 | F23: 0 | G23: 0 | H23: 0 | I23: 0 | J23: 0 | L23: 0 | M23: 0
D24: क्षेत्रिय कार्यालयाने करावयाची कामे एकूण बेरीज | E24: 0 | F24: 398987928 | G24: 398987928 | H24: 376587928 | I24: 4620772 | J24: 17779228 | L24: 13750000 | M24: 13750000
E25: 0 | F25: 0 | G25: 0 | H25: 0 | I25: 0 | J25: 0 | L25: 0 | M25: 0
D26: ४. झोपडपट्टी निर्मूलन व पुनर्वसन निधीतून करावयाची कामे + क्षेत्रिय कार्यालयाने करावयाची कामे एकूण बेरीज | E26: 33377000 | F26: 4272395440 | G26: 4305772440 | H26: 3633372440 | I26: 303567610 | J26: 368832390 | L26: 483450000 | M26: 483450000
E27: 0 | F27: 0 | G27: 0 | H27: 0 | I27: 0 | J27: 0 | L27: 0 | M27: 0
D28: ४अ. मागासवर्गीय कल्याणकारी योजना निधी | E28: 0 | F28: 0 | G28: 0 | H28: 0 | I28: 0 | J28: 0 | L28: 0 | M28: 0
A29: FE14B101 | C29: B-FA | D29: समाज विकास विभाग अंतर्गत मागासवर्गीय योजना | E29: 0 | F29: 520654616 | G29: 520654616 | H29: 445654616 | I29: 29154934 | J29: 45845066 | L29: 35000000 | M29: 35000000
A30: FE14B112 | C30: B-FA | D30: लोकशाहीर अण्णाभाऊ साठे शैक्षणिक मदत योजना | E30: 0 | F30: 219867082 | G30: 219867082 | H30: 147867082 | I30: 22525000 | J30: 49475000 | L30: 45000000 | M30: 45000000
A31: FE14B113 | C31: B-FA | D31: मौ. अबुल कलाम आझाद शैक्षणिक मदत योजना | E31: 0 | F31: 454758546 | G31: 454758546 | H31: 332758546 | I31: 33800000 | J31: 88200000 | L31: 75000000 | M31: 75000000
A32: FE14B121 | C32: B-T | D32: मागासवर्गीय विद्यार्थ्यांना स्पर्धा परिक्षा मार्गदर्शन केंद्र चालविणे | E32: 0 | F32: 11843896 | G32: 11843896 | H32: 5843896 | I32: 0 | J32: 6000000 | L32: 3000000 | M32: 3000000
A33: FE14B122 | C33: B-T | D33: बालविकास केंद्र व वस्ती रिसोर्स सेंटर सुरू करणे | E33: 0 | F33: 14929939 | G33: 14929939 | H33: 10929939 | I33: 1868243 | J33: 2131757 | L33: 1500000 | M33: 1500000
A34: FE14B123 | C34: B | D34: मागासवर्गीय कल्याणकारी योजनेअंतर्गत विविध योजना राबविणेसाठी मानधन तत्वावरील सेवकांचा मानधन खर्च | E34: 0 | F34: 36002659 | G34: 36002659 | H34: 31002659 | I34: 0 | J34: 5000000 | L34: 5000000 | M34: 5000000
A35: FE14B127 | C35: B | D35: माता रमार्इ भिमराव आंबेडकर योजनेअंतर्गत गवनि घोषीत व शहरी गरीब योजनेतील पात्र ठरणाऱ्या विधवा, निराधार महिलांसाठी दरमहा रू.1,000/- अर्थसहाय्य करणे (मागासवर्गीय कल्याणकारी योजना) | E35: 0 | F35: 23002788 | G35: 23002788 | H35: 1002788 | I35: 2400000 | J35: 19600000 | L35: 17000000 | M35: 17000000
A36: FE14B128 | C36: B-FA | D36: डॉ. बाबासाहेब आंबेडकर विद्यार्थी वसतिगृह, घोले रोड येथील खाणावळीचा खर्च | E36: 0 | F36: 17136257 | G36: 17136257 | H36: 7136257 | I36: 2310794 | J36: 7689206 | L36: 5000000 | M36: 5000000
A37: FE14B129 | C37: B-I | D37: शहरात आदिवासी विद्यार्थ्यांसाठी वसतिगृहे उभारणे | E37: 0 | F37: 53885336 | G37: 53885336 | H37: 3885336 | I37: 13860473 | J37: 36139527 | L37: 30000000 | M37: 30000000
A38: FE14B130 | D38: बार्टी संस्थेच्या मदतीने विविध व्यावसायिक प्रशिक्षण देणे | E38: 0 | F38: 0 | G38: 0 | H38: 0 | I38: 0 | J38: 0 | L38: 0 | M38: 0
A39: FE14B131 | C39: B-T | D39: विविध व्यावसायिक प्रशिक्षण देणे | E39: 0 | F39: 2795454 | G39: 2795454 | H39: 795454 | I39: 1999989 | J39: 11 | L39: 0 | M39: 0
A40: FE14B132 | C40: B-S | D40: मागासवर्गीय कल्याणकारी योजनेचा अभ्यास, ऑडिट व सर्वेक्षण करणे | E40: 0 | F40: 0 | G40: 0 | H40: 0 | I40: 0 | J40: 0 | L40: 0 | M40: 0
A41: FE14B133 | C41: B | D41: लोकशाहिर अण्णा भाऊ साठे यांच्या जन्मशताब्दी वर्षानिमित्त विविध कार्यक्रमाचे आयोजन करणे | E41: 0 | F41: 10000000 | G41: 10000000 | H41: 0 | I41: 0 | J41: 10000000 | L41: 0 | M41: 0
E42: 0 | F42: 0 | G42: 0 | H42: 0 | I42: 0 | J42: 0 | L42: 0 | M42: 0
D43: ४अ. मागासवर्गीय कल्याणकारी योजना निधी एकूण बेरीज | E43: 0 | F43: 1364876573 | G43: 1364876573 | H43: 986876573 | I43: 107919433 | J43: 270080567 | L43: 216500000 | M43: 216500000
E44: 0 | F44: 0 | G44: 0 | H44: 0 | I44: 0 | J44: 0 | L44: 0 | M44: 0
...

Sheet A_DPDC_Machinery_Tree
A1: विवरण | C1: नक्की आकडा | F1: मान्य अंदाज 2020-21 | G1: नवीन अंदाज 2021-22
C2: 2017-18 | D2: 2018-19 | E2: 2019-20
B6: ५. पुणे जिल्हा नियोजन व विकास मंडळ निधीतून करावयाची कामे
B7: ५अ. मा. आमदारांनी सुचविल्याप्रमाणे करावयाची विकासाची कामे
A8: FE15A101 | B8: बोपोडी मतदार संघ क्र. २४६ | C8: 0 | D8: 0 | E8: 0 | F8: 5000000 | G8: 5000000
A9: FE15A102 | B9: शिवाजीनगर मतदार संघ क्र. २४७ | C9: 8245720 | D9: 7569383 | E9: 5663108 | F9: 5000000 | G9: 5000000
A10: FE15A103 | B10: पर्वती मतदार संघ क्र. २४८ | C10: 7741474 | D10: 4049517 | E10: 20538895 | F10: 5000000 | G10: 5000000
A11: FE15A104 | B11: कसबा पेठ मतदार संघ क्र. २४९ | C11: 19590563 | D11: 17250785 | E11: 7008244 | F11: 5000000 | G11: 5000000
A12: FE15A105 | B12: भवानी पेठ मतदार संघ क्र. २५० | C12: 2233120 | D12: 0 | E12: 0 | F12: 5000000 | G12: 5000000
A13: FE15A106 | B13: पुणे (कॅन्टोन्मेंट) मतदार संघ क्र. २५१ | C13: 6010802 | D13: 6022891 | E13: 928911 | F13: 5000000 | G13: 5000000
A14: FE15A107 | B14: विधान परिषद सदस्य | C14: 2598815 | D14: 1627378 | E14: 1348324 | F14: 2500000 | G14: 2500000
C15: 0 | D15: 0 | E15: 0 | F15: 0 | G15: 0
A16: FE15A108 | B16: ५ब. मा. खासदारांनी सुचविल्याप्रमाणे करावयाची विकासाची कामे | C16: 12299310 | D16: 48067028 | E16: 39082990 | F16: 20000000 | G16: 20000000
C17: 0 | D17: 0 | E17: 0 | F17: 0 | G17: 0
A18: FE15A110 | B18: महानगरपालिका क्षेत्रात मुलभूत सोईसुविधांसाठी विशेष अनुदान | C18: 43052096 | D18: 8971934 | E18: 20903967 | F18: 0 | G18: 0
A19: FE15A111 | B19: मुळशी मतदार संघ | C19: 0 | D19: 0 | E19: 0 | F19: 2500000 | G19: 2500000
A20: FE15A112 | B20: कोथरूड विधानसभा मतदार संघ | C20: 4660732 | D20: 2487968 | E20: 0 | F20: 5000000 | G20: 5000000
A21: FE15A113 | B21: हडपसर विधानसभा मतदार संघ | C21: 950400 | D21: 1486525 | E21: 338906 | F21: 5000000 | G21: 5000000
A22: FE15A114 | B22: वडगांवशेरी विधानसभा मतदार संघ | C22: 0 | D22: 0 | E22: 0 | F22: 5000000 | G22: 5000000
A23: FE15A115 | B23: खडकवासला विधानसभा मतदार संघ | C23: 2531383 | D23: 0 | E23: 0 | F23: 5000000 | G23: 5000000
A24: FE15A117 | B24: सर्वसाधारण जिल्हा वार्षिक योजना अंतर्गत नाविन्यपूर्ण योजनांचा निधी | C24: 2499811 | D24: 0 | E24: 0 | F24: 0 | G24: 0
B25: ५. पुणे जिल्हा नियोजन व विकास मंडळ निधीतून करावयाची कामे बेरीज | C25: 112414226 | D25: 97533409 | E25: 95813345 | F25: 75000000 | G25: 75000000
C26: 0 | D26: 0 | E26: 0 | F26: 0 | G26: 0
C27: 0 | D27: 0 | E27: 0 | F27: 0 | G27: 0
B28: ७. यंत्रसामुग्री घसारा निधीतून विकत घ्याववयाची नवीन सामुग्री | C28: 0 | D28: 0 | E28: 0 | F28: 0 | G28: 0
B29: अग्निशामक दलासाठी यंत्रसामुग्री :- | C29: 0 | D29: 0 | E29: 0 | F29: 0 | G29: 0
A30: FE17A103-1 | B30: वॉटर टँकर पंपासह (2 नग) | C30: 9299998 | D30: 11680000 | E30: 0 | F30: 0 | G30: 29400000
A31: FE17A103-2 | B31: फायर इंजिन गाडी (7 नग) | C31: 9300000 | D31: 29199998 | E31: 26292205 | F31: 56000000 | G31: 36820000
A32: FE17A103-4 | B32: हायड्रोलिक प्लॅटफॉर्म | C32: 12798069 | D32: 0 | E32: 0 | F32: 0 | G32: 0
A33: FE17A103-12 | B33: रेस्क्यू इक्वीपमेंट व लाईट मास्ट | C33: 7388960 | D33: 0 | E33: 1460426 | F33: 44000000 | G33: 0
A34: FE17A107-23 | B34: आरोग्य विभागाकडील सरासरी आयुर्मान संपलेल्या आर्टीक्युलेटेड क्रेन निरस्त करून नवीन वाहने खरेदी करणे | C34: 0 | D34: 0 | E34: 0 | F34: 5600000 | G34: 0
A35: FE17A113-6 | B35: विद्युत विभाग :- हायड्रॉलिक प्लॅटफॉर्म (2 नग) | C35: 0 | D35: 0 | E35: 0 | F35: 0 | G35: 2800000
A36: FE17A114-6 | B36: बॅकहो लोडर खरेदी करणे | C36: 0 | D36: 4000200 | E36: 9840186 | F36: 0 | G36: 0
A37: FE17A114-9 | B37: पथ विभागासाठी टिपर खरेदी करणे | C37: 0 | D37: 13749120 | E37: 0 | F37: 8000000 | G37: 0
A38: FE17A114-10 | B38: पथ विभागाकडील कोठ्यांसाठी रोलर्स, मिक्‍सर्स, पेव्हर अन्य यंत्रसामुग्री खरेदी करणे | C38: 18701411 | D38: 0 | E38: 0 | F38: 0 | G38: 0
A39: FE17A124 | B39: मोटार वाहन विभाग मशिनरी | C39: 124045 | D39: 81895 | E39: 631216 | F39: 1600000 | G39: 1330000
A40: FE17A146 | B40: मनपा पदाधिकारी व अधिकार्‍यांसाठी मोटारकार खरेदी करणे | C40: 9660473 | D40: 3145700 | E40: 6706341 | F40: 8000000 | G40: 6510000
A41: FE17A149-3 | B41: कंटेनर दुरुस्ती व रंगवणे | C41: 1844372 | D41: 1973896 | E41: 999989 | F41: 2000000 | G41: 1680000
... A56: FE17A277# | B56: यंत्रसामुग्री घसारा निधीतून विकत घ्याववयाची सामुग्री (यादी Y1) | C56: 40925716 | D56: 40881598 | E56: 135664718 | F56: 106000000 | G56: 165500000
C57: 0 | D57: 0 | E57: 0 | F57: 0 | G57: 0
...

Sheet C_Revenue_Income
A1: पाणीपुरवठा व जलोत्सारण प्रकल्पांतर्गत | G1: खास निधी 'क' चा जमेचा गोषवारा व तपशील
A2: विवरण | C2: नक्की आकडा | H2: 2020-21 वर्षाचा अंदाज | J2: 2021-22 वर्षाचा अंदाज | M2: 2020-21 वर्षाच्या मान्य अंदाजाशी तुलना केलेला 2021-22 वर्षाचा मा. स्थायी समितीने मान्यता दिलेला अंदाज
C3: 2017-18 | D3: 2018-19 | E3: 2019-20 | F3: 2019-20 शेवटची सहामाही | G3: 2020-21 पहिली सहामाही | H3: मान्य अंदाज | I3: दुरूस्त अंदाज | J3: मा. महापालिका आयुक्त यांनी सुचविलेला | K3: मा. स्थायी समितीने मान्यता दिलेला | L3: मा. महानगर- पालिकेने संमत केलेला
M5: अधिक | N5: कमी
A7: अधिनियमाप्रमाणे कमीत कमी रोख शिल्लक ठेवण्याची रक्कम जमेस धरून वर्षारंभीची शिल्लक | C7: 100000 | D7: 100000 | E7: 100000 | F7: 100000 | G7: 0 | H7: 100000 | I7: 100000 | J7: 100000 | K7: 100000 | L7: 0 | M7: 0 | N7: 0
C8: 0 | D8: 0 | E8: 0 | F8: 0 | G8: 0 | H8: 0 | I8: 0 | J8: 0 | K8: 0 | L8: 0 | M8: 0 | N8: 0
A9: १. पाणीपुरवठा (अति. न.अ.) | C9: 0 | D9: 0 | E9: 0 | F9: 0 | G9: 0 | H9: 0 | I9: 0 | J9: 0 | K9: 0 | L9: 0 | M9: 0 | N9: 0
A10: क. पाणीपट्टी साधारण पाणीपट्टी (कआकसंप्र) | B10: XI12A101 | C10: 1147803539 | D10: 1337732647 | E10: 1606183124 | F10: 280361192 | G10: 1328408721 | H10: 2610000000 | I10: 2610000000 | J10: 2900000000 | K10: 2900000000 | L10: 0 | M10: 290000000 | N10: 0
A11: ख. शासनाकडून (कआकसंप्र) | B11: XI12B101 | C11: 0 | D11: 0 | E11: 0 | F11: 0 | G11: 0 | H11: 100000 | I11: 100000 | J11: 100000 | K11: 100000 | L11: 0 | M11: 0 | N11: 0
A12: च. PMPML कडील मिळकतीवरील पाणीपट्टी (कआकसंप्र) | B12: XI12F101 | C12: 0 | D12: 0 | E12: 0 | F12: 0 | G12: 0 | H12: 100000 | I12: 100000 | J12: 100000 | K12: 100000 | L12: 0 | M12: 0 | N12: 0
A13: छ. जललाभ कर (Water Benefit Tax) (कआकसंप्र) | B13: XI12G101 | C13: 519828924 | D13: 558386876 | E13: 579046635 | F13: 145239422 | G13: 400453285 | H13: 1180000000 | I13: 1180000000 | J13: 1180000000 | K13: 1180000000 | L13: 0 | M13: 0 | N13: 0
A14: ग. पाणीपट्टी पाणीमापकानुसार (अति.न.अ.) | B14: XI12C101 | C14: 545850894 | D14: 884181735 | E14: 529584384 | F14: 289521361 | G14: 217956046 | H14: 1650000000 | I14: 1650000000 | J14: 1650000000 | K14: 1650000000 | L14: 0 | M14: 0 | N14: 0
A15: ग१. मीटर पाणीपट्टी थकबाकीपोटी जमा | B15: XI12C101A | C15: 0 | D15: 0 | E15: 0 | F15: 0 | G15: 0 | H15: 50000000 | I15: 50000000 | J15: 50000000 | K15: 1750000000 | L15: 0 | M15: 1700000000 | N15: 0
A16: ग२. गवनि खात्याअंतर्गत होणारी पाणीपट्टी जमा | B16: XI12C101B | C16: 8191908 | D16: 14631177 | E16: 9411692 | F16: 796322 | G16: 0 | H16: 25000000 | I16: 25000000 | J16: 25000000 | K16: 25000000 | L16: 0 | M16: 0 | N16: 0
A17: अनधिकृत कनेक्शन नियमित करण्यापोटी जमा | B17: XI12S101 | C17: 3067 | D17: 0 | E17: 3087 | F17: 0 | G17: 0 | H17: 5000000 | I17: 5000000 | J17: 5000000 | K17: 5000000 | L17: 0 | M17: 0 | N17: 0
A18: घ. पाणीमापक भाडे | B18: XI12D101 | C18: 13202 | D18: 2741759 | E18: 0 | F18: 0 | G18: 0 | H18: 2500000 | I18: 2500000 | J18: 2500000 | K18: 2500000 | L18: 0 | M18: 0 | N18: 0
A19: ड. नवीन नळ आकार नळदुरुस्ती व साफसफी (परतजमा) | B19: XI12E101 | C19: 15447884 | D19: 6506111 | E19: 4606709 | F19: 1588209 | G19: 1773867 | H19: 2500000 | I19: 2500000 | J19: 2500000 | K19: 2500000 | L19: 0 | M19: 0 | N19: 0
A20: ठ. कॉलनी रस्त्यावर पाईप टाकणे कामापोटी सुपरव्हिजन स्क्रुटीनी फी व अन्य जमा होणार | B20: XI12K101 | C20: 10956334 | D20: 17461303 | E20: 710997 | F20: 360180 | G20: 0 | H20: 32500000 | I20: 32500000 | J20: 30000000 | K20: 30000000 | L20: 0 | M20: 0 | N20: 2500000
A21: ढ. जलकेंद्राच्या आवारांतील निवास स्थानापोटी जमा होणारे भाडे | B21: XI12L101 | C21: 1412457 | D21: 0 | E21: 0 | F21: 0 | G21: 0 | H21: 2000000 | I21: 2000000 | J21: 1500000 | K21: 1500000 | L21: 0 | M21: 0 | N21: 500000
... A28: ण. अंदाजपत्रक 'अ' कडून वर्ग | B28: XI12M101 | C28: -696342303 | D28: 1955095785 | E28: -574449956 | F28: -574449956 | G28: 0 | H28: 1243100000 | I28: 1243100000 | J28: 781550000 | K28: -1025900000 | L28: 0 | M28: 0 | N28: 2269000000
C29: 0 | D29: 0 | E29: 0 | F29: 0 | G29: 0 | H29: 0 | I29: 0 | J29: 0 | K29: 0 | L29: 0 | M29: 0 | N29: 0
A30: १. बेरीज | C30: 1619170660 | D30: 4860707869 | E30: 2227088474 | F30: 184320717 | G30: 1963807173 | H30: 6975000000 | I30: 6975000000 | J30: 6800450000 | K30: 6693000000 | L30: 0 | M30: 1990000000 | N30: 2272000000
C31: 0 | D31: 0 | E31: 0 | F31: 0 | G31: 0 | H31: 0 | I31: 0 | J31: 0 | K31: 0 | L31: 0 | M31: 0 | N31: 0
A32: १अ. पुणे कॅन्टोन्मेंट पाणीपुरवठा जमा (अति.न.अ.) | C32: 0 | D32: 0 | E32: 0 | F32: 0 | G32: 0 | H32: 0 | I32: 0 | J32: 0 | K32: 0 | L32: 0 | M32: 0 | N32: 0
A33: (१) पाणीमापकानुसार पाणीपट्टी | B33: XI12Q101 | C33: 74930244 | D33: 164167267 | E33: 280745047 | F33: 167223310 | G33: 31168960 | H33: 210000000 | I33: 210000000 | J33: 210000000 | K33: 210000000 | L33: 0 | M33: 0 | N33: 0
A34: (२) H.E. Factory कडून येणारी जमा | B34: XI12Q102 | C34: 156399237 | D34: 50889083 | E34: 75708335 | F34: 59943068 | G34: 46045247 | H34: 85000000 | I34: 85000000 | J34: 85000000 | K34: 85000000 | L34: 0 | M34: 0 | N34: 0
C35: 0 | D35: 0 | E35: 0 | F35: 0 | G35: 0 | H35: 0 | I35: 0 | J35: 0 | K35: 0 | L35: 0 | M35: 0 | N35: 0
A36: १अ. बेरीज | C36: 231329481 | D36: 215056350 | E36: 356453382 | F36: 227166378 | G36: 77214207 | H36: 295000000 | I36: 295000000 | J36: 295000000 | K36: 295000000 | L36: 0 | M36: 0 | N36: 0
C37: 0 | D37: 0 | E37: 0 | F37: 0 | G37: 0 | H37: 0 | I37: 0 | J37: 0 | K37: 0 | L37: 0 | M37: 0 | N37: 0
A38: पुणे शहरात तंत्रशुध्द पध्दतीने पाणीपुरवठा (24x7 समान पाणीपुरवठा योजना) योजनेंतर्गत टाक्या बांधणेसाठी अनुदान (AMRUT) | B38: ZI12A111A | C38: 399000000 | D38: 308700000 | E38: 236100000 | F38: 236100000 | G38: 0 | H38: 310000000 | I38: 310000000 | J38: 235900000 | K38: 235900000 | L38: 0 | M38: 0 | N38: 74100000
A39: पुणे शहरात तंत्रशुध्द पध्दतीने पाणीपुरवठा करण्याची योजना (24x7 समान पाणीपुरवठा योजना) कर्जरोखे विक्री | B39: ZI12A112 | C39: 2000000000 | D39: 0 | E39: 0 | F39: 0 | G39: 0 | H39: 2000000000 | I39: 2000000000 | J39: 2000000000 | K39: 2000000000 | L39: 0 | M39: 0 | N39: 0
C40: 0 | D40: 0 | E40: 0 | F40: 0 | G40: 0 | H40: 0 | I40: 0 | J40: 0 | K40: 0 | L40: 0 | M40: 0 | N40: 0
A41: राष्ट्रीय नदीसुधारणा प्रकल्पातंर्गत (JICA) केंद्र सरकारकडून अनुदान | B41: ZI12A102 | C41: 0 | D41: 317500000 | E41: 0 | F41: 0 | G41: 0 | H41: 250000000 | I41: 250000000 | J41: 1258000000 | K41: 1258000000 | L41: 0 | M41: 1008000000 | N41: 0
C42: 0 | D42: 0 | E42: 0 | F42: 0 | G42: 0 | H42: 0 | I42: 0 | J42: 0 | K42: 0 | L42: 0 | M42: 0 | N42: 0
A43: १. एकूण बेरीज | C43: 4249500141 | D43: 5701964219 | E43: 2819641856 | F43: 647587095 | G43: 2041021380 | H43: 9830000000 | I43: 9830000000 | J43: 10589350000 | K43: 10481900000 | L43: 0 | M43: 2998000000 | N43: 2346100000
C44: 0 | D44: 0 | E44: 0 | F44: 0 | G44: 0 | H44: 0 | I44: 0 | J44: 0 | K44: 0 | L44: 0 | M44: 0 | N44: 0
A45: २. गटारे व नाले सुधारणा (अति.न.अ.) | C45: 0 | D45: 0 | E45: 0 | F45: 0 | G45: 0 | H45: 0 | I45: 0 | J45: 0 | K45: 0 | L45: 0 | M45: 0 | N45: 0
A46: क. सफाईपट्टी (कआकसंप्र) | B46: XI23A101 | C46: 1941205852 | D46: 2085529792 | E46: 2141634540 | F46: 543520498 | G46: 1457481380 | H46: 3400000000 | I46: 3400000000 | J46: 4350000000 | K46: 4350000000 | L46: 0 | M46: 950000000 | N46: 0
A47: घ. सुअरेज बेनिफीट टॅक्स (कआकसंप्र) | B47: XI23D101 | C47: 896401311 | D47: 961744905 | E47: 999407213 | F47: 254328108 | G47: 689728636 | H47: 2280000000 | I47: 2280000000 | J47: 2260000000 | K47: 2260000000 | L47: 0 | M47: 0 | N47: 20000000
A48: ग. ड्रेनेज / सलेज कनेक्शन व सेवावाढ आकार नियोजित बांधकाम क्षेत्रफळावर रु. ११ चौ. मि. | B48: XI23C101 | C48: 7945543 | D48: 9453661 | E48: 5410009 | F48: 1669980 | G48: 818585 | H48: 0 | I48: 0 | J48: 0 | K48: 0 | L48: 0 | M48: 0 | N48: 0
...

Sheet C_Revenue_Expenditure
A1: योजनेतर खर्च तपशील
A2: विवरण | D2: नक्‍की आकडा | G2: मान्य अंदाज 2020-21 | H2: नवीन अंदाज
D3: 2017-18 | E3: 2018-19 | F3: 2019-20 | H3: 2021-22
A5: १. पाणीपुरवठा | D5: 0 | E5: 0 | F5: 0 | G5: 0 | H5: 0
A6: क. पाणीपुरवठा | D6: 0 | E6: 0 | F6: 0 | G6: 0 | H6: 0
A7: १. मध्यवर्ती कार्यालय, कायम सेवकवर्ग वेतन | B7: XE12A101A | D7: 23580337 | E7: 21639240 | F7: 22930820 | G7: 23300000 | H7: 27500000
A8: २अ. कायम सेवकवर्ग वेतन | B8: XE12A101B | D8: 144923511 | E8: 133028605 | F8: 143995350 | G8: 140000000 | H8: 160000000
A9: २ब. कायम सेवकवर्ग वेतन (वि.का.) | B9: XE12A###A | D9: 9860217 | E9: 8092170 | F9: 4911867 | G9: 15000000 | H9: 7000000
A10: ३. संकीर्ण | B10: XE12A103 | D10: 650931 | E10: 446243 | F10: 241045 | G10: 900000 | H10: 600000
A11: ४. पाण्याची किंमत (पर्वती पंपिंग स्टेशन) | B11: XE12A104 | D11: 319936464 | E11: 793046040 | F11: 714875404 | G11: 729000000 | H11: 790000000
A12: ५. पाणी शुद्ध करणे व तद्‌नुषंगिक कामे करणे | B12: XE12A105 | D12: 58867962 | E12: 50205650 | F12: 67013632 | G12: 64800000 | H12: 67500000
A13: ६. प्रयोगशाळा देखभाल खर्च | B13: XE12A106 | D13: 227793 | E13: 0 | F13: 881357 | G13: 1080000 | H13: 1500000
A14: ७-अ. पंपिंग वीज खर्च | B14: XE12A107 | D14: 601043722 | E14: 693640000 | F14: 778342594 | G14: 792000000 | H14: 801200000
A15: ९. कोठी इतर साहित्य खर्च | B15: XE12A109 | D15: 1189931 | E15: 340813 | F15: 697066 | G15: 2250000 | H15: 1500000
A16: १२. पर्वती जलकेंद्रातील यंत्रसामुग्रीवरील घसारा (मु.ले.) | B16: XE12A112 | D16: 190000 | E16: 215000 | F16: 0 | G16: 0 | H16: 0
A17: १४. जलप्रदूषण प्रतिबंधक खर्च | B17: XE12A115 | D17: 2007642 | E17: 0 | F17: 0 | G17: 2700000 | H17: 2500000
A18: १८. जलकेंद्र पाण्याच्या टाक्या येथे प्रकाश व्यवस्था व दूरध्वनी व्यवस्था | B18: XE12A120 | D18: 0 | E18: 0 | F18: 0 | G18: 900000 | H18: 500000
... A38: पर्वती जलकेंद्र प्रयोगशाळा येथे पाणी तपासणीसाठी लागणारी विविध उपकरणे व तद्‌नुषंगिक साहित्य खरेदी करणे | B38: XE12A146 | D38: 359999 | E38: 0 | F38: 328798 | G38: 0 | H38: 0
A39: क. बेरीज | D39: 1278265818 | E39: 1799104371 | F39: 1835097980 | G39: 1981945000 | H39: 1994500000
D40: 0 | E40: 0 | F40: 0 | G40: 0 | H40: 0
A41: ख१. नळ खाते (स्वारगेट विभाग) | D41: 0 | E41: 0 | F41: 0 | G41: 0 | H41: 0
A42: १. कायम सेवक वर्ग वेतन | B42: XE12B101A | D42: 215760319 | E42: 221769160 | F42: 228669863 | G42: 244000000 | H42: 270000000
A43: २. संकीर्ण | B43: XE12B102 | D43: 652480 | E43: 463550 | F43: 323698 | G43: 648000 | H43: 300000
A44: ४. शहरांतील / नव्याने समाविष्ट गावांतील सर्व व्हॉल्व्हज्‌ चालू व बंद करणे | B44: XE12B107 | D44: 36455792 | E44: 39585979 | F44: 61215355 | G44: 47250000 | H44: 60000000
A45: ८. टँकरने पाणीपुरवठा करणे | B45: XE12B111 | D45: 9305117 | E45: 14825987 | F45: 26968695 | G45: 19800000 | H45: 22000000
A46: ९. कोठी व इतर साहित्य खरेदी | B46: XE12B112 | D46: 20282433 | E46: 17886533 | F46: 19658619 | G46: 27000000 | H46: 20000000
A47: १०. देखभाल दुरुस्ती : नळदुरुस्ती व स्वच्छता तातडीच्या दुरुस्त्या चेंबर करणे, आर.सी.सी, कव्हर बसविणे व तदनुषंगिक कामे करणे | B47: XE12B113 | D47: 45376228 | E47: 47904841 | F47: 45727778 | G47: 50400000 | H47: 52000000
A48: ११. टाक्‍यांची दुरुस्ती | B48: XE12B114 | D48: 719282 | E48: 0 | F48: 0 | G48: 926100 | H48: 0
A49: पाणीपुरवठा विभागाकडील देखभाल दुरूस्तीची कामे (यादी X1) | B49: XE12B115# | D49: 9880350 | E49: 2634964 | F49: 0 | G49: 30700000 | H49: 36000000
D50: 0 | E50: 0 | F50: 0 | G50: 0 | H50: 0
A51: ख१. बेरीज | D51: 338432001 | E51: 345071014 | F51: 382564008 | G51: 420724100 | H51: 460300000
D52: 0 | E52: 0 | F52: 0 | G52: 0 | H52: 0
A53: ख२. नळ खाते (विभागीय कार्यालय) | D53: 0 | E53: 0 | F53: 0 | G53: 0 | H53: 0
A54: १. कायम सेवकवर्ग वेतन | B54: XE12B###A | D54: 31495599 | E54: 23964490 | F54: 22633204 | G54: 40000000 | H54: 27000000
A55: क्षेत्रीय कार्यालयाने करावयाची योजनेतर कामे | B55: XE12B301/W6-# | D55: 0 | E55: 943661 | F55: 2313036 | G55: 0 | H55: 1000000
A56: क्षेत्रीय कार्यालयाने नागरिकांच्या सहभागातून करावयाची योजनेतर कामे | B56: XE12B302/C6-# | D56: 2161144 | E56: 2817441 | F56: 4296733 | G56: 10300000 | H56: 4300000
D57: 0 | E57: 0 | F57: 0 | G57: 0 | H57: 0
A58: ख२. बेरीज | D58: 33656743 | E58: 27725592 | F58: 29242973 | G58: 50300000 | H58: 32300000
D59: 0 | E59: 0 | F59: 0 | G59: 0 | H59: 0
A60: ख. एकूण बेरीज | D60: 372088744 | E60: 372796606 | F60: 411806981 | G60: 471024100 | H60: 492600000
...

Sheet WO_Work21_MC
A1: उप आयुक्त विभाग क्र. : | B1: 1 | C1: 1 | D1: 1 | E1: 2 | F1: 2 | G1: 2 | H1: 3 | I1: 3 | J1: 3 | K1: 4 | L1: 4 | M1: 4 | N1: 5 | O1: 5 | P1: 5
A2: विवरण | B2: नगररोड - वडगावशेरी | C2: येरवडा - कळस - धानोरी | D2: ढोलेपाटील | E2: औंध - बाणेर | F2: शिवाजीनगर - घोले रोड | G2: कोथरूड - बावधन | H2: धनकवडी - सहकारनगर | I2: सिंहगड रोड | J2: वारजे - कर्वेनगर | K2: हडपसर - मुंढवा | L2: वानवडी - रामटेकडी | M2: कोंढवा - येवलेवाडी | N2: कसबा - विश्रामबागवाडा | O2: भवानी पेठ | P2: बिबवेवाडी | Q2: एकूण
A4: अंदाजपत्रकातील तरतुदींचा विभागवार वाटप तक्ता - अंदाजपत्रक 'अ'
A6: १. मुख्य देखरेख वसुली
A7: र. विभागीय कार्यालये | B7: RE11W111A | C7: RE11W114A | D7: RE11W110A | E7: RE11W112A | F7: RE11W103A | G7: RE11W104A | H7: RE11W115A | I7: RE11W105A | J7: RE11W113A | K7: RE11W109A | L7: RE11W116A | M7: RE11W106A | N7: RE11W102A | O7: RE11W108A | P7: RE11W107A
A8: ३. क्षेत्रीय कार्यालये कायम सेवकवर्ग वेतन | B8: 64247000 | C8: 22276000 | D8: 30743000 | E8: 42872000 | F8: 28581000 | G8: 28581000 | H8: 35546000 | I8: 49957000 | J8: 46354000 | K8: 35546000 | L8: 35546000 | M8: 35546000 | N8: 42872000 | O8: 42872000 | P8: 28461000 | Q8: 570000000
B9: RE11W111B | C9: RE11W114B | D9: RE11W110B | E9: RE11W112B | F9: RE11W103B | G9: RE11W104B | H9: RE11W115B | I9: RE11W105B | J9: RE11W113B | K9: RE11W109B | L9: RE11W116B | M9: RE11W106B | N9: RE11W102B | O9: RE11W108B | P9: RE11W107B
A10: ४. क्षेत्रीय कार्यालये संकीर्ण | B10: 432000 | C10: 432000 | D10: 432000 | E10: 432000 | F10: 432000 | G10: 432000 | H10: 432000 | I10: 432000 | J10: 432000 | K10: 432000 | L10: 432000 | M10: 432000 | N10: 432000 | O10: 432000 | P10: 432000 | Q10: 6480000
B11: RE11W111E | C11: RE11W114E | D11: RE11W110E | E11: RE11W112E | F11: RE11W103E | G11: RE11W104E | H11: RE11W115E | I11: RE11W105E | J11: RE11W113E | K11: RE11W109E | L11: RE11W116E | M11: RE11W106E | N11: RE11W102E | O11: RE11W108E | P11: RE11W107E
A12: ५. प्रभाग समिती चहापान खर्च | B12: 45000 | C12: 45000 | D12: 45000 | E12: 45000 | F12: 45000 | G12: 45000 | H12: 45000 | I12: 45000 | J12: 45000 | K12: 45000 | L12: 45000 | M12: 45000 | N12: 45000 | O12: 45000 | P12: 45000 | Q12: 675000
B13: RE11W111G | C13: RE11W114G | D13: RE11W110G | E13: RE11W112G | F13: RE11W103G | G13: RE11W104G | H13: RE11W115G | I13: RE11W105G | J13: RE11W113G | K13: RE11W109G | L13: RE11W116G | M13: RE11W106G | N13: RE11W102G | O13: RE11W108G | P13: RE11W107G
A14: समाविष्ट गावांमध्ये देखभाल दुरूस्तीची कामे करणे (पथ, विद्युत, भवन, पाणीपुरवठा, मलनिःसारण इ.) | B14: 3600000 | H14: 7200000 | I14: 3600000 | J14: 7200000 | K14: 14400000 | M14: 3600000 | Q14: 39600000
A16: ४. झोपडपट्टी निर्मूलन व पुनर्वसन
A17: ख२. सबइंजिनियर (हेल्थ) (वि.का.) | B17: RE14B211A | C17: RE14B214A | D17: RE14B210A | E17: RE14B212A | F17: RE14B203A | G17: RE14B204A | H17: RE14B215A | I17: RE14B205A | J17: RE14B213A | K17: RE14B209A | L17: RE14B216A | M17: RE14B206A | N17: RE14B202A | O17: RE14B208A | P17: RE14B207A
A18: सार्वजनिक/सुलभ शौचालय दुरूस्ती, मुतार्‍या दुरूस्ती कामे करणे | B18: 1800000 | C18: 1800000 | D18: 1800000 | E18: 1800000 | F18: 1800000 | G18: 1800000 | H18: 1800000 | I18: 1800000 | J18: 1800000 | K18: 1800000 | L18: 1800000 | M18: 1800000 | N18: 1800000 | O18: 1800000 | P18: 1800000 | Q18: 27000000
B19: RE14B211B | C19: RE14B214B | D19: RE14B210B | E19: RE14B212B | F19: RE14B203B | G19: RE14B204B | H19: RE14B215B | I19: RE14B205B | J19: RE14B213B | K19: RE14B209B | L19: RE14B216B | M19: RE14B206B | N19: RE14B202B | O19: RE14B208B | P19: RE14B207B
A20: काँक्रीटीकरणाची व फरशीची कामे / पेव्हींगची कामे व देखभाल दुरूस्ती करणे | B20: 972000 | C20: 954000 | D20: 954000 | E20: 936000 | F20: 936000 | G20: 1008000 | H20: 936000 | I20: 1008000 | J20: 936000 | K20: 936000 | L20: 1008000 | M20: 936000 | N20: 972000 | O20: 954000 | P20: 954000 | Q20: 14400000
B21: RE14B211C | C21: RE14B214C | D21: RE14B210C | E21: RE14B212C | F21: RE14B203C | G21: RE14B204C | H21: RE14B215C | I21: RE14B205C | J21: RE14B213C | K21: RE14B209C | L21: RE14B216C | M21: RE14B206C | N21: RE14B202C | O21: RE14B208C | P21: RE14B207C
A22: जुन्या ड्रेनेज लाईन बदलणे व दुरूस्ती करणे | B22: 972000 | C22: 954000 | D22: 954000 | E22: 936000 | F22: 936000 | G22: 1008000 | H22: 936000 | I22: 1008000 | J22: 936000 | K22: 936000 | L22: 1008000 | M22: 936000 | N22: 972000 | O22: 954000 | P22: 954000 | Q22: 14400000
B23: RE14B211D | C23: RE14B214D | D23: RE14B210D | E23: RE14B212D | F23: RE14B203D | G23: RE14B204D | H23: RE14B215D | I23: RE14B205D | J23: RE14B213D | K23: RE14B209D | L23: RE14B216D | M23: RE14B206D | N23: RE14B202D | O23: RE14B208D | P23: RE14B207D
A24: ड्रेनेज लाईन व चेंबर साफसफाई करणे | B24: 1044000 | C24: 1044000 | D24: 1067040 | E24: 1008000 | F24: 1008000 | G24: 1139040 | H24: 1008000 | I24: 1139040 | J24: 1008000 | K24: 1296000 | L24: 1008000 | M24: 851040 | N24: 1044000 | O24: 1044000 | P24: 1067040 | Q24: 15775200
B25: RE14B211E | C25: RE14B214E | D25: RE14B210E | E25: RE14B212E | F25: RE14B203E | G25: RE14B204E | H25: RE14B215E | I25: RE14B205E | J25: RE14B213E | K25: RE14B209E | L25: RE14B216E | M25: RE14B206E | N25: RE14B202E | O25: RE14B208E | P25: RE14B207E
A26: देखभाल दुरुस्तीसाठी साहित्य खरेदी - पुरविणे व बसविणे | B26: 288000 | C26: 288000 | D26: 288000 | E26: 288000 | F26: 288000 | G26: 288000 | H26: 288000 | I26: 288000 | J26: 288000 | K26: 288000 | L26: 288000 | M26: 288000 | N26: 288000 | O26: 288000 | P26: 288000 | Q26: 4320000
A28: ७. आरोग्य
A29: लोकारोग्य (विभागीय कार्यालय) | B29: RE17F211A | C29: RE17F214A | D29: RE17F210A | E29: RE17F212A | F29: RE17F203A | G29: RE17F204A | H29: RE17F215A | I29: RE17F205A | J29: RE17F213A | K29: RE17F209A | L29: RE17F216A | M29: RE17F206A | N29: RE17F202A | O29: RE17F208A | P29: RE17F207A
A30: १. कायम सेवकवर्ग वेतन | B30: 12740000 | C30: 6712000 | D30: 9726000 | E30: 4521000 | F30: 8219000 | G30: 3014000 | H30: 4795000 | I30: 9041000 | J30: 3014000 | K30: 7534000 | L30: 10548000 | M30: 6712000 | N30: 22603000 | O30: 5205000 | P30: 5616000 | Q30: 120000000
A32: ९. पथांची झाडलोट, कचरावाहतूक इ.
A33: क२. पथांची झाडलोट (विभा. कार्या.) | B33: RE19A211A | C33: RE19A214A | D33: RE19A210A | E33: RE19A212A | F33: RE19A203A | G33: RE19A204A | H33: RE19A215A | I33: RE19A205A | J33: RE19A213A | K33: RE19A209A | L33: RE19A216A | M33: RE19A206A | N33: RE19A202A | O33: RE19A208A | P33: RE19A207A
A34: १. कायम सेवकवर्ग वेतन | B34: 80000000 | C34: 80000000 | D34: 80000000 | E34: 80000000 | F34: 80000000 | G34: 80000000 | H34: 80000000 | I34: 80000000 | J34: 80000000 | K34: 80000000 | L34: 80000000 | M34: 80000000 | N34: 80000000 | O34: 80000000 | P34: 80000000 | Q34: 1200000000
B35: RE19A211C | C35: RE19A214C | D35: RE19A210C | E35: RE19A212C | F35: RE19A203C | G35: RE19A204C | H35: RE19A215C | I35: RE19A205C | J35: RE19A213C | K35: RE19A209C | L35: RE19A216C | M35: RE19A206C | N35: RE19A202C | O35: RE19A208C | P35: RE19A207C
A36: घंटागाड्या,सायकल रिक्षा पुरविणे व दुरूस्ती,बकेट खरेदी करणे, आरोग्यकोठ्या दुरूस्त करणे | B36: 504000 | C36: 504000 | D36: 432000 | E36: 468000 | F36: 468000 | G36: 504000 | H36: 468000 | I36: 504000 | J36: 468000 | K36: 504000 | L36: 468000 | M36: 468000 | N36: 504000 | O36: 504000 | P36: 432000 | Q36: 7200000
B37: RE19A211D | C37: RE19A214D | D37: RE19A210D | E37: RE19A212D | F37: RE19A203D | G37: RE19A204D | H37: RE19A215D | I37: RE19A205D | J37: RE19A213D | K37: RE19A209D | L37: RE19A216D | M37: RE19A206D | N37: RE19A202D | O37: RE19A208D | P37: RE19A207D
A38: आऊटसोर्सिंगने कचरा संदर्भात कामे करून घेणे | B38: 102500000 | C38: 80700000 | D38: 48800000 | E38: 94900000 | F38: 32200000 | G38: 56400000 | H38: 75000000 | I38: 68000000 | J38: 76200000 | K38: 102500000 | L38: 70500000 | M38: 59200000 | N38: 14200000 | O38: 0 | P38: 51200000 | Q38: 932300000
B39: RE19A211F | C39: RE19A214F | D39: RE19A210F | E39: RE19A212F | F39: RE19A203F | G39: RE19A204F | H39: RE19A215F | I39: RE19A205F | J39: RE19A213F | K39: RE19A209F | L39: RE19A216F | M39: RE19A206F | N39: RE19A202F | O39: RE19A208F | P39: RE19A207F
A40: स्वच्छ सर्वेक्षण संबंधित कामे करणे | B40: 1080000 | C40: 1080000 | D40: 1080000 | E40: 1080000 | F40: 1080000 | G40: 1080000 | H40: 1080000 | I40: 1080000 | J40: 1080000 | K40: 1080000 | L40: 1080000 | M40: 1080000 | N40: 1080000 | O40: 1080000 | P40: 1080000 | Q40: 16200000
B41: RE19A211G | C41: RE19A214G | D41: RE19A210G | E41: RE19A212G | F41: RE19A203G | G41: RE19A204G | H41: RE19A215G | I41: RE19A205G | J41: RE19A213G | K41: RE19A209G | L41: RE19A216G | M41: RE19A206G | N41: RE19A202G | O41: RE19A208G | P41: RE19A207G
A42: Third Party Quality Aasurance करिता सल्लागार फी देणे | B42: 665000 | C42: 665000 | D42: 670000 | E42: 670000 | F42: 665000 | G42: 665000 | H42: 665000 | I42: 670000 | J42: 665000 | K42: 670000 | L42: 665000 | M42: 665000 | N42: 670000 | O42: 665000 | P42: 665000 | Q42: 10000000
A44: ख२. कचरा वाहतूक (विभा. कार्या.) | B44: RE19B211A | C44: RE19B214A | D44: RE19B210A | E44: RE19B212A | F44: RE19B203A | G44: RE19B204A | H44: RE19B215A | I44: RE19B205A | J44: RE19B213A | K44: RE19B209A | L44: RE19B216A | M44: RE19B206A | N44: RE19B202A | O44: RE19B208A | P44: RE19B207A
A45: १. कायम सेवकवर्ग वेतन | B45: 58036000 | C45: 57928000 | D45: 58036000 | E45: 58036000 | F45: 57928000 | G45: 58036000 | H45: 58036000 | I45: 58036000 | J45: 57928000 | K45: 58036000 | L45: 57928000 | M45: 58036000 | N45: 58036000 | O45: 58036000 | P45: 57928000 | Q45: 870000000
A46: ग२. मैला व मैलापाणी वाहतूक (आ.प्र.) | B46: RE19C211A | C46: RE19C214A | D46: RE19C210A | E46: RE19C212A | F46: RE19C203A | G46: RE19C204A | H46: RE19C215A | I46: RE19C205A | J46: RE19C213A | K46: RE19C209A | L46: RE19C216A | M46: RE19C206A | N46: RE19C202A | O46: RE19C208A | P46: RE19C207A
...

Sheet list21
A2: यादी क्र. R1
A3: थोर व्यक्तींच्या जयंती / पुण्यतिथी साजरी करणे (यादी R1)
A4: RE11A274/R1-
A6: code | B6: ward | C6: कामाचे नाव | D6: प्रकल्पीय रक्कम | E6: तरतूद
A8: RE11A274/R1-1 | C8: महात्मा फुले जयंती | E8: 100000
A9: RE11A274/R1-2 | C9: डॉ. बाबासाहेब आंबेडकर जयंती | E9: 150000
A10: RE11A274/R1-3 | C10: लोकशाहीर अण्णाभाऊ साठे जयंती | E10: 200000
A11: RE11A274/R1-4 | C11: ईद-ए-मिलाद (पैगंबर जयंती) | E11: 150000
A12: RE11A274/R1-5 | C12: शहरातील शिवजयंती साजरी करणे, रोषणाई करणे | E12: 200000
A13: RE11A274/R1-6 | C13: महात्मा फुले यांची पुण्यतिथी साजरी करणे (दि. 28 नोव्हेंबर) | E13: 500000
A14: RE11A274/R1-7 | C14: मौलाना अब्दुल कलाम आझाद जयंती व पुण्यतिथी साजरी करणे | E14: 600000
A15: RE11A274/R1-8 | C15: लहुजी वस्ताद साळवे जयंती महोत्सव गंज पेठ व संगमवाडी येथे साजरा करणे | E15: 500000
A16: RE11A274/R1-9 | C16: नेताजी सुभाषचंद्र बोस यांची जयंती साजरी करणे | E16: 10000
A17: RE11A274/R1-10 | C17: येरवडा येथे लोकशाहिर अण्णाभाऊ साठे जयंती महोत्सव साजरा करणे | E17: 100000
A18: RE11A274/R1-11 | C18: श्री संत रोहिदास महाराज जयंती, पुण्यतिथी साजरी करणे | E18: 50000
A19: RE11A274/R1-13 | C19: मौलाना अबुल कलाम आझाद जयंती महोत्सव | E19: 500000
A20: RE11A274/R1-14 | C20: महावीर जयंती | E20: 100000
C22: यादी क्र. R1 एकूण | D22: 0 | E22: 3160000
A25: यादी क्र. R2
A26: शहरामध्ये विविध कार्यक्रम, उत्सव, महोत्सव, संमेलन/ सहप्रायोजक तत्वावर कार्यक्रम साजरे करणे (यादी R2)
A27: RE11A275/R2-
A29: code | B29: ward | C29: कामाचे नाव | D29: प्रकल्पीय रक्कम | E29: तरतूद
A31: RE11A275/R2-1 | C31: महानगरपालिका वर्धापन दिन / सुवर्ण महोत्सव साजरा करणे | E31: 700000
A32: RE11A275/R2-2 | C32: वर्षातील महत्त्वपूर्ण दिन | E32: 600000
A33: RE11A275/R2-3 | C33: शिवाजीमहाराज आग्र्‍याहून सुटून परत आले तो स्मृती दिन साजरा करणे | E33: 515000
A34: RE11A275/R2-4 | C34: शनिवारवाडा सांस्कृतिक महोत्सव | E34: 2000000
A35: RE11A275/R2-5 | C35: भारतरत्न डॉ. बाबासाहेब आंबेडकर सांस्कृतिक महोत्सव साजरा करणे/ भिम फेस्टिवल (शनिवारवाडा पटांगण) / फुले आंबेडकर फेस्टिवल (समताभूमी) | E35: 2000000
A36: RE11A275/R2-6 | C36: शिवमहोत्सव साजरा करणे (१४ ते २० फेब्रुवारी) | E36: 2000000
A37: RE11A275/R2-7 | C37: अण्णाभाऊ साठे महोत्सव | E37: 2000000
A38: RE11A275/R2-8 | C38: जागतिक आदिवासी दिन | E38: 500000
A39: RE11A275/R2-11 | C39: प्रभाग क्र.३९ क धनकवडी आंबेगाव पठार मध्ये सांस्कृतिक व क्रीडा महोत्सव आयोजन करणे. | E39: 2000000
C41: यादी क्र. R2 एकूण | D41: 0 | E41: 12315000
A44: यादी क्र. R3
A45: सत्कार, अभिनंदन, पुरस्कार, बक्षिसे यासारखे कार्यक्रम साजरे करणे (यादी R3)
A46: RE11A276/R3-
A48: code | B48: ward | C48: कामाचे नाव | D48: प्रकल्पीय रक्कम | E48: तरतूद
A50: RE11A276/R3-1 | C50: गणेशोत्सव प्रशस्तिपत्रके वितरण | E50: 1000000
A51: RE11A276/R3-2 | C51: श्री संत ज्ञानेश्वर व तुकाराम महाराज पालखी स्वागत व दिंडी प्रमुखांचा स्मृतीचिन्ह देऊन सत्कार | E51: 1000000
A52: RE11A276/R3-3 | C52: प्रतिवर्षी पुणे शहरातील इयत्ता १० वी, १२ वी परिक्षेत गुणवत्ता यादीत येणार्‍या विद्यार्थ्यांचे अभिनंदन | E52: 60000
A53: RE11A276/R3-4 | C53: बालगंधर्व पुरस्कार प्रदानकरिता | E53: 500000
...

Sheet JNNURM
A1: • | B1: • | C1: • | D1: • | E1: code | F1: AMRUT, JNNURM (वाढीव कालावधी) व Smart City आभियान | G1: सुधारित मंजूर तरतूद | H1: 2122 स्थायी | I1: H
H2: 0
H3: 0
A4: 6 | F4: शहरी गरिबांसाठी मुलभूत सुविधा (BSUP) : | H4: 0
B5: 8 | E5: FE38A108 | F5: इनसिटू रिहॅबिलीटेशन | G5: 1404200000 | H5: 10500000
H6: 0
F7: शहरी गरिबांसाठी मुलभूत सुविधा (BSUP) : एकूण | H7: 10500000
H8: 0
H9: 0
A10: 14 | E10: FE48A101 | F10: केंद्र शासन पुरस्कृत विविध योजनांसाठी (JNNURM, AMRUT व Smart City आभियान इत्यादी) प्रकल्पासंबधित केंद्रशासन व राज्यशासनाशी समन्वय साधणेसाठी व अन्य विशेष इतर कामांसाठी PIU Cell | G10: 5400000 | H10: 12600000
H11: 0
E12: FE49A104 | F12: JUUNRM वाढीव कालावधी मध्ये मंजूर झालेले तसेच AMRUT अभियानामध्ये समावेश झालेल्या भामा आसखेड पाणी पुरवठा प्रकल्पासाठी तरतूद | H12: 371000000
E13: FE49A105 | F13: JNNURM वाढीव कालावधी मध्ये मंजूर झालेले तसेच AMRUT अभियानामध्ये समावेश झालेल्या वडगाव बुद्रुक प्रकल्पासाठी तरतूद | H13: 14000000
H14: 0
A15: 17 | F15: अमृत अभियानांतर्गत नव्याने सुरु होणाऱ्या प्रकल्पांसाठी तरतूद | H15: 0
E16: FE50A103A | F16: अमृत अभियानांतर्गत पुणे हरित क्षेत्र विकास प्रकल्प २०१५-१६ | H16: 700000
E17: FE50A103B | F17: अमृत अभियानांतर्गत पुणे हरित क्षेत्र विकास प्रकल्प २०१६-१७ | H17: 5740000
E18: FE50A103D | F18: अमृत अभियानांतर्गत पुणे हरित क्षेत्र विकास प्रकल्प २०१७-१८ | H18: 9400000
E19: FE50A104 | F19: स्मार्ट सिटी अभियान अंतर्गत नव्याने सुरु होणाऱ्या प्रकल्पांसाठी तरतूद (केंद्रशासन व राज्यशासन अनुदानासहित) | H19: 500000000
H20: 0
A21: • | B21: • | C21: • | D21: • | E21: • | F21: AMRUT, JNNURM (वाढीव कालावधी) व Smart City आभियान एकूण | H21: 923940000
H22: 0
F23: ( टीप 1 :- जवाहरलाल नेहरू नागरी पुनर्निर्माण योजना निधीतून काम पूर्ण होण्यासाठी आवश्यक असलेल्या रकमेपर्यंत खर्च करण्यात येईल.) | H23: 0
F24: ( टीप 2 :- केंद्र शासनाकडून प्रकल्प मान्य होऊन पहिला हप्ता प्राप्त झाल्यानंतरच खर्च करण्यात येईल.) | H24: 0
A25: • | B25: • | C25: • | D25: • | E25: • | F25: ज.ने.रा.श.पु.अ., अमृत व स्मार्ट सिटी आभियान - फेज 2 एकूण | H25: 923940000

Sheet SPV
C1: code | F1: प्रकल्पीय रक्कम | G1: 2122 स्थायी | H1: H
E2: सार्वजनिक वाहतूक सुधारणा व विशेष प्रकल्प विभागामार्फत करावयाची कामे : | G2: 0
G3: 0
G4: 0
