Workbook
Name BdgtNo: #REF!
Name BdgtYear: #REF!
Name CurrentYear: #REF!
Name Description: "P_A_C_Ex"
Name Head: #REF!
Name Last2Yr: #REF!
Name Last3Yr: #REF!
Name Last4Yr: #REF!
Name Last5Yr: #REF!
Name List_Smry_0: A_List!#REF!
Name List_Smry_0: C_List!#REF!
Name List_Smry_1: A_List!#REF!
Name List_Smry_1: C_List!#REF!
Name List_Smry_2: A_List!#REF!
Name List_Smry_2: C_List!#REF!
Name NextYear: #REF!
Name P_A_A_Ex: #REF!
Name P_A_A01: #REF!
Name P_A_A02: #REF!
Name P_A_A03: A_Revenue_Income!$A$7:$N$540
Name P_A_A04: #REF!
Name P_A_A05: A_Revenue_Expenditure!$A$4:$H$1634
Name P_A_A08: #REF!
Name P_A_A09: #REF!
Name P_A_A10: #REF!,#REF!,#REF!
Name P_A_A11: #REF!
Name P_A_A12: A_Capital_Expenditure!$A$7:$N$215
Name P_A_A13: #REF!
Name P_A_A14: A_Land_Acquisition!$A$4:$E$386
Name P_A_A15: A_Fund_Expenditure!$A$6:$N$137
Name P_A_A16: A_DPDC_Machinery_Tree!$A$6:$G$115
Name P_A_AC_In1: #REF!
Name P_A_APP: #REF!
Name P_A_Bdgt: A_DPDC_Machinery_Tree!$A$6:$G$115
Name P_A_Bdgt: A_Fund_Expenditure!$A$6:$N$137
Name P_A_Bdgt: A_Land_Acquisition!$A$4:$E$386
Name P_A_Bdgt: A_Revenue_Income!$A$7:$N$540
Name P_A_Bdgt: C_Capital_Expenditure!$A$6:$N$63
Name P_A_Bdgt: C_Revenue_Expenditure!$A$4:$H$397
Name P_A_Bdgt: WO_Work22_MC!$A$4:$Q$145
Name P_A_C_Ex: #REF!
Name P_A_C01: #REF!
Name P_A_C02: C_Revenue_Income!$A$7:$N$62
Name P_A_C02A: #REF!
Name P_A_C03: C_Revenue_Expenditure!$A$4:$H$397
Name P_A_C05: #REF!
Name P_A_C07: C_Capital_Expenditure!$A$6:$N$63
Name P_A_Doller_MC: #REF!,#REF!,#REF!
Name P_A_Doller_SC: #REF!,#REF!,#REF!
Name P_A_dvdr: #REF!
Name P_A_Fnl_Rec: #REF!
Name P_A_Info: #REF!
Name P_A_Info1: #REF!
Name P_A_Info2: #REF!
Name P_A_jnnurm: JNNURM!$A$1:$D$26
Name P_A_ListA: A_List!$A$1:$F$433
Name P_A_ListA: C_List!#REF!
Name P_A_ListC: A_List!$A$434:$F$434
Name P_A_ListC: C_List!$A$1:$F$72
Name P_A_S_Wtr: #REF!

Sheet A_Revenue_Income
A1: जमेचा | G1: तपशील
A2: विवरण | C2: नक्की आकडा | H2: 2021-22 वर्षाचा अंदाज | J2: 2022-23 वर्षाचा अंदाज | M2: 2021-22 वर्षाच्या मान्य अंदाजाशी तुलना केलेला 2022-23 वर्षाचा मा. महा. आयुक्त यांनी सुचविलेला अंदाज
C3: 2018-19 | D3: 2019-20 | E3: 2020-21 | F3: 2020-21 शेवटची सहामाही | G3: 2021-22 पहिली सहामाही | H3: मान्य अंदाज | I3: दुरूस्त अंदाज | J3: मा. महापालिका आयुक्त यांनी सुचविलेला | K3: मा. स्थायी समितीने मान्यता दिलेला | L3: मा. महानगर- पालिकेने संमत केलेला
M5: अधिक | N5: कमी
A7: अधिनियमाप्रमाणे कमीत कमी रोख शिल्लक ठेवण्याची रक्कम जमेस धरून वर्षारंभीची शिल्लक | B7: 0 | C7: 100000 | D7: 100000 | E7: 100000 | F7: 100000 | G7: 0 | H7: 100000 | I7: 100000 | J7: 100000 | K7: 0 | L7: 0 | M7: 0 | N7: 0
C8: 0 | D8: 0 | E8: 0 | F8: 0 | G8: 0 | H8: 0 | I8: 0 | J8: 0 | K8: 0 | L8: 0 | M8: 0 | N8: 0
A9: १. सर्वसाधारण कर, अप्रत्यक्ष कर व इतर जमा | C9: 0 | D9: 0 | E9: 0 | F9: 0 | G9: 0 | H9: 0 | I9: 0 | J9: 0 | K9: 0 | L9: 0 | M9: 0 | N9: 0
A10: क. सर्वसाधारण पट्टी | C10: 0 | D10: 0 | E10: 0 | F10: 0 | G10: 0 | H10: 0 | I10: 0 | J10: 0 | K10: 0 | L10: 0 | M10: 0 | N10: 0
A11: १. नागरिकांकडून (कआकसंप्र) | B11: RI11A101 | C11: 3361147014 | D11: 3613696720 | E11: 5001213963 | F11: 2469739845 | G11: 3367138173 | H11: 11050000000 | I11: 11050000000 | J11: 8370000000 | K11: 0 | L11: 0 | M11: 0 | N11: 2680000000
A12: लोहगाव (उर्वरित) | B12: RI11AA101 | C12: 37675 | D12: 646073 | E12: 1565320 | F12: 1374270 | G12: 509585 | H12: 0 | I12: 0 | J12: 0 | K12: 0 | L12: 0 | M12: 0 | N12: 0
A13: मुंढवा (उर्वरित केशवनगर) | B13: RI11AB101 | C13: 8185 | D13: 1067975 | E13: 964210 | F13: 893215 | G13: 323820 | H13: 0 | I13: 0 | J13: 0 | K13: 0 | L13: 0 | M13: 0 | N13: 0
A14: हडपसर (संपूर्ण साडेसतरानळी) | B14: RI11AC101 | C14: 3735 | D14: 85825 | E14: 1300405 | F14: 1291605 | G14: 176780 | H14: 0 | I14: 0 | J14: 0 | K14: 0 | L14: 0 | M14: 0 | N14: 0
A15: शिवणे (संपूर्ण उत्तमनगर) | B15: RI11AD101 | C15: 13465 | D15: 387130 | E15: 226850 | F15: 141645 | G15: 578520 | H15: 0 | I15: 0 | J15: 0 | K15: 0 | L15: 0 | M15: 0 | N15: 0
A16: शिवणे | B16: RI11AE101 | C16: 9565 | D16: 2103535 | E16: 1492950 | F16: 1354400 | G16: 0 | H16: 0 | I16: 0 | J16: 0 | K16: 0 | L16: 0 | M16: 0 | N16: 0
A17: आंबेगाव खुर्द | B17: RI11AF101 | C17: 6810 | D17: 1974340 | E17: 1087355 | F17: 1001085 | G17: 599315 | H17: 0 | I17: 0 | J17: 0 | K17: 0 | L17: 0 | M17: 0 | N17: 0
A18: उंड्री | B18: RI11AG101 | C18: 3755 | D18: 1132345 | E18: 2069140 | F18: 1242295 | G18: 728795 | H18: 0 | I18: 0 | J18: 0 | K18: 0 | L18: 0 | M18: 0 | N18: 0
A19: धायरी | B19: RI11AH101 | C19: 32565 | D19: 24150 | E19: 895530 | F19: 770995 | G19: 253455 | H19: 0 | I19: 0 | J19: 0 | K19: 0 | L19: 0 | M19: 0 | N19: 0
A20: आंबेगाव बुद्रुक | B20: RI11AJ101 | C20: 19645 | D20: 2560515 | E20: 1698345 | F20: 1482600 | G20: 793320 | H20: 0 | I20: 0 | J20: 0 | K20: 0 | L20: 0 | M20: 0 | N20: 0
A21: फुरसुंगी | B21: RI11AK101 | C21: 110450 | D21: 2070710 | E21: 1818395 | F21: 1524885 | G21: 588400 | H21: 0 | I21: 0 | J21: 0 | K21: 0 | L21: 0 | M21: 0 | N21: 0
A22: उरुळी देवाची | B22: RI11AL101 | C22: 33235 | D22: 101150 | E22: 127750 | F22: 86980 | G22: 164735 | H22: 0 | I22: 0 | J22: 0 | K22: 0 | L22: 0 | M22: 0 | N22: 0
... A49: पुणे मनपा हद्दीमध्ये नव्याने समाविष्ट होणारी 23 गावे (कआकसंप्र) | B49: RI11A107 | C49: 0 | D49: 0 | E49: 0 | F49: 0 | G49: 0 | H49: 2300000000 | I49: 2300000000 | J49: 0 | K49: 0 | L49: 0 | M49: 0 | N49: 2300000000
C50: 0 | D50: 0 | E50: 0 | F50: 0 | G50: 0 | H50: 0 | I50: 0 | J50: 0 | K50: 0 | L50: 0 | M50: 0 | N50: 0
A51: क. सर्वसाधारण कर बेरीज | C51: 3525303066 | D51: 3803991790 | E51: 5157049218 | F51: 2561038231 | G51: 3498218178 | H51: 13516500000 | I51: 13516500000 | J51: 10026200000 | K51: 0 | L51: 0 | M51: 0 | N51: 3490300000
C52: 0 | D52: 0 | E52: 0 | F52: 0 | G52: 0 | H52: 0 | I52: 0 | J52: 0 | K52: 0 | L52: 0 | M52: 0 | N52: 0
A53: ख. आयातकर | C53: 0 | D53: 0 | E53: 0 | F53: 0 | G53: 0 | H53: 0 | I53: 0 | J53: 0 | K53: 0 | L53: 0 | M53: 0 | N53: 0
A54: १. पक्की जमा (आ.क.प्र.) | B54: RI11B101 | C54: -5618500 | D54: -4881548 | E54: 0 | F54: 0 | G54: 0 | H54: 0 | I54: 0 | J54: 0 | K54: 0 | L54: 0 | M54: 0 | N54: 0
C55: 0 | D55: 0 | E55: 0 | F55: 0 | G55: 0 | H55: 0 | I55: 0 | J55: 0 | K55: 0 | L55: 0 | M55: 0 | N55: 0
A56: ख. निव्वळ आयातकर एकूण बेरीज | C56: -5618500 | D56: -4881548 | E56: 0 | F56: 0 | G56: 0 | H56: 0 | I56: 0 | J56: 0 | K56: 0 | L56: 0 | M56: 0 | N56: 0
C57: 0 | D57: 0 | E57: 0 | F57: 0 | G57: 0 | H57: 0 | I57: 0 | J57: 0 | K57: 0 | L57: 0 | M57: 0 | N57: 0
A58: ख-१. स्थानिक संस्था कर | C58: 0 | D58: 0 | E58: 0 | F58: 0 | G58: 0 | H58: 0 | I58: 0 | J58: 0 | K58: 0 | L58: 0 | M58: 0 | N58: 0
A59: स्थानिक संस्था कर नोंदणी शुल्क | B59: RI11B201 | C59: 300 | D59: 0 | E59: 0 | F59: 0 | G59: 0 | H59: 0 | I59: 0 | J59: 0 | K59: 0 | L59: 0 | M59: 0 | N59: 0
A60: स्थानिक संस्था कर | B60: RI11B202 | C60: 14074585 | D60: 1120093 | E60: 0 | F60: 0 | G60: 0 | H60: 5000000 | I60: 5000000 | J60: 5000000 | K60: 0 | L60: 0 | M60: 0 | N60: 0
A61: चौरस मीटर बांधकामाप्रमाणे भरावयाची ठोक रक्कम | B61: RI11B202B | C61: 3832035 | D61: 5510120 | E61: 1442790 | F61: 1442790 | G61: 29226 | H61: 200000 | I61: 200000 | J61: 300000 | K61: 0 | L61: 0 | M61: 100000 | N61: 0
A62: इतर जमा - स्थानिक संस्था कर | B62: RI11B202E | C62: 25232 | D62: 1780 | E62: 0 | F62: 0 | G62: 0 | H62: 0 | I62: 0 | J62: 0 | K62: 0 | L62: 0 | M62: 0 | N62: 0
A63: स्थानिक संस्था करापोटी व्याज | B63: RI11B203 | C63: 6911393 | D63: 821243 | E63: 0 | F63: 0 | G63: 0 | H63: 500000 | I63: 500000 | J63: 1400000 | K63: 0 | L63: 0 | M63: 900000 | N63: 0
A64: स्थानिक संस्था कर शास्ती (दंड) | B64: RI11B204 | C64: 80000 | D64: 25000 | E64: 35000 | F64: 30000 | G64: 25000 | H64: 0 | I64: 0 | J64: 0 | K64: 0 | L64: 0 | M64: 0 | N64: 0
A65: राज्य शासनाकडून मुद्रांक शुल्क अधिभारापोटी मिळालेली रक्कम (१%) | B65: RI11B206 | C65: 2758200420 | D65: 1749317051 | E65: 247275393 | F65: 0 | G65: 0 | H65: 1700000000 | I65: 1700000000 | J65: 3353000000 | K65: 0 | L65: 0 | M65: 1653000000 | N65: 0
A66: मनपा ठेकेदारांच्या बिलांमधून LBT वसुली | B66: RI11B207 | C66: 92301 | D66: 889 | E66: 16326 | F66: 10244 | G66: 0 | H66: 0 | I66: 0 | J66: 0 | K66: 0 | L66: 0 | M66: 0 | N66: 0
C67: 0 | D67: 0 | E67: 0 | F67: 0 | G67: 0 | H67: 0 | I67: 0 | J67: 0 | K67: 0 | L67: 0 | M67: 0 | N67: 0
A68: ख-१. स्थानिक संस्था कर बेरीज | C68: 2783216266 | D68: 1756796176 | E68: 248769509 | F68: 1483034 | G68: 54226 | H68: 1705700000 | I68: 1705700000 | J68: 3359700000 | K68: 0 | L68: 0 | M68: 1654000000 | N68: 0
...

Sheet A_Revenue_Expenditure
A1: योजनेतर खर्च तपशील
A2: विवरण | D2: नक्‍की आकडा | G2: मान्य अंदाज 2021-22 | H2: नवीन अंदाज 2022-23
D3: 2018-19 | E3: 2019-20 | F3: 2020-21
A4: १. मुख्य देखरेख, वसुली वगैरे | D4: 0 | E4: 0 | F4: 0 | G4: 0 | H4: 0
A5: क. महानगरपालिका व स्थायी समिती | D5: 0 | E5: 0 | F5: 0 | G5: 0 | H5: 0
A6: १ नगरसचिव यांचे कार्यालय | D6: 0 | E6: 0 | F6: 0 | G6: 0 | H6: 0
A7: १. नगरसचिव (म्युनिसिपल सेक्रेटरी) (मुं.प्रां. मनपा अधिनियम, कलम४५(३) प्रमाणे) वेतन | B7: RE11A101A | D7: 1357957 | E7: 1343918 | F7: 1757440 | G7: 1500000 | H7: 2500000
A8: २. कायम सेवकवर्ग वेतन | B8: RE11A102A | D8: 38537287 | E8: 37739899 | F8: 40716333 | G8: 45000000 | H8: 51100000
A9: ३. संकीर्ण (न.स.) | B9: RE11A103 | D9: 4967904 | E9: 727424 | F9: 3701446 | G9: 10000000 | H9: 10000000
A10: ३अ. मागील बिले देण्यासाठी (न.स.) | B10: RE11A103A | D10: 2886671 | E10: 1251212 | F10: 2627800 | G10: 4000000 | H10: 4000000
A11: ४. प्रवास खर्च (न.स.) | B11: RE11A104 | D11: 35207 | E11: 133002 | F11: 26355 | G11: 2000000 | H11: 2000000
A12: ५. ग्रंथालय व वाचनालय | B12: RE11A105 | D12: 172716 | E12: 189625 | F12: 188737 | G12: 250000 | H12: 250000
A13: ६. समारंभ खर्च (न.स. व वि.अ.) | B13: RE11A106 | D13: 68200 | E13: 0 | F13: 0 | G13: 500000 | H13: 500000
A14: १०. अखिल भारतीय/महाराष्ट्र महापौर परिषद व अखिल भारतीय स्थानिक स्वराज्य संस्था प्रतिनिधी अधिवेशन | B14: RE11A110 | D14: 0 | E14: 0 | F14: 0 | G14: 300000 | H14: 300000
A15: ११. मनपा व शासकीय निवृत्त सेवकांना द्यावयाचा चहापान खर्च | B15: RE11A111 | D15: 3000 | E15: 0 | F15: 0 | G15: 300000 | H15: 300000
A16: १३. महाराष्ट्र राज्य महानगरपालिका स्थायी समिती अध्यक्ष परिषद वर्गणी व तद्‌नुषंगिक खर्च | B16: RE11A113 | D16: 0 | E16: 0 | F16: 0 | G16: 1000 | H16: 1000
A17: १४. मा. महापौर यांचा व्ययनियमन (सम्प्च्युअरी) भत्ता | B17: RE11A114 | D17: 0 | E17: 0 | F17: 0 | G17: 5000 | H17: 5000
A18: १५. मा. महापौर यांचा ऐच्छिक खर्च | B18: RE11A115 | D18: 95427 | E18: 57402 | F18: 122823 | G18: 200000 | H18: 200000
... A53: नगरसचिव विभागामार्फत आवश्यक सेवक भरती करणे (कंत्राटी) | B53: RE11A280 | D53: 0 | E53: 0 | F53: 0 | G53: 10000000 | H53: 0
D54: 0 | E54: 0 | F54: 0 | G54: 0 | H54: 0
A55: क. मनपा व स्थायी समिती बेरीज | D55: 87211238 | E55: 94077423 | F55: 98581149 | G55: 173656000 | H55: 176990000
D56: 0 | E56: 0 | F56: 0 | G56: 0 | H56: 0
A57: ख. मुख्य लेखापरिक्षक यांचे कार्यालय | D57: 0 | E57: 0 | F57: 0 | G57: 0 | H57: 0
A58: १. मुख्य लेखापरिक्षक (म्युनिसिपल चीफ ऑडिटर) (मु.प्रां. मनपा अधिनियम, कलम ४५ (३) प्रमाणे) यांचे वेतन | B58: RE11B101A | D58: 2623589 | E58: 2390291 | F58: 2617074 | G58: 2500000 | H58: 3773000
A59: २. कायम सेवकवर्ग वेतन | B59: RE11B102A | D59: 29232284 | E59: 26552946 | F59: 22830016 | G59: 29000000 | H59: 41220000
A60: ३. संकीर्ण | B60: RE11B103 | D60: 115189 | E60: 66256 | F60: 82905 | G60: 225000 | H60: 200000
D61: 0 | E61: 0 | F61: 0 | G61: 0 | H61: 0
A62: ख. मुख्यलेखापरिक्षक यांचे कार्या. बेरीज | D62: 31971062 | E62: 29009493 | F62: 25529995 | G62: 31725000 | H62: 45193000
D63: 0 | E63: 0 | F63: 0 | G63: 0 | H63: 0
A64: ग१. महापालिका आयुक्त यांचे कार्यालय | D64: 0 | E64: 0 | F64: 0 | G64: 0 | H64: 0
A65: १. महापालिका आयुक्त (म्युनिसिपल कमिशनर) (मु. प्रां. मनपा अधिनियम, कलम ३७ (१) प्रमाणे) यांचे वेतन | B65: RE11C101A | D65: 2531394 | E65: 2816569 | F65: 2971037 | G65: 3000000 | H65: 3000000
A66: २. उपआयुक्त (जनरल) (मुं. प्रां. मनपा अधिनियम, कलम ४५(३) प्रमाणे) यांचे वेतन | B66: RE11C102A | D66: 1175614 | E66: 1635153 | F66: 1378496 | G66: 2500000 | H66: 2500000
A67: ३. कायम सेवकवर्ग वेतन | B67: RE11C103A | D67: 29549463 | E67: 28289154 | F67: 24591421 | G67: 29500000 | H67: 41754000
A68: ४. संकीर्ण | B68: RE11C104 | D68: 1356556 | E68: 1450875 | F68: 1191416 | G68: 2000000 | H68: 2200000
A69: ६. मा. महापालिका आयुक्त यांचा ऐच्छिक खर्च (म.स.आ.) | B69: RE11C106 | D69: 50003 | E69: 139240 | F69: 164482 | G69: 850000 | H69: 800000
D70: 0 | E70: 0 | F70: 0 | G70: 0 | H70: 0
A71: ग१. महापालिका आयुक्त कार्यालय बेरीज | D71: 34663030 | E71: 34330991 | F71: 30296852 | G71: 37850000 | H71: 50254000
D72: 0 | E72: 0 | F72: 0 | G72: 0 | H72: 0
A73: ग२. अतिरिक्त महापालिका आयुक्त (विशेष) यांचे कार्यालय | D73: 0 | E73: 0 | F73: 0 | G73: 0 | H73: 0
A74: १. अतिरिक्त महापालिका आयुक्त (विशेष) यांचे वेतन | B74: RE11C126A | D74: 2041368 | E74: 1390901 | F74: 1407008 | G74: 3000000 | H74: 3000000
...

Sheet A_Capital_Expenditure
A1: सन 2022-23 चे योजनांतर्गत | H1: खर्चाबाबतचे अंदाजपत्रक
A2: मान्यतेचा ठराव क्र. दिनांक (Code) | B2: प्रभाग क्रमांक | C2: BPL | D2: कामाचे नाव अगर वर्णन | E2: दि. 31 मार्च 2022 अखेरपर्यंत केलेली तरतूद | H2: दि. 31 मार्च 2021 पर्यंतचा खर्चाचा नक्‍की आकडा | I2: 2021-22 मधील खर्चाची अंदाजी रक्कम | K2: 2022-23 साठी अधिक तरतूद | M2: 2022-23 साठी एकूण तरतूद | N2: प्रकल्पीय रक्कम
E3: कर्जातून | F3: महसूल निधीतून | G3: एकूण | I3: प्रत्यक्ष उपलब्ध तरतूद | J3: कर्जातून तरतूद | K3: कर्जातून | L3: महसूल निधी व इतर निधी
D7: १. मनपा भवन व मनपा इमारती | E7: 0 | F7: 0 | G7: 0 | H7: 0 | I7: 0 | L7: 0 | M7: 0
A8: CE11A129# | B8: J1- | C8: _ | D8: शहरात विविध ठिकाणी मनपासाठी इमारती बांधणे व विकास कामे करणे | E8: 0 | F8: 808496291 | G8: 808496291 | H8: 691071262 | I8: 117425029 | L8: 195000000 | M8: 195000000
E9: 0 | F9: 0 | G9: 0 | H9: 0 | I9: 0 | L9: 0 | M9: 0
D10: १. मनपा भवन व मनपा इमारती एकूण बेरीज | E10: 0 | F10: 808496291 | G10: 808496291 | H10: 691071262 | I10: 117425029 | L10: 195000000 | M10: 195000000
E11: 0 | F11: 0 | G11: 0 | H11: 0 | I11: 0 | L11: 0 | M11: 0
D12: २. प्राथमिक शिक्षण | E12: 0 | F12: 0 | G12: 0 | H12: 0 | I12: 0 | L12: 0 | M12: 0
A13: CE12A381# | B13: _ | C13: _ | D13: प्राथमिक शाळेमध्ये मुलभूत सोयी सुविधांसाठी विविध विकासकामे करणे | E13: 0 | F13: 1301502862 | G13: 1301502862 | H13: 1301502862 | I13: 0 | L13: 0 | M13: 0
A14: CE12A422# | B14: J2- | C14: _ | D14: प्राथमिक शाळेसाठी नवीन इमारत बांधणे / वर्गखोल्या बांधणे / मैदाने विकसित करणे व मुलभूत सोयी सुविधांसाठी विविध विकासकामे करणे | E14: 0 | F14: 1325472139 | G14: 1325472139 | H14: 1093094755 | I14: 232377384 | L14: 315500000 | M14: 315500000
E15: 0 | F15: 0 | G15: 0 | H15: 0 | I15: 0 | L15: 0 | M15: 0
C16: B | D16: २. प्राथमिक शिक्षण एकूण बेरीज | E16: 0 | F16: 2686415818 | G16: 2686415818 | H16: 2454038434 | I16: 232377384 | L16: 315500000 | M16: 315500000
E17: 0 | F17: 0 | G17: 0 | H17: 0 | I17: 0 | L17: 0 | M17: 0
D18: ३. दुय्यम शिक्षण | E18: 0 | F18: 0 | G18: 0 | H18: 0 | I18: 0 | L18: 0 | M18: 0
A19: CE13A128# | B19: J5- | C19: _ | D19: माध्यमिक शाळांमध्ये मुलभूत सोयी सुविधांसाठी विविध विकासकामे करणे | E19: 0 | F19: 68490996 | G19: 68490996 | H19: 60693416 | I19: 7797580 | L19: 3500000 | M19: 3500000
E20: 0 | F20: 0 | G20: 0 | H20: 0 | I20: 0 | L20: 0 | M20: 0
C21: B | D21: ३. दुय्यम शिक्षण एकूण बेरीज | E21: 0 | F21: 68490996 | G21: 68490996 | H21: 60693416 | I21: 7797580 | L21: 3500000 | M21: 3500000
E22: 0 | F22: 0 | G22: 0 | H22: 0 | I22: 0 | L22: 0 | M22: 0
D23: ७. आरोग्य विभाग | E23: 0 | F23: 0 | G23: 0 | H23: 0 | I23: 0 | L23: 0 | M23: 0
A24: CE17A192# | B24: _ | C24: _ | D24: दवाखान्यातील मुलभूत सोयी सुविधांसाठी विविध विकासकामे करणे | E24: 0 | F24: 583746804 | G24: 583746804 | H24: 583746804 | I24: 0 | L24: 0 | M24: 0
A25: CE17A227# | B25: J12- | C25: _ | D25: शहरामध्ये विविध ठिकाणी स्मशानभूमी / दफनभूमी विकसित करणे / दशक्रीया विधीसाठी घाट बांधणे व विविध विकासकामे करणे | E25: 0 | F25: 789005778 | G25: 789005778 | H25: 661059560 | I25: 127946218 | L25: 63000000 | M25: 63000000
A26: CE17A242# | B26: J6- | C26: _ | D26: शहरामध्ये दवाखाने / प्रसुतिगृह बांधणे / दवाखान्यांसाठी विविध उपकरणे खरेदी करणे / दवाखान्यातील मुलभूत सोयी सुविधांसाठी विविध विकासकामे करणे | E26: 0 | F26: 1104500955 | G26: 1104500955 | H26: 667053162 | I26: 437447793 | L26: 1202500000 | M26: 1202500000
A27: CE17A244# | B27: _ | C27: _ | D27: शहरातील दवाखान्यांसाठी विविध उपकरणे खरेदी करणे | E27: 0 | F27: 153267558 | G27: 153267558 | H27: 153267558 | I27: 0 | L27: 0 | M27: 0
E28: 0 | F28: 0 | G28: 0 | H28: 0 | I28: 0 | L28: 0 | M28: 0
C29: B | D29: ७. आरोग्य विभाग एकूण बेरीज | E29: 0 | F29: 2658568233 | G29: 2658568233 | H29: 2093174222 | I29: 565394011 | L29: 1265500000 | M29: 1265500000
E30: 0 | F30: 0 | G30: 0 | H30: 0 | I30: 0 | L30: 0 | M30: 0
D31: ९. पथांची झाडलोट / घनकचरा व्यवस्थापन विभाग | E31: 0 | F31: 0 | G31: 0 | H31: 0 | I31: 0 | L31: 0 | M31: 0
A32: CE19A116 | D32: उरूळी देवाची/फुरसंगी डेपो परिसर कचरा डेपोवरील उर्वरित कचर्‍याचे नॉर्म्सप्रमाणे कॅपिंग करणे व तद्‌नुषंगिक कामे करणे | E32: 0 | F32: 828238528 | G32: 828238528 | H32: 811712664 | I32: 16525864 | L32: 9000000 | M32: 9000000
A33: CE19A117 | D33: उरुळी देवाची/फुरसुंगी येथील कचरा डेपोच्या भोवती सिमाभिंत बांधणे. | E33: 0 | F33: 58029046 | G33: 58029046 | H33: 48245253 | I33: 9783793 | L33: 4500000 | M33: 4500000
A34: CE19A120 | D34: व्हर्मीकंपोस्ट पध्दतीचे प्रक्रिया प्रकल्प उभारणे. | E34: 0 | F34: 153449062 | G34: 153449062 | H34: 153449062 | I34: 0 | L34: 0 | M34: 0
A35: CE19A122 | D35: कचरा प्रक्रिया प्रकल्पासाठी जागा ताब्यात घेणे, कंपाउंड करणे, रस्ते करणे व तदनुषंगिक कामे करणे. | E35: 0 | F35: 80797347 | G35: 80797347 | H35: 70039173 | I35: 10758174 | L35: 9000000 | M35: 9000000
A36: CE19A123 | D36: ताब्यात येणार्‍या जागांवर प्रक्रिया प्रकल्प उभारणे, प्रकल्पांसाठी आवश्यक सुविधा विषयक कामे करणे इत्यादी. | E36: 0 | F36: 319085651 | G36: 319085651 | H36: 245750959 | I36: 73334692 | L36: 129150000 | M36: 129150000
A37: CE19A139 | D37: उरुळी देवाची/फुरसंगी येथील गावांमध्ये विविध विकास कामे करणे | E37: 0 | F37: 518198479 | G37: 518198479 | H37: 510456552 | I37: 7741927 | L37: 9000000 | M37: 9000000
A38: CE19A141 | D38: घनकचरा व्यवस्थापनकडील कचरागाडया, बंदिस्त करणे विविध रॅम्प बंदिस्त करणे व कॉक्रीट करणे. | E38: 0 | F38: 131705349 | G38: 131705349 | H38: 117603119 | I38: 14102230 | L38: 13500000 | M38: 13500000
A39: CE19A143 | D39: गार्डन वेस्टसाठी विविध ठिकाणी पुणे मनपा हद्दीत श्रेडर मशिन बसविणे | E39: 0 | F39: 8198533 | G39: 8198533 | H39: 6357180 | I39: 1841353 | L39: 900000 | M39: 900000
A40: CE19A153 | D40: प्लास्टिक व इलेक्ट्रॉनिक वस्तू विभाजीत करणेकरीता शेड बांधणे | E40: 0 | F40: 19528393 | G40: 19528393 | H40: 16028393 | I40: 3500000 | L40: 2250000 | M40: 2250000
A41: CE19A154# | C41: _ | D41: शहरात घनकचरा संदर्भात विविध विकास कामे करणे | E41: 0 | F41: 289378553 | G41: 289378553 | H41: 254278545 | I41: 35100008 | L41: 0 | M41: 0
A42: CE19A155 | D42: e-waste जमा करणे व प्रक्रिया करणे | E42: 0 | F42: 4350000 | G42: 4350000 | H42: 850000 | I42: 3500000 | L42: 3150000 | M42: 3150000
A43: CE19A156 | D43: कचरा वाहतुकीसाठी नव्याने उपनगरांमध्ये रॅम्पचे आधुनिकीकरण, विकासकामे करणे, यंत्रसामग्री | E43: 0 | F43: 89889926 | G43: 89889926 | H43: 61791166 | I43: 28098760 | L43: 144000000 | M43: 144000000
...

Sheet A_Land_Acquisition
A1: सन 2022-23 चे अंदाजपत्रक - खास निधीतून करावयाची योजनांतर्गत कामे
A2: अनुक्रमांक | C2: कामाचे नाव | D2: मान्य अंदाज 2021-22 | E2: नवीन अंदाज 2022-23
A5: (अ) | C5: भूमी संपादन निधीतून करावयाचा खर्च | D5: 0 | E5: 0
D6: 0 | E6: 0
A7: 1 | B7: FE11A101 | C7: भूमी संपादन विशेष अधिकारी यांचा कार्यालयीन खर्च - | D7: 14000000 | E7: 50000000
A8: 2 | C8: कोर्टाच्या निकालानुसार वाढीव नुकसानभरपाई कोर्ट खर्च, वकील फी, जॉइन्ट जज्ज यांचा खर्च वगैरे | D8: 0 | E8: 0
A9: 3 | C9: भूमी संपादन अधिनियमात नव्याने केलेल्या दुरुस्तीमुळे यापूर्वी जाहीर झालेल्या योजनापोटी ावयाच्या वाढीव रकमेचा खर्च | D9: 0 | E9: 0
A10: 4 | C10: परचेस नोटीसांमुळे (नवीन) पाठवावयाच्या भूमी संपादन योजनांसाठी तरतूद | D10: 0 | E10: 0
A11: 5 | C11: ताब्यात घेतलेल्या मिळकती पाडणे, ड्रेनेज, वॉटर, इलेक्ट्रीक टेलिफोन वगैरे कनेक्शन्स हलविणे, जोडणे व इतर तद्‌नुषंगिक कामे करणे. | D11: 0 | E11: 0
A12: 6 | C12: कार्यालयीन कामासाठी साधने, डेडस्टॉक वस्तू खरेदी करणे, हत्यारे खरेदी करणे, कार्यालय व कोठीची दुरुस्ती करणे, आवश्यक सुधारणा करणे, प्रकटन खर्च, प्रवास खर्च वगैर | D12: 0 | E12: 0
A13: 7 | C13: मुंबई प्रांतिक मनपा अधिनियम १९४९ च्या कलम २१३ अन्वये रस्तारूंदीसाठी ताब्यात घेतलेल्या मोकळ्या जागा व त्याप्रित्यर्थ ावयाची नुकसानभरपाईची रक्कम | D13: 0 | E13: 0
A14: 8 | C14: इतर योजनांमधील मोजणी फी व इतर तद्‌नुषंगिक रक्कम | D14: 0 | E14: 0
A15: 9 | C15: भूमी संपादन अधिकारी ह्यांचेकडील खालील नमूद केलेल्या ज्या जागांचे निवाडे जाहीर करतील त्यासाठी रक्कम | D15: 0 | E15: 0
A16: 10 | C16: संगणक दुरूस्ती व आवश्यक साहित्य | D16: 0 | E16: 0
D17: 0 | E17: 0
C18: (अ) बेरीज | D18: 14000000 | E18: 50000000
D19: 0 | E19: 0
D20: 0 | E20: 0
B21: FE11A102 | C21: भूसंपादनासाठी आवश्यक जागांची यादी :- | D21: 161000000 | E21: 250000000
D22: 0 | E22: 0
C23: सी.वाय.जी अंतर्गत रस्ते : | D23: 0 | E23: 0
C24: बाणेर मुख्य रस्ता २६१ ते १०५ | D24: 0 | E24: 0
C25: बाणेर स.क्र. १३३ ते बालेवाडी स.क्र. १० बालेवाडीकडे जाणारा रस्ता मुख्य रस्ता (बालेवाडी) | D25: 0 | E25: 0
C26: बालेवाडी स.क्र. ३४, ३५ जी१ गार्डनचे आरक्षण | D26: 0 | E26: 0
C27: बाणेर स.क्र. २८, २९० जी२ गार्डनचे आरक्षण व बाणेर स.क्र. ३५ जी३ गार्डनचे आरक्षण | D27: 0 | E27: 0
C28: कल्याणीनगर जंक्शन ते आळंदी रोड | D28: 0 | E28: 0
C29: बाणेर स.क्र. १०५, १०६, ११०, १११ पीएमटी१ | D29: 0 | E29: 0
C30: बाणेर स.क्र. ३३ पी.३ | D30: 0 | E30: 0
C31: बाणेर स.क्र. १०० पी.४ | D31: 0 | E31: 0
C32: बाणेर स.क्र. १७४ पी.४ | D32: 0 | E32: 0
C33: बाणेर स.क्र. ७९ पी.६ | D33: 0 | E33: 0
C34: बाणेर स.क्र. १०५, १०६ पी.७ पार्किंगचे आरक्षण | D34: 0 | E34: 0
... C40: एअरपोर्ट रोड ते डेक्कन कॉलेज व्हाया हॉटमिक्स प्लँट | D40: 0 | E40: 0
D41: 0 | E41: 0
C42: जेएनएनयुआरएम / बीआरटी अंतर्गत रस्ते : | D42: 0 | E42: 0
C43: बाणेर स.क्र. १०७, १०८ व ११० मधून जाणारा १८ मी. रस्ता. | D43: 0 | E43: 0
C44: मौजे खराडी ता. हवेली, संगमवाडी ते खराडी २४ मी. नदीकाठचा डी.पी. रस्ता | D44: 0 | E44: 0
C45: मौजे वडगांव शेरी ता. हवेली, संगमवाडी ते खराडी २४ मी. नदीकाठचा डी.पी. रस्ता | D45: 0 | E45: 0
C46: सिंहगड रस्ता महानगरपालिका हद्द दरम्यान नियोजनाते विकसीत करणे (वडगांव बुद्रुक) | D46: 0 | E46: 0
C47: सिंहगड रस्ता महानगरपालिका हद्द दरम्यान नियोजनाते विकसीत करणे (वडगांव खुर्द) | D47: 0 | E47: 0
...

Sheet A_Fund_Expenditure
A1: सन 2022-23 चे उपनगरे विकास निधीचे | H1: योजनांतर्गत खर्चाबाबतचे अंदाजपत्रक
A2: मान्यतेचा ठराव क्र. दिनांक (कोड) | B2: प्रभाग क्रमांक | C2: BPL | D2: कामाचे नाव अगर वर्णन | E2: दि. 31 मार्च 2022 अखेरपर्यंत केलेली तरतूद | H2: दि. 31 मार्च 2020 पर्यंतचा खर्चाचा नक्‍की आकडा | I2: 2020-21 मधील खर्चाचा नक्‍की आकडा | J2: 2021-22 मधील खर्चाची अंदाजी रक्‍कम | K2: 2022-23 साठी अधिक तरतूद | M2: 2022-23 साठी एकूण तरतूद | N2: शेरा
E3: कर्जातून | F3: महसूल निधीतून | G3: एकूण | K3: कर्जातून | L3: महसूल निधी व इतर निधी
D7: ४. झोपडपट्टी निर्मूलन व पुनर्वसन निधी | E7: 0 | F7: 0 | G7: 0 | H7: 0 | I7: 0 | J7: 0 | L7: 0 | M7: 0
A8: FE14A101# | B8: _ | C8: _ | D8: निरनिराळ्या झोपडपट्टींमध्ये विविध विकासाची कामे करणे | E8: 33377000 | F8: 1670472010 | G8: 1703849010 | H8: 1504273354 | I8: 39139701 | J8: 160435955 | L8: 0 | M8: 0
A9: FE14A104 | C9: B | D9: झो.नि.पु. अंतर्गत करावयाची कामे | E9: 0 | F9: 250159611 | G9: 250159611 | H9: 209140985 | I9: 23992261 | J9: 17026365 | L9: 15800000 | M9: 15800000
A10: FE14A105# | B10: _ | C10: _ | D10: शहरामध्ये शौच्छालये / मुताऱ्या बांधणे | E10: 0 | F10: 1921763843 | G10: 1921763843 | H10: 1531843629 | I10: 110695897 | J10: 279224317 | L10: 0 | M10: 0
A11: FE14A107 | C11: B | D11: दलित वस्ती सुधारणा अंतर्गत कामे करणे | E11: 0 | F11: 224696636 | G11: 224696636 | H11: 224696636 | I11: 14720804 | J11: -14720804 | L11: 0 | M11: 0
A12: FE14A129 | C12: PL | D12: सार्वजनिक ठिकाणी शौचालय बांधणे | E12: 0 | F12: 92709466 | G12: 92709466 | H12: 55159998 | I12: 20109765 | J12: 17439703 | L12: 15750000 | M12: 15750000
A13: FE14A130 | C13: PL | D13: सार्वजनिक ठिकाणी मुतार्‍या बांधणे | E13: 0 | F13: 70678303 | G13: 70678303 | H13: 30616748 | I13: 21862549 | J13: 18199006 | L13: 15750000 | M13: 15750000
A14: FE14A135 | D14: प्रभाग क्र.14ब, मधील बाबासाहेब आंबेडकर हॉस्टेल विकसित करणेकरिता अहवाल तयार करणे | E14: 0 | F14: 0 | G14: 0 | H14: 0 | I14: 0 | J14: 0 | L14: 0 | M14: 0
E15: 0 | F15: 0 | G15: 0 | H15: 0 | I15: 0 | J15: 0 | L15: 0 | M15: 0
D16: ४. झोपडपट्टी निर्मूलन व पुनर्वसन निधी एकूण बेरीज | E16: 33377000 | F16: 4230479869 | G16: 4263856869 | H16: 3555731350 | I16: 230520977 | J16: 477604542 | L16: 47300000 | M16: 47300000
E17: 0 | F17: 0 | G17: 0 | H17: 0 | I17: 0 | J17: 0 | L17: 0 | M17: 0
D18: क्षेत्रिय कार्यालयाने करावयाची कामे | E18: 0 | F18: 0 | G18: 0 | H18: 0 | I18: 0 | J18: 0 | L18: 0 | M18: 0
E19: 0 | F19: 0 | G19: 0 | H19: 0 | I19: 0 | J19: 0 | L19: 0 | M19: 0
A20: FE14A118# | B20: W5 | C20: B | D20: क्षेत्रिय कार्यालय : झो.नि.पु. विभागाने करावयाची कामे | E20: 0 | F20: 263527952 | G20: 263527952 | H20: 241301496 | I20: 1740454 | J20: 20486002 | L20: 3750000 | M20: 3750000
A21: FE14A121# | B21: C5 | C21: B | D21: क्षेत्रिय कार्यालय : नागरिकांच्या सहभाग योजनेतून झो.नि.पु. विभागाने करावयाची कामे | E21: 0 | F21: 146137357 | G21: 146137357 | H21: 139907204 | I21: 566153 | J21: 5664000 | L21: 5550000 | M21: 5550000
E22: 0 | F22: 0 | G22: 0 | H22: 0 | I22: 0 | J22: 0 | L22: 0 | M22: 0
D23: क्षेत्रिय कार्यालयाने करावयाची कामे एकूण बेरीज | E23: 0 | F23: 409665309 | G23: 409665309 | H23: 381208700 | I23: 2306607 | J23: 26150002 | L23: 9300000 | M23: 9300000
E24: 0 | F24: 0 | G24: 0 | H24: 0 | I24: 0 | J24: 0 | L24: 0 | M24: 0
D25: ४. झोपडपट्टी निर्मूलन व पुनर्वसन निधीतून करावयाची कामे + क्षेत्रिय कार्यालयाने करावयाची कामे एकूण बेरीज | E25: 33377000 | F25: 4640145178 | G25: 4673522178 | H25: 3936940050 | I25: 232827584 | J25: 503754544 | L25: 56600000 | M25: 56600000
E26: 0 | F26: 0 | G26: 0 | H26: 0 | I26: 0 | J26: 0 | L26: 0 | M26: 0
D27: ४अ. मागासवर्गीय कल्याणकारी योजना निधी | E27: 0 | F27: 0 | G27: 0 | H27: 0 | I27: 0 | J27: 0 | L27: 0 | M27: 0
A28: FE14B101 | C28: B-FA | D28: समाज विकास विभाग अंतर्गत मागासवर्गीय योजना | E28: 0 | F28: 544809550 | G28: 544809550 | H28: 474809550 | I28: 23433297 | J28: 46566703 | L28: 35000000 | M28: 35000000
A29: FE14B112 | C29: B-FA | D29: लोकशाहीर अण्णाभाऊ साठे शैक्षणिक मदत योजना | E29: 0 | F29: 256392082 | G29: 256392082 | H29: 170392082 | I29: 25625000 | J29: 60375000 | L29: 50000000 | M29: 50000000
A30: FE14B113 | C30: B-FA | D30: मौ. अबुल कलाम आझाद शैक्षणिक मदत योजना | E30: 0 | F30: 512558546 | G30: 512558546 | H30: 366558546 | I30: 46875000 | J30: 99125000 | L30: 80000000 | M30: 80000000
A31: FE14B121 | C31: B-T | D31: मागासवर्गीय विद्यार्थ्यांना स्पर्धा परिक्षा मार्गदर्शन केंद्र चालविणे | E31: 0 | F31: 11843896 | G31: 11843896 | H31: 5843896 | I31: 1020000 | J31: 4980000 | L31: 3000000 | M31: 3000000
A32: FE14B122 | C32: B-T | D32: बालविकास केंद्र व वस्ती रिसोर्स सेंटर सुरू करणे | E32: 0 | F32: 16298182 | G32: 16298182 | H32: 12798182 | I32: 130680 | J32: 3369320 | L32: 1500000 | M32: 1500000
A33: FE14B123 | C33: B | D33: मागासवर्गीय कल्याणकारी योजनेअंतर्गत विविध योजना राबविणेसाठी मानधन तत्वावरील सेवकांचा मानधन खर्च | E33: 0 | F33: 41002659 | G33: 41002659 | H33: 31002659 | I33: 3388892 | J33: 6611108 | L33: 6000000 | M33: 6000000
A34: FE14B127 | C34: B | D34: माता रमार्इ भिमराव आंबेडकर योजनेअंतर्गत गवनि घोषीत व शहरी गरीब योजनेतील पात्र ठरणाऱ्या विधवा, निराधार महिलांसाठी दरमहा रू.1,000/- अर्थसहाय्य करणे (मागासवर्गीय कल्याणकारी योजना) | E34: 0 | F34: 37402788 | G34: 37402788 | H34: 3402788 | I34: 1613000 | J34: 32387000 | L34: 17000000 | M34: 17000000
A35: FE14B128 | C35: B-FA | D35: डॉ. बाबासाहेब आंबेडकर विद्यार्थी वसतिगृह, घोले रोड येथील खाणावळीचा खर्च | E35: 0 | F35: 19447051 | G35: 19447051 | H35: 9447051 | I35: 172229 | J35: 9827771 | L35: 5000000 | M35: 5000000
A36: FE14B129 | C36: B-I | D36: शहरात आदिवासी विद्यार्थ्यांसाठी वसतिगृहे उभारणे | E36: 0 | F36: 77745809 | G36: 77745809 | H36: 17745809 | I36: 24825240 | J36: 35174760 | L36: 50000000 | M36: 50000000
A37: FE14B131 | C37: B-T | D37: विविध व्यावसायिक प्रशिक्षण देणे | E37: 0 | F37: 2795443 | G37: 2795443 | H37: 2795443 | I37: 0 | J37: 0 | L37: 0 | M37: 0
A38: FE14B133 | C38: B | D38: लोकशाहिर अण्णा भाऊ साठे यांच्या जन्मशताब्दी वर्षानिमित्त विविध कार्यक्रमाचे आयोजन करणे | E38: 0 | F38: 10000000 | G38: 10000000 | H38: 0 | I38: 0 | J38: 10000000 | L38: 0 | M38: 0
E39: 0 | F39: 0 | G39: 0 | H39: 0 | I39: 0 | J39: 0 | L39: 0 | M39: 0
D40: ४अ. मागासवर्गीय कल्याणकारी योजना निधी एकूण बेरीज | E40: 0 | F40: 1530296006 | G40: 1530296006 | H40: 1094796006 | I40: 127083338 | J40: 308416662 | L40: 247500000 | M40: 247500000
E41: 0 | F41: 0 | G41: 0 | H41: 0 | I41: 0 | J41: 0 | L41: 0 | M41: 0
D42: ४ब. महिलाबालकल्याण योजना निधी | E42: 0 | F42: 0 | G42: 0 | H42: 0 | I42: 0 | J42: 0 | L42: 0 | M42: 0
A43: FE14C101 | C43: PL-FA | D43: महिलाबालकल्याण योजना | E43: 0 | F43: 495419703 | G43: 495419703 | H43: 424848849 | I43: 15814293 | J43: 54756561 | L43: 35000000 | M43: 35000000
...

Sheet A_DPDC_Machinery_Tree
A1: सन 2022-23 चे अंदाजपत्रक – खास निधीतून करावयाची योजनांतर्गत कामे
A2: विवरण | C2: नक्की आकडा | F2: मान्य अंदाज 2021-22 | G2: नवीन अंदाज 2022-23
C4: 2018-19 | D4: 2019-20 | E4: 2020-21
B6: ५. पुणे जिल्हा नियोजन व विकास मंडळ निधीतून करावयाची कामे
B7: ५अ. मा. आमदारांनी सुचविल्याप्रमाणे करावयाची विकासाची कामे
A8: FE15A101 | B8: बोपोडी मतदार संघ क्र. २४६ | C8: 0 | D8: 0 | E8: 0 | F8: 5000000 | G8: 5000000
A9: FE15A102 | B9: शिवाजीनगर मतदार संघ क्र. २४७ | C9: 7569383 | D9: 5663108 | E9: 5222480 | F9: 5000000 | G9: 5000000
A10: FE15A103 | B10: पर्वती मतदार संघ क्र. २४८ | C10: 4049517 | D10: 20538895 | E10: 8224490 | F10: 5000000 | G10: 5000000
A11: FE15A104 | B11: कसबा पेठ मतदार संघ क्र. २४९ | C11: 17250785 | D11: 7008244 | E11: 9752843 | F11: 5000000 | G11: 5000000
A12: FE15A105 | B12: भवानी पेठ मतदार संघ क्र. २५० | C12: 0 | D12: 0 | E12: 0 | F12: 5000000 | G12: 5000000
A13: FE15A106 | B13: पुणे (कॅन्टोन्मेंट) मतदार संघ क्र. २५१ | C13: 6022891 | D13: 928911 | E13: 424631 | F13: 5000000 | G13: 5000000
A14: FE15A107 | B14: विधान परिषद सदस्य | C14: 1627378 | D14: 1348324 | E14: 20726398 | F14: 2500000 | G14: 2500000
C15: 0 | D15: 0 | E15: 0 | F15: 0 | G15: 0
A16: FE15A108 | B16: ५ब. मा. खासदारांनी सुचविल्याप्रमाणे करावयाची विकासाची कामे | C16: 48067028 | D16: 39082990 | E16: 17265839 | F16: 20000000 | G16: 20000000
C17: 0 | D17: 0 | E17: 0 | F17: 0 | G17: 0
A18: FE15A110 | B18: महानगरपालिका क्षेत्रात मुलभूत सोईसुविधांसाठी विशेष अनुदान | C18: 8971934 | D18: 20903967 | E18: 48163144 | F18: 0 | G18: 0
A19: FE15A111 | B19: मुळशी मतदार संघ | C19: 0 | D19: 0 | E19: 0 | F19: 2500000 | G19: 2500000
A20: FE15A112 | B20: कोथरूड विधानसभा मतदार संघ | C20: 2487968 | D20: 0 | E20: 0 | F20: 5000000 | G20: 5000000
A21: FE15A113 | B21: हडपसर विधानसभा मतदार संघ | C21: 1486525 | D21: 338906 | E21: 0 | F21: 5000000 | G21: 5000000
A22: FE15A114 | B22: वडगांवशेरी विधानसभा मतदार संघ | C22: 0 | D22: 0 | E22: 273673 | F22: 5000000 | G22: 5000000
A23: FE15A115 | B23: खडकवासला विधानसभा मतदार संघ | C23: 0 | D23: 0 | E23: 2366999 | F23: 5000000 | G23: 5000000
A24: RE53A101 | B24: ५. पुणे जिल्हा नियोजन व विकास मंडळ निधीतून करावयाची कामे बेरीज | C24: 97533409 | D24: 95813345 | E24: 112420497 | F24: 75000000 | G24: 75000000
C25: 0 | D25: 0 | E25: 0 | F25: 0 | G25: 0
C26: 0 | D26: 0 | E26: 0 | F26: 0 | G26: 0
B27: ७. यंत्रसामुग्री घसारा निधीतून विकत घ्याववयाची नवीन सामुग्री | C27: 0 | D27: 0 | E27: 0 | F27: 0 | G27: 0
B28: अग्निशामक दलासाठी यंत्रसामुग्री :- | C28: 0 | D28: 0 | E28: 0 | F28: 0 | G28: 0
A29: FE17A103-1 | B29: वॉटर टँकर पंपासह | C29: 11680000 | D29: 0 | E29: 0 | F29: 29400000 | G29: 21000000
A30: FE17A103-2 | B30: फायर इंजिन गाडी | C30: 29199998 | D30: 26292205 | E30: 0 | F30: 36820000 | G30: 80000000
A31: FE17A103-12 | B31: रेस्क्यू इक्वीपमेंट व लाईट मास्ट | C31: 0 | D31: 1460426 | E31: 16276396 | F31: 0 | G31: 0
A32: FE17A113-6 | B32: विद्युत विभाग :- हायड्रॉलिक प्लॅटफॉर्म (2 नग) | C32: 0 | D32: 0 | E32: 0 | F32: 2800000 | G32: 0
A33: FE17A114-6 | B33: बॅकहो लोडर खरेदी करणे | C33: 4000200 | D33: 9840186 | E33: 0 | F33: 0 | G33: 5000000
A34: FE17A114-9 | B34: पथ विभागासाठी टिपर खरेदी करणे | C34: 13749120 | D34: 0 | E34: 0 | F34: 0 | G34: 8000000
A35: FE17A114-10 | B35: पथ विभागाकडील कोठ्यांसाठी रोलर्स, मिक्‍सर्स, पेव्हर अन्य यंत्रसामुग्री खरेदी करणे | C35: 0 | D35: 0 | E35: 0 | F35: 0 | G35: 9000000
A36: FE17A124 | B36: मोटार वाहन विभाग मशिनरी | C36: 81895 | D36: 631216 | E36: 496687 | F36: 1330000 | G36: 1500000
A37: FE17A146 | B37: मनपा पदाधिकारी व अधिकार्‍यांसाठी मोटारकार खरेदी करणे | C37: 3145700 | D37: 6706341 | E37: 0 | F37: 6510000 | G37: 500000
A38: FE17A149-3 | B38: कंटेनर दुरुस्ती व रंगवणे | C38: 1973896 | D38: 999989 | E38: 930424 | F38: 1680000 | G38: 2000000
A39: FE17A149-4 | B39: कचरा निर्मूलन विषयक यंत्रसामुग्री | C39: 179900 | D39: 996545 | E39: 0 | F39: 980000 | G39: 500000
A40: FE17A149-13 | B40: आयुर्मान संपलेली वाहणे बदलणे | C40: 2228582 | D40: 9907998 | E40: 9601015 | F40: 0 | G40: 30000000
... A53: FE17A277# | B53: यंत्रसामुग्री घसारा निधीतून विकत घ्याववयाची सामुग्री (यादी Y1) | C53: 40881598 | D53: 135664718 | E53: 13294690 | F53: 165500000 | G53: 6000000
C54: 0 | D54: 0 | E54: 0 | F54: 0 | G54: 0
...

Sheet A_List
D1: यादी क्र. R1
D2: थोर व्यक्तींच्या जयंती / पुण्यतिथी साजरी करणे (यादी R1)
D3: RE11A274/R1-
A5: code | B5: ward | D5: कामाचे नाव | E5: प्रकल्पीय रक्कम | F5: तरतूद
A7: RE11A274/R1-1 | D7: महात्मा फुले जयंती | F7: 100000
A8: RE11A274/R1-2 | D8: डॉ. बाबासाहेब आंबेडकर जयंती | F8: 150000
A9: RE11A274/R1-3 | D9: लोकशाहीर अण्णाभाऊ साठे जयंती | F9: 200000
A10: RE11A274/R1-4 | D10: ईद-ए-मिलाद (पैगंबर जयंती) | F10: 150000
A11: RE11A274/R1-5 | D11: शहरातील शिवजयंती साजरी करणे, रोषणाई करणे | F11: 200000
A12: RE11A274/R1-6 | D12: महात्मा फुले यांची पुण्यतिथी साजरी करणे (दि. 28 नोव्हेंबर) | F12: 500000
A13: RE11A274/R1-7 | D13: मौलाना अब्दुल कलाम आझाद जयंती व पुण्यतिथी साजरी करणे | F13: 600000
A14: RE11A274/R1-8 | D14: लहुजी वस्ताद साळवे जयंती महोत्सव गंज पेठ व संगमवाडी येथे साजरा करणे | F14: 500000
A15: RE11A274/R1-9 | D15: नेताजी सुभाषचंद्र बोस यांची जयंती साजरी करणे | F15: 10000
A16: RE11A274/R1-10 | D16: येरवडा येथे लोकशाहिर अण्णाभाऊ साठे जयंती महोत्सव साजरा करणे | F16: 100000
A17: RE11A274/R1-11 | D17: श्री संत रोहिदास महाराज जयंती, पुण्यतिथी साजरी करणे | F17: 50000
A18: RE11A274/R1-13 | D18: मौलाना अबुल कलाम आझाद जयंती महोत्सव | F18: 500000
A19: RE11A274/R1-14 | D19: महावीर जयंती | F19: 100000
D21: यादी क्र. R1 एकूण | E21: 0 | F21: 3160000
D24: यादी क्र. R2
D25: शहरामध्ये विविध कार्यक्रम, उत्सव, महोत्सव, संमेलन/ सहप्रायोजक तत्वावर कार्यक्रम साजरे करणे (यादी R2)
D26: RE11A275/R2-
A28: code | B28: ward | D28: कामाचे नाव | E28: प्रकल्पीय रक्कम | F28: तरतूद
A30: RE11A275/R2-1 | D30: महानगरपालिका वर्धापन दिन / सुवर्ण महोत्सव साजरा करणे | F30: 700000
A31: RE11A275/R2-2 | D31: वर्षातील महत्त्वपूर्ण दिन | F31: 600000
A32: RE11A275/R2-3 | D32: शिवाजीमहाराज आग्र्‍याहून सुटून परत आले तो स्मृती दिन साजरा करणे | F32: 515000
A33: RE11A275/R2-4 | D33: शनिवारवाडा सांस्कृतिक महोत्सव | F33: 2000000
A34: RE11A275/R2-5 | D34: भारतरत्न डॉ. बाबासाहेब आंबेडकर सांस्कृतिक महोत्सव साजरा करणे/ भिम फेस्टिवल (शनिवारवाडा पटांगण) / फुले आंबेडकर फेस्टिवल (समताभूमी) | F34: 2000000
A35: RE11A275/R2-6 | D35: शिवमहोत्सव साजरा करणे (१४ ते २० फेब्रुवारी) | F35: 2000000
A36: RE11A275/R2-7 | D36: अण्णाभाऊ साठे महोत्सव | F36: 2000000
A37: RE11A275/R2-8 | D37: जागतिक आदिवासी दिन | F37: 500000
A38: RE11A275/R2-11 | D38: प्रभाग क्र.३९ क धनकवडी आंबेगाव पठार मध्ये सांस्कृतिक व क्रीडा महोत्सव आयोजन करणे. | F38: 2000000
D40: यादी क्र. R2 एकूण | E40: 0 | F40: 12315000
D43: यादी क्र. R3
D44: सत्कार, अभिनंदन, पुरस्कार, बक्षिसे यासारखे कार्यक्रम साजरे करणे (यादी R3)
D45: RE11A276/R3-
A47: code | B47: ward | D47: कामाचे नाव | E47: प्रकल्पीय रक्कम | F47: तरतूद
A49: RE11A276/R3-1 | D49: गणेशोत्सव प्रशस्तिपत्रके वितरण | F49: 1000000
A50: RE11A276/R3-2 | D50: श्री संत ज्ञानेश्वर व तुकाराम महाराज पालखी स्वागत व दिंडी प्रमुखांचा स्मृतीचिन्ह देऊन सत्कार | F50: 1000000
A51: RE11A276/R3-3 | D51: प्रतिवर्षी पुणे शहरातील इयत्ता १० वी, १२ वी परिक्षेत गुणवत्ता यादीत येणार्‍या विद्यार्थ्यांचे अभिनंदन | F51: 60000
A52: RE11A276/R3-4 | D52: बालगंधर्व पुरस्कार प्रदानकरिता | F52: 500000
...

Sheet C_Revenue_Income
A1: पाणीपुरवठा व जलोत्सारण प्रकल्पांतर्गत | G1: खास निधी 'क' चा जमेचा गोषवारा व तपशील
A2: विवरण | C2: नक्की आकडा | H2: 2021-22 वर्षाचा अंदाज | J2: 2022-23 वर्षाचा अंदाज | M2: 2021-22 वर्षाच्या मान्य अंदाजाशी तुलना केलेला 2022-23 वर्षाचा मा. महा. आयुक्त यांनी सुचविलेला अंदाज
C3: 2018-19 | D3: 2019-20 | E3: 2020-21 | F3: 2020-21 शेवटची सहामाही | G3: 2021-22 पहिली सहामाही | H3: मान्य अंदाज | I3: दुरूस्त अंदाज | J3: मा. महापालिका आयुक्त यांनी सुचविलेला | K3: मा. स्थायी समितीने मान्यता दिलेला | L3: मा. महानगर- पालिकेने संमत केलेला
M5: अधिक | N5: कमी
A7: अधिनियमाप्रमाणे कमीत कमी रोख शिल्लक ठेवण्याची रक्कम जमेस धरून वर्षारंभीची शिल्लक | C7: 100000 | D7: 100000 | E7: 100000 | F7: 100000 | G7: 0 | H7: 100000 | I7: 100000 | J7: 100000 | K7: 0 | L7: 0 | M7: 0 | N7: 0
C8: 0 | D8: 0 | E8: 0 | F8: 0 | G8: 0 | H8: 0 | I8: 0 | J8: 0 | K8: 0 | L8: 0 | M8: 0 | N8: 0
A9: १. पाणीपुरवठा (अति. न.अ.) | C9: 0 | D9: 0 | E9: 0 | F9: 0 | G9: 0 | H9: 0 | I9: 0 | J9: 0 | K9: 0 | L9: 0 | M9: 0 | N9: 0
A10: क. पाणीपट्टी साधारण पाणीपट्टी (कआकसंप्र) | B10: XI12A101 | C10: 1337732647 | D10: 1606183124 | E10: 2058845761 | F10: 730437040 | G10: 1465395040 | H10: 2900000000 | I10: 2900000000 | J10: 2940000000 | K10: 0 | L10: 0 | M10: 40000000 | N10: 0
A11: ख. शासनाकडून (कआकसंप्र) | B11: XI12B101 | C11: 0 | D11: 0 | E11: 0 | F11: 0 | G11: 0 | H11: 100000 | I11: 100000 | J11: 100000 | K11: 0 | L11: 0 | M11: 0 | N11: 0
A12: च. PMPML कडील मिळकतीवरील पाणीपट्टी (कआकसंप्र) | B12: XI12F101 | C12: 0 | D12: 0 | E12: 0 | F12: 0 | G12: 0 | H12: 100000 | I12: 100000 | J12: 100000 | K12: 0 | L12: 0 | M12: 0 | N12: 0
A13: छ. जललाभ कर (Water Benefit Tax) (कआकसंप्र) | B13: XI12G101 | C13: 558386876 | D13: 579046635 | E13: 758285451 | F13: 357832166 | G13: 531045484 | H13: 1180000000 | I13: 1180000000 | J13: 965000000 | K13: 0 | L13: 0 | M13: 0 | N13: 215000000
A14: ग. पाणीपट्टी पाणीमापकानुसार (अति.न.अ.) | B14: XI12C101 | C14: 884181735 | D14: 529584384 | E14: 753359388 | F14: 535403342 | G14: 327782319 | H14: 1650000000 | I14: 1650000000 | J14: 1690000000 | K14: 0 | L14: 0 | M14: 40000000 | N14: 0
A15: ग१. मीटर पाणीपट्टी थकबाकीपोटी जमा | B15: XI12C101A | C15: 0 | D15: 0 | E15: 0 | F15: 0 | G15: 0 | H15: 1750000000 | I15: 1750000000 | J15: 70000000 | K15: 0 | L15: 0 | M15: 0 | N15: 1680000000
A16: ग२. गवनि खात्याअंतर्गत होणारी पाणीपट्टी जमा | B16: XI12C101B | C16: 14631177 | D16: 9411692 | E16: 0 | F16: 0 | G16: 0 | H16: 25000000 | I16: 25000000 | J16: 35000000 | K16: 0 | L16: 0 | M16: 10000000 | N16: 0
A17: अनधिकृत कनेक्शन नियमित करण्यापोटी जमा | B17: XI12S101 | C17: 0 | D17: 3087 | E17: 6900 | F17: 6900 | G17: 622000 | H17: 5000000 | I17: 5000000 | J17: 5000000 | K17: 0 | L17: 0 | M17: 0 | N17: 0
A18: घ. पाणीमापक भाडे | B18: XI12D101 | C18: 2741759 | D18: 0 | E18: 0 | F18: 0 | G18: 0 | H18: 2500000 | I18: 2500000 | J18: 2500000 | K18: 0 | L18: 0 | M18: 0 | N18: 0
A19: ड. नवीन नळ आकार नळदुरुस्ती व साफसफी (परतजमा) | B19: XI12E101 | C19: 6506111 | D19: 4606709 | E19: 16279484 | F19: 14505617 | G19: 28837561 | H19: 2500000 | I19: 2500000 | J19: 5000000 | K19: 0 | L19: 0 | M19: 2500000 | N19: 0
A20: ठ. कॉलनी रस्त्यावर पाईप टाकणे कामापोटी सुपरव्हिजन स्क्रुटीनी फी व अन्य जमा होणार | B20: XI12K101 | C20: 17461303 | D20: 710997 | E20: 0 | F20: 0 | G20: 23400 | H20: 30000000 | I20: 30000000 | J20: 32500000 | K20: 0 | L20: 0 | M20: 2500000 | N20: 0
A21: ढ. जलकेंद्राच्या आवारांतील निवास स्थानापोटी जमा होणारे भाडे | B21: XI12L101 | C21: 0 | D21: 0 | E21: 0 | F21: 0 | G21: 0 | H21: 1500000 | I21: 1500000 | J21: 2000000 | K21: 0 | L21: 0 | M21: 500000 | N21: 0
... A28: ण. अंदाजपत्रक 'अ' कडून वर्ग | B28: XI12M101 | C28: 1955095785 | D28: -574449956 | E28: 394235273 | F28: 394235273 | G28: 0 | H28: -1025900000 | I28: -1025900000 | J28: 3972040000 | K28: 0 | L28: 0 | M28: 4997940000 | N28: 0
C29: 0 | D29: 0 | E29: 0 | F29: 0 | G29: 0 | H29: 0 | I29: 0 | J29: 0 | K29: 0 | L29: 0 | M29: 0 | N29: 0
A30: १. बेरीज | C30: 4860707869 | D30: 2227088474 | E30: 4037494219 | F30: 2073687046 | G30: 2371937089 | H30: 6693000000 | I30: 6693000000 | J30: 9901740000 | K30: 0 | L30: 0 | M30: 3208740000 | N30: 0
C31: 0 | D31: 0 | E31: 0 | F31: 0 | G31: 0 | H31: 0 | I31: 0 | J31: 0 | K31: 0 | L31: 0 | M31: 0 | N31: 0
A32: १अ. पुणे कॅन्टोन्मेंट पाणीपुरवठा जमा (अति.न.अ.) | C32: 0 | D32: 0 | E32: 0 | F32: 0 | G32: 0 | H32: 0 | I32: 0 | J32: 0 | K32: 0 | L32: 0 | M32: 0 | N32: 0
A33: (१) पाणीमापकानुसार पाणीपट्टी | B33: XI12Q101 | C33: 164167267 | D33: 280745047 | E33: 132107578 | F33: 100938618 | G33: 110455073 | H33: 210000000 | I33: 210000000 | J33: 230000000 | K33: 0 | L33: 0 | M33: 20000000 | N33: 0
A34: (२) H.E. Factory कडून येणारी जमा | B34: XI12Q102 | C34: 50889083 | D34: 75708335 | E34: 65743017 | F34: 19697770 | G34: 29136474 | H34: 85000000 | I34: 85000000 | J34: 95000000 | K34: 0 | L34: 0 | M34: 10000000 | N34: 0
C35: 0 | D35: 0 | E35: 0 | F35: 0 | G35: 0 | H35: 0 | I35: 0 | J35: 0 | K35: 0 | L35: 0 | M35: 0 | N35: 0
A36: १अ. बेरीज | C36: 215056350 | D36: 356453382 | E36: 197850595 | F36: 120636388 | G36: 139591547 | H36: 295000000 | I36: 295000000 | J36: 325000000 | K36: 0 | L36: 0 | M36: 30000000 | N36: 0
C37: 0 | D37: 0 | E37: 0 | F37: 0 | G37: 0 | H37: 0 | I37: 0 | J37: 0 | K37: 0 | L37: 0 | M37: 0 | N37: 0
A38: पुणे शहरात तंत्रशुध्द पध्दतीने पाणीपुरवठा (24x7 समान पाणीपुरवठा योजना) योजनेंतर्गत टाक्या बांधणेसाठी अनुदान (AMRUT) | B38: ZI12A111A | C38: 308700000 | D38: 236100000 | E38: 0 | F38: 0 | G38: 0 | H38: 235900000 | I38: 235900000 | J38: 234200000 | K38: 0 | L38: 0 | M38: 0 | N38: 1700000
A39: पुणे शहरात तंत्रशुध्द पध्दतीने पाणीपुरवठा करण्याची योजना (24x7 समान पाणीपुरवठा योजना) कर्जरोखे विक्री | B39: ZI12A112 | C39: 0 | D39: 0 | E39: 0 | F39: 0 | G39: 0 | H39: 2000000000 | I39: 2000000000 | J39: 4000000000 | K39: 0 | L39: 0 | M39: 2000000000 | N39: 0
A40: पुणे शहरात तंत्रशुध्द पध्दतीने पाणीपुरवठा (24x7 समान पाणीपुरवठा योजना) योजनेंतर्गत केलेल्या कामासाठी पुणे स्मार्ट सिटीकडून प्राप्त झालेली रक्कम | B40: ZI12A113 | C40: 0 | D40: 0 | E40: 346600000 | F40: 346600000 | G40: 0 | H40: 0 | I40: 0 | J40: 0 | K40: 0 | L40: 0 | M40: 0 | N40: 0
C41: 0 | D41: 0 | E41: 0 | F41: 0 | G41: 0 | H41: 0 | I41: 0 | J41: 0 | K41: 0 | L41: 0 | M41: 0 | N41: 0
A42: राष्ट्रीय नदीसुधारणा प्रकल्पातंर्गत (JICA) केंद्र सरकारकडून अनुदान | B42: ZI12A102 | C42: 317500000 | D42: 0 | E42: 0 | F42: 0 | G42: 0 | H42: 1258000000 | I42: 1258000000 | J42: 2500000000 | K42: 0 | L42: 0 | M42: 1242000000 | N42: 0
C43: 0 | D43: 0 | E43: 0 | F43: 0 | G43: 0 | H43: 0 | I43: 0 | J43: 0 | K43: 0 | L43: 0 | M43: 0 | N43: 0
A44: १. एकूण बेरीज | C44: 5701964219 | D44: 2819641856 | E44: 4581944814 | F44: 2540923434 | G44: 2511528636 | H44: 10481900000 | I44: 10481900000 | J44: 16960940000 | K44: 0 | L44: 0 | M44: 6479040000 | N44: 0
C45: 0 | D45: 0 | E45: 0 | F45: 0 | G45: 0 | H45: 0 | I45: 0 | J45: 0 | K45: 0 | L45: 0 | M45: 0 | N45: 0
A46: २. गटारे व नाले सुधारणा (अति.न.अ.) | C46: 0 | D46: 0 | E46: 0 | F46: 0 | G46: 0 | H46: 0 | I46: 0 | J46: 0 | K46: 0 | L46: 0 | M46: 0 | N46: 0
A47: क. सफाईपट्टी (कआकसंप्र) | B47: XI23A101 | C47: 2085529792 | D47: 2141634540 | E47: 2774526408 | F47: 1317045028 | G47: 1862246673 | H47: 4350000000 | I47: 4350000000 | J47: 4020000000 | K47: 0 | L47: 0 | M47: 0 | N47: 330000000
A48: घ. सुअरेज बेनिफीट टॅक्स (कआकसंप्र) | B48: XI23D101 | C48: 961744905 | D48: 999407213 | E48: 1310741121 | F48: 621012485 | G48: 888524732 | H48: 2260000000 | I48: 2260000000 | J48: 1220000000 | K48: 0 | L48: 0 | M48: 0 | N48: 1040000000
...

Sheet C_Revenue_Expenditure
A1: योजनेतर खर्च तपशील
A2: विवरण | D2: नक्‍की आकडा | G2: मान्य अंदाज 2021-22 | H2: नवीन अंदाज 2022-23
D3: 2018-19 | E3: 2019-20 | F3: 2020-21
A5: १. पाणीपुरवठा | D5: 0 | E5: 0 | F5: 0 | G5: 0 | H5: 0
A6: क. पाणीपुरवठा | D6: 0 | E6: 0 | F6: 0 | G6: 0 | H6: 0
A7: १. मध्यवर्ती कार्यालय, कायम सेवकवर्ग वेतन | B7: XE12A101A | D7: 21639240 | E7: 22930820 | F7: 22379238 | G7: 27500000 | H7: 33990000
A8: २अ. कायम सेवकवर्ग वेतन | B8: XE12A101B | D8: 133028605 | E8: 143995350 | F8: 135107365 | G8: 160000000 | H8: 189160000
A9: २ब. कायम सेवकवर्ग वेतन (वि.का.) | B9: XE12A###A | D9: 8092170 | E9: 4911867 | F9: 6390031 | G9: 7000000 | H9: 7000000
A10: ३. संकीर्ण | B10: XE12A103 | D10: 446243 | E10: 241045 | F10: 345090 | G10: 600000 | H10: 700000
A11: ४. पाण्याची किंमत (पर्वती पंपिंग स्टेशन) | B11: XE12A104 | D11: 793046040 | E11: 714875404 | F11: 478919198 | G11: 790000000 | H11: 808500000
A12: ५. पाणी शुद्ध करणे व तद्‌नुषंगिक कामे करणे | B12: XE12A105 | D12: 50205650 | E12: 67013632 | F12: 58328083 | G12: 67500000 | H12: 85200000
A13: ६. प्रयोगशाळा देखभाल खर्च | B13: XE12A106 | D13: 0 | E13: 881357 | F13: 811793 | G13: 1500000 | H13: 1500000
A14: ७-अ. पंपिंग वीज खर्च | B14: XE12A107 | D14: 693640000 | E14: 778342594 | F14: 806361533 | G14: 801200000 | H14: 800000000
A15: ९. कोठी इतर साहित्य खर्च | B15: XE12A109 | D15: 340813 | E15: 697066 | F15: 460849 | G15: 1500000 | H15: 1000000
A16: १२. पर्वती जलकेंद्रातील यंत्रसामुग्रीवरील घसारा (मु.ले.) | B16: XE12A112 | D16: 215000 | E16: 0 | F16: 0 | G16: 0 | H16: 0
A17: १४. जलप्रदूषण प्रतिबंधक खर्च | B17: XE12A115 | D17: 0 | E17: 0 | F17: 734191 | G17: 2500000 | H17: 2500000
A18: १८. जलकेंद्र पाण्याच्या टाक्या येथे प्रकाश व्यवस्था व दूरध्वनी व्यवस्था | B18: XE12A120 | D18: 0 | E18: 0 | F18: 0 | G18: 500000 | H18: 500000
... A38: पर्वती जलकेंद्र प्रयोगशाळा येथे पाणी तपासणीसाठी लागणारी विविध उपकरणे व तद्‌नुषंगिक साहित्य खरेदी करणे | B38: XE12A146 | D38: 0 | E38: 328798 | F38: 0 | G38: 0 | H38: 0
A39: क. बेरीज | D39: 1799104371 | E39: 1835097980 | F39: 1625140673 | G39: 1994500000 | H39: 2051750000
D40: 0 | E40: 0 | F40: 0 | G40: 0 | H40: 0
A41: ख१. नळ खाते (स्वारगेट विभाग) | D41: 0 | E41: 0 | F41: 0 | G41: 0 | H41: 0
A42: १. कायम सेवक वर्ग वेतन | B42: XE12B101A | D42: 221769160 | E42: 228669863 | F42: 226930999 | G42: 270000000 | H42: 314807000
A43: २. संकीर्ण | B43: XE12B102 | D43: 463550 | E43: 323698 | F43: 353403 | G43: 300000 | H43: 300000
A44: ४. शहरांतील / नव्याने समाविष्ट गावांतील सर्व व्हॉल्व्हज्‌ चालू व बंद करणे | B44: XE12B107 | D44: 39585979 | E44: 61215355 | F44: 95825633 | G44: 60000000 | H44: 70000000
A45: ८. टँकरने पाणीपुरवठा करणे | B45: XE12B111 | D45: 14825987 | E45: 26968695 | F45: 26948995 | G45: 22000000 | H45: 22000000
A46: ९. कोठी व इतर साहित्य खरेदी | B46: XE12B112 | D46: 17886533 | E46: 19658619 | F46: 12586142 | G46: 20000000 | H46: 20000000
A47: १०. देखभाल दुरुस्ती : नळदुरुस्ती व स्वच्छता तातडीच्या दुरुस्त्या चेंबर करणे, आर.सी.सी, कव्हर बसविणे व तदनुषंगिक कामे करणे | B47: XE12B113 | D47: 47904841 | E47: 45727778 | F47: 77831942 | G47: 52000000 | H47: 60000000
A48: पाणीपुरवठा विभागाकडील देखभाल दुरूस्तीची कामे (यादी X1) | B48: XE12B115# | D48: 2634964 | E48: 0 | F48: 0 | G48: 36000000 | H48: 0
D49: 0 | E49: 0 | F49: 0 | G49: 0 | H49: 0
A50: ख१. बेरीज | D50: 345071014 | E50: 382564008 | F50: 440477114 | G50: 460300000 | H50: 487107000
D51: 0 | E51: 0 | F51: 0 | G51: 0 | H51: 0
A52: ख२. नळ खाते (विभागीय कार्यालय) | D52: 0 | E52: 0 | F52: 0 | G52: 0 | H52: 0
A53: १. कायम सेवकवर्ग वेतन | B53: XE12B###A | D53: 23964490 | E53: 22633204 | F53: 20941786 | G53: 27000000 | H53: 30993000
A54: क्षेत्रीय कार्यालयाने करावयाची योजनेतर कामे | B54: XE12B301/W6-# | D54: 943661 | E54: 2313036 | F54: 0 | G54: 1000000 | H54: 2000000
A55: क्षेत्रीय कार्यालयाने नागरिकांच्या सहभागातून करावयाची योजनेतर कामे | B55: XE12B302/C6-# | D55: 2817441 | E55: 4296733 | F55: 0 | G55: 4300000 | H55: 6550000
D56: 0 | E56: 0 | F56: 0 | G56: 0 | H56: 0
A57: ख२. बेरीज | D57: 27725592 | E57: 29242973 | F57: 20941786 | G57: 32300000 | H57: 39543000
D58: 0 | E58: 0 | F58: 0 | G58: 0 | H58: 0
A59: ख. एकूण बेरीज | D59: 372796606 | E59: 411806981 | F59: 461418900 | G59: 492600000 | H59: 526650000
D60: 0 | E60: 0 | F60: 0 | G60: 0 | H60: 0
...

Sheet C_Capital_Expenditure
A1: सन 2022-23 चे योजनांतर्गत | H1: खर्चाबाबतचे अंदाजपत्रक
A2: मान्यतेचा ठराव क्र. दिनांक (कोड) | B2: प्रभाग क्रमांक | C2: BPL | D2: कामाचे नाव अगर वर्णन | E2: दि. 31 मार्च 2022 अखेरपर्यंत केलेली तरतूद | H2: दि. 31 मार्च 2021 पर्यंतचा खर्चाचा नक्‍की आकडा | I2: 2021-22 मधील खर्चाची अंदाजी रक्कम | K2: 2022-23 साठी अधिक तरतूद | M2: 2022-23 साठी एकूण तरतूद | N2: प्रकल्पीय रक्कम
E3: कर्जातून | F3: महसूल निधीतून | G3: एकूण | I3: प्रत्यक्ष उपलब्ध तरतूद | J3: कर्जातून तरतूद | K3: कर्जातून | L3: महसूल निधी व इतर निधी
D7: 1. पाणीपुरवठा विभाग | F7: 0 | G7: 0 | H7: 0 | I7: 0 | L7: 0 | M7: 0
F8: 0 | G8: 0 | H8: 0 | I8: 0 | L8: 0 | M8: 0
A9: ZE16A103# | B9: P1- | C9: _ | D9: शहरामध्ये पाण्याच्या टाक्या बांधणे / बोअरवेल घेणे / जलशुध्दीकरण केंद्रे बांधणे आणि विद्युत / स्थापत्य / यांत्रिकीविषयक कामे करणे | F9: 557991260 | G9: 557991260 | H9: 98616001 | I9: 459375259 | L9: 384600000 | M9: 384600000
A10: ZE16A104# | B10: P2- | C10: _ | D10: शहरामध्ये पाण्याच्या लाईन टाकणे | F10: 7252192595 | G10: 7252192595 | H10: 6502125477 | I10: 750067118 | L10: 198400000 | M10: 198400000
A11: ZE16A106# | B11: _ | C11: _ | D11: शहरामध्ये पाण्याच्या टाक्या बांधणे / बोअरवेल घेणे | F11: 346015472 | G11: 346015472 | H11: 346015469 | I11: 3 | L11: 0 | M11: 0
A12: ZE16A107# | B12: _ | C12: _ | D12: शहरामध्ये जलशुध्दीकरण केंद्रे बांधणे आणि विद्युत विषयक, स्थापत्य विषयक, यांत्रिकीविषयक कामे करणे | F12: 670330361 | G12: 670330361 | H12: 598580359 | I12: 71750002 | L12: 0 | M12: 0
F13: 0 | G13: 0 | H13: 0 | I13: 0 | L13: 0 | M13: 0
D14: 1. पाणीपुरवठा विभाग एकूण बेरीज | F14: 8826529688 | G14: 8826529688 | H14: 7545337306 | I14: 1281192382 | L14: 583000000 | M14: 583000000
F15: 0 | G15: 0 | H15: 0 | I15: 0 | L15: 0 | M15: 0
F16: 0 | G16: 0 | H16: 0 | I16: 0 | L16: 0 | M16: 0
D17: 2. मलनिःसारण विभाग | F17: 0 | G17: 0 | H17: 0 | I17: 0 | L17: 0 | M17: 0
F18: 0 | G18: 0 | H18: 0 | I18: 0 | L18: 0 | M18: 0
A19: ZE16B102# | B19: D2- | C19: _ | D19: शहरामध्ये मलवाहिन्या विकसित करणे | F19: 11908710881 | G19: 11908710881 | H19: 8140284953 | I19: 3768425928 | L19: 3553600000 | M19: 3553600000
A20: ZE16B103# | B20: D3- | C20: _ | D20: शहरामध्ये नाला चॅनलायझेशन करणे / नाल्याला सिमाभिंत बांधणे व तदनुषंगिक कामे करणे | F20: 947709603 | G20: 947709603 | H20: 439631714 | I20: 508077889 | L20: 37000000 | M20: 37000000
A21: ZE16B105# | B21: D5- | C21: _ | D21: शहरामध्ये मैलापाणी शुध्दीकरण केंद्रे बांधणे आणि विद्युत / स्थापत्य / यांत्रिकीविषयक कामे करणे | F21: 333115622 | G21: 333115622 | H21: 267922800 | I21: 65192822 | L21: 16200000 | M21: 16200000
F22: 0 | G22: 0 | H22: 0 | I22: 0 | L22: 0 | M22: 0
D23: 2. मलनिःसारण विभाग एकूण बेरीज | F23: 13189536106 | G23: 13189536106 | H23: 8847839467 | I23: 4341696639 | L23: 3606800000 | M23: 3606800000
F24: 0 | G24: 0 | H24: 0 | I24: 0 | L24: 0 | M24: 0
D25: 3. पाणीपुरवठा प्रकल्प | F25: 0 | G25: 0 | H25: 0 | I25: 0 | L25: 0 | M25: 0
F26: 0 | G26: 0 | H26: 0 | I26: 0 | L26: 0 | M26: 0
A27: ZE16C101# | B27: PR1- | D27: शहरामध्ये पाणीपुरवठा प्रकल्प अंतर्गत कामे करणे | F27: 7873341271 | G27: 7873341271 | H27: 6837141228 | I27: 1036200043 | L27: 625500000 | M27: 625500000
A28: ZE16C102# | B28: _ | D28: राष्ट्रीय नदी सुधारणा योजना (JICA) | F28: 1115946204 | G28: 1115946204 | H28: 373167055 | I28: 742779149 | L28: 0 | M28: 0
A29: ZE16C103# | B29: PR3- | D29: पुणे शहरात तंत्रशुध्द पध्दतीने पाणीपुरवठा करण्याची योजना (24x7 समान पाणीपुरवठा योजना) | F29: 10293750854 | G29: 10293750854 | H29: 5420776679 | I29: 4872974175 | L29: 6000000000 | M29: 6000000000
F30: 0 | G30: 0 | H30: 0 | I30: 0 | L30: 0 | M30: 0
D31: 3. पाणीपुरवठा प्रकल्प एकूण बेरीज | F31: 19283038329 | G31: 19283038329 | H31: 12631084962 | I31: 6651953367 | L31: 6625500000 | M31: 6625500000
F32: 0 | G32: 0 | H32: 0 | I32: 0 | L32: 0 | M32: 0
D33: 4. मलनिःसारण प्रकल्प | F33: 0 | G33: 0 | H33: 0 | I33: 0 | L33: 0 | M33: 0
F34: 0 | G34: 0 | H34: 0 | I34: 0 | L34: 0 | M34: 0
A35: ZE16D102# | B35: _ | C35: _ | D35: शहरामध्ये मोठ्या व्यासाच्या मलवाहिन्या विकसित करणे | F35: 1166380684 | G35: 1166380684 | H35: 936022100 | I35: 230358584 | L35: 0 | M35: 0
A36: ZE16D103# | B36: MP3- | C36: _ | D36: शहरामध्ये मैलापाणी शुध्दीकरण केंद्र उभारणे / पंपिंग स्टेशन उभारणे | F36: 107106864 | G36: 107106864 | H36: 6106864 | I36: 101000000 | L36: 120000000 | M36: 120000000
A37: ZE16D104# | B37: MP4- | C37: _ | D37: राष्ट्रीय नदी सुधारणा योजना (JICA) | F37: 1200000000 | G37: 1200000000 | H37: 0 | I37: 1200000000 | L37: 2950000000 | M37: 2950000000
F38: 0 | G38: 0 | H38: 0 | I38: 0 | L38: 0 | M38: 0
D39: 4. मलनिःसारण प्रकल्प एकूण बेरीज | F39: 2473487548 | G39: 2473487548 | H39: 942128964 | I39: 1531358584 | L39: 3070000000 | M39: 3070000000
F40: 0 | G40: 0 | H40: 0 | I40: 0 | L40: 0 | M40: 0
D41: क्षेत्रिय कार्यालयाने करावयाची कामे | F41: 0 | G41: 0 | H41: 0 | I41: 0 | L41: 0 | M41: 0
F42: 0 | G42: 0 | H42: 0 | I42: 0 | L42: 0 | M42: 0
A43: ZE16A115# | B43: W6 | D43: क्षेत्रिय कार्यालय : पाणीपुरवठा विभागाने करावयाची कामे | F43: 111742587 | G43: 111742587 | H43: 111492587 | I43: 250000 | L43: 2750000 | M43: 2750000
...

Sheet C_List
D1: यादी क्र. X2
D2: मलनिःस्सारण विभागाकडील देखभाल दुरूस्तीची कामे
D3: XE23A117/X2-
A5: code | B5: ward | D5: कामाचे नाव | E5: प्रकल्पीय रक्कम | F5: तरतूद
A7: XE23A117/X2-386 | D7: मलनि:सारण विभागाची मागील वर्षाची पेंडिंग बिले देणे | F7: 20000000
A8: XE23A117/X2-387 | D8: मलनि:सारण विभागाची अचानक उद्भवणारी कामे करणे | F8: 20000000
A9: XE23A117/X2-401 | D9: येरवडा कळस धानोरी क्षेञिय कार्यालयाच्‍या अखत्‍यारीतील पावसाळी गटाराची साफसफाई व तद्नुषंगिक कामे करणे | F9: 5000000
A10: XE23A117/X2-402 | D10: नगररोड वडगाव शेरी क्षेञिय कार्यालयाच्‍या अखत्‍यारीतील पावसाळी गटाराची साफसफाई व तद्नुषंगिक कामे करणे | F10: 5000000
A11: XE23A117/X2-403 | D11: ढोले पाटील क्षेञिय कार्यालयाच्‍या अखत्‍यारीतील पावसाळी गटाराची साफसफाई व तद्नुषंगिक कामे करणे | F11: 5000000
A12: XE23A117/X2-404 | D12: औंध बाणेर क्षेञिय कार्यालयाच्‍या अखत्‍यारीतील पावसाळी गटाराची साफसफाई व तद्नुषंगिक कामे करणे | F12: 5000000
A13: XE23A117/X2-405 | D13: शिवाजीनगर घोले रोड क्षेञिय कार्यालयाच्‍या अखत्‍यारीतील पावसाळी गटाराची व तद्नुषंगिक कामे करणे | F13: 5000000
A14: XE23A117/X2-406 | D14: कोथरूड बावधन क्षेञिय कार्यालयाच्‍या अखत्‍यारीतील पावसाळी गटाराची साफसफाई व तद्नुषंगिक कामे करणे | F14: 5000000
A15: XE23A117/X2-407 | D15: धनकवडी सहकारनगर क्षेञिय कार्यालयाच्‍या अखत्‍यारीतील पावसाळी गटाराची साफसफाई व तद्नुषंगिक कामे करणे | F15: 5000000
A16: XE23A117/X2-408 | D16: वारजे कर्वेनगर रोड क्षेञिय कार्यालयाच्‍या अखत्‍यारीतील पावसाळी गटाराची साफसफाई व तद्नुषंगिक कामे करणे | F16: 5000000
A17: XE23A117/X2-409 | D17: सिंहगड रोड क्षेञिय कार्यालयाच्‍या अखत्‍यारीतील पावसाळी गटाराची साफसफाई व तद्नुषंगिक कामे करणे | F17: 5000000
A18: XE23A117/X2-410 | D18: कोंढवा येवलेवाडी क्षेञिय कार्यालयाच्‍या अखत्‍यारीतील पावसाळी गटाराची साफसफाई व तद्नुषंगिक कामे करणे | F18: 5000000
... A69: XE23A117/X2-461 | D69: बिबवेवाडी क्षेञिय कार्यालयाच्‍या अखत्‍यारितील ओढ्या नाल्‍यातील मलवाहिन्‍यांची देखभाल व दुरुस्‍तीची कामे करणे. | F69: 6500000
D71: यादी क्र. X2 एकूण | E71: 0 | F71: 425000000
A73: पाणीपुरवठा विभागाकडील कामाच्या याद्या
D75: यादी क्र. P1
D76: शहरामध्ये पाण्याच्या टाक्या बांधणे / बोअरवेल घेणे / जलशुध्दीकरण केंद्रे बांधणे आणि विद्युत / स्थापत्य / यांत्रिकीविषयक कामे करणे
D77: ZE16A103/P1-
A79: code | B79: ward | D79: कामाचे नाव | E79: प्रकल्पीय रक्कम | F79: तरतूद
A81: ZE16A103/P1-81 | D81: राष्ट्रीय पेयजेल कार्यक्रमाअंतर्गत महाराष्ट्र जीवन प्राधिकरणामार्फत फुरसुंगी व उरुळी देवाची येथे सुरु असलेल्या योजनेसाठी उर्वरित रक्कम देणे | F81: 62500000
A82: ZE16A103/P1-82 | D82: गांधीभवन येथे २ एम एल डी पाण्याची टाकी बांधणे | F82: 20000000
A83: ZE16A103/P1-83 | D83: लष्कर जलशुद्धीकरण केंद्राची नव्याने उभारणी करणे | F83: 20000000
A84: ZE16A103/P1-84 | D84: पर्वती येथे रॉ वॉटर पंपिंग स्टेशन उभारणे | F84: 7500000
A85: ZE16A103/P1-85 | D85: पाण्याच्या साठवण टाक्यांना आतील बाजूनी क्लोरीन प्रतिबंधक कोटिंग करणे | F85: 50000000
A86: ZE16A103/P1-86 | D86: पर्वती जलकेंद्र अंतर्गत रॉ वाटर पंपींग स्टेशन मधील जुने 3.3 केव्ही क्षमतेचे व्हीसीबी पॅनल काढून त्या जागी नवीन पॅनल बसविणे व तदनुषंगीक कामे करणे | F86: 3500000
A87: ZE16A103/P1-87 | D87: पर्वती जलकेंद्र अंतर्गत नवीन बुस्टर पंपींग यंत्रणेसाठी 10 ठिकाणी फ्लोमीटर पुरविणे व बसविणे. | F87: 2500000
A88: ZE16A103/P1-88 | D88: खोराड वस्ती येथील बुस्टर पंपींग यंत्रणा सुधारणा करणे. | F88: 2500000
A89: ZE16A103/P1-89 | D89: साईनगर येथील बुस्टर पंपींग यंत्रणा स्थलांतरीत करणे | F89: 3000000
A90: ZE16A103/P1-90 | D90: पर्वती जलकेंद्र येथील टप्पा क्र - २ फिल्टर बेंड रिग्रेडशन करणे. | F90: 5000000
A91: ZE16A103/P1-91 | D91: पर्वती जलकेंद्रामधील फिल्टरबेड मधील पाण्याची गळती थांबविणे. | F91: 2000000
A92: ZE16A103/P1-92 | D92: पर्वती जलकेंद्र मधील स्टिलिंग चेंबरची देखभाल दुरूस्ती करणे. | F92: 1000000
... A124: ZE16A103/P1-124 | D124: लष्कर जलकेंद्र अंतर्गत येणार्‍या चिखली व फुरसुंगी जलकेंद्राच्या प्रयोगशाळेसाठी विविध साहित्य पुरविणे. | F124: 2500000
D126: सन 2021-22 मधील अपूर्ण कामांसाठी सन 2022-23 मध्ये उपलब्ध केलेली तरतूद
A127: ZE16A103/P1-9 | D127: पर्वती जलकेंद्र येथे पंप हाऊस क्र.१,२ व ३ साठी ए.पी.एफ.सी. युनिट पुरविणे व बसविणे. | F127: 2000000
A128: ZE16A103/P1-12 | D128: पर्वती जलकेंद्र येथील सेकंड स्टेजकडील बेड वॉशिंगकरीता ७.५ एच.पी. क्षमतेचा कॉम्प्रेसर पुरविणे व बसविणे | F128: 1000000
A129: ZE16A103/P1-13 | D129: पर्वती जलकेंद्र येथील सेंकंड स्टेजकडील क्लॅरिफायर क्र.३ चे क्लॅरिफॉक्युलेटर, गिअर असेंब्ली पुरविणे व बसविणे | F129: 1500000
...

Sheet SMRY-2223
A1: code | B1: ward | C1: * | D1: क्षेत्रीय कार्यालयाने करावयाची कामे : सन 2022-23 | E1: पथ | F1: विद्युत | G1: भवन | H1: झोनिपु | I1: पाणीपुरवठा | J1: मलनिःसारण | K1: एकूण
D4: (आकडे लाखात) | E4: 2 | F4: 1 | G4: 4 | H4: 5 | I4: 6 | J4: 7 | K4: Total
A6: code | B6: Sr. | C6: Wards | D6: क्षेत्रीय कार्यालयाने करावयाची कामे : सन 2022-23 | E6: 2 | F6: 1 | G6: 4 | H6: 5 | I6: 6 | J6: 7 | K6: Total
B8: =WardOfficeNonPlan2223!B8 -> 1 | C8: =WardOfficeNonPlan2223!C8 -> 3, 4, 5 | D8: =WardOfficeNonPlan2223!D8 -> नगररोड - वडगावशेरी क्षेत्रीय कार्यालय एकूण बेरीज | E8: =WardOfficeNonPlan2223!E8+WardOfficePlan2223!E8+CitizensNonPlan2223!E8+CitizensPlan2223!E8 -> 237 | F8: =WardOfficeNonPlan2223!F8+WardOfficePlan2223!F8+CitizensNonPlan2223!F8+CitizensPlan2223!F8 -> 130 | G8: =WardOfficeNonPlan2223!G8+WardOfficePlan2223!G8+CitizensNonPlan2223!G8+CitizensPlan2223!G8 -> 92.5 | H8: =WardOfficeNonPlan2223!H8+WardOfficePlan2223!H8+CitizensNonPlan2223!H8+CitizensPlan2223!H8 -> 5 | I8: =WardOfficeNonPlan2223!I8+WardOfficePlan2223!I8+CitizensNonPlan2223!I8+CitizensPlan2223!I8 -> 42.5 | J8: =WardOfficeNonPlan2223!J8+WardOfficePlan2223!J8+CitizensNonPlan2223!J8+CitizensPlan2223!J8 -> 242.5 | K8: =SUM(E8:J8) -> 749.5
B9: =WardOfficeNonPlan2223!B9 -> 2 | C9: =WardOfficeNonPlan2223!C9 -> 1, 2, 6 | D9: =WardOfficeNonPlan2223!D9 -> येरवडा - कळस - धानोरी क्षेत्रीय कार्यालय एकूण बेरीज | E9: =WardOfficeNonPlan2223!E9+WardOfficePlan2223!E9+CitizensNonPlan2223!E9+CitizensPlan2223!E9 -> 211.5 | F9: =WardOfficeNonPlan2223!F9+WardOfficePlan2223!F9+CitizensNonPlan2223!F9+CitizensPlan2223!F9 -> 82.5 | G9: =WardOfficeNonPlan2223!G9+WardOfficePlan2223!G9+CitizensNonPlan2223!G9+CitizensPlan2223!G9 -> 115 | H9: =WardOfficeNonPlan2223!H9+WardOfficePlan2223!H9+CitizensNonPlan2223!H9+CitizensPlan2223!H9 -> 102.5 | I9: =WardOfficeNonPlan2223!I9+WardOfficePlan2223!I9+CitizensNonPlan2223!I9+CitizensPlan2223!I9 -> 0 | J9: =WardOfficeNonPlan2223!J9+WardOfficePlan2223!J9+CitizensNonPlan2223!J9+CitizensPlan2223!J9 -> 238.5 | K9: =SUM(E9:J9) -> 750
B10: =WardOfficeNonPlan2223!B10 -> 3 | C10: =WardOfficeNonPlan2223!C10 -> 20, 21 | D10: =WardOfficeNonPlan2223!D10 -> ढोलेपाटील क्षेत्रीय कार्यालय एकूण बेरीज | E10: =WardOfficeNonPlan2223!E10+WardOfficePlan2223!E10+CitizensNonPlan2223!E10+CitizensPlan2223!E10 -> 82.5 | F10: =WardOfficeNonPlan2223!F10+WardOfficePlan2223!F10+CitizensNonPlan2223!F10+CitizensPlan2223!F10 -> 32 | G10: =WardOfficeNonPlan2223!G10+WardOfficePlan2223!G10+CitizensNonPlan2223!G10+CitizensPlan2223!G10 -> 48 | H10: =WardOfficeNonPlan2223!H10+WardOfficePlan2223!H10+CitizensNonPlan2223!H10+CitizensPlan2223!H10 -> 160 | I10: =WardOfficeNonPlan2223!I10+WardOfficePlan2223!I10+CitizensNonPlan2223!I10+CitizensPlan2223!I10 -> 12.5 | J10: =WardOfficeNonPlan2223!J10+WardOfficePlan2223!J10+CitizensNonPlan2223!J10+CitizensPlan2223!J10 -> 90 | K10: =SUM(E10:J10) -> 425
